File: 20G1652/ST 20G1652_0018.csv
Rate 1,"1.00000",mm/s
Start date,"9/19/2021"
Specimen label,""

Time,Extension,2 kg Beam Load Cell
(s),(mm),(N)
"0.00000","0.00000","0.00055"
"0.05000","0.00000","0.00153"
"0.10000","0.01131","0.00131"
"0.15000","0.04458","0.00140"
"0.20000","0.08651","0.00192"
"0.25000","0.13393","0.00214"
"0.30000","0.18433","0.00284"
"0.35000","0.23653","0.00319"
"0.40000","0.28975","0.00414"
"0.45000","0.34370","0.00431"
"0.50000","0.39803","0.00523"
"0.55000","0.45252","0.00577"
"0.60000","0.50699","0.00611"
"0.65000","0.56133","0.00694"
"0.70000","0.61553","0.00762"
"0.75000","0.66950","0.00805"
"0.80000","0.72317","0.00877"
"0.85000","0.77655","0.00909"
"0.90000","0.82954","0.01007"
"0.95000","0.88238","0.01025"
"1.00000","0.93540","0.01088"
"1.05000","0.98834","0.01161"
"1.10000","1.04094","0.01234"
"1.15000","1.09338","0.01266"
"1.20000","1.14594","0.01312"
"1.25000","1.19824","0.01399"
"1.30000","1.25032","0.01443"
"1.35000","1.30240","0.01498"
"1.40000","1.35420","0.01566"
"1.45000","1.40586","0.01601"
"1.50000","1.45712","0.01674"
"1.55000","1.50837","0.01766"
"1.60000","1.55981","0.01782"
"1.65000","1.61113","0.01883"
"1.70000","1.66228","0.01918"
"1.75000","1.71356","0.01956"
"1.80000","1.76475","0.01998"
"1.85000","1.81577","0.02099"
"1.90000","1.86672","0.02149"
"1.95000","1.91756","0.02239"
"2.00000","1.96845","0.02271"
"2.05000","2.01906","0.02321"
"2.10000","2.06990","0.02343"
"2.15000","2.12044","0.02429"
"2.20000","2.17091","0.02479"
"2.25000","2.22138","0.02612"
"2.30000","2.27183","0.02616"
"2.35000","2.32241","0.02682"
"2.40000","2.37302","0.02737"
"2.45000","2.42345","0.02825"
"2.50000","2.47401","0.02839"
"2.55000","2.52444","0.02938"
"2.60000","2.57555","0.02970"
"2.65000","2.62511","0.03052"
"2.70000","2.67523","0.03103"
"2.75000","2.72550","0.03185"
"2.80000","2.77565","0.03227"
"2.85000","2.82591","0.03320"
"2.90000","2.87680","0.03336"
"2.95000","2.92661","0.03411"
"3.00000","2.97659","0.03469"
"3.05000","3.02682","0.03563"
"3.10000","3.07707","0.03648"
"3.15000","3.12723","0.03667"
"3.20000","3.17776","0.03742"
"3.25000","3.22873","0.03794"
"3.30000","3.27813","0.03867"
"3.35000","3.32801","0.03942"
"3.40000","3.37769","0.04028"
"3.45000","3.42769","0.04104"
"3.50000","3.47769","0.04124"
"3.55000","3.52780","0.04177"
"3.60000","3.57787","0.04252"
"3.65000","3.62822","0.04318"
"3.70000","3.67849","0.04435"
"3.75000","3.72857","0.04461"
"3.80000","3.77850","0.04542"
"3.85000","3.82855","0.04590"
"3.90000","3.87931","0.04676"
"3.95000","3.92936","0.04738"
"4.00000","3.97877","0.04831"
"4.05000","4.02860","0.04906"
"4.10000","4.07849","0.04964"
"4.15000","4.12846","0.05020"
"4.20000","4.17889","0.05091"
"4.25000","4.22874","0.05164"
"4.30000","4.27876","0.05301"
"4.35000","4.32862","0.05311"
"4.40000","4.37868","0.05403"
"4.45000","4.42867","0.05437"
"4.50000","4.47868","0.05512"
"4.55000","4.52862","0.05593"
"4.60000","4.57842","0.05714"
"4.65000","4.62826","0.05758"
"4.70000","4.67815","0.05836"
"4.75000","4.72832","0.05855"
"4.80000","4.77894","0.05968"
"4.85000","4.82932","0.06060"
"4.90000","4.87908","0.06150"
"4.95000","4.92892","0.06208"
"5.00000","4.97878","0.06303"
"5.05000","5.02883","0.06349"
"5.10000","5.07878","0.06419"
"5.15000","5.12871","0.06531"
"5.20000","5.17863","0.06601"
"5.25000","5.22924","0.06686"
"5.30000","5.27922","0.06756"
"5.35000","5.32887","0.06825"
"5.40000","5.37885","0.06909"
"5.45000","5.42886","0.07003"
"5.50000","5.47894","0.07079"
"5.55000","5.52922","0.07171"
"5.60000","5.57924","0.07246"
"5.65000","5.62898","0.07317"
"5.70000","5.67907","0.07404"
"5.75000","5.72950","0.07512"
"5.80000","5.77917","0.07574"
"5.85000","5.82895","0.07701"
"5.90000","5.87875","0.07751"
"5.95000","5.92866","0.07848"
"6.00000","5.97875","0.07897"
"6.05000","6.02965","0.08016"
"6.10000","6.07938","0.08095"
"6.15000","6.12903","0.08224"
"6.20000","6.17898","0.08266"
"6.25000","6.22914","0.08360"
"6.30000","6.27898","0.08463"
"6.35000","6.32882","0.08541"
"6.40000","6.37882","0.08632"
"6.45000","6.42927","0.08743"
"6.50000","6.47871","0.08797"
"6.55000","6.52840","0.08922"
"6.60000","6.57848","0.08991"
"6.65000","6.62863","0.09102"
"6.70000","6.67873","0.09199"
"6.75000","6.72942","0.09317"
"6.80000","6.77948","0.09380"
"6.85000","6.82909","0.09485"
"6.90000","6.87900","0.09584"
"6.95000","6.92902","0.09680"
"7.00000","6.97895","0.09775"
"7.05000","7.02873","0.09873"
"7.10000","7.07850","0.09971"
"7.15000","7.12881","0.10079"
"7.20000","7.17894","0.10168"
"7.25000","7.22876","0.10275"
"7.30000","7.27890","0.10360"
"7.35000","7.32891","0.10444"
"7.40000","7.37885","0.10540"
"7.45000","7.42887","0.10676"
"7.50000","7.47889","0.10773"
"7.55000","7.52885","0.10872"
"7.60000","7.57928","0.10998"
"7.65000","7.62900","0.11057"
"7.70000","7.67871","0.11179"
"7.75000","7.72856","0.11280"
"7.80000","7.77823","0.11421"
"7.85000","7.82808","0.11504"
"7.90000","7.87819","0.11627"
"7.95000","7.92837","0.11705"
"8.00000","7.97848","0.11827"
"8.05000","8.02888","0.11930"
"8.10000","8.07954","0.12048"
"8.15000","8.12902","0.12140"
"8.20000","8.17889","0.12272"
"8.25000","8.22886","0.12343"
"8.30000","8.27880","0.12483"
"8.35000","8.32870","0.12575"
"8.40000","8.37864","0.12732"
"8.45000","8.42847","0.12818"
"8.50000","8.47830","0.12934"
"8.55000","8.52834","0.13025"
"8.60000","8.57848","0.13171"
"8.65000","8.62870","0.13269"
"8.70000","8.67909","0.13424"
"8.75000","8.72881","0.13508"
"8.80000","8.77856","0.13639"
"8.85000","8.82847","0.13724"
"8.90000","8.87857","0.13865"
"8.95000","8.92869","0.13952"
"9.00000","8.97877","0.14100"
"9.05000","9.02872","0.14224"
"9.10000","9.07888","0.14339"
"9.15000","9.12958","0.14471"
"9.20000","9.17903","0.14598"
"9.25000","9.22877","0.14708"
"9.30000","9.27883","0.14843"
"9.35000","9.32873","0.14941"
"9.40000","9.37862","0.15067"
"9.45000","9.42857","0.15219"
"9.50000","9.47844","0.15336"
"9.55000","9.52833","0.15475"
"9.60000","9.57830","0.15594"
"9.65000","9.62827","0.15704"
"9.70000","9.67839","0.15822"
"9.75000","9.72865","0.15961"
"9.80000","9.77960","0.16094"
"9.85000","9.82905","0.16243"
"9.90000","9.87885","0.16357"
"9.95000","9.92875","0.16478"
"10.00000","9.97876","0.16601"
"10.05000","10.02873","0.16749"
"10.10000","10.07863","0.16849"
"10.15000","10.12860","0.17040"
"10.20000","10.17862","0.17127"
"10.25000","10.22870","0.17280"
"10.30000","10.27916","0.17394"
"10.35000","10.32892","0.17533"
"10.40000","10.37880","0.17660"
"10.45000","10.42875","0.17823"
"10.50000","10.47882","0.17937"
"10.55000","10.52874","0.18067"
"10.60000","10.57869","0.18193"
"10.65000","10.62873","0.18353"
"10.70000","10.67914","0.18473"
"10.75000","10.73007","0.18657"
"10.80000","10.77920","0.18731"
"10.85000","10.82893","0.18869"
"10.90000","10.87879","0.19012"
"10.95000","10.92864","0.19164"
"11.00000","10.97862","0.19299"
"11.05000","11.02853","0.19483"
"11.10000","11.07862","0.19582"
"11.15000","11.12937","0.19727"
"11.20000","11.17893","0.19825"
"11.25000","11.22871","0.19999"
"11.30000","11.27864","0.20158"
"11.35000","11.32867","0.20305"
"11.40000","11.37865","0.20411"
"11.45000","11.42869","0.20572"
"11.50000","11.47875","0.20698"
"11.55000","11.52900","0.20829"
"11.60000","11.57868","0.20998"
"11.65000","11.62846","0.21124"
"11.70000","11.67847","0.21289"
"11.75000","11.72923","0.21410"
"11.80000","11.77946","0.21563"
"11.85000","11.82885","0.21676"
"11.90000","11.87867","0.21851"
"11.95000","11.92869","0.21952"
"12.00000","11.97857","0.22099"
"12.05000","12.02862","0.22245"
"12.10000","12.07875","0.22365"
"12.15000","12.12888","0.22508"
"12.20000","12.17889","0.22683"
"12.25000","12.22874","0.22794"
"12.30000","12.27854","0.22947"
"12.35000","12.32837","0.23061"
"12.40000","12.37857","0.23216"
"12.45000","12.42964","0.23339"
"12.50000","12.47897","0.23523"
"12.55000","12.52876","0.23612"
"12.60000","12.57893","0.23788"
"12.65000","12.62903","0.23896"
"12.70000","12.67900","0.24052"
"12.75000","12.72902","0.24211"
"12.80000","12.77893","0.24369"
"12.85000","12.82882","0.24452"
"12.90000","12.87859","0.24615"
"12.95000","12.92840","0.24735"
"13.00000","12.97830","0.24885"
"13.05000","13.02862","0.25035"
"13.10000","13.07888","0.25170"
"13.15000","13.12860","0.25279"
"13.20000","13.17853","0.25479"
"13.25000","13.22851","0.25568"
"13.30000","13.27868","0.25737"
"13.35000","13.32918","0.25854"
"13.40000","13.37957","0.25989"
"13.45000","13.43061","0.26117"
"13.50000","13.47952","0.26282"
"13.55000","13.52903","0.26386"
"13.60000","13.57860","0.26530"
"13.65000","13.62835","0.26679"
"13.70000","13.67830","0.26785"
"13.75000","13.72842","0.26937"
"13.80000","13.77854","0.27053"
"13.85000","13.82888","0.27183"
"13.90000","13.87894","0.27345"
"13.95000","13.92894","0.27448"
"14.00000","13.97897","0.27577"
"14.05000","14.02880","0.27723"
"14.10000","14.07872","0.27835"
"14.15000","14.12918","0.27992"
"14.20000","14.17848","0.28134"
"14.25000","14.22821","0.28271"
"14.30000","14.27824","0.28381"
"14.35000","14.32828","0.28529"
"14.40000","14.37837","0.28624"
"14.45000","14.42857","0.28786"
"14.50000","14.47895","0.28900"
"14.55000","14.52963","0.29038"
"14.60000","14.58061","0.29149"
"14.65000","14.62978","0.29302"
"14.70000","14.67947","0.29378"
"14.75000","14.72914","0.29553"
"14.80000","14.77878","0.29651"
"14.85000","14.82848","0.29812"
"14.90000","14.87888","0.29908"
"14.95000","14.92850","0.30042"
"15.00000","14.97843","0.30116"
"15.05000","15.02853","0.30278"
"15.10000","15.07885","0.30369"
"15.15000","15.12912","0.30492"
"15.20000","15.17929","0.30618"
"15.25000","15.22911","0.30721"
"15.30000","15.27909","0.30809"
"15.35000","15.32896","0.30979"
"15.40000","15.37880","0.31062"
"15.45000","15.42858","0.31181"
"15.50000","15.47836","0.31283"
"15.55000","15.52898","0.31404"
"15.60000","15.57872","0.31522"
"15.65000","15.62850","0.31672"
"15.70000","15.67886","0.31777"
"15.75000","15.72924","0.31891"
"15.80000","15.77931","0.32027"
"15.85000","15.82928","0.32124"
"15.90000","15.87932","0.32269"
"15.95000","15.92939","0.32384"
"16.00000","15.97927","0.32516"
"16.05000","16.02896","0.32604"
"16.10000","16.07871","0.32702"
"16.15000","16.12863","0.32811"
"16.20000","16.17845","0.32959"
"16.25000","16.22839","0.33084"
"16.30000","16.27842","0.33240"
"16.35000","16.32879","0.33328"
"16.40000","16.37886","0.33447"
"16.45000","16.42924","0.33526"
"16.50000","16.48015","0.33667"
"16.55000","16.53029","0.33779"
"16.60000","16.57964","0.33952"
"16.65000","16.62936","0.34038"
"16.70000","16.67903","0.34140"
"16.75000","16.72876","0.34209"
"16.80000","16.77885","0.34356"
"16.85000","16.82879","0.34429"
"16.90000","16.87868","0.34592"
"16.95000","16.92872","0.34677"
"17.00000","16.97884","0.34777"
"17.05000","17.02887","0.34856"
"17.10000","17.07890","0.34993"
"17.15000","17.12899","0.35085"
"17.20000","17.17913","0.35252"
"17.25000","17.22931","0.35319"
"17.30000","17.27933","0.35401"
"17.35000","17.32984","0.35467"
"17.40000","17.37948","0.35579"
"17.45000","17.42905","0.35654"
"17.50000","17.47890","0.35810"
"17.55000","17.52884","0.35896"
"17.60000","17.57876","0.36008"
"17.65000","17.62882","0.36097"
"17.70000","17.67885","0.36191"
"17.75000","17.72881","0.36296"
"17.80000","17.77890","0.36425"
"17.85000","17.82898","0.36497"
"17.90000","17.87905","0.36602"
"17.95000","17.92961","0.36685"
"18.00000","17.97912","0.36767"
"18.05000","18.02883","0.36883"
"18.10000","18.07878","0.36969"
"18.15000","18.12879","0.37061"
"18.20000","18.17876","0.37134"
"18.25000","18.22880","0.37239"
"18.30000","18.27991","0.37329"
"18.35000","18.33034","0.37440"
"18.40000","18.37955","0.37522"
"18.45000","18.42943","0.37601"
"18.50000","18.47942","0.37680"
"18.55000","18.52921","0.37786"
"18.60000","18.57905","0.37853"
"18.65000","18.62883","0.37981"
"18.70000","18.67874","0.38037"
"18.75000","18.72875","0.38127"
"18.80000","18.77878","0.38177"
"18.85000","18.82894","0.38288"
"18.90000","18.87942","0.38353"
"18.95000","18.92916","0.38471"
"19.00000","18.97902","0.38498"
"19.05000","19.02908","0.38602"
"19.10000","19.07924","0.38661"
"19.15000","19.12935","0.38768"
"19.20000","19.17922","0.38821"
"19.25000","19.22910","0.38928"
"19.30000","19.27954","0.38995"
"19.35000","19.32934","0.39068"
"19.40000","19.37898","0.39153"
"19.45000","19.42899","0.39235"
"19.50000","19.47926","0.39314"
"19.55000","19.52937","0.39431"
"19.60000","19.58016","0.39465"
"19.65000","19.62948","0.39591"
"19.70000","19.67928","0.39632"
"19.75000","19.72914","0.39729"
"19.80000","19.77893","0.39819"
"19.85000","19.82866","0.39887"
"19.90000","19.87885","0.39970"
"19.95000","19.92911","0.40031"
"20.00000","19.97900","0.40114"
"20.05000","20.02895","0.40186"
"20.10000","20.07894","0.40277"
"20.15000","20.12911","0.40326"
"20.20000","20.17909","0.40378"
"20.25000","20.22924","0.40433"
"20.30000","20.27958","0.40506"
"20.35000","20.32961","0.40571"
"20.40000","20.37947","0.40687"
"20.45000","20.42926","0.40742"
"20.50000","20.47901","0.40847"
"20.55000","20.52914","0.40898"
"20.60000","20.58087","0.40950"
"20.65000","20.63052","0.40995"
"20.70000","20.67971","0.41088"
"20.75000","20.72955","0.41104"
"20.80000","20.77931","0.41221"
"20.85000","20.82920","0.41228"
"20.90000","20.87921","0.41304"
"20.95000","20.92914","0.41355"
"21.00000","20.97899","0.41431"
"21.05000","21.02893","0.41433"
"21.10000","21.07893","0.41541"
"21.15000","21.12891","0.41529"
"21.20000","21.17865","0.41622"
"21.25000","21.22858","0.41683"
"21.30000","21.27863","0.41759"
"21.35000","21.32887","0.41820"
"21.40000","21.37967","0.41910"
"21.45000","21.42978","0.41914"
"21.50000","21.47923","0.41988"
"21.55000","21.52910","0.42070"
"21.60000","21.57885","0.42130"
"21.65000","21.62877","0.42189"
"21.70000","21.67857","0.42253"
"21.75000","21.72857","0.42275"
"21.80000","21.77865","0.42347"
"21.85000","21.82864","0.42394"
"21.90000","21.87868","0.42470"
"21.95000","21.92913","0.42536"
"22.00000","21.97905","0.42587"
"22.05000","22.02920","0.42642"
"22.10000","22.07942","0.42711"
"22.15000","22.12934","0.42764"
"22.20000","22.17911","0.42832"
"22.25000","22.22896","0.42890"
"22.30000","22.27871","0.42923"
"22.35000","22.32863","0.42985"
"22.40000","22.37864","0.43045"
"22.45000","22.42868","0.43116"
"22.50000","22.47871","0.43142"
"22.55000","22.52884","0.43194"
"22.60000","22.57890","0.43189"
"22.65000","22.62948","0.43266"
"22.70000","22.67957","0.43298"
"22.75000","22.72940","0.43366"
"22.80000","22.77923","0.43402"
"22.85000","22.82909","0.43461"
"22.90000","22.87893","0.43452"
"22.95000","22.92870","0.43542"
"23.00000","22.97861","0.43566"
"23.05000","23.02852","0.43632"
"23.10000","23.07866","0.43661"
"23.15000","23.12851","0.43715"
"23.20000","23.17858","0.43721"
"23.25000","23.22852","0.43766"
"23.30000","23.27876","0.43789"
"23.35000","23.32886","0.43846"
"23.40000","23.37886","0.43882"
"23.45000","23.42893","0.43918"
"23.50000","23.47912","0.43890"
"23.55000","23.52897","0.43946"
"23.60000","23.57873","0.43958"
"23.65000","23.62855","0.44023"
"23.70000","23.67963","0.44049"
"23.75000","23.73015","0.44057"
"23.80000","23.77894","0.44085"
"23.85000","23.82881","0.44130"
"23.90000","23.87885","0.44139"
"23.95000","23.92898","0.44212"
"24.00000","23.97921","0.44234"
"24.05000","24.02929","0.44251"
"24.10000","24.07943","0.44279"
"24.15000","24.12908","0.44296"
"24.20000","24.17888","0.44313"
"24.25000","24.22860","0.44348"
"24.30000","24.27846","0.44403"
"24.35000","24.32828","0.44399"
"24.40000","24.37858","0.44399"
"24.45000","24.42855","0.44372"
"24.50000","24.47840","0.44399"
"24.55000","24.52864","0.44408"
"24.60000","24.57895","0.44440"
"24.65000","24.62915","0.44425"
"24.70000","24.67914","0.44461"
"24.75000","24.72902","0.44426"
"24.80000","24.77902","0.44490"
"24.85000","24.83016","0.44456"
"24.90000","24.87914","0.44479"
"24.95000","24.92871","0.44475"
"25.00000","24.97831","0.44484"
"25.05000","25.02811","0.44407"
"25.10000","25.07838","0.44468"
"25.15000","25.12865","0.44437"
"25.20000","25.17884","0.44485"
"25.25000","25.22898","0.44451"
"25.30000","25.27925","0.44477"
"25.35000","25.32939","0.44438"
"25.40000","25.37933","0.44470"
"25.45000","25.42911","0.44446"
"25.50000","25.47892","0.44456"
"25.55000","25.52871","0.44442"
"25.60000","25.57846","0.44478"
"25.65000","25.62835","0.44457"
"25.70000","25.67892","0.44500"
"25.75000","25.72903","0.44468"
"25.80000","25.77876","0.44512"
"25.85000","25.82888","0.44509"
"25.90000","25.87920","0.44500"
"25.95000","25.92933","0.44513"
"26.00000","25.97948","0.44523"
"26.05000","26.02965","0.44482"
"26.10000","26.07989","0.44517"
"26.15000","26.13038","0.44498"
"26.20000","26.17916","0.44500"
"26.25000","26.22868","0.44464"
"26.30000","26.27851","0.44443"
"26.35000","26.32838","0.44372"
"26.40000","26.37837","0.44347"
"26.45000","26.42867","0.44338"
"26.50000","26.47913","0.44301"
"26.55000","26.52909","0.44313"
"26.60000","26.57920","0.44277"
"26.65000","26.62922","0.44275"
"26.70000","26.67915","0.44255"
"26.75000","26.72947","0.44207"
"26.80000","26.77903","0.44096"
"26.85000","26.82859","0.44114"
"26.90000","26.87832","0.44067"
"26.95000","26.92811","0.44053"
"27.00000","26.97814","0.43966"
"27.05000","27.02828","0.43919"
"27.10000","27.07866","0.43905"
"27.15000","27.12898","0.43904"
"27.20000","27.17938","0.43831"
"27.25000","27.22957","0.43836"
"27.30000","27.27996","0.43799"
"27.35000","27.32995","0.43808"
"27.40000","27.37966","0.43764"
"27.45000","27.43027","0.43773"
"27.50000","27.47933","0.43711"
"27.55000","27.52882","0.43733"
"27.60000","27.57866","0.43710"
"27.65000","27.62861","0.43712"
"27.70000","27.67883","0.43682"
"27.75000","27.72907","0.43683"
"27.80000","27.77909","0.43620"
"27.85000","27.82937","0.43647"
"27.90000","27.87967","0.43631"
"27.95000","27.92950","0.43664"
"28.00000","27.97921","0.43652"
"28.05000","28.02912","0.43629"
"28.10000","28.07886","0.43614"
"28.15000","28.12870","0.43627"
"28.20000","28.17856","0.43625"
"28.25000","28.22848","0.43646"
"28.30000","28.27849","0.43639"
"28.35000","28.32991","0.43612"
"28.40000","28.37997","0.43596"
"28.45000","28.42946","0.43578"
"28.50000","28.47964","0.43596"
"28.55000","28.52969","0.43594"
"28.60000","28.57953","0.43628"
"28.65000","28.62961","0.43556"
"28.70000","28.67930","0.43558"
"28.75000","28.72891","0.43571"
"28.80000","28.77876","0.43598"
"28.85000","28.82870","0.43615"
"28.90000","28.87864","0.43632"
"28.95000","28.92890","0.43629"
"29.00000","28.97925","0.43698"
"29.05000","29.02917","0.43684"
"29.10000","29.08012","0.43753"
"29.15000","29.12970","0.43767"
"29.20000","29.17956","0.43812"
"29.25000","29.22939","0.43800"
"29.30000","29.27913","0.43876"
"29.35000","29.32906","0.43904"
"29.40000","29.37905","0.43952"
"29.45000","29.42908","0.43974"
"29.50000","29.47884","0.44023"
"29.55000","29.52877","0.44032"
"29.60000","29.57888","0.44090"
"29.65000","29.62912","0.44092"
"29.70000","29.67942","0.44171"
"29.75000","29.72946","0.44172"
"29.80000","29.78010","0.44227"
"29.85000","29.82980","0.44247"
"29.90000","29.88026","0.44284"
"29.95000","29.93044","0.44297"
"30.00000","29.97911","0.44340"
"30.05000","30.02878","0.44341"
"30.10000","30.07860","0.44370"
"30.15000","30.12861","0.44419"
"30.20000","30.17878","0.44465"
"30.25000","30.22895","0.44513"
"30.30000","30.27894","0.44561"
"30.35000","30.32919","0.44569"
"30.40000","30.37949","0.44585"
"30.45000","30.42969","0.44636"
"30.50000","30.47961","0.44666"
"30.55000","30.52940","0.44729"
"30.60000","30.57907","0.44775"
"30.65000","30.62873","0.44795"
"30.70000","30.67862","0.44828"
"30.75000","30.72852","0.44884"
"30.80000","30.77851","0.44908"
"30.85000","30.82887","0.44993"
"30.90000","30.87890","0.45018"
"30.95000","30.92884","0.45092"
"31.00000","30.97891","0.45120"
"31.05000","31.02919","0.45183"
"31.10000","31.07936","0.45200"
"31.15000","31.12956","0.45295"
"31.20000","31.18031","0.45316"
"31.25000","31.22905","0.45388"
"31.30000","31.27858","0.45400"
"31.35000","31.32842","0.45481"
"31.40000","31.37851","0.45524"
"31.45000","31.42829","0.45632"
"31.50000","31.47835","0.45632"
"31.55000","31.52848","0.45702"
"31.60000","31.57878","0.45731"
"31.65000","31.62912","0.45764"
"31.70000","31.67927","0.45824"
"31.75000","31.72921","0.45920"
"31.80000","31.77933","0.45941"
"31.85000","31.82908","0.46051"
"31.90000","31.87877","0.46043"
"31.95000","31.92863","0.46110"
"32.00000","31.97849","0.46159"
"32.05000","32.02833","0.46238"
"32.10000","32.07953","0.46304"
"32.15000","32.12924","0.46361"
"32.20000","32.17884","0.46405"
"32.25000","32.22896","0.46427"
"32.30000","32.27919","0.46497"
"32.35000","32.32938","0.46564"
"32.40000","32.37945","0.46639"
"32.45000","32.42929","0.46721"
"32.50000","32.47910","0.46751"
"32.55000","32.52896","0.46765"
"32.60000","32.57872","0.46803"
"32.65000","32.62868","0.46822"
"32.70000","32.67879","0.46892"
"32.75000","32.72939","0.46959"
"32.80000","32.77930","0.47004"
"32.85000","32.82938","0.47019"
"32.90000","32.87927","0.47077"
"32.95000","32.92947","0.47076"
"33.00000","32.97942","0.47185"
"33.05000","33.02936","0.47219"
"33.10000","33.08019","0.47275"
"33.15000","33.13092","0.47294"
"33.20000","33.17971","0.47370"
"33.25000","33.22918","0.47394"
"33.30000","33.27894","0.47500"
"33.35000","33.32890","0.47524"
"33.40000","33.37886","0.47603"
"33.45000","33.42925","0.47621"
"33.50000","33.47930","0.47676"
"33.55000","33.52935","0.47712"
"33.60000","33.57948","0.47807"
"33.65000","33.62962","0.47814"
"33.70000","33.67947","0.47897"
"33.75000","33.72925","0.47937"
"33.80000","33.77889","0.47991"
"33.85000","33.82871","0.48037"
"33.90000","33.87856","0.48124"
"33.95000","33.92861","0.48133"
"34.00000","33.97911","0.48222"
"34.05000","34.02919","0.48230"
"34.10000","34.07904","0.48287"
"34.15000","34.12916","0.48318"
"34.20000","34.17934","0.48411"
"34.25000","34.22926","0.48441"
"34.30000","34.27919","0.48495"
"34.35000","34.32912","0.48506"
"34.40000","34.37904","0.48543"
"34.45000","34.42884","0.48606"
"34.50000","34.47867","0.48679"
"34.55000","34.52869","0.48707"
"34.60000","34.57882","0.48766"
"34.65000","34.62879","0.48794"
"34.70000","34.67883","0.48808"
"34.75000","34.72948","0.48872"
"34.80000","34.78109","0.48899"
"34.85000","34.83009","0.48942"
"34.90000","34.87967","0.48929"
"34.95000","34.92940","0.48973"
"35.00000","34.97927","0.48940"
"35.05000","35.02931","0.48926"
"35.10000","35.07890","0.48851"
"35.15000","35.12867","0.48819"
"35.20000","35.17866","0.48743"
"35.25000","35.22864","0.48525"
"35.30000","35.27874","0.48389"
"35.35000","35.32929","0.48365"
"35.40000","35.37923","0.48281"
"35.45000","35.42915","0.48285"
"35.50000","35.47903","0.48245"
"35.55000","35.52906","0.48215"
"35.60000","35.57915","0.48169"
"35.65000","35.62922","0.48159"
"35.70000","35.67907","0.48117"
"35.75000","35.72883","0.48120"
"35.80000","35.77872","0.48063"
"35.85000","35.82871","0.48029"
"35.90000","35.87891","0.47999"
"35.95000","35.93103","0.47999"
"36.00000","35.98030","0.47967"
"36.05000","36.02967","0.47961"
"36.10000","36.07946","0.47916"
"36.15000","36.12939","0.47884"
"36.20000","36.17936","0.47840"
"36.25000","36.22931","0.47850"
"36.30000","36.27980","0.47825"
"36.35000","36.32973","0.47850"
"36.40000","36.37914","0.47786"
"36.45000","36.42903","0.47763"
"36.50000","36.47912","0.47743"
"36.55000","36.52906","0.47706"
"36.60000","36.57972","0.47687"
"36.65000","36.62959","0.47612"
"36.70000","36.67923","0.47564"
"36.75000","36.72915","0.47479"
"36.80000","36.77901","0.47450"
"36.85000","36.82903","0.47381"
"36.90000","36.87908","0.47380"
"36.95000","36.92916","0.47325"
"37.00000","36.98005","0.47274"
"37.05000","37.03038","0.47241"
"37.10000","37.07948","0.47201"
"37.15000","37.12909","0.47151"
"37.20000","37.17894","0.47146"
"37.25000","37.22894","0.47055"
"37.30000","37.27899","0.47062"
"37.35000","37.32901","0.46988"
"37.40000","37.37910","0.46940"
"37.45000","37.42935","0.46846"
"37.50000","37.47910","0.46820"
"37.55000","37.52900","0.46711"
"37.60000","37.57885","0.46655"
"37.65000","37.62886","0.46556"
"37.70000","37.67896","0.46519"
"37.75000","37.72898","0.46436"
"37.80000","37.77887","0.46432"
"37.85000","37.82895","0.46323"
"37.90000","37.87883","0.46324"
"37.95000","37.92900","0.46237"
"38.00000","37.97899","0.46178"
"38.05000","38.02971","0.46124"
"38.10000","38.08095","0.46083"
"38.15000","38.13009","0.46013"
"38.20000","38.17960","0.45963"
"38.25000","38.22921","0.45871"
"38.30000","38.27900","0.45809"
"38.35000","38.32879","0.45737"
"38.40000","38.37883","0.45692"
"38.45000","38.42886","0.45628"
"38.50000","38.47906","0.45555"
"38.55000","38.52935","0.45473"
"38.60000","38.58025","0.45373"
"38.65000","38.62942","0.45325"
"38.70000","38.67891","0.45209"
"38.75000","38.72880","0.45145"
"38.80000","38.77870","0.45007"
"38.85000","38.82874","0.44890"
"38.90000","38.87871","0.44762"
"38.95000","38.92840","0.44647"
"39.00000","38.97829","0.44453"
"39.05000","39.02821","0.44374"
"39.10000","39.07872","0.44219"
"39.15000","39.12965","0.44099"
"39.20000","39.17910","0.43969"
"39.25000","39.22904","0.43892"
"39.30000","39.27896","0.43703"
"39.35000","39.32885","0.43575"
"39.40000","39.37889","0.43355"
"39.45000","39.42922","0.43198"
"39.50000","39.47984","0.43065"
"39.55000","39.52893","0.42969"
"39.60000","39.57862","0.42796"
"39.65000","39.62864","0.42663"
"39.70000","39.67883","0.42495"
"39.75000","39.72891","0.42370"
"39.80000","39.77895","0.42215"
"39.85000","39.82892","0.42078"
"39.90000","39.87893","0.41892"
"39.95000","39.92902","0.41757"
"40.00000","39.97987","0.41542"
"40.05000","40.03021","0.41386"
"40.10000","40.07936","0.41211"
"40.15000","40.12902","0.41039"
"40.20000","40.17874","0.40834"
"40.25000","40.22859","0.40640"
"40.30000","40.27869","0.40404"
"40.35000","40.32894","0.40231"
"40.40000","40.37867","0.40027"
"40.45000","40.42875","0.39788"
"40.50000","40.47887","0.39547"
"40.55000","40.52885","0.39228"
"40.60000","40.57880","0.38941"
"40.65000","40.63012","0.38604"
"40.70000","40.67943","0.38285"
"40.75000","40.72892","0.37883"
"40.80000","40.77863","0.37533"
"40.85000","40.82853","0.37204"
"40.90000","40.87850","0.36920"
"40.95000","40.92854","0.36612"
"41.00000","40.97855","0.36281"
"41.05000","41.02900","0.35954"
"41.10000","41.07930","0.35647"
"41.15000","41.12876","0.35283"
"41.20000","41.17865","0.34987"
"41.25000","41.22861","0.34649"
"41.30000","41.27866","0.34325"
"41.35000","41.32924","0.33968"
"41.40000","41.37870","0.33618"
"41.45000","41.42867","0.33191"
"41.50000","41.47856","0.32831"
"41.55000","41.52847","0.32408"
"41.60000","41.57853","0.31991"
"41.65000","41.62891","0.31518"
"41.70000","41.67871","0.30988"
"41.75000","41.72860","0.30025"
"41.80000","41.77878","0.27851"
"41.85000","41.82884","0.26495"
"41.90000","41.87859","0.25511"
"41.95000","41.92856","0.23039"
"42.00000","41.97859","0.21750"
"42.05000","42.02874","0.20548"
"42.10000","42.07867","0.19536"
"42.15000","42.12864","0.18725"
"42.20000","42.17951","0.17959"
"42.25000","42.22975","0.17102"
"42.30000","42.27978","0.16259"
"42.35000","42.32951","0.15554"
"42.40000","42.37892","0.14837"
"42.45000","42.42871","0.14129"
"42.50000","42.47860","0.13762"
"42.55000","42.52851","0.13341"
"42.60000","42.57846","0.12929"
"42.65000","42.62849","0.12419"
"42.70000","42.67862","0.12129"
"42.75000","42.72877","0.11867"
"42.80000","42.77855","0.11613"
"42.85000","42.82837","0.11366"
"42.90000","42.87838","0.11129"
"42.95000","42.92847","0.10946"
"43.00000","42.97860","0.10725"
"43.05000","43.02842","0.10548"
"43.10000","43.07822","0.10352"
"43.15000","43.12820","0.10158"
"43.20000","43.17834","0.09950"
"43.25000","43.22871","0.09788"
"43.30000","43.27999","0.09528"
"43.35000","43.32927","0.09317"
"43.40000","43.37894","0.09080"
"43.45000","43.42872","0.08844"
"43.50000","43.47865","0.08466"
"43.55000","43.52855","0.08006"
"43.60000","43.57864","0.07448"
"43.65000","43.62858","0.02230"
"43.70000","43.67844","-0.02121"
"43.75000","43.72826","-0.01614"
"43.80000","43.77836","-0.01750"
"43.85000","43.82956","-0.01628"
"43.90000","43.87953","-0.01738"
"43.95000","43.92904","-0.01619"
"44.00000","43.97886","-0.01724"
"44.05000","44.02874","-0.01637"
"44.10000","44.07867","-0.01719"
"44.15000","44.12869","-0.01632"
"44.20000","44.17863","-0.01704"
"44.25000","44.22858","-0.01647"
"44.30000","44.27848","-0.01705"
"44.35000","44.32829","-0.01689"
"44.40000","44.37858","-0.01681"
"44.45000","44.42961","-0.01685"
"44.50000","44.47897","-0.01699"
"44.55000","44.52871","-0.01674"
"44.60000","44.57866","-0.01740"
"44.65000","44.62862","-0.01675"
"44.70000","44.67852","-0.01691"
"44.75000","44.72858","-0.01676"
"44.80000","44.77850","-0.01709"
"44.85000","44.82858","-0.01707"
"44.90000","44.87874","-0.01701"
"44.95000","44.92857","-0.01702"
"45.00000","44.97850","-0.01676"
"45.05000","45.02843","-0.01697"
"45.10000","45.07867","-0.01716"
"45.15000","45.12879","-0.01711"
"45.20000","45.17863","-0.01704"
"45.25000","45.22853","-0.01703"
"45.30000","45.27855","-0.01678"
"45.35000","45.32874","-0.01717"
"45.40000","45.37999","-0.01691"
"45.45000","45.42945","-0.01712"
"45.50000","45.47912","-0.01701"
"45.55000","45.52889","-0.01688"
"45.60000","45.57861","-0.01698"
"45.65000","45.62855","-0.01715"
"45.70000","45.67840","-0.01700"
"45.75000","45.72840","-0.01727"
"45.80000","45.77839","-0.01679"
"45.85000","45.82838","-0.01696"
"45.90000","45.87851","-0.01671"
"45.95000","45.92846","-0.01734"
"46.00000","45.97845","-0.01702"
"46.05000","46.02849","-0.01682"
"46.10000","46.07830","-0.01665"
"46.15000","46.12842","-0.01716"
"46.20000","46.17843","-0.01709"
"46.25000","46.22828","-0.01738"
"46.30000","46.27944","-0.01729"
"46.35000","46.32980","-0.01710"
"46.40000","46.37915","-0.01675"
"46.45000","46.42887","-0.01705"
"46.50000","46.47885","-0.01679"
"46.55000","46.52868","-0.01724"
"46.60000","46.57850","-0.01714"
"46.65000","46.62853","-0.01716"
"46.70000","46.67853","-0.01690"
"46.75000","46.72856","-0.01705"
"46.80000","46.77867","-0.01693"
"46.85000","46.82962","-0.01720"
"46.90000","46.87930","-0.01738"
"46.95000","46.92878","-0.01710"
"47.00000","46.97860","-0.01683"
"47.05000","47.02853","-0.01694"
"47.10000","47.07858","-0.01698"
"47.15000","47.12847","-0.01688"
"47.20000","47.17840","-0.01743"
"47.25000","47.22867","-0.01691"
"47.30000","47.27945","-0.01695"
"47.35000","47.32896","-0.01687"
"47.40000","47.37881","-0.01692"
"47.45000","47.42854","-0.01694"
"47.50000","47.47836","-0.01718"
"47.55000","47.52824","-0.01705"
"47.60000","47.57842","-0.01702"
"47.65000","47.62843","-0.01688"
"47.70000","47.67867","-0.01700"
"47.75000","47.72965","-0.01689"
"47.80000","47.77907","-0.01730"
"47.85000","47.82872","-0.01660"
"47.90000","47.87862","-0.01685"
"47.95000","47.92867","-0.01666"
"48.00000","47.97876","-0.01702"
"48.05000","48.02872","-0.01704"
"48.10000","48.07869","-0.01721"
"48.15000","48.12871","-0.01685"
"48.20000","48.17933","-0.01717"
"48.25000","48.22918","-0.01666"
"48.30000","48.27875","-0.01681"
"48.35000","48.32866","-0.01691"
"48.40000","48.37866","-0.01715"
"48.45000","48.42853","-0.01667"
"48.50000","48.47844","-0.01695"
"48.55000","48.52853","-0.01657"
"48.60000","48.57858","-0.01690"
"48.65000","48.62847","-0.01715"
"48.70000","48.67845","-0.01701"
"48.75000","48.72840","-0.01696"
"48.80000","48.77838","-0.01681"
"48.85000","48.82836","-0.01647"
"48.90000","48.87951","-0.01686"
"48.95000","48.92928","-0.01706"
"49.00000","48.97874","-0.01697"
"49.05000","49.02857","-0.01687"
"49.10000","49.07839","-0.01681"
"49.15000","49.12835","-0.01669"
"49.20000","49.17826","-0.01683"
"49.25000","49.22821","-0.01705"
"49.30000","49.27858","-0.01688"
"49.35000","49.32939","-0.01718"
"49.40000","49.37919","-0.01662"
"49.45000","49.42886","-0.01664"
"49.50000","49.47871","-0.01661"
"49.55000","49.52848","-0.01714"
"49.60000","49.57832","-0.01697"
"49.65000","49.62834","-0.01723"
"49.70000","49.67841","-0.01667"
"49.73500","49.71335","-0.01665"