File: 20G1652/ST 20G1652_00014.csv
Rate 1,"0.10000",mm/s
Start date,"9/25/2021"
Specimen label,""

Time,Extension,2 kg Beam Load Cell
(s),(mm),(N)
"0.00000","0.00000","-0.00084"
"0.17500","0.00000","-0.00071"
"0.35000","0.01895","-0.00051"
"0.52500","0.03953","-0.00041"
"0.70000","0.05921","-0.00029"
"0.87500","0.07858","-0.00022"
"1.05000","0.09738","0.00003"
"1.22500","0.11586","0.00016"
"1.40000","0.13425","0.00033"
"1.57500","0.15239","0.00064"
"1.75000","0.17049","0.00073"
"1.92500","0.18839","0.00091"
"2.10000","0.20633","0.00095"
"2.27500","0.22398","0.00124"
"2.45000","0.24173","0.00107"
"2.62500","0.25944","0.00120"
"2.80000","0.27702","0.00119"
"2.97500","0.29458","0.00173"
"3.15000","0.31206","0.00172"
"3.32500","0.32962","0.00173"
"3.50000","0.34702","0.00197"
"3.67500","0.36462","0.00212"
"3.85000","0.38212","0.00196"
"4.02500","0.39978","0.00257"
"4.20000","0.41721","0.00257"
"4.37500","0.43475","0.00245"
"4.55000","0.45223","0.00290"
"4.72500","0.46971","0.00291"
"4.90000","0.48719","0.00288"
"5.07500","0.50474","0.00269"
"5.25000","0.52233","0.00311"
"5.42500","0.53981","0.00343"
"5.60000","0.55816","0.00334"
"5.77500","0.57471","0.00335"
"5.95000","0.59216","0.00369"
"6.12500","0.60960","0.00383"
"6.30000","0.62716","0.00365"
"6.47500","0.64477","0.00396"
"6.65000","0.66232","0.00399"
"6.82500","0.67983","0.00419"
"7.00000","0.69720","0.00406"
"7.17500","0.71475","0.00453"
"7.35000","0.73212","0.00455"
"7.52500","0.74974","0.00455"
"7.70000","0.76720","0.00472"
"7.87500","0.78476","0.00490"
"8.05000","0.80222","0.00505"
"8.22500","0.81974","0.00507"
"8.40000","0.83718","0.00524"
"8.57500","0.85465","0.00567"
"8.75000","0.87225","0.00558"
"8.92500","0.88981","0.00566"
"9.10000","0.90734","0.00569"
"9.27500","0.92483","0.00587"
"9.45000","0.94231","0.00588"
"9.62500","0.95982","0.00585"
"9.80000","0.97721","0.00616"
"9.97500","0.99474","0.00627"
"10.15000","1.01230","0.00620"
"10.32500","1.02987","0.00652"
"10.50000","1.04731","0.00661"
"10.67500","1.06482","0.00658"
"10.85000","1.08226","0.00672"
"11.02500","1.09979","0.00713"
"11.20000","1.11724","0.00707"
"11.37500","1.13483","0.00698"
"11.55000","1.15241","0.00726"
"11.72500","1.16987","0.00731"
"11.90000","1.18741","0.00733"
"12.07500","1.20479","0.00751"
"12.25000","1.22232","0.00780"
"12.42500","1.23977","0.00782"
"12.60000","1.25736","0.00796"
"12.77500","1.27580","0.00819"
"12.95000","1.29240","0.00837"
"13.12500","1.30974","0.00834"
"13.30000","1.32720","0.00813"
"13.47500","1.34476","0.00847"
"13.65000","1.36219","0.00851"
"13.82500","1.37974","0.00866"
"14.00000","1.39729","0.00891"
"14.17500","1.41483","0.00909"
"14.35000","1.43236","0.00908"
"14.52500","1.44972","0.00916"
"14.70000","1.46723","0.00948"
"14.87500","1.48467","0.00959"
"15.05000","1.50222","0.00968"
"15.22500","1.51974","0.00989"
"15.40000","1.53729","0.01009"
"15.57500","1.55476","0.01002"
"15.75000","1.57226","0.01014"
"15.92500","1.58974","0.01036"
"16.10000","1.60724","0.01037"
"16.27500","1.62479","0.01029"
"16.45000","1.64232","0.01035"
"16.62500","1.65991","0.01070"
"16.80000","1.67867","0.01065"
"16.97500","1.69490","0.01077"
"17.15000","1.71215","0.01108"
"17.32500","1.72967","0.01140"
"17.50000","1.74719","0.01140"
"17.67500","1.76480","0.01131"
"17.85000","1.78239","0.01150"
"18.02500","1.79991","0.01167"
"18.20000","1.81754","0.01147"
"18.37500","1.83481","0.01189"
"18.55000","1.85237","0.01192"
"18.72500","1.86984","0.01198"
"18.90000","1.88743","0.01222"
"19.07500","1.90499","0.01257"
"19.25000","1.92243","0.01245"
"19.42500","1.93996","0.01257"
"19.60000","1.95736","0.01274"
"19.77500","1.97484","0.01298"
"19.95000","1.99225","0.01310"
"20.12500","2.00984","0.01309"
"20.30000","2.02736","0.01319"
"20.47500","2.04487","0.01325"
"20.65000","2.06237","0.01312"
"20.82500","2.07977","0.01338"
"21.00000","2.09731","0.01368"
"21.17500","2.11470","0.01377"
"21.35000","2.13224","0.01395"
"21.52500","2.14977","0.01423"
"21.70000","2.16733","0.01421"
"21.87500","2.18486","0.01414"
"22.05000","2.20230","0.01448"
"22.22500","2.21992","0.01460"
"22.40000","2.23763","0.01459"
"22.57500","2.25469","0.01471"
"22.75000","2.27222","0.01498"
"22.92500","2.28985","0.01495"
"23.10000","2.30734","0.01530"
"23.27500","2.32479","0.01531"
"23.45000","2.34225","0.01553"
"23.62500","2.35971","0.01559"
"23.80000","2.37723","0.01560"
"23.97500","2.39483","0.01582"
"24.15000","2.41238","0.01578"
"24.32500","2.42992","0.01602"
"24.50000","2.44741","0.01609"
"24.67500","2.46489","0.01650"
"24.85000","2.48239","0.01656"
"25.02500","2.49982","0.01666"
"25.20000","2.51741","0.01665"
"25.37500","2.53494","0.01667"
"25.55000","2.55242","0.01687"
"25.72500","2.56993","0.01703"
"25.90000","2.58733","0.01743"
"26.07500","2.60480","0.01740"
"26.25000","2.62224","0.01757"
"26.42500","2.63977","0.01780"
"26.60000","2.65732","0.01783"
"26.77500","2.67508","0.01773"
"26.95000","2.69225","0.01797"
"27.12500","2.70963","0.01810"
"27.30000","2.72723","0.01833"
"27.47500","2.74462","0.01845"
"27.65000","2.76224","0.01871"
"27.82500","2.77971","0.01881"
"28.00000","2.79733","0.01854"
"28.17500","2.81482","0.01893"
"28.35000","2.83224","0.01915"
"28.52500","2.84979","0.01906"
"28.70000","2.86726","0.01915"
"28.87500","2.88482","0.01961"
"29.05000","2.90232","0.01963"
"29.22500","2.91988","0.01977"
"29.40000","2.93735","0.01989"
"29.57500","2.95487","0.02008"
"29.75000","2.97229","0.02006"
"29.92500","2.98985","0.02034"
"30.10000","3.00726","0.02041"
"30.27500","3.02483","0.02046"
"30.45000","3.04244","0.02063"
"30.62500","3.05996","0.02078"
"30.80000","3.07742","0.02095"
"30.97500","3.09483","0.02106"
"31.15000","3.11236","0.02124"
"31.32500","3.12977","0.02148"
"31.50000","3.14741","0.02144"
"31.67500","3.16606","0.02141"
"31.85000","3.18252","0.02173"
"32.02500","3.19987","0.02179"
"32.20000","3.21728","0.02180"
"32.37500","3.23480","0.02196"
"32.55000","3.25219","0.02233"
"32.72500","3.26984","0.02251"
"32.90000","3.28738","0.02262"
"33.07500","3.30490","0.02291"
"33.25000","3.32232","0.02297"
"33.42500","3.33975","0.02291"
"33.60000","3.35729","0.02290"
"33.77500","3.37470","0.02314"
"33.95000","3.39222","0.02320"
"34.12500","3.40975","0.02339"
"34.30000","3.42735","0.02368"
"34.47500","3.44481","0.02381"
"34.65000","3.46234","0.02380"
"34.82500","3.48014","0.02394"
"35.00000","3.49723","0.02415"
"35.17500","3.51473","0.02419"
"35.35000","3.53228","0.02449"
"35.52500","3.54985","0.02452"
"35.70000","3.56731","0.02460"
"35.87500","3.58487","0.02473"
"36.05000","3.60226","0.02505"
"36.22500","3.61983","0.02513"
"36.40000","3.63730","0.02522"
"36.57500","3.65486","0.02533"
"36.75000","3.67240","0.02574"
"36.92500","3.68990","0.02586"
"37.10000","3.70743","0.02598"
"37.27500","3.72484","0.02608"
"37.45000","3.74238","0.02612"
"37.62500","3.75979","0.02622"
"37.80000","3.77742","0.02632"
"37.97500","3.79489","0.02666"
"38.15000","3.81243","0.02675"
"38.32500","3.82994","0.02682"
"38.50000","3.84734","0.02704"
"38.67500","3.86563","0.02724"
"38.85000","3.88234","0.02727"
"39.02500","3.89972","0.02756"
"39.20000","3.91719","0.02757"
"39.37500","3.93478","0.02788"
"39.55000","3.95233","0.02790"
"39.72500","3.96974","0.02778"
"39.90000","3.98728","0.02798"
"40.07500","4.00476","0.02815"
"40.25000","4.02225","0.02850"
"40.42500","4.03977","0.02866"
"40.60000","4.05738","0.02872"
"40.77500","4.07484","0.02891"
"40.95000","4.09233","0.02911"
"41.12500","4.10979","0.02938"
"41.30000","4.12725","0.02928"
"41.47500","4.14479","0.02942"
"41.65000","4.16231","0.02968"
"41.82500","4.17992","0.02976"
"42.00000","4.19742","0.02982"
"42.17500","4.21495","0.03004"
"42.35000","4.23254","0.02994"
"42.52500","4.24977","0.03020"
"42.70000","4.26717","0.03056"
"42.87500","4.28474","0.03060"
"43.05000","4.30238","0.03077"
"43.22500","4.31990","0.03088"
"43.40000","4.33744","0.03107"
"43.57500","4.35482","0.03105"
"43.75000","4.37239","0.03134"
"43.92500","4.38978","0.03145"
"44.10000","4.40738","0.03146"
"44.27500","4.42489","0.03163"
"44.45000","4.44244","0.03182"
"44.62500","4.45992","0.03211"
"44.80000","4.47733","0.03213"
"44.97500","4.49485","0.03226"
"45.15000","4.51224","0.03241"
"45.32500","4.52980","0.03231"
"45.50000","4.54732","0.03269"
"45.67500","4.56496","0.03295"
"45.85000","4.58240","0.03298"
"46.02500","4.59985","0.03297"
"46.20000","4.61749","0.03326"
"46.37500","4.63461","0.03335"
"46.55000","4.65215","0.03340"
"46.72500","4.66967","0.03377"
"46.90000","4.68735","0.03399"
"47.07500","4.70481","0.03429"
"47.25000","4.72234","0.03410"
"47.42500","4.73984","0.03434"
"47.60000","4.75731","0.03463"
"47.77500","4.77479","0.03453"
"47.95000","4.79238","0.03473"
"48.12500","4.80991","0.03470"
"48.30000","4.82739","0.03515"
"48.47500","4.84492","0.03526"
"48.65000","4.86235","0.03556"
"48.82500","4.87991","0.03554"
"49.00000","4.89733","0.03565"
"49.17500","4.91487","0.03582"
"49.35000","4.93242","0.03608"
"49.52500","4.94992","0.03593"
"49.70000","4.96743","0.03629"
"49.87500","4.98483","0.03642"
"50.05000","5.00238","0.03659"
"50.22500","5.01979","0.03686"
"50.40000","5.03742","0.03707"
"50.57500","5.05493","0.03715"
"50.75000","5.07249","0.03732"
"50.92500","5.08998","0.03744"
"51.10000","5.10733","0.03766"
"51.27500","5.12488","0.03780"
"51.45000","5.14223","0.03776"
"51.62500","5.15986","0.03804"
"51.80000","5.17735","0.03819"
"51.97500","5.19494","0.03812"
"52.15000","5.21239","0.03830"
"52.32500","5.22983","0.03867"
"52.50000","5.24730","0.03862"
"52.67500","5.26476","0.03899"
"52.85000","5.28224","0.03924"
"53.02500","5.29980","0.03933"
"53.20000","5.31754","0.03940"
"53.37500","5.33524","0.03957"
"53.55000","5.35228","0.03978"
"53.72500","5.36966","0.03987"
"53.90000","5.38721","0.04023"
"54.07500","5.40470","0.04027"
"54.25000","5.42229","0.04029"
"54.42500","5.43989","0.04041"
"54.60000","5.45736","0.04075"
"54.77500","5.47488","0.04094"
"54.95000","5.49235","0.04079"
"55.12500","5.50986","0.04110"
"55.30000","5.52728","0.04140"
"55.47500","5.54484","0.04152"
"55.65000","5.56240","0.04171"
"55.82500","5.57989","0.04202"
"56.00000","5.59743","0.04213"
"56.17500","5.61481","0.04209"
"56.35000","5.63236","0.04234"
"56.52500","5.64979","0.04257"
"56.70000","5.66735","0.04255"
"56.87500","5.68494","0.04295"
"57.05000","5.70241","0.04323"
"57.22500","5.71993","0.04322"
"57.40000","5.73738","0.04327"
"57.57500","5.75485","0.04339"
"57.75000","5.77228","0.04360"
"57.92500","5.78980","0.04375"
"58.10000","5.80731","0.04391"
"58.27500","5.82493","0.04433"
"58.45000","5.84239","0.04427"
"58.62500","5.85985","0.04451"
"58.80000","5.87731","0.04481"
"58.97500","5.89476","0.04492"
"59.15000","5.91227","0.04490"
"59.32500","5.92979","0.04503"
"59.50000","5.94739","0.04543"
"59.67500","5.96485","0.04543"
"59.85000","5.98243","0.04552"
"60.02500","6.00118","0.04584"
"60.20000","6.01734","0.04596"
"60.37500","6.03464","0.04606"
"60.55000","6.05222","0.04636"
"60.72500","6.06981","0.04668"
"60.90000","6.08731","0.04668"
"61.07500","6.10486","0.04676"
"61.25000","6.12226","0.04694"
"61.42500","6.13981","0.04708"
"61.60000","6.15724","0.04712"
"61.77500","6.17482","0.04749"
"61.95000","6.19238","0.04766"
"62.12500","6.20991","0.04792"
"62.30000","6.22740","0.04806"
"62.47500","6.24480","0.04817"
"62.65000","6.26235","0.04829"
"62.82500","6.27982","0.04843"
"63.00000","6.29738","0.04870"
"63.17500","6.31490","0.04888"
"63.35000","6.33248","0.04889"
"63.52500","6.35002","0.04910"
"63.70000","6.36736","0.04943"
"63.87500","6.38485","0.04967"
"64.05000","6.40224","0.04952"
"64.22500","6.41979","0.04971"
"64.40000","6.43730","0.04971"
"64.57500","6.45495","0.04990"
"64.75000","6.47238","0.05055"
"64.92500","6.48987","0.05065"
"65.10000","6.50734","0.05065"
"65.27500","6.52476","0.05092"
"65.45000","6.54229","0.05101"
"65.62500","6.55984","0.05101"
"65.80000","6.57739","0.05105"
"65.97500","6.59488","0.05130"
"66.15000","6.61242","0.05167"
"66.32500","6.62977","0.05188"
"66.50000","6.64731","0.05200"
"66.67500","6.66475","0.05218"
"66.85000","6.68231","0.05241"
"67.02500","6.69988","0.05241"
"67.20000","6.71735","0.05286"
"67.37500","6.73487","0.05293"
"67.55000","6.75228","0.05281"
"67.72500","6.76986","0.05330"
"67.90000","6.78734","0.05345"
"68.07500","6.80490","0.05357"
"68.25000","6.82243","0.05386"
"68.42500","6.83994","0.05411"
"68.60000","6.85872","0.05412"
"68.77500","6.87483","0.05426"
"68.95000","6.89221","0.05445"
"69.12500","6.90972","0.05482"
"69.30000","6.92726","0.05470"
"69.47500","6.94482","0.05507"
"69.65000","6.96231","0.05521"
"69.82500","6.97985","0.05528"
"70.00000","6.99728","0.05538"
"70.17500","7.01482","0.05558"
"70.35000","7.03221","0.05583"
"70.52500","7.04977","0.05597"
"70.70000","7.06726","0.05622"
"70.87500","7.08486","0.05656"
"71.05000","7.10235","0.05649"
"71.22500","7.11984","0.05663"
"71.40000","7.13729","0.05729"
"71.57500","7.15473","0.05699"
"71.75000","7.17228","0.05731"
"71.92500","7.18973","0.05749"
"72.10000","7.20736","0.05764"
"72.27500","7.22482","0.05762"
"72.45000","7.24232","0.05790"
"72.62500","7.25972","0.05814"
"72.80000","7.27725","0.05851"
"72.97500","7.29474","0.05855"
"73.15000","7.31225","0.05878"
"73.32500","7.32980","0.05906"
"73.50000","7.34729","0.05895"
"73.67500","7.36483","0.05929"
"73.85000","7.38222","0.05929"
"74.02500","7.39984","0.05946"
"74.20000","7.41727","0.05964"
"74.37500","7.43481","0.05999"
"74.55000","7.45238","0.06009"
"74.72500","7.46989","0.06010"
"74.90000","7.48739","0.06045"
"75.07500","7.50480","0.06055"
"75.25000","7.52237","0.06073"
"75.42500","7.53978","0.06100"
"75.60000","7.55740","0.06134"
"75.77500","7.57488","0.06126"
"75.95000","7.59249","0.06124"
"76.12500","7.60996","0.06165"
"76.30000","7.62744","0.06198"
"76.47500","7.64503","0.06211"
"76.65000","7.66219","0.06226"
"76.82500","7.67968","0.06253"
"77.00000","7.69716","0.06266"
"77.17500","7.71484","0.06259"
"77.35000","7.73227","0.06292"
"77.52500","7.74980","0.06321"
"77.70000","7.76726","0.06322"
"77.87500","7.78471","0.06355"
"78.05000","7.80219","0.06371"
"78.22500","7.81977","0.06387"
"78.40000","7.83737","0.06406"
"78.57500","7.85485","0.06435"
"78.75000","7.87234","0.06434"
"78.92500","7.88974","0.06448"
"79.10000","7.90734","0.06489"
"79.27500","7.92475","0.06502"
"79.45000","7.94232","0.06526"
"79.62500","7.95988","0.06531"
"79.80000","7.97742","0.06559"
"79.97500","7.99488","0.06570"
"80.15000","8.01227","0.06580"
"80.32500","8.02985","0.06595"
"80.50000","8.04725","0.06631"
"80.67500","8.06486","0.06642"
"80.85000","8.08237","0.06674"
"81.02500","8.09993","0.06701"
"81.20000","8.11744","0.06689"
"81.37500","8.13487","0.06711"
"81.55000","8.15238","0.06727"
"81.72500","8.16976","0.06748"
"81.90000","8.18735","0.06774"
"82.07500","8.20484","0.06794"
"82.25000","8.22239","0.06819"
"82.42500","8.23985","0.06827"
"82.60000","8.25731","0.06857"
"82.77500","8.27481","0.06881"
"82.95000","8.29223","0.06876"
"83.12500","8.30982","0.06895"
"83.30000","8.32736","0.06914"
"83.47500","8.34493","0.06954"
"83.65000","8.36237","0.06938"
"83.82500","8.37983","0.06973"
"84.00000","8.39729","0.07023"
"84.17500","8.41477","0.07009"
"84.35000","8.43228","0.07034"
"84.52500","8.44976","0.07068"
"84.70000","8.46738","0.07098"
"84.87500","8.48482","0.07093"
"85.05000","8.50235","0.07112"
"85.22500","8.51981","0.07150"
"85.40000","8.53737","0.07145"
"85.57500","8.55481","0.07170"
"85.75000","8.57239","0.07203"
"85.92500","8.59043","0.07212"
"86.10000","8.60739","0.07233"
"86.27500","8.62482","0.07269"
"86.45000","8.64219","0.07279"
"86.62500","8.65971","0.07283"
"86.80000","8.67717","0.07326"
"86.97500","8.69474","0.07342"
"87.15000","8.71228","0.07360"
"87.32500","8.72980","0.07385"
"87.50000","8.74728","0.07397"
"87.67500","8.76469","0.07412"
"87.85000","8.78231","0.07424"
"88.02500","8.79973","0.07438"
"88.20000","8.81727","0.07493"
"88.37500","8.83476","0.07484"
"88.55000","8.85236","0.07540"
"88.72500","8.86984","0.07535"
"88.90000","8.88726","0.07568"
"89.07500","8.90475","0.07568"
"89.25000","8.92222","0.07603"
"89.42500","8.93978","0.07609"
"89.60000","8.95725","0.07607"
"89.77500","8.97491","0.07642"
"89.95000","8.99230","0.07656"
"90.12500","9.00986","0.07702"
"90.30000","9.02726","0.07711"
"90.47500","9.04475","0.07732"
"90.65000","9.06222","0.07750"
"90.82500","9.07983","0.07755"
"91.00000","9.09738","0.07784"
"91.17500","9.11485","0.07808"
"91.35000","9.13239","0.07806"
"91.52500","9.14987","0.07849"
"91.70000","9.16803","0.07862"
"91.87500","9.18477","0.07893"
"92.05000","9.20225","0.07902"
"92.22500","9.21982","0.07928"
"92.40000","9.23734","0.07936"
"92.57500","9.25483","0.07942"
"92.75000","9.27225","0.07970"
"92.92500","9.28980","0.08008"
"93.10000","9.30723","0.08026"
"93.27500","9.32481","0.08048"
"93.45000","9.34231","0.08086"
"93.62500","9.35983","0.08084"
"93.80000","9.37739","0.08098"
"93.97500","9.39478","0.08110"
"94.15000","9.41234","0.08144"
"94.32500","9.42974","0.08158"
"94.50000","9.44731","0.08194"
"94.67500","9.46478","0.08213"
"94.85000","9.48238","0.08229"
"95.02500","9.49981","0.08241"
"95.20000","9.51729","0.08305"
"95.37500","9.53478","0.08295"
"95.55000","9.55223","0.08301"
"95.72500","9.56976","0.08321"
"95.90000","9.58725","0.08350"
"96.07500","9.60487","0.08378"
"96.25000","9.62236","0.08403"
"96.42500","9.63985","0.08437"
"96.60000","9.65733","0.08445"
"96.77500","9.67479","0.08446"
"96.95000","9.69222","0.08470"
"97.12500","9.70980","0.08494"
"97.30000","9.72736","0.08506"
"97.47500","9.74485","0.08534"
"97.65000","9.76233","0.08560"
"97.82500","9.77975","0.08591"
"98.00000","9.79734","0.08582"
"98.17500","9.81473","0.08603"
"98.35000","9.83231","0.08620"
"98.52500","9.84987","0.08631"
"98.70000","9.86738","0.08665"
"98.87500","9.88492","0.08682"
"99.05000","9.90229","0.08695"
"99.22500","9.91980","0.08741"
"99.40000","9.93721","0.08781"
"99.57500","9.95482","0.08764"
"99.75000","9.97235","0.08776"
"99.92500","9.98990","0.08800"
"100.10000","10.00739","0.08797"
"100.27500","10.02485","0.08843"
"100.45000","10.04235","0.08859"
"100.62500","10.05972","0.08887"
"100.80000","10.07731","0.08904"
"100.97500","10.09485","0.08915"
"101.15000","10.11242","0.08955"
"101.32500","10.12987","0.08955"
"101.50000","10.14736","0.08994"
"101.67500","10.16668","0.08995"
"101.85000","10.18243","0.09031"
"102.02500","10.19961","0.09025"
"102.20000","10.21716","0.09053"
"102.37500","10.23474","0.09074"
"102.55000","10.25221","0.09094"
"102.72500","10.26969","0.09120"
"102.90000","10.28716","0.09140"
"103.07500","10.30471","0.09170"
"103.25000","10.32222","0.09170"
"103.42500","10.33982","0.09203"
"103.60000","10.35740","0.09231"
"103.77500","10.37489","0.09265"
"103.95000","10.39237","0.09240"
"104.12500","10.40975","0.09279"
"104.30000","10.42729","0.09290"
"104.47500","10.44469","0.09302"
"104.65000","10.46231","0.09311"
"104.82500","10.47993","0.09337"
"105.00000","10.49743","0.09341"
"105.17500","10.51492","0.09386"
"105.35000","10.53226","0.09415"
"105.52500","10.54978","0.09425"
"105.70000","10.56721","0.09428"
"105.87500","10.58478","0.09467"
"106.05000","10.60232","0.09475"
"106.22500","10.61988","0.09476"
"106.40000","10.63737","0.09499"
"106.57500","10.65484","0.09532"
"106.75000","10.67227","0.09543"
"106.92500","10.68976","0.09563"
"107.10000","10.70730","0.09605"
"107.27500","10.72483","0.09615"
"107.45000","10.74244","0.09608"
"107.62500","10.75989","0.09633"
"107.80000","10.77732","0.09655"
"107.97500","10.79478","0.09667"
"108.15000","10.81226","0.09673"
"108.32500","10.83058","0.09697"
"108.50000","10.84738","0.09719"
"108.67500","10.86475","0.09715"
"108.85000","10.88227","0.09730"
"109.02500","10.89974","0.09767"
"109.20000","10.91718","0.09778"
"109.37500","10.93468","0.09794"
"109.55000","10.95221","0.09847"
"109.72500","10.96977","0.09847"
"109.90000","10.98738","0.09861"
"110.07500","11.00490","0.09883"
"110.25000","11.02239","0.09899"
"110.42500","11.03983","0.09895"
"110.60000","11.05734","0.09918"
"110.77500","11.07477","0.09946"
"110.95000","11.09237","0.09954"
"111.12500","11.10990","0.09972"
"111.30000","11.12740","0.10007"
"111.47500","11.14492","0.10018"
"111.65000","11.16227","0.10032"
"111.82500","11.17977","0.10055"
"112.00000","11.19722","0.10084"
"112.17500","11.21480","0.10085"
"112.35000","11.23236","0.10112"
"112.52500","11.24989","0.10131"
"112.70000","11.26744","0.10151"
"112.87500","11.28500","0.10168"
"113.05000","11.30223","0.10195"
"113.22500","11.31970","0.10197"
"113.40000","11.33723","0.10218"
"113.57500","11.35480","0.10246"
"113.75000","11.37241","0.10280"
"113.92500","11.38985","0.10278"
"114.10000","11.40728","0.10306"
"114.27500","11.42473","0.10333"
"114.45000","11.44219","0.10332"
"114.62500","11.45971","0.10340"
"114.80000","11.47723","0.10373"
"114.97500","11.49482","0.10393"
"115.15000","11.51230","0.10408"
"115.32500","11.52978","0.10458"
"115.50000","11.54719","0.10477"
"115.67500","11.56473","0.10469"
"115.85000","11.58222","0.10497"
"116.02500","11.59974","0.10520"
"116.20000","11.61738","0.10538"
"116.37500","11.63484","0.10530"
"116.55000","11.65255","0.10577"
"116.72500","11.66972","0.10604"
"116.90000","11.68731","0.10604"
"117.07500","11.70474","0.10627"
"117.25000","11.72227","0.10644"
"117.42500","11.73982","0.10654"
"117.60000","11.75738","0.10663"
"117.77500","11.77487","0.10699"
"117.95000","11.79227","0.10710"
"118.12500","11.80987","0.10749"
"118.30000","11.82725","0.10768"
"118.47500","11.84485","0.10778"
"118.65000","11.86255","0.10777"
"118.82500","11.87990","0.10793"
"119.00000","11.89738","0.10823"
"119.17500","11.91480","0.10838"
"119.35000","11.93233","0.10850"
"119.52500","11.94975","0.10917"
"119.70000","11.96731","0.10937"
"119.87500","11.98480","0.10925"
"120.05000","12.00242","0.10940"
"120.22500","12.01988","0.10958"
"120.40000","12.03738","0.10993"
"120.57500","12.05480","0.11015"
"120.75000","12.07232","0.11045"
"120.92500","12.08982","0.11046"
"121.10000","12.10744","0.11059"
"121.27500","12.12491","0.11086"
"121.45000","12.14240","0.11132"
"121.62500","12.16066","0.11131"
"121.80000","12.17717","0.11146"
"121.97500","12.19467","0.11165"
"122.15000","12.21215","0.11194"
"122.32500","12.22976","0.11190"
"122.50000","12.24736","0.11227"
"122.67500","12.26481","0.11249"
"122.85000","12.28232","0.11246"
"123.02500","12.29978","0.11277"
"123.20000","12.31728","0.11297"
"123.37500","12.33471","0.11297"
"123.55000","12.35230","0.11320"
"123.72500","12.36984","0.11364"
"123.90000","12.38740","0.11391"
"124.07500","12.40489","0.11405"
"124.25000","12.42227","0.11426"
"124.42500","12.43980","0.11437"
"124.60000","12.45723","0.11456"
"124.77500","12.47484","0.11466"
"124.95000","12.49232","0.11483"
"125.12500","12.50992","0.11494"
"125.30000","12.52740","0.11506"
"125.47500","12.54479","0.11536"
"125.65000","12.56232","0.11552"
"125.82500","12.57978","0.11571"
"126.00000","12.59728","0.11596"
"126.17500","12.61481","0.11626"
"126.35000","12.63240","0.11622"
"126.52500","12.64988","0.11648"
"126.70000","12.66734","0.11664"
"126.87500","12.68482","0.11665"
"127.05000","12.70234","0.11671"
"127.22500","12.71992","0.11689"
"127.40000","12.73716","0.11715"
"127.57500","12.75479","0.11726"
"127.75000","12.77232","0.11763"
"127.92500","12.78983","0.11778"
"128.10000","12.80724","0.11792"
"128.27500","12.82475","0.11799"
"128.45000","12.84226","0.11834"
"128.62500","12.85978","0.11830"
"128.80000","12.87739","0.11833"
"128.97500","12.89485","0.11865"
"129.15000","12.91241","0.11887"
"129.32500","12.92975","0.11887"
"129.50000","12.94734","0.11916"
"129.67500","12.96472","0.11927"
"129.85000","12.98233","0.11964"
"130.02500","12.99981","0.11983"
"130.20000","13.01737","0.12008"
"130.37500","13.03488","0.11991"
"130.55000","13.05232","0.12011"
"130.72500","13.06980","0.12027"
"130.90000","13.08724","0.12056"
"131.07500","13.10484","0.12054"
"131.25000","13.12235","0.12088"
"131.42500","13.13988","0.12095"
"131.60000","13.15735","0.12130"
"131.77500","13.17483","0.12128"
"131.95000","13.19229","0.12134"
"132.12500","13.20977","0.12155"
"132.30000","13.22731","0.12162"
"132.47500","13.24508","0.12196"
"132.65000","13.26227","0.12204"
"132.82500","13.27970","0.12215"
"133.00000","13.29726","0.12230"
"133.17500","13.31467","0.12264"
"133.35000","13.33222","0.12292"
"133.52500","13.34971","0.12280"
"133.70000","13.36728","0.12310"
"133.87500","13.38483","0.12322"
"134.05000","13.40237","0.12330"
"134.22500","13.41988","0.12343"
"134.40000","13.43727","0.12356"
"134.57500","13.45481","0.12376"
"134.75000","13.47222","0.12378"
"134.92500","13.48982","0.12405"
"135.10000","13.50738","0.12433"
"135.27500","13.52487","0.12423"
"135.45000","13.54239","0.12466"
"135.62500","13.55976","0.12473"
"135.80000","13.57734","0.12513"
"135.97500","13.59472","0.12493"
"136.15000","13.61232","0.12524"
"136.32500","13.62985","0.12522"
"136.50000","13.64747","0.12534"
"136.67500","13.66500","0.12551"
"136.85000","13.68235","0.12582"
"137.02500","13.69993","0.12582"
"137.20000","13.71727","0.12605"
"137.37500","13.73483","0.12635"
"137.55000","13.75234","0.12636"
"137.72500","13.76995","0.12641"
"137.90000","13.78739","0.12666"
"138.07500","13.80488","0.12680"
"138.25000","13.82242","0.12685"
"138.42500","13.83998","0.12721"
"138.60000","13.85744","0.12726"
"138.77500","13.87462","0.12734"
"138.95000","13.89228","0.12753"
"139.12500","13.90980","0.12771"
"139.30000","13.92731","0.12784"
"139.47500","13.94477","0.12778"
"139.65000","13.96230","0.12830"
"139.82500","13.97974","0.12852"
"140.00000","13.99733","0.12857"
"140.17500","14.01491","0.12861"
"140.35000","14.03235","0.12885"
"140.52500","14.04989","0.12889"
"140.70000","14.06728","0.12906"
"140.87500","14.08493","0.12932"
"141.05000","14.10224","0.12928"
"141.22500","14.11974","0.12932"
"141.40000","14.13735","0.12953"
"141.57500","14.15488","0.12981"
"141.75000","14.17241","0.12976"
"141.92500","14.18983","0.13020"
"142.10000","14.20736","0.13039"
"142.27500","14.22476","0.13030"
"142.45000","14.24234","0.13050"
"142.62500","14.25981","0.13067"
"142.80000","14.27739","0.13078"
"142.97500","14.29488","0.13065"
"143.15000","14.31233","0.13102"
"143.32500","14.32979","0.13098"
"143.50000","14.34726","0.13135"
"143.67500","14.36611","0.13158"
"143.85000","14.38228","0.13170"
"144.02500","14.39983","0.13157"
"144.20000","14.41733","0.13167"
"144.37500","14.43478","0.13206"
"144.55000","14.45228","0.13198"
"144.72500","14.46972","0.13216"
"144.90000","14.48720","0.13244"
"145.07500","14.50475","0.13286"
"145.25000","14.52233","0.13275"
"145.42500","14.53979","0.13269"
"145.60000","14.55747","0.13297"
"145.77500","14.57473","0.13299"
"145.95000","14.59225","0.13311"
"146.12500","14.60976","0.13347"
"146.30000","14.62732","0.13357"
"146.47500","14.64485","0.13348"
"146.65000","14.66228","0.13367"
"146.82500","14.67985","0.13383"
"147.00000","14.69725","0.13375"
"147.17500","14.71485","0.13393"
"147.35000","14.73223","0.13403"
"147.52500","14.74978","0.13437"
"147.70000","14.76735","0.13461"
"147.87500","14.78485","0.13470"
"148.05000","14.80231","0.13474"
"148.22500","14.81975","0.13479"
"148.40000","14.83729","0.13484"
"148.57500","14.85471","0.13521"
"148.75000","14.87236","0.13507"
"148.92500","14.88990","0.13529"
"149.10000","14.90745","0.13569"
"149.27500","14.92490","0.13555"
"149.45000","14.94235","0.13569"
"149.62500","14.95980","0.13578"
"149.80000","14.97718","0.13583"
"149.97500","14.99477","0.13600"
"150.15000","15.01429","0.13621"
"150.32500","15.02991","0.13643"
"150.50000","15.04717","0.13638"
"150.67500","15.06470","0.13653"
"150.85000","15.08220","0.13670"
"151.02500","15.09972","0.13673"
"151.20000","15.11725","0.13679"
"151.37500","15.13478","0.13707"
"151.55000","15.15240","0.13719"
"151.72500","15.16986","0.13740"
"151.90000","15.18737","0.13757"
"152.07500","15.20490","0.13797"
"152.25000","15.22229","0.13776"
"152.42500","15.23976","0.13779"
"152.60000","15.25728","0.13789"
"152.77500","15.27486","0.13825"
"152.95000","15.29230","0.13833"
"153.12500","15.30986","0.13819"
"153.30000","15.32722","0.13854"
"153.47500","15.34479","0.13874"
"153.65000","15.36217","0.13867"
"153.82500","15.37980","0.13915"
"154.00000","15.39727","0.13914"
"154.17500","15.41611","0.13925"
"154.35000","15.43225","0.13956"
"154.52500","15.44959","0.13937"
"154.70000","15.46725","0.13956"
"154.87500","15.48468","0.13954"
"155.05000","15.50233","0.13984"
"155.22500","15.51982","0.13999"
"155.40000","15.53736","0.13999"
"155.57500","15.55486","0.14009"
"155.75000","15.57230","0.13992"
"155.92500","15.58979","0.14001"
"156.10000","15.60728","0.14022"
"156.27500","15.62483","0.14037"
"156.45000","15.64233","0.14030"
"156.62500","15.65990","0.14029"
"156.80000","15.67734","0.14056"
"156.97500","15.69481","0.14037"
"157.15000","15.71232","0.14070"
"157.32500","15.72975","0.14065"
"157.50000","15.74731","0.14101"
"157.67500","15.76479","0.14097"
"157.85000","15.78247","0.14122"
"158.02500","15.79991","0.14149"
"158.20000","15.81773","0.14140"
"158.37500","15.83487","0.14134"
"158.55000","15.85238","0.14135"
"158.72500","15.86980","0.14132"
"158.90000","15.88736","0.14130"
"159.07500","15.90491","0.14138"
"159.25000","15.92237","0.14167"
"159.42500","15.93986","0.14171"
"159.60000","15.95728","0.14177"
"159.77500","15.97482","0.14186"
"159.95000","15.99219","0.14185"
"160.12500","16.00981","0.14188"
"160.30000","16.02735","0.14196"
"160.47500","16.04489","0.14218"
"160.65000","16.06239","0.14207"
"160.82500","16.07979","0.14219"
"161.00000","16.09735","0.14248"
"161.17500","16.11484","0.14221"
"161.35000","16.13230","0.14238"
"161.52500","16.14981","0.14252"
"161.70000","16.16735","0.14231"
"161.87500","16.18485","0.14241"
"162.05000","16.20226","0.14249"
"162.22500","16.21977","0.14250"
"162.40000","16.23724","0.14236"
"162.57500","16.25481","0.14243"
"162.75000","16.27227","0.14258"
"162.92500","16.28989","0.14264"
"163.10000","16.30731","0.14278"
"163.27500","16.32483","0.14283"
"163.45000","16.34229","0.14295"
"163.62500","16.35983","0.14283"
"163.80000","16.37737","0.14307"
"163.97500","16.39498","0.14329"
"164.15000","16.41242","0.14314"
"164.32500","16.43095","0.14313"
"164.50000","16.44727","0.14319"
"164.67500","16.46466","0.14333"
"164.85000","16.48221","0.14317"
"165.02500","16.49966","0.14343"
"165.20000","16.51725","0.14367"
"165.37500","16.53487","0.14369"
"165.55000","16.55226","0.14391"
"165.72500","16.56984","0.14404"
"165.90000","16.58720","0.14392"
"166.07500","16.60472","0.14414"
"166.25000","16.62214","0.14437"
"166.42500","16.63972","0.14435"
"166.60000","16.65721","0.14419"
"166.77500","16.67475","0.14448"
"166.95000","16.69226","0.14454"
"167.12500","16.70967","0.14451"
"167.30000","16.72728","0.14478"
"167.47500","16.74472","0.14477"
"167.65000","16.76230","0.14489"
"167.82500","16.77978","0.14491"
"168.00000","16.79740","0.14512"
"168.17500","16.81490","0.14514"
"168.35000","16.83236","0.14519"
"168.52500","16.84982","0.14521"
"168.70000","16.86725","0.14537"
"168.87500","16.88482","0.14550"
"169.05000","16.90235","0.14561"
"169.22500","16.91994","0.14585"
"169.40000","16.93736","0.14571"
"169.57500","16.95483","0.14578"
"169.75000","16.97231","0.14587"
"169.92500","16.98979","0.14589"
"170.10000","17.00736","0.14600"
"170.27500","17.02483","0.14616"
"170.45000","17.04242","0.14639"
"170.62500","17.05986","0.14628"
"170.80000","17.07737","0.14640"
"170.97500","17.09485","0.14640"
"171.15000","17.11239","0.14651"
"171.32500","17.12983","0.14641"
"171.50000","17.14884","0.14681"
"171.67500","17.16482","0.14678"
"171.85000","17.18227","0.14696"
"172.02500","17.19982","0.14711"
"172.20000","17.21722","0.14720"
"172.37500","17.23476","0.14727"
"172.55000","17.25222","0.14724"
"172.72500","17.26973","0.14733"
"172.90000","17.28726","0.14740"
"173.07500","17.30479","0.14731"
"173.25000","17.32229","0.14769"
"173.42500","17.33974","0.14766"
"173.60000","17.35725","0.14769"
"173.77500","17.37472","0.14815"
"173.95000","17.39224","0.14812"
"174.12500","17.40978","0.14815"
"174.30000","17.42742","0.14799"
"174.47500","17.44488","0.14794"
"174.65000","17.46230","0.14813"
"174.82500","17.47984","0.14798"
"175.00000","17.49727","0.14831"
"175.17500","17.51479","0.14837"
"175.35000","17.53230","0.14839"
"175.52500","17.54990","0.14822"
"175.70000","17.56736","0.14857"
"175.87500","17.58487","0.14849"
"176.05000","17.60229","0.14845"
"176.22500","17.61980","0.14875"
"176.40000","17.63732","0.14882"
"176.57500","17.65492","0.14883"
"176.75000","17.67251","0.14900"
"176.92500","17.68988","0.14912"
"177.10000","17.70742","0.14892"
"177.27500","17.72482","0.14902"
"177.45000","17.74237","0.14936"
"177.62500","17.75980","0.14928"
"177.80000","17.77732","0.14911"
"177.97500","17.79491","0.14933"
"178.15000","17.81238","0.14931"
"178.32500","17.82990","0.14947"
"178.50000","17.84725","0.14933"
"178.67500","17.86475","0.14940"
"178.85000","17.88219","0.14941"
"179.02500","17.89975","0.14952"
"179.20000","17.91733","0.14934"
"179.37500","17.93482","0.14928"
"179.55000","17.95236","0.14937"
"179.72500","17.96977","0.14960"
"179.90000","17.98724","0.14943"
"180.07500","18.00468","0.14960"
"180.25000","18.02227","0.14962"
"180.42500","18.03986","0.14960"
"180.60000","18.05743","0.14964"
"180.77500","18.07597","0.14954"
"180.95000","18.09218","0.14968"
"181.12500","18.10970","0.14986"
"181.30000","18.12718","0.14950"
"181.47500","18.14478","0.14975"
"181.65000","18.16230","0.14966"
"181.82500","18.17991","0.14988"
"182.00000","18.19738","0.14992"
"182.17500","18.21491","0.15015"
"182.35000","18.23235","0.15006"
"182.52500","18.24984","0.15013"
"182.70000","18.26734","0.15049"
"182.87500","18.28486","0.15042"
"183.05000","18.30244","0.15033"
"183.22500","18.31984","0.15034"
"183.40000","18.33745","0.15077"
"183.57500","18.35489","0.15059"
"183.75000","18.37242","0.15071"
"183.92500","18.38980","0.15103"
"184.10000","18.40731","0.15087"
"184.27500","18.42489","0.15098"
"184.45000","18.44239","0.15107"
"184.62500","18.45991","0.15111"
"184.80000","18.47730","0.15118"
"184.97500","18.49480","0.15119"
"185.15000","18.51220","0.15125"
"185.32500","18.52980","0.15120"
"185.50000","18.54733","0.15109"
"185.67500","18.56487","0.15130"
"185.85000","18.58237","0.15140"
"186.02500","18.59981","0.15151"
"186.20000","18.61734","0.15143"
"186.37500","18.63470","0.15167"
"186.55000","18.65226","0.15151"
"186.72500","18.66978","0.15161"
"186.90000","18.68737","0.15173"
"187.07500","18.70486","0.15152"
"187.25000","18.72232","0.15162"
"187.42500","18.73979","0.15174"
"187.60000","18.75726","0.15183"
"187.77500","18.77479","0.15195"
"187.95000","18.79235","0.15202"
"188.12500","18.80997","0.15197"
"188.30000","18.82741","0.15203"
"188.47500","18.84490","0.15217"
"188.65000","18.86231","0.15235"
"188.82500","18.87987","0.15241"
"189.00000","18.89730","0.15232"
"189.17500","18.91484","0.15243"
"189.35000","18.93245","0.15253"
"189.52500","18.94995","0.15222"
"189.70000","18.96744","0.15243"
"189.87500","18.98482","0.15269"
"190.05000","19.00236","0.15257"
"190.22500","19.01980","0.15261"
"190.40000","19.03731","0.15269"
"190.57500","19.05490","0.15282"
"190.75000","19.07237","0.15263"
"190.92500","19.08990","0.15294"
"191.10000","19.10727","0.15282"
"191.27500","19.12491","0.15295"
"191.45000","19.14274","0.15286"
"191.62500","19.16009","0.15266"
"191.80000","19.17721","0.15274"
"191.97500","19.19477","0.15285"
"192.15000","19.21226","0.15285"
"192.32500","19.22972","0.15293"
"192.50000","19.24718","0.15281"
"192.67500","19.26465","0.15295"
"192.85000","19.28221","0.15303"
"193.02500","19.29971","0.15314"
"193.20000","19.31732","0.15298"
"193.37500","19.33479","0.15317"
"193.55000","19.35238","0.15333"
"193.72500","19.36974","0.15338"
"193.90000","19.38719","0.15320"
"194.07500","19.40471","0.15330"
"194.25000","19.42230","0.15320"
"194.42500","19.43990","0.15326"
"194.60000","19.45740","0.15362"
"194.77500","19.47493","0.15353"
"194.95000","19.49233","0.15347"
"195.12500","19.50985","0.15368"
"195.30000","19.52728","0.15366"
"195.47500","19.54483","0.15374"
"195.65000","19.56244","0.15377"
"195.82500","19.57991","0.15368"
"196.00000","19.59741","0.15365"
"196.17500","19.61481","0.15374"
"196.35000","19.63235","0.15384"
"196.52500","19.64974","0.15371"
"196.70000","19.66730","0.15377"
"196.87500","19.68526","0.15375"
"197.05000","19.70237","0.15351"
"197.22500","19.71983","0.15352"
"197.40000","19.73718","0.15339"
"197.57500","19.75475","0.15367"
"197.75000","19.77218","0.15349"
"197.92500","19.78983","0.15352"
"198.10000","19.80733","0.15365"
"198.27500","19.82487","0.15338"
"198.45000","19.84235","0.15336"
"198.62500","19.85975","0.15332"
"198.80000","19.87725","0.15348"
"198.97500","19.89473","0.15342"
"199.15000","19.91226","0.15322"
"199.32500","19.92977","0.15329"
"199.50000","19.94863","0.15290"
"199.67500","19.96497","0.15302"
"199.85000","19.98220","0.15307"
"200.02500","19.99966","0.15279"
"200.20000","20.01716","0.15275"
"200.37500","20.03471","0.15276"
"200.55000","20.05226","0.15274"
"200.72500","20.06986","0.15220"
"200.90000","20.08737","0.15216"
"201.07500","20.10494","0.15201"
"201.25000","20.12230","0.15170"
"201.42500","20.13980","0.15135"
"201.60000","20.15728","0.15108"
"201.77500","20.17481","0.15099"
"201.95000","20.19238","0.15069"
"202.12500","20.20986","0.15074"
"202.30000","20.22741","0.15084"
"202.47500","20.24483","0.15045"
"202.65000","20.26236","0.15043"
"202.82500","20.27979","0.15023"
"203.00000","20.29729","0.15003"
"203.17500","20.31489","0.14983"
"203.35000","20.33240","0.14968"
"203.52500","20.34990","0.14932"
"203.70000","20.36740","0.14874"
"203.87500","20.38485","0.14853"
"204.05000","20.40219","0.14840"
"204.22500","20.41980","0.14813"
"204.40000","20.43729","0.14777"
"204.57500","20.45487","0.14745"
"204.75000","20.47234","0.14716"
"204.92500","20.49027","0.14693"
"205.10000","20.50746","0.14685"
"205.27500","20.52458","0.14676"
"205.45000","20.54211","0.14647"
"205.62500","20.55965","0.14649"
"205.80000","20.57733","0.14621"
"205.97500","20.59484","0.14605"
"206.15000","20.61235","0.14587"
"206.32500","20.62982","0.14587"
"206.50000","20.64731","0.14593"
"206.67500","20.66483","0.14579"
"206.85000","20.68232","0.14548"
"207.02500","20.69989","0.14525"
"207.20000","20.71736","0.14516"
"207.37500","20.73491","0.14507"
"207.55000","20.75228","0.14496"
"207.72500","20.76984","0.14498"
"207.90000","20.78727","0.14473"
"208.07500","20.80485","0.14477"
"208.25000","20.82241","0.14472"
"208.42500","20.83991","0.14443"
"208.60000","20.85745","0.14425"
"208.77500","20.87486","0.14430"
"208.95000","20.89237","0.14436"
"209.12500","20.90983","0.14413"
"209.30000","20.92743","0.14420"
"209.47500","20.94493","0.14407"
"209.65000","20.96245","0.14392"
"209.82500","20.97999","0.14398"
"210.00000","20.99736","0.14396"
"210.17500","21.01485","0.14365"
"210.35000","21.03227","0.14359"
"210.52500","21.04986","0.14355"
"210.70000","21.06735","0.14336"
"210.87500","21.08496","0.14329"
"211.05000","21.10239","0.14345"
"211.22500","21.11983","0.14311"
"211.40000","21.13735","0.14278"
"211.57500","21.15480","0.14283"
"211.75000","21.17233","0.14290"
"211.92500","21.18983","0.14231"
"212.10000","21.20744","0.14247"
"212.27500","21.22486","0.14259"
"212.45000","21.24234","0.14240"
"212.62500","21.26003","0.14235"
"212.80000","21.27730","0.14198"
"212.97500","21.29480","0.14198"
"213.15000","21.31234","0.14186"
"213.32500","21.32994","0.14176"
"213.50000","21.34746","0.14193"
"213.67500","21.36489","0.14172"
"213.85000","21.38231","0.14154"
"214.02500","21.39984","0.14144"
"214.20000","21.41730","0.14137"
"214.37500","21.43482","0.14118"
"214.55000","21.45239","0.14088"
"214.72500","21.46991","0.14091"
"214.90000","21.48739","0.14056"
"215.07500","21.50487","0.14076"
"215.25000","21.52238","0.14063"
"215.42500","21.53983","0.14055"
"215.60000","21.55738","0.14031"
"215.77500","21.57495","0.14028"
"215.95000","21.59242","0.14029"
"216.12500","21.60994","0.13993"
"216.30000","21.62737","0.13971"
"216.47500","21.64637","0.13951"
"216.65000","21.66241","0.13950"
"216.82500","21.67963","0.13934"
"217.00000","21.69714","0.13935"
"217.17500","21.71476","0.13929"
"217.35000","21.73224","0.13884"
"217.52500","21.74974","0.13898"
"217.70000","21.76726","0.13864"
"217.87500","21.78474","0.13850"
"218.05000","21.80226","0.13852"
"218.22500","21.81975","0.13851"
"218.40000","21.83731","0.13842"
"218.57500","21.85479","0.13827"
"218.75000","21.87231","0.13828"
"218.92500","21.88970","0.13808"
"219.10000","21.90724","0.13808"
"219.27500","21.92473","0.13801"
"219.45000","21.94228","0.13811"
"219.62500","21.95989","0.13797"
"219.80000","21.97738","0.13809"
"219.97500","21.99490","0.13798"
"220.15000","22.01233","0.13795"
"220.32500","22.02978","0.13763"
"220.50000","22.04717","0.13727"
"220.67500","22.06477","0.13742"
"220.85000","22.08232","0.13698"
"221.02500","22.09986","0.13712"
"221.20000","22.11737","0.13720"
"221.37500","22.13482","0.13698"
"221.55000","22.15236","0.13687"
"221.72500","22.16974","0.13705"
"221.90000","22.18738","0.13689"
"222.07500","22.20494","0.13674"
"222.25000","22.22240","0.13685"
"222.42500","22.23992","0.13684"
"222.60000","22.25752","0.13665"
"222.77500","22.27466","0.13640"
"222.95000","22.29202","0.13652"
"223.12500","22.30969","0.13638"
"223.30000","22.32724","0.13630"
"223.47500","22.34486","0.13633"
"223.65000","22.36226","0.13623"
"223.82500","22.37974","0.13591"
"224.00000","22.39725","0.13584"
"224.17500","22.41467","0.13593"
"224.35000","22.43225","0.13564"
"224.52500","22.44972","0.13548"
"224.70000","22.46734","0.13567"
"224.87500","22.48482","0.13502"
"225.05000","22.50236","0.13499"
"225.22500","22.51978","0.13503"
"225.40000","22.53727","0.13505"
"225.57500","22.55476","0.13498"
"225.75000","22.57236","0.13468"
"225.92500","22.58993","0.13491"
"226.10000","22.60735","0.13474"
"226.27500","22.62488","0.13453"
"226.45000","22.64239","0.13440"
"226.62500","22.65980","0.13424"
"226.80000","22.67719","0.13416"
"226.97500","22.69479","0.13418"
"227.15000","22.71234","0.13422"
"227.32500","22.72987","0.13408"
"227.50000","22.74739","0.13395"
"227.67500","22.76501","0.13383"
"227.85000","22.78230","0.13346"
"228.02500","22.79980","0.13328"
"228.20000","22.81738","0.13323"
"228.37500","22.83484","0.13325"
"228.55000","22.85239","0.13313"
"228.72500","22.86989","0.13279"
"228.90000","22.88730","0.13274"
"229.07500","22.90484","0.13263"
"229.25000","22.92225","0.13255"
"229.42500","22.93975","0.13225"
"229.60000","22.95726","0.13180"
"229.77500","22.97489","0.13156"
"229.95000","22.99236","0.13133"
"230.12500","23.00981","0.13143"
"230.30000","23.02730","0.13085"
"230.47500","23.04472","0.13080"
"230.65000","23.06224","0.13067"
"230.82500","23.07977","0.13049"
"231.00000","23.09738","0.13043"
"231.17500","23.11483","0.13040"
"231.35000","23.13238","0.13006"
"231.52500","23.14978","0.12988"
"231.70000","23.16728","0.12995"
"231.87500","23.18480","0.13005"
"232.05000","23.20235","0.12972"
"232.22500","23.21991","0.12961"
"232.40000","23.23736","0.12970"
"232.57500","23.25487","0.12951"
"232.75000","23.27231","0.12929"
"232.92500","23.28982","0.12950"
"233.10000","23.30726","0.12930"
"233.27500","23.32479","0.12902"
"233.45000","23.34236","0.12923"
"233.62500","23.35986","0.12910"
"233.80000","23.37740","0.12893"
"233.97500","23.39481","0.12899"
"234.15000","23.41236","0.12895"
"234.32500","23.42979","0.12892"
"234.50000","23.44737","0.12886"
"234.67500","23.46491","0.12893"
"234.85000","23.48242","0.12889"
"235.02500","23.49987","0.12869"
"235.20000","23.51728","0.12908"
"235.37500","23.53691","0.12899"
"235.55000","23.55217","0.12878"
"235.72500","23.56957","0.12878"
"235.90000","23.58715","0.12890"
"236.07500","23.60477","0.12878"
"236.25000","23.62229","0.12891"
"236.42500","23.63975","0.12899"
"236.60000","23.65726","0.12881"
"236.77500","23.67472","0.12893"
"236.95000","23.69228","0.12891"
"237.12500","23.70979","0.12898"
"237.30000","23.72744","0.12867"
"237.47500","23.74476","0.12866"
"237.65000","23.76228","0.12902"
"237.82500","23.77970","0.12891"
"238.00000","23.79720","0.12865"
"238.17500","23.81473","0.12901"
"238.35000","23.83233","0.12877"
"238.52500","23.84992","0.12880"
"238.70000","23.86737","0.12855"
"238.87500","23.88499","0.12865"
"239.05000","23.90233","0.12844"
"239.22500","23.91990","0.12853"
"239.40000","23.93734","0.12856"
"239.57500","23.95497","0.12848"
"239.75000","23.97240","0.12821"
"239.92500","23.98988","0.12808"
"240.10000","24.00739","0.12799"
"240.27500","24.02477","0.12786"
"240.45000","24.04234","0.12773"
"240.62500","24.05977","0.12780"
"240.80000","24.07731","0.12775"
"240.97500","24.09487","0.12753"
"241.15000","24.11244","0.12771"
"241.32500","24.12991","0.12749"
"241.50000","24.14728","0.12719"
"241.67500","24.16482","0.12741"
"241.85000","24.18221","0.12739"
"242.02500","24.19975","0.12712"
"242.20000","24.21726","0.12719"
"242.37500","24.23490","0.12711"
"242.55000","24.25233","0.12688"
"242.72500","24.26986","0.12660"
"242.90000","24.28735","0.12652"
"243.07500","24.30480","0.12622"
"243.25000","24.32227","0.12592"
"243.42500","24.33979","0.12591"
"243.60000","24.35737","0.12576"
"243.77500","24.37481","0.12565"
"243.95000","24.39236","0.12524"
"244.12500","24.40974","0.12499"
"244.30000","24.42726","0.12470"
"244.47500","24.44477","0.12447"
"244.65000","24.46238","0.12450"
"244.82500","24.47989","0.12396"
"245.00000","24.49796","0.12359"
"245.17500","24.51482","0.12309"
"245.35000","24.53220","0.12251"
"245.52500","24.54977","0.12184"
"245.70000","24.56720","0.12105"
"245.87500","24.58480","0.11993"
"246.05000","24.60237","0.11841"
"246.22500","24.61989","0.11665"
"246.40000","24.63741","0.11478"
"246.57500","24.65481","0.11063"
"246.75000","24.67239","0.10614"
"246.92500","24.68980","0.10488"
"247.10000","24.70737","0.10370"
"247.27500","24.72484","0.10091"
"247.45000","24.74237","0.09846"
"247.62500","24.75983","0.09608"
"247.80000","24.77731","0.09360"
"247.97500","24.79482","0.09045"
"248.15000","24.81226","0.08781"
"248.32500","24.82978","0.08488"
"248.50000","24.84728","0.08085"
"248.67500","24.86492","0.07528"
"248.85000","24.88238","0.07368"
"249.02500","24.89989","0.07224"
"249.20000","24.91743","0.07027"
"249.37500","24.93482","0.06914"
"249.55000","24.95226","0.06800"
"249.72500","24.96981","0.06685"
"249.90000","24.98738","0.06559"
"250.07500","25.00482","0.06447"
"250.25000","25.02236","0.06322"
"250.42500","25.03975","0.06158"
"250.60000","25.05729","0.05957"
"250.77500","25.07472","0.05610"
"250.95000","25.09230","0.05038"
"251.12500","25.10988","0.04561"
"251.30000","25.12738","0.03984"
"251.47500","25.14490","0.02878"
"251.65000","25.16234","0.01036"
"251.82500","25.17990","-0.00782"
"252.00000","25.19734","-0.01361"
"252.17500","25.21488","-0.01325"
"252.35000","25.23246","-0.01315"
"252.52500","25.25159","-0.01336"
"252.70000","25.26748","-0.01332"
"252.87500","25.28454","-0.01334"
"253.05000","25.30216","-0.01334"
"253.22500","25.31959","-0.01341"
"253.40000","25.33723","-0.01341"
"253.57500","25.35470","-0.01321"
"253.75000","25.37224","-0.01329"
"253.92500","25.38976","-0.01355"
"254.10000","25.40716","-0.01337"
"254.27500","25.42475","-0.01330"
"254.45000","25.44209","-0.01399"
"254.62500","25.45960","-0.01359"
"254.80000","25.47721","-0.01333"
"254.97500","25.49483","-0.01344"
"255.15000","25.51233","-0.01354"
"255.32500","25.52985","-0.01330"
"255.50000","25.54731","-0.01355"
"255.67500","25.56480","-0.01353"
"255.85000","25.58233","-0.01358"
"256.02500","25.59982","-0.01347"
"256.20000","25.61739","-0.01367"
"256.37500","25.63486","-0.01333"
"256.55000","25.65245","-0.01342"
"256.72500","25.67005","-0.01346"
"256.90000","25.68716","-0.01339"
"257.07500","25.70462","-0.01334"
"257.25000","25.72224","-0.01348"
"257.42500","25.73986","-0.01346"
"257.60000","25.75743","-0.01348"
"257.77500","25.77492","-0.01336"
"257.95000","25.79228","-0.01344"
"258.12500","25.80986","-0.01330"
"258.30000","25.82734","-0.01328"
"258.47500","25.84483","-0.01356"
"258.65000","25.86246","-0.01353"
"258.82500","25.87988","-0.01342"
"259.00000","25.89731","-0.01351"
"259.17500","25.91469","-0.01369"
"259.35000","25.93230","-0.01320"
"259.52500","25.94971","-0.01334"
"259.70000","25.96742","-0.01344"
"259.87500","25.98487","-0.01359"
"260.05000","26.00250","-0.01354"
"260.22500","26.01991","-0.01361"
"260.40000","26.03898","-0.01391"
"260.57500","26.05470","-0.01361"
"260.75000","26.07210","-0.01361"
"260.92400","26.08954","-0.01362"