File: 20G1652/ST 20G1652_005.csv
Rate 1,"1.60000",mm/s
Start date,"9/25/2021"
Specimen label,""

Time,Extension,2 kg Beam Load Cell
(s),(mm),(N)
"0.00000","-0.00127","0.00017"
"0.02500","-0.00122","0.00037"
"0.05000","0.00165","0.00194"
"0.07500","0.01210","0.00137"
"0.10000","0.02983","0.00204"
"0.12500","0.05332","0.00236"
"0.15000","0.08186","0.00247"
"0.17500","0.11381","0.00325"
"0.20000","0.14730","0.00386"
"0.22500","0.18283","0.00493"
"0.25000","0.21995","0.00542"
"0.27500","0.25854","0.00641"
"0.30000","0.29813","0.00738"
"0.32500","0.33840","0.00810"
"0.35000","0.37952","0.00925"
"0.37500","0.42112","0.00974"
"0.40000","0.46293","0.01069"
"0.42500","0.50504","0.01178"
"0.45000","0.54725","0.01258"
"0.47500","0.58968","0.01392"
"0.50000","0.63241","0.01457"
"0.52500","0.67503","0.01553"
"0.55000","0.71762","0.01645"
"0.57500","0.76040","0.01714"
"0.60000","0.80331","0.01842"
"0.62500","0.84623","0.01936"
"0.65000","0.88914","0.02030"
"0.67500","0.93238","0.02125"
"0.70000","0.97566","0.02202"
"0.72500","1.01858","0.02305"
"0.75000","1.06155","0.02412"
"0.77500","1.10448","0.02510"
"0.80000","1.14725","0.02589"
"0.82500","1.18982","0.02686"
"0.85000","1.23246","0.02774"
"0.87500","1.27508","0.02877"
"0.90000","1.31774","0.02987"
"0.92500","1.36033","0.03065"
"0.95000","1.40285","0.03179"
"0.97500","1.44545","0.03257"
"1.00000","1.48848","0.03333"
"1.02500","1.53113","0.03461"
"1.05000","1.57340","0.03537"
"1.07500","1.61585","0.03641"
"1.10000","1.65849","0.03712"
"1.12500","1.70102","0.03838"
"1.15000","1.74326","0.03912"
"1.17500","1.78535","0.04017"
"1.20000","1.82737","0.04142"
"1.22500","1.86930","0.04215"
"1.25000","1.91115","0.04323"
"1.27500","1.95303","0.04385"
"1.30000","1.99492","0.04437"
"1.32500","2.03742","0.04700"
"1.35000","2.08008","0.04672"
"1.37500","2.12239","0.04839"
"1.40000","2.16448","0.04881"
"1.42500","2.20643","0.04996"
"1.45000","2.24863","0.05108"
"1.47500","2.29077","0.05157"
"1.50000","2.33287","0.05343"
"1.52500","2.37476","0.05337"
"1.55000","2.41670","0.05499"
"1.57500","2.45869","0.05586"
"1.60000","2.50053","0.05688"
"1.62500","2.54207","0.05801"
"1.65000","2.58352","0.05858"
"1.67500","2.62506","0.06005"
"1.70000","2.66659","0.06081"
"1.72500","2.70807","0.06200"
"1.75000","2.74952","0.06289"
"1.77500","2.79097","0.06371"
"1.80000","2.83228","0.06497"
"1.82500","2.87361","0.06573"
"1.85000","2.91558","0.06676"
"1.87500","2.95623","0.06786"
"1.90000","2.99617","0.06885"
"1.92500","3.03609","0.06985"
"1.95000","3.07605","0.07081"
"1.97500","3.11619","0.07169"
"2.00000","3.15629","0.07270"
"2.02500","3.19616","0.07384"
"2.05000","3.23597","0.07492"
"2.07500","3.27583","0.07588"
"2.10000","3.31603","0.07686"
"2.12500","3.35658","0.07784"
"2.15000","3.39656","0.07868"
"2.17500","3.43647","0.07982"
"2.20000","3.47654","0.08077"
"2.22500","3.51678","0.08191"
"2.25000","3.55701","0.08297"
"2.27500","3.59774","0.08393"
"2.30000","3.63846","0.08515"
"2.32500","3.67836","0.08604"
"2.35000","3.71802","0.08714"
"2.37500","3.75775","0.08790"
"2.40000","3.79768","0.08895"
"2.42500","3.83781","0.09010"
"2.45000","3.87812","0.09109"
"2.47500","3.91825","0.09240"
"2.50000","3.95828","0.09341"
"2.52500","3.99820","0.09420"
"2.55000","4.03823","0.09537"
"2.57500","4.07842","0.09665"
"2.60000","4.11864","0.09742"
"2.62500","4.15885","0.09863"
"2.65000","4.19906","0.09974"
"2.67500","4.23939","0.10067"
"2.70000","4.27987","0.10188"
"2.72500","4.32014","0.10302"
"2.75000","4.36022","0.10401"
"2.77500","4.40054","0.10509"
"2.80000","4.44106","0.10635"
"2.82500","4.48081","0.10732"
"2.85000","4.52042","0.10844"
"2.87500","4.56024","0.10954"
"2.90000","4.60028","0.11061"
"2.92500","4.64038","0.11190"
"2.95000","4.68051","0.11305"
"2.97500","4.72079","0.11381"
"3.00000","4.76153","0.11513"
"3.02500","4.80189","0.11641"
"3.05000","4.84206","0.11746"
"3.07500","4.88201","0.11844"
"3.10000","4.92201","0.11968"
"3.12500","4.96210","0.12069"
"3.15000","5.00216","0.12176"
"3.17500","5.04239","0.12313"
"3.20000","5.08236","0.12424"
"3.22500","5.12229","0.12531"
"3.25000","5.16227","0.12657"
"3.27500","5.20230","0.12752"
"3.30000","5.24237","0.12884"
"3.32500","5.28249","0.12989"
"3.35000","5.32261","0.13110"
"3.37500","5.36278","0.13213"
"3.40000","5.40309","0.13358"
"3.42500","5.44419","0.13470"
"3.45000","5.48475","0.13571"
"3.47500","5.52457","0.13715"
"3.50000","5.56439","0.13790"
"3.52500","5.60430","0.13933"
"3.55000","5.64421","0.14072"
"3.57500","5.68411","0.14166"
"3.60000","5.72398","0.14306"
"3.62500","5.76394","0.14438"
"3.65000","5.80391","0.14544"
"3.67500","5.84386","0.14634"
"3.70000","5.88379","0.14769"
"3.72500","5.92385","0.14892"
"3.75000","5.96390","0.14995"
"3.77500","6.00398","0.15145"
"3.80000","6.04446","0.15256"
"3.82500","6.08520","0.15385"
"3.85000","6.12528","0.15515"
"3.87500","6.16526","0.15616"
"3.90000","6.20541","0.15742"
"3.92500","6.24562","0.15866"
"3.95000","6.28566","0.16030"
"3.97500","6.32562","0.16117"
"4.00000","6.36546","0.16276"
"4.02500","6.40523","0.16384"
"4.05000","6.44560","0.16491"
"4.07500","6.48591","0.16625"
"4.10000","6.52560","0.16758"
"4.12500","6.56532","0.16872"
"4.15000","6.60523","0.17015"
"4.17500","6.64540","0.17144"
"4.20000","6.68557","0.17266"
"4.22500","6.72564","0.17375"
"4.25000","6.76576","0.17508"
"4.27500","6.80591","0.17636"
"4.30000","6.84604","0.17776"
"4.32500","6.88604","0.17909"
"4.35000","6.92593","0.18011"
"4.37500","6.96599","0.18164"
"4.40000","7.00643","0.18295"
"4.42500","7.04611","0.18434"
"4.45000","7.08556","0.18559"
"4.47500","7.12513","0.18683"
"4.50000","7.16490","0.18821"
"4.52500","7.20477","0.18945"
"4.55000","7.24472","0.19108"
"4.57500","7.28468","0.19223"
"4.60000","7.32468","0.19320"
"4.62500","7.36479","0.19496"
"4.65000","7.40530","0.19583"
"4.67500","7.44564","0.19753"
"4.70000","7.48536","0.19882"
"4.72500","7.52500","0.19992"
"4.75000","7.56486","0.20173"
"4.77500","7.60514","0.20262"
"4.80000","7.64516","0.20445"
"4.82500","7.68472","0.20549"
"4.85000","7.72431","0.20684"
"4.87500","7.76419","0.20829"
"4.90000","7.80427","0.20951"
"4.92500","7.84426","0.21132"
"4.95000","7.88421","0.21241"
"4.97500","7.92426","0.21366"
"5.00000","7.96440","0.21525"
"5.02500","8.00461","0.21650"
"5.05000","8.04533","0.21791"
"5.07500","8.08583","0.21940"
"5.10000","8.12553","0.22083"
"5.12500","8.16526","0.22211"
"5.15000","8.20506","0.22356"
"5.17500","8.24483","0.22494"
"5.20000","8.28463","0.22618"
"5.22500","8.32442","0.22790"
"5.25000","8.36430","0.22914"
"5.27500","8.40422","0.23052"
"5.30000","8.44414","0.23228"
"5.32500","8.48410","0.23332"
"5.35000","8.52413","0.23491"
"5.37500","8.56419","0.23609"
"5.40000","8.60433","0.23770"
"5.42500","8.64487","0.23881"
"5.45000","8.68561","0.24030"
"5.47500","8.72554","0.24178"
"5.50000","8.76531","0.24294"
"5.52500","8.80519","0.24490"
"5.55000","8.84505","0.24580"
"5.57500","8.88491","0.24729"
"5.60000","8.92475","0.24865"
"5.62500","8.96461","0.25011"
"5.65000","9.00453","0.25151"
"5.67500","9.04447","0.25297"
"5.70000","9.08477","0.25437"
"5.72500","9.12524","0.25583"
"5.75000","9.16517","0.25700"
"5.77500","9.20490","0.25867"
"5.80000","9.24476","0.25971"
"5.82500","9.28484","0.26148"
"5.85000","9.32498","0.26296"
"5.87500","9.36504","0.26414"
"5.90000","9.40500","0.26575"
"5.92500","9.44487","0.26700"
"5.95000","9.48505","0.26844"
"5.97500","9.52552","0.26986"
"6.00000","9.56531","0.27131"
"6.02500","9.60489","0.27244"
"6.05000","9.64456","0.27389"
"6.07500","9.68438","0.27563"
"6.10000","9.72429","0.27685"
"6.12500","9.76424","0.27817"
"6.15000","9.80427","0.27977"
"6.17500","9.84439","0.28103"
"6.20000","9.88512","0.28257"
"6.22500","9.92538","0.28367"
"6.25000","9.96519","0.28518"
"6.27500","10.00493","0.28668"
"6.30000","10.04469","0.28800"
"6.32500","10.08447","0.28942"
"6.35000","10.12427","0.29038"
"6.37500","10.16415","0.29186"
"6.40000","10.20419","0.29324"
"6.42500","10.24479","0.29469"
"6.45000","10.28475","0.29631"
"6.47500","10.32436","0.29730"
"6.50000","10.36407","0.29871"
"6.52500","10.40395","0.29978"
"6.55000","10.44402","0.30124"
"6.57500","10.48459","0.30235"
"6.60000","10.52490","0.30383"
"6.62500","10.56479","0.30520"
"6.65000","10.60472","0.30632"
"6.67500","10.64467","0.30817"
"6.70000","10.68462","0.30925"
"6.72500","10.72449","0.31032"
"6.75000","10.76438","0.31205"
"6.77500","10.80434","0.31327"
"6.80000","10.84427","0.31469"
"6.82500","10.88419","0.31605"
"6.85000","10.92411","0.31779"
"6.87500","10.96410","0.31893"
"6.90000","11.00408","0.32038"
"6.92500","11.04410","0.32173"
"6.95000","11.08475","0.32308"
"6.97500","11.12590","0.32428"
"7.00000","11.16621","0.32584"
"7.02500","11.20600","0.32707"
"7.05000","11.24580","0.32876"
"7.07500","11.28578","0.32992"
"7.10000","11.32583","0.33122"
"7.12500","11.36565","0.33268"
"7.15000","11.40550","0.33395"
"7.17500","11.44538","0.33537"
"7.20000","11.48525","0.33691"
"7.22500","11.52510","0.33839"
"7.25000","11.56499","0.33940"
"7.27500","11.60487","0.34092"
"7.30000","11.64476","0.34233"
"7.32500","11.68474","0.34349"
"7.35000","11.72549","0.34486"
"7.37500","11.76583","0.34648"
"7.40000","11.80564","0.34756"
"7.42500","11.84553","0.34888"
"7.45000","11.88554","0.35050"
"7.47500","11.92551","0.35171"
"7.50000","11.96534","0.35312"
"7.52500","12.00511","0.35441"
"7.55000","12.04493","0.35559"
"7.57500","12.08482","0.35713"
"7.60000","12.12482","0.35838"
"7.62500","12.16509","0.35999"
"7.65000","12.20551","0.36110"
"7.67500","12.24535","0.36260"
"7.70000","12.28502","0.36392"
"7.72500","12.32476","0.36527"
"7.75000","12.36466","0.36661"
"7.77500","12.40469","0.36774"
"7.80000","12.44476","0.36937"
"7.82500","12.48484","0.37044"
"7.85000","12.52475","0.37180"
"7.87500","12.56462","0.37307"
"7.90000","12.60455","0.37450"
"7.92500","12.64506","0.37571"
"7.95000","12.68511","0.37688"
"7.97500","12.72478","0.37835"
"8.00000","12.76451","0.37946"
"8.02500","12.80437","0.38085"
"8.05000","12.84440","0.38219"
"8.07500","12.88448","0.38337"
"8.10000","12.92479","0.38456"
"8.12500","12.96488","0.38595"
"8.15000","13.00477","0.38689"
"8.17500","13.04463","0.38829"
"8.20000","13.08469","0.38949"
"8.22500","13.12471","0.39084"
"8.25000","13.16464","0.39200"
"8.27500","13.20451","0.39361"
"8.30000","13.24444","0.39470"
"8.32500","13.28445","0.39564"
"8.35000","13.32454","0.39705"
"8.37500","13.36536","0.39828"
"8.40000","13.40638","0.39941"
"8.42500","13.44682","0.40096"
"8.45000","13.48651","0.40175"
"8.47500","13.52626","0.40321"
"8.50000","13.56624","0.40427"
"8.52500","13.60634","0.40543"
"8.55000","13.64640","0.40647"
"8.57500","13.68628","0.40758"
"8.60000","13.72617","0.40908"
"8.62500","13.76618","0.41007"
"8.65000","13.80622","0.41141"
"8.67500","13.84617","0.41231"
"8.70000","13.88606","0.41313"
"8.72500","13.92598","0.41471"
"8.75000","13.96592","0.41551"
"8.77500","14.00590","0.41666"
"8.80000","14.04653","0.41774"
"8.82500","14.08699","0.41865"
"8.85000","14.12676","0.41991"
"8.87500","14.16651","0.42071"
"8.90000","14.20643","0.42192"
"8.92500","14.24639","0.42265"
"8.95000","14.28640","0.42403"
"8.97500","14.32643","0.42511"
"9.00000","14.36646","0.42603"
"9.02500","14.40637","0.42715"
"9.05000","14.44630","0.42800"
"9.07500","14.48631","0.42910"
"9.10000","14.52626","0.43024"
"9.12500","14.56606","0.43133"
"9.15000","14.60595","0.43228"
"9.17500","14.64591","0.43324"
"9.20000","14.68588","0.43433"
"9.22500","14.72587","0.43521"
"9.25000","14.76597","0.43609"
"9.27500","14.80613","0.43694"
"9.30000","14.84612","0.43723"
"9.32500","14.88610","0.43866"
"9.35000","14.92611","0.43926"
"9.37500","14.96613","0.44013"
"9.40000","15.00609","0.44105"
"9.42500","15.04613","0.44191"
"9.45000","15.08678","0.44259"
"9.47500","15.12698","0.44305"
"9.50000","15.16654","0.44426"
"9.52500","15.20615","0.44490"
"9.55000","15.24602","0.44560"
"9.57500","15.28609","0.44668"
"9.60000","15.32619","0.44713"
"9.62500","15.36626","0.44807"
"9.65000","15.40628","0.44887"
"9.67500","15.44622","0.44948"
"9.70000","15.48620","0.45056"
"9.72500","15.52625","0.45102"
"9.75000","15.56626","0.45218"
"9.77500","15.60631","0.45253"
"9.80000","15.64642","0.45356"
"9.82500","15.68636","0.45391"
"9.85000","15.72626","0.45474"
"9.87500","15.76681","0.45580"
"9.90000","15.80706","0.45585"
"9.92500","15.84654","0.45704"
"9.95000","15.88604","0.45749"
"9.97500","15.92595","0.45822"
"10.00000","15.96603","0.45888"
"10.02500","16.00596","0.45965"
"10.05000","16.04595","0.46062"
"10.07500","16.08602","0.46081"
"10.10000","16.12602","0.46205"
"10.12500","16.16597","0.46251"
"10.15000","16.20591","0.46303"
"10.17500","16.24589","0.46395"
"10.20000","16.28593","0.46433"
"10.22500","16.32593","0.46503"
"10.25000","16.36585","0.46564"
"10.27500","16.40567","0.46622"
"10.30000","16.44552","0.46693"
"10.32500","16.48578","0.46732"
"10.35000","16.52590","0.46826"
"10.37500","16.56566","0.46851"
"10.40000","16.60536","0.46931"
"10.42500","16.64521","0.46998"
"10.45000","16.68522","0.47021"
"10.47500","16.72522","0.47114"
"10.50000","16.76518","0.47150"
"10.52500","16.80515","0.47208"
"10.55000","16.84508","0.47270"
"10.57500","16.88499","0.47311"
"10.60000","16.92495","0.47383"
"10.62500","16.96492","0.47415"
"10.65000","17.00491","0.47472"
"10.67500","17.04482","0.47477"
"10.70000","17.08514","0.47555"
"10.72500","17.12556","0.47611"
"10.75000","17.16533","0.47630"
"10.77500","17.20499","0.47717"
"10.80000","17.24486","0.47746"
"10.82500","17.28482","0.47815"
"10.85000","17.32481","0.47861"
"10.87500","17.36480","0.47907"
"10.90000","17.40479","0.47935"
"10.92500","17.44480","0.47993"
"10.95000","17.48477","0.48038"
"10.97500","17.52474","0.48090"
"11.00000","17.56461","0.48150"
"11.02500","17.60440","0.48205"
"11.05000","17.64428","0.48239"
"11.07500","17.68416","0.48288"
"11.10000","17.72414","0.48335"
"11.12500","17.76424","0.48346"
"11.15000","17.80426","0.48396"
"11.17500","17.84455","0.48429"
"11.20000","17.88531","0.48453"
"11.22500","17.92557","0.48514"
"11.25000","17.96563","0.48542"
"11.27500","18.00538","0.48558"
"11.30000","18.04520","0.48585"
"11.32500","18.08511","0.48618"
"11.35000","18.12502","0.48640"
"11.37500","18.16491","0.48689"
"11.40000","18.20488","0.48748"
"11.42500","18.24489","0.48761"
"11.45000","18.28486","0.48832"
"11.47500","18.32482","0.48878"
"11.50000","18.36491","0.48913"
"11.52500","18.40530","0.48955"
"11.55000","18.44579","0.49020"
"11.57500","18.48563","0.49057"
"11.60000","18.52530","0.49112"
"11.62500","18.56505","0.49132"
"11.65000","18.60491","0.49188"
"11.67500","18.64484","0.49214"
"11.70000","18.68484","0.49251"
"11.72500","18.72483","0.49278"
"11.75000","18.76472","0.49272"
"11.77500","18.80467","0.49309"
"11.80000","18.84470","0.49325"
"11.82500","18.88473","0.49357"
"11.85000","18.92467","0.49333"
"11.87500","18.96456","0.49316"
"11.90000","19.00450","0.49332"
"11.92500","19.04443","0.49374"
"11.95000","19.08438","0.49392"
"11.97500","19.12436","0.49422"
"12.00000","19.16479","0.49450"
"12.02500","19.20568","0.49464"
"12.05000","19.24586","0.49500"
"12.07500","19.28561","0.49534"
"12.10000","19.32532","0.49539"
"12.12500","19.36515","0.49558"
"12.15000","19.40512","0.49593"
"12.17500","19.44515","0.49630"
"12.20000","19.48519","0.49640"
"12.22500","19.52524","0.49676"
"12.25000","19.56522","0.49699"
"12.27500","19.60517","0.49709"
"12.30000","19.64507","0.49750"
"12.32500","19.68487","0.49769"
"12.35000","19.72471","0.49778"
"12.37500","19.76466","0.49821"
"12.40000","19.80473","0.49838"
"12.42500","19.84535","0.49879"
"12.45000","19.88560","0.49895"
"12.47500","19.92527","0.49910"
"12.50000","19.96504","0.49931"
"12.52500","20.00489","0.49957"
"12.55000","20.04475","0.50009"
"12.57500","20.08479","0.50004"
"12.60000","20.12488","0.50061"
"12.62500","20.16499","0.50063"
"12.65000","20.20503","0.50067"
"12.67500","20.24506","0.50122"
"12.70000","20.28501","0.50113"
"12.72500","20.32491","0.50137"
"12.75000","20.36479","0.50154"
"12.77500","20.40463","0.50177"
"12.80000","20.44457","0.50227"
"12.82500","20.48456","0.50225"
"12.85000","20.52467","0.50281"
"12.87500","20.56478","0.50269"
"12.90000","20.60485","0.50313"
"12.92500","20.64490","0.50350"
"12.95000","20.68494","0.50347"
"12.97500","20.72495","0.50408"
"13.00000","20.76497","0.50418"
"13.02500","20.80509","0.50454"
"13.05000","20.84509","0.50482"
"13.07500","20.88550","0.50493"
"13.10000","20.92606","0.50531"
"13.12500","20.96596","0.50536"
"13.15000","21.00562","0.50603"
"13.17500","21.04532","0.50613"
"13.20000","21.08510","0.50658"
"13.22500","21.12498","0.50717"
"13.25000","21.16495","0.50702"
"13.27500","21.20498","0.50768"
"13.30000","21.24496","0.50786"
"13.32500","21.28503","0.50813"
"13.35000","21.32509","0.50829"
"13.37500","21.36509","0.50864"
"13.40000","21.40522","0.50895"
"13.42500","21.44534","0.50906"
"13.45000","21.48599","0.50964"
"13.47500","21.52629","0.50964"
"13.50000","21.56590","0.50988"
"13.52500","21.60546","0.51042"
"13.55000","21.64518","0.51046"
"13.57500","21.68494","0.51093"
"13.60000","21.72487","0.51093"
"13.62500","21.76484","0.51090"
"13.65000","21.80485","0.51111"
"13.67500","21.84493","0.51127"
"13.70000","21.88503","0.51176"
"13.72500","21.92515","0.51178"
"13.75000","21.96522","0.51219"
"13.77500","22.00525","0.51248"
"13.80000","22.04526","0.51239"
"13.82500","22.08519","0.51298"
"13.85000","22.12532","0.51270"
"13.87500","22.16580","0.51287"
"13.90000","22.20555","0.51298"
"13.92500","22.24504","0.51313"
"13.95000","22.28467","0.51325"
"13.97500","22.32444","0.51341"
"14.00000","22.36435","0.51364"
"14.02500","22.40443","0.51360"
"14.05000","22.44450","0.51373"
"14.07500","22.48459","0.51360"
"14.10000","22.52480","0.51341"
"14.12500","22.56508","0.51385"
"14.15000","22.60524","0.51407"
"14.17500","22.64528","0.51411"
"14.20000","22.68532","0.51450"
"14.22500","22.72534","0.51439"
"14.25000","22.76533","0.51482"
"14.27500","22.80536","0.51475"
"14.30000","22.84558","0.51522"
"14.32500","22.88579","0.51517"
"14.35000","22.92556","0.51567"
"14.37500","22.96525","0.51587"
"14.40000","23.00513","0.51598"
"14.42500","23.04515","0.51628"
"14.45000","23.08520","0.51658"
"14.47500","23.12533","0.51684"
"14.50000","23.16543","0.51729"
"14.52500","23.20555","0.51765"
"14.55000","23.24565","0.51778"
"14.57500","23.28571","0.51801"
"14.60000","23.32570","0.51832"
"14.62500","23.36561","0.51831"
"14.65000","23.40549","0.51883"
"14.67500","23.44532","0.51884"
"14.70000","23.48520","0.51913"
"14.72500","23.52521","0.51943"
"14.75000","23.56541","0.51978"
"14.77500","23.60534","0.52016"
"14.80000","23.64509","0.52029"
"14.82500","23.68497","0.52062"
"14.85000","23.72507","0.52099"
"14.87500","23.76522","0.52132"
"14.90000","23.80531","0.52166"
"14.92500","23.84538","0.52185"
"14.95000","23.88545","0.52198"
"14.97500","23.92544","0.52246"
"15.00000","23.96544","0.52254"
"15.02500","24.00536","0.52272"
"15.05000","24.04527","0.52305"
"15.07500","24.08514","0.52289"
"15.10000","24.12521","0.52315"
"15.12500","24.16572","0.52342"
"15.15000","24.20622","0.52358"
"15.17500","24.24620","0.52350"
"15.20000","24.28583","0.52350"
"15.22500","24.32552","0.52311"
"15.25000","24.36540","0.52356"
"15.27500","24.40546","0.52357"
"15.30000","24.44549","0.52371"
"15.32500","24.48550","0.52371"
"15.35000","24.52555","0.52384"
"15.37500","24.56570","0.52403"
"15.40000","24.60584","0.52394"
"15.42500","24.64592","0.52416"
"15.45000","24.68583","0.52427"
"15.47500","24.72563","0.52418"
"15.50000","24.76549","0.52459"
"15.52500","24.80556","0.52479"
"15.55000","24.84618","0.52486"
"15.57500","24.88661","0.52540"
"15.60000","24.92623","0.52532"
"15.62500","24.96584","0.52575"
"15.65000","25.00571","0.52587"
"15.67500","25.04568","0.52626"
"15.70000","25.08564","0.52633"
"15.72500","25.12569","0.52661"
"15.75000","25.16585","0.52706"
"15.77500","25.20599","0.52676"
"15.80000","25.24612","0.52744"
"15.82500","25.28621","0.52731"
"15.85000","25.32630","0.52769"
"15.87500","25.36624","0.52805"
"15.90000","25.40610","0.52791"
"15.92500","25.44604","0.52844"
"15.95000","25.48597","0.52820"
"15.97500","25.52588","0.52885"
"16.00000","25.56574","0.52858"
"16.02500","25.60574","0.52913"
"16.05000","25.64596","0.52908"
"16.07500","25.68663","0.52854"
"16.10000","25.72688","0.52869"
"16.12500","25.76663","0.52896"
"16.15000","25.80646","0.52911"
"16.17500","25.84644","0.52942"
"16.20000","25.88647","0.52971"
"16.22500","25.92648","0.52976"
"16.25000","25.96640","0.52989"
"16.27500","26.00637","0.53007"
"16.30000","26.04632","0.53011"
"16.32500","26.08624","0.52961"
"16.35000","26.12621","0.52990"
"16.37500","26.16610","0.52975"
"16.40000","26.20599","0.53011"
"16.42500","26.24602","0.53014"
"16.45000","26.28635","0.53019"
"16.47500","26.32701","0.53053"
"16.50000","26.36753","0.53058"
"16.52500","26.40730","0.53107"
"16.55000","26.44697","0.53106"
"16.57500","26.48698","0.53140"
"16.60000","26.52707","0.53139"
"16.62500","26.56696","0.53165"
"16.65000","26.60676","0.53178"
"16.67500","26.64668","0.53139"
"16.70000","26.68669","0.53165"
"16.72500","26.72659","0.53157"
"16.75000","26.76652","0.53148"
"16.77500","26.80659","0.53175"
"16.80000","26.84666","0.53179"
"16.82500","26.88660","0.53206"
"16.85000","26.92651","0.53198"
"16.87500","26.96643","0.53244"
"16.90000","27.00649","0.53260"
"16.92500","27.04689","0.53245"
"16.95000","27.08771","0.53299"
"16.97500","27.12778","0.53273"
"17.00000","27.16762","0.53324"
"17.02500","27.20744","0.53352"
"17.05000","27.24720","0.53346"
"17.07500","27.28709","0.53382"
"17.10000","27.32697","0.53386"
"17.12500","27.36694","0.53418"
"17.15000","27.40692","0.53425"
"17.17500","27.44684","0.53466"
"17.20000","27.48683","0.53489"
"17.22500","27.52685","0.53474"
"17.25000","27.56681","0.53540"
"17.27500","27.60691","0.53525"
"17.30000","27.64715","0.53550"
"17.32500","27.68718","0.53577"
"17.35000","27.72709","0.53586"
"17.37500","27.76701","0.53630"
"17.40000","27.80683","0.53630"
"17.42500","27.84664","0.53674"
"17.45000","27.88647","0.53696"
"17.47500","27.92638","0.53728"
"17.50000","27.96650","0.53757"
"17.52500","28.00666","0.53756"
"17.55000","28.04667","0.53814"
"17.57500","28.08670","0.53795"
"17.60000","28.12702","0.53835"
"17.62500","28.16784","0.53854"
"17.65000","28.20808","0.53882"
"17.67500","28.24781","0.53899"
"17.70000","28.28757","0.53915"
"17.72500","28.32758","0.53966"
"17.75000","28.36768","0.53929"
"17.77500","28.40776","0.53951"
"17.80000","28.44769","0.53967"
"17.82500","28.48751","0.53958"
"17.85000","28.52735","0.53990"
"17.87500","28.56727","0.54008"
"17.90000","28.60718","0.54035"
"17.92500","28.64709","0.54023"
"17.95000","28.68700","0.54041"
"17.97500","28.72691","0.54052"
"18.00000","28.76690","0.54094"
"18.02500","28.80685","0.54095"
"18.05000","28.84691","0.54117"
"18.07500","28.88715","0.54137"
"18.10000","28.92735","0.54177"
"18.12500","28.96775","0.54183"
"18.15000","29.00755","0.54171"
"18.17500","29.04714","0.54199"
"18.20000","29.08688","0.54187"
"18.22500","29.12680","0.54236"
"18.25000","29.16672","0.54248"
"18.27500","29.20669","0.54265"
"18.30000","29.24676","0.54261"
"18.32500","29.28673","0.54318"
"18.35000","29.32660","0.54310"
"18.37500","29.36654","0.54320"
"18.40000","29.40656","0.54318"
"18.42500","29.44661","0.54311"
"18.45000","29.48664","0.54307"
"18.47500","29.52659","0.54335"
"18.50000","29.56652","0.54356"
"18.52500","29.60641","0.54336"
"18.55000","29.64627","0.54376"
"18.57500","29.68616","0.54377"
"18.60000","29.72618","0.54392"
"18.62500","29.76627","0.54400"
"18.65000","29.80659","0.54379"
"18.67500","29.84726","0.54406"
"18.70000","29.88776","0.54422"
"18.72500","29.92762","0.54446"
"18.75000","29.96712","0.54451"
"18.77500","30.00685","0.54472"
"18.80000","30.04681","0.54511"
"18.82500","30.08694","0.54506"
"18.85000","30.12702","0.54545"
"18.87500","30.16703","0.54546"
"18.90000","30.20701","0.54569"
"18.92500","30.24698","0.54604"
"18.95000","30.28692","0.54612"
"18.97500","30.32680","0.54614"
"19.00000","30.36660","0.54654"
"19.02500","30.40648","0.54662"
"19.05000","30.44644","0.54683"
"19.07500","30.48641","0.54712"
"19.10000","30.52640","0.54737"
"19.12500","30.56628","0.54745"
"19.15000","30.60626","0.54775"
"19.17500","30.64635","0.54809"
"19.20000","30.68691","0.54776"
"19.22500","30.72714","0.54818"
"19.25000","30.76692","0.54834"
"19.27500","30.80679","0.54870"
"19.30000","30.84671","0.54882"
"19.32500","30.88653","0.54905"
"19.35000","30.92633","0.54927"
"19.37500","30.96612","0.54958"
"19.40000","31.00596","0.54992"
"19.42500","31.04581","0.54980"
"19.45000","31.08576","0.55012"
"19.47500","31.12574","0.55046"
"19.50000","31.16572","0.55031"
"19.52500","31.20566","0.55085"
"19.55000","31.24568","0.55081"
"19.57500","31.28583","0.55089"
"19.60000","31.32604","0.55103"
"19.62500","31.36634","0.55145"
"19.65000","31.40652","0.55146"
"19.67500","31.44639","0.55165"
"19.70000","31.48628","0.55198"
"19.72500","31.52615","0.55193"
"19.75000","31.56596","0.55226"
"19.77500","31.60573","0.55210"
"19.80000","31.64550","0.55228"
"19.82500","31.68528","0.55228"
"19.85000","31.72519","0.55224"
"19.87500","31.76517","0.55199"
"19.90000","31.80511","0.55169"
"19.92500","31.84499","0.55148"
"19.95000","31.88494","0.55130"
"19.97500","31.92497","0.55139"
"20.00000","31.96514","0.55140"
"20.02500","32.00528","0.55113"
"20.05000","32.04544","0.55111"
"20.07500","32.08579","0.55108"
"20.10000","32.12628","0.55101"
"20.12500","32.16683","0.55076"
"20.15000","32.20727","0.55082"
"20.17500","32.24718","0.55060"
"20.20000","32.28648","0.55003"
"20.22500","32.32598","0.55013"
"20.25000","32.36574","0.54969"
"20.27500","32.40554","0.54962"
"20.30000","32.44540","0.54948"
"20.32500","32.48531","0.54922"
"20.35000","32.52528","0.54906"
"20.37500","32.56528","0.54880"
"20.40000","32.60539","0.54838"
"20.42500","32.64562","0.54821"
"20.45000","32.68592","0.54783"
"20.47500","32.72609","0.54763"
"20.50000","32.76607","0.54686"
"20.52500","32.80605","0.54594"
"20.55000","32.84612","0.54416"
"20.57500","32.88605","0.54245"
"20.60000","32.92579","0.54122"
"20.62500","32.96556","0.53967"
"20.65000","33.00533","0.53843"
"20.67500","33.04501","0.53702"
"20.70000","33.08479","0.53604"
"20.72500","33.12468","0.53444"
"20.75000","33.16470","0.53337"
"20.77500","33.20482","0.53212"
"20.80000","33.24495","0.53065"
"20.82500","33.28507","0.52863"
"20.85000","33.32529","0.52596"
"20.87500","33.36556","0.52030"
"20.90000","33.40593","0.51159"
"20.92500","33.44635","0.50120"
"20.95000","33.48683","0.49463"
"20.97500","33.52681","0.49041"
"21.00000","33.56624","0.48653"
"21.02500","33.60580","0.48304"
"21.05000","33.64548","0.47951"
"21.07500","33.68541","0.47626"
"21.10000","33.72535","0.47328"
"21.12500","33.76520","0.47023"
"21.15000","33.80509","0.46730"
"21.17500","33.84507","0.46434"
"21.20000","33.88516","0.46167"
"21.22500","33.92538","0.45878"
"21.25000","33.96588","0.45602"
"21.27500","34.00615","0.45330"
"21.30000","34.04612","0.45093"
"21.32500","34.08609","0.44834"
"21.35000","34.12598","0.44594"
"21.37500","34.16584","0.44348"
"21.40000","34.20566","0.44095"
"21.42500","34.24557","0.43845"
"21.45000","34.28544","0.43599"
"21.47500","34.32523","0.43338"
"21.50000","34.36502","0.43089"
"21.52500","34.40490","0.42811"
"21.55000","34.44473","0.42542"
"21.57500","34.48471","0.42283"
"21.60000","34.52484","0.42014"
"21.62500","34.56504","0.41701"
"21.65000","34.60524","0.41458"
"21.67500","34.64534","0.41185"
"21.70000","34.68541","0.40912"
"21.72500","34.72561","0.40633"
"21.75000","34.76561","0.40346"
"21.77500","34.80536","0.40078"
"21.80000","34.84504","0.39771"
"21.82500","34.88478","0.39518"
"21.85000","34.92451","0.39221"
"21.87500","34.96427","0.38966"
"21.90000","35.00410","0.38696"
"21.92500","35.04430","0.38434"
"21.95000","35.08525","0.38150"
"21.97500","35.12597","0.37864"
"22.00000","35.16606","0.37552"
"22.02500","35.20599","0.37200"
"22.05000","35.24607","0.36825"
"22.07500","35.28619","0.36419"
"22.10000","35.32637","0.36006"
"22.12500","35.36665","0.35627"
"22.15000","35.40658","0.35180"
"22.17500","35.44622","0.34723"
"22.20000","35.48588","0.34243"
"22.22500","35.52566","0.33788"
"22.25000","35.56551","0.33309"
"22.27500","35.60534","0.32841"
"22.30000","35.64511","0.32359"
"22.32500","35.68498","0.31871"
"22.35000","35.72495","0.31329"
"22.37500","35.76501","0.30830"
"22.40000","35.80544","0.30337"
"22.42500","35.84569","0.29909"
"22.45000","35.88601","0.29480"
"22.47500","35.92667","0.29020"
"22.50000","35.96714","0.28579"
"22.52500","36.00690","0.28112"
"22.55000","36.04644","0.27636"
"22.57500","36.08619","0.27151"
"22.60000","36.12598","0.26689"
"22.62500","36.16575","0.26177"
"22.65000","36.20546","0.25676"
"22.67500","36.24523","0.25157"
"22.70000","36.28514","0.24579"
"22.72500","36.32528","0.24014"
"22.75000","36.36540","0.23419"
"22.77500","36.40531","0.22698"
"22.80000","36.44534","0.21985"
"22.82500","36.48556","0.20547"
"22.85000","36.52580","0.18177"
"22.87500","36.56596","0.14334"
"22.90000","36.60622","0.03974"
"22.92500","36.64628","-0.01534"
"22.95000","36.68605","-0.01867"
"22.97500","36.72591","-0.01469"
"23.00000","36.76592","-0.01275"
"23.02500","36.80584","-0.01246"
"23.05000","36.84569","-0.01292"
"23.07500","36.88551","-0.01287"
"23.10000","36.92553","-0.01324"
"23.12500","36.96554","-0.01277"
"23.15000","37.00539","-0.01304"
"23.17500","37.04534","-0.01304"
"23.20000","37.08552","-0.01307"
"23.22500","37.12583","-0.01307"
"23.25000","37.16604","-0.01303"
"23.27500","37.20607","-0.01299"
"23.30000","37.24610","-0.01305"
"23.32500","37.28605","-0.01305"
"23.35000","37.32601","-0.01296"
"23.37500","37.36613","-0.01304"
"23.40000","37.40614","-0.01315"
"23.42500","37.44593","-0.01293"
"23.45000","37.48575","-0.01316"
"23.47500","37.52562","-0.01324"
"23.50000","37.56554","-0.01307"
"23.52500","37.60620","-0.01324"
"23.55000","37.64696","-0.01308"
"23.57500","37.68690","-0.01315"
"23.60000","37.72662","-0.01314"
"23.62500","37.76650","-0.01313"
"23.65000","37.80639","-0.01304"
"23.67500","37.84632","-0.01321"
"23.70000","37.88638","-0.01317"
"23.72500","37.92651","-0.01311"
"23.75000","37.96627","-0.01295"
"23.77500","38.00583","-0.01300"
"23.80000","38.04552","-0.01307"
"23.82500","38.08542","-0.01324"
"23.85000","38.12540","-0.01336"
"23.87500","38.16546","-0.01312"
"23.90000","38.20543","-0.01310"
"23.92500","38.24529","-0.01297"
"23.95000","38.28515","-0.01310"
"23.97500","38.32516","-0.01316"
"24.00000","38.36536","-0.01315"
"24.02500","38.40564","-0.01297"
"24.05000","38.44609","-0.01320"
"24.07500","38.48635","-0.01328"
"24.10000","38.52640","-0.01332"
"24.12500","38.56654","-0.01320"
"24.15000","38.60713","-0.01314"
"24.17500","38.64677","-0.01297"
"24.20000","38.68621","-0.01311"
"24.22500","38.72587","-0.01319"
"24.25000","38.76574","-0.01324"
"24.27500","38.80558","-0.01320"
"24.30000","38.84539","-0.01350"
"24.32500","38.88528","-0.01305"
"24.35000","38.92538","-0.01322"
"24.37500","38.96556","-0.01318"
"24.40000","39.00559","-0.01331"
"24.42500","39.04567","-0.01303"
"24.45000","39.08574","-0.01269"
"24.47500","39.12563","-0.01354"
"24.50000","39.16549","-0.01303"
"24.52500","39.20534","-0.01350"
"24.55000","39.24528","-0.01305"
"24.57500","39.28514","-0.01302"
"24.60000","39.32486","-0.01318"
"24.62500","39.36457","-0.01316"
"24.65000","39.40432","-0.01329"
"24.67500","39.44429","-0.01315"
"24.70000","39.48441","-0.01315"
"24.72500","39.52465","-0.01310"
"24.75000","39.56463","-0.01342"
"24.77500","39.60535","-0.01327"
"24.80000","39.64553","-0.01308"
"24.82500","39.68525","-0.01308"
"24.85000","39.72522","-0.01319"
"24.87500","39.76534","-0.01351"
"24.90000","39.80540","-0.01310"
"24.92500","39.84536","-0.01323"
"24.95000","39.88515","-0.01323"
"24.97500","39.92492","-0.01290"
"25.00000","39.96476","-0.01318"
"25.02500","40.00468","-0.01275"
"25.05000","40.04457","-0.01325"
"25.07500","40.08450","-0.01320"
"25.10000","40.12442","-0.01320"
"25.12500","40.16425","-0.01337"
"25.15000","40.20414","-0.01304"
"25.17500","40.24419","-0.01321"
"25.20000","40.28460","-0.01305"
"25.22500","40.32492","-0.01342"
"25.25000","40.36512","-0.01296"
"25.27500","40.40554","-0.01319"
"25.30000","40.44595","-0.01307"
"25.32500","40.48564","-0.01303"
"25.35000","40.52524","-0.01344"
"25.37500","40.56503","-0.01314"
"25.40000","40.60488","-0.01313"
"25.42500","40.64473","-0.01328"
"25.45000","40.68469","-0.01337"
"25.47500","40.72471","-0.01323"
"25.50000","40.76467","-0.01278"
"25.52500","40.80462","-0.01336"
"25.55000","40.84456","-0.01298"
"25.57500","40.88457","-0.01325"
"25.60000","40.92479","-0.01343"
"25.62500","40.96526","-0.01291"
"25.65000","41.00586","-0.01307"
"25.67500","41.04609","-0.01302"
"25.70000","41.08634","-0.01324"
"25.72500","41.12663","-0.01317"
"25.75000","41.16662","-0.01314"
"25.77500","41.20628","-0.01310"
"25.80000","41.24597","-0.01290"
"25.82500","41.28578","-0.01331"
"25.85000","41.32564","-0.01306"
"25.87500","41.36551","-0.01320"
"25.90000","41.40539","-0.01322"
"25.92500","41.44556","-0.01293"
"25.95000","41.48570","-0.01341"
"25.97500","41.52571","-0.01300"
"26.00000","41.56581","-0.01328"
"26.02500","41.60611","-0.01306"
"26.05000","41.64648","-0.01319"
"26.07500","41.68641","-0.01326"
"26.10000","41.72609","-0.01289"
"26.12500","41.76585","-0.01345"
"26.15000","41.80569","-0.01312"
"26.17500","41.84559","-0.01324"
"26.20000","41.88556","-0.01313"
"26.22500","41.92561","-0.01296"
"26.25000","41.96569","-0.01316"
"26.27500","42.00573","-0.01295"
"26.30000","42.04579","-0.01329"
"26.32500","42.08644","-0.01317"
"26.35000","42.12705","-0.01316"
"26.37500","42.16686","-0.01305"
"26.40000","42.20655","-0.01289"
"26.42500","42.24638","-0.01333"
"26.45000","42.28640","-0.01308"
"26.47500","42.32650","-0.01298"
"26.50000","42.36640","-0.01325"
"26.52500","42.40622","-0.01310"
"26.55000","42.44602","-0.01331"
"26.57500","42.48584","-0.01318"
"26.60000","42.52589","-0.01322"
"26.62500","42.56585","-0.01310"
"26.65000","42.60568","-0.01324"
"26.67500","42.64553","-0.01340"
"26.70000","42.68546","-0.01292"
"26.72500","42.72547","-0.01306"
"26.75000","42.76543","-0.01326"
"26.77500","42.80539","-0.01302"
"26.80000","42.84540","-0.01342"
"26.82500","42.88552","-0.01304"
"26.85000","42.92601","-0.01317"
"26.87500","42.96593","-0.01325"
"26.90000","43.00588","-0.01319"
"26.92500","43.04641","-0.01331"
"26.95000","43.08647","-0.01309"
"26.97500","43.12596","-0.01311"
"27.00000","43.16553","-0.01306"
"27.02500","43.20533","-0.01319"
"27.05000","43.24554","-0.01322"
"27.07500","43.28552","-0.01319"
"27.10000","43.32539","-0.01307"
"27.12500","43.36530","-0.01319"
"27.15000","43.40526","-0.01312"
"27.17500","43.44530","-0.01325"
"27.20000","43.48532","-0.01308"
"27.22500","43.52526","-0.01313"
"27.25000","43.56521","-0.01324"
"27.27500","43.60541","-0.01326"
"27.30000","43.64570","-0.01306"
"27.32500","43.68576","-0.01301"
"27.35000","43.72570","-0.01321"
"27.37500","43.76577","-0.01307"
"27.40000","43.80617","-0.01324"
"27.42500","43.84612","-0.01315"
"27.45000","43.88584","-0.01321"
"27.47500","43.92564","-0.01334"
"27.50000","43.96557","-0.01320"
"27.52500","44.00549","-0.01310"
"27.55000","44.04547","-0.01317"
"27.57500","44.08556","-0.01320"
"27.60000","44.12566","-0.01328"
"27.62500","44.16576","-0.01331"
"27.65000","44.20586","-0.01329"
"27.67500","44.24585","-0.01311"
"27.70000","44.28585","-0.01319"
"27.72500","44.32584","-0.01330"
"27.75000","44.36585","-0.01309"
"27.77500","44.40587","-0.01310"
"27.80000","44.44592","-0.01338"
"27.82500","44.48600","-0.01308"
"27.83100","44.49564","-0.01311"