File: 10G1650/ST 10G1650_001.csv
Rate 1,"0.50000",mm/s
Start date,"9/3/2021"
Specimen label,""

Time,Extension,2 kg Beam Load Cell
(s),(mm),(N)
"0.00000","0.00127","-0.00012"
"0.05000","0.00127","0.00044"
"0.10000","0.00787","0.00061"
"0.15000","0.02394","0.00027"
"0.20000","0.04462","0.00054"
"0.25000","0.06810","0.00038"
"0.30000","0.09340","0.00068"
"0.35000","0.11962","0.00063"
"0.40000","0.14626","0.00100"
"0.45000","0.17328","0.00102"
"0.50000","0.20035","0.00121"
"0.55000","0.22753","0.00116"
"0.60000","0.25461","0.00111"
"0.65000","0.28160","0.00133"
"0.70000","0.30840","0.00178"
"0.75000","0.33525","0.00155"
"0.80000","0.36213","0.00193"
"0.85000","0.38881","0.00199"
"0.90000","0.41536","0.00223"
"0.95000","0.44189","0.00252"
"1.00000","0.46819","0.00253"
"1.05000","0.49452","0.00240"
"1.10000","0.52085","0.00244"
"1.15000","0.54717","0.00260"
"1.20000","0.57327","0.00289"
"1.25000","0.59940","0.00311"
"1.30000","0.62556","0.00332"
"1.35000","0.65145","0.00325"
"1.40000","0.67724","0.00368"
"1.45000","0.70298","0.00348"
"1.50000","0.72873","0.00363"
"1.55000","0.75446","0.00402"
"1.60000","0.78011","0.00404"
"1.65000","0.80582","0.00397"
"1.70000","0.83140","0.00423"
"1.75000","0.85691","0.00440"
"1.80000","0.88258","0.00479"
"1.85000","0.90824","0.00459"
"1.90000","0.93339","0.00471"
"1.95000","0.95874","0.00453"
"2.00000","0.98409","0.00472"
"2.05000","1.00944","0.00366"
"2.10000","1.03482","0.00392"
"2.15000","1.06025","0.00419"
"2.20000","1.08557","0.00389"
"2.25000","1.11091","0.00432"
"2.30000","1.13617","0.00458"
"2.35000","1.16143","0.00459"
"2.40000","1.18672","0.00461"
"2.45000","1.21201","0.00470"
"2.50000","1.23727","0.00494"
"2.55000","1.26250","0.00522"
"2.60000","1.28777","0.00537"
"2.65000","1.31300","0.00550"
"2.70000","1.33806","0.00545"
"2.75000","1.36332","0.00561"
"2.80000","1.38851","0.00560"
"2.85000","1.41355","0.00500"
"2.90000","1.43875","0.00529"
"2.95000","1.46398","0.00511"
"3.00000","1.49022","0.00521"
"3.05000","1.51517","0.00545"
"3.10000","1.53967","0.00566"
"3.15000","1.56454","0.00613"
"3.20000","1.58948","0.00549"
"3.25000","1.61457","0.00602"
"3.30000","1.63948","0.00617"
"3.35000","1.66449","0.00638"
"3.40000","1.68949","0.00654"
"3.45000","1.71452","0.00663"
"3.50000","1.73962","0.00603"
"3.55000","1.76474","0.00619"
"3.60000","1.78983","0.00663"
"3.65000","1.81489","0.00603"
"3.70000","1.83997","0.00649"
"3.75000","1.86499","0.00655"
"3.80000","1.89001","0.00633"
"3.85000","1.91508","0.00660"
"3.90000","1.94011","0.00691"
"3.95000","1.96504","0.00720"
"4.00000","1.99005","0.00734"
"4.05000","2.01502","0.00713"
"4.10000","2.04002","0.00676"
"4.15000","2.06509","0.00705"
"4.20000","2.09002","0.00746"
"4.25000","2.11492","0.00716"
"4.30000","2.13987","0.00714"
"4.35000","2.16491","0.00739"
"4.40000","2.18980","0.00774"
"4.45000","2.21476","0.00769"
"4.50000","2.23995","0.00783"
"4.55000","2.26509","0.00785"
"4.60000","2.28997","0.00788"
"4.65000","2.31515","0.00786"
"4.70000","2.34161","0.00837"
"4.75000","2.36592","0.00840"
"4.80000","2.39046","0.00846"
"4.85000","2.41529","0.00862"
"4.90000","2.44018","0.00887"
"4.95000","2.46516","0.00864"
"5.00000","2.49011","0.00910"
"5.05000","2.51514","0.00914"
"5.10000","2.54012","0.00935"
"5.15000","2.56515","0.00937"
"5.20000","2.59025","0.00935"
"5.25000","2.61526","0.00809"
"5.30000","2.64020","0.00848"
"5.35000","2.66532","0.00877"
"5.40000","2.69034","0.00865"
"5.45000","2.71513","0.00876"
"5.50000","2.74007","0.00901"
"5.55000","2.76516","0.00922"
"5.60000","2.79005","0.00957"
"5.65000","2.81506","0.00931"
"5.70000","2.84010","0.00969"
"5.75000","2.86508","0.00968"
"5.80000","2.89019","0.00976"
"5.85000","2.91514","0.00976"
"5.90000","2.94018","0.00927"
"5.95000","2.96518","0.00957"
"6.00000","2.99016","0.00940"
"6.05000","3.01524","0.00999"
"6.10000","3.04020","0.00990"
"6.15000","3.06524","0.00996"
"6.20000","3.09145","0.01037"
"6.25000","3.11641","0.01054"
"6.30000","3.14073","0.01055"
"6.35000","3.16556","0.01064"
"6.40000","3.19045","0.01081"
"6.45000","3.21520","0.01106"
"6.50000","3.24019","0.01118"
"6.55000","3.26519","0.01121"
"6.60000","3.29002","0.01126"
"6.65000","3.31498","0.01148"
"6.70000","3.34016","0.01133"
"6.75000","3.36517","0.01118"
"6.80000","3.39007","0.01103"
"6.85000","3.41502","0.01084"
"6.90000","3.44001","0.01141"
"6.95000","3.46500","0.01140"
"7.00000","3.48999","0.01149"
"7.05000","3.51506","0.01111"
"7.10000","3.54040","0.01127"
"7.15000","3.56521","0.01160"
"7.20000","3.59011","0.01188"
"7.25000","3.61505","0.01201"
"7.30000","3.64007","0.01215"
"7.35000","3.66508","0.01182"
"7.40000","3.69014","0.01180"
"7.45000","3.71507","0.01199"
"7.50000","3.74005","0.01221"
"7.55000","3.76505","0.01245"
"7.60000","3.79004","0.01248"
"7.65000","3.81513","0.01296"
"7.70000","3.84017","0.01272"
"7.75000","3.86518","0.01296"
"7.80000","3.89018","0.01312"
"7.85000","3.91625","0.01318"
"7.90000","3.94083","0.01325"
"7.95000","3.96532","0.01277"
"8.00000","3.99014","0.01304"
"8.05000","4.01505","0.01338"
"8.10000","4.04003","0.01336"
"8.15000","4.06508","0.01349"
"8.20000","4.09019","0.01333"
"8.25000","4.11535","0.01310"
"8.30000","4.14025","0.01347"
"8.35000","4.16518","0.01368"
"8.40000","4.19011","0.01359"
"8.45000","4.21503","0.01358"
"8.50000","4.24001","0.01422"
"8.55000","4.26539","0.01391"
"8.60000","4.29009","0.01433"
"8.65000","4.31500","0.01470"
"8.70000","4.33993","0.01477"
"8.75000","4.36494","0.01464"
"8.80000","4.38993","0.01427"
"8.85000","4.41489","0.01426"
"8.90000","4.43993","0.01474"
"8.95000","4.46503","0.01469"
"9.00000","4.49014","0.01472"
"9.05000","4.51511","0.01502"
"9.10000","4.54049","0.01546"
"9.15000","4.56529","0.01523"
"9.20000","4.59006","0.01571"
"9.25000","4.61500","0.01555"
"9.30000","4.63998","0.01567"
"9.35000","4.66501","0.01598"
"9.40000","4.69001","0.01620"
"9.45000","4.71518","0.01604"
"9.50000","4.74022","0.01538"
"9.55000","4.76529","0.01596"
"9.60000","4.79032","0.01585"
"9.65000","4.81534","0.01589"
"9.70000","4.84027","0.01580"
"9.75000","4.86514","0.01613"
"9.80000","4.89007","0.01662"
"9.85000","4.91503","0.01651"
"9.90000","4.94004","0.01658"
"9.95000","4.96506","0.01692"
"10.00000","4.99022","0.01708"
"10.05000","5.01658","0.01751"
"10.10000","5.04116","0.01734"
"10.15000","5.06559","0.01740"
"10.20000","5.09034","0.01767"
"10.25000","5.11518","0.01798"
"10.30000","5.14016","0.01723"
"10.35000","5.16514","0.01702"
"10.40000","5.19013","0.01737"
"10.45000","5.21509","0.01738"
"10.50000","5.24020","0.01746"
"10.55000","5.26520","0.01791"
"10.60000","5.29014","0.01784"
"10.65000","5.31529","0.01802"
"10.70000","5.34031","0.01822"
"10.75000","5.36528","0.01836"
"10.80000","5.39032","0.01858"
"10.85000","5.41529","0.01867"
"10.90000","5.44028","0.01869"
"10.95000","5.46521","0.01888"
"11.00000","5.49018","0.01839"
"11.05000","5.51507","0.01877"
"11.10000","5.53997","0.01885"
"11.15000","5.56497","0.01900"
"11.20000","5.58995","0.01886"
"11.25000","5.61492","0.01950"
"11.30000","5.64118","0.01941"
"11.35000","5.66568","0.01967"
"11.40000","5.69024","0.01971"
"11.45000","5.71517","0.01960"
"11.50000","5.74016","0.01977"
"11.55000","5.76506","0.02010"
"11.60000","5.78999","0.02030"
"11.65000","5.81501","0.02057"
"11.70000","5.84003","0.02070"
"11.75000","5.86508","0.02024"
"11.80000","5.89011","0.02057"
"11.85000","5.91515","0.02077"
"11.90000","5.94025","0.02058"
"11.95000","5.96524","0.02090"
"12.00000","5.99024","0.02109"
"12.05000","6.01529","0.02104"
"12.10000","6.04030","0.02142"
"12.15000","6.06532","0.02144"
"12.20000","6.09034","0.02165"
"12.25000","6.11531","0.02184"
"12.30000","6.14020","0.02182"
"12.35000","6.16511","0.02145"
"12.40000","6.19003","0.02169"
"12.45000","6.21510","0.02152"
"12.50000","6.24003","0.02157"
"12.55000","6.26591","0.02203"
"12.60000","6.29032","0.02175"
"12.65000","6.31502","0.02208"
"12.70000","6.33997","0.02239"
"12.75000","6.36500","0.02245"
"12.80000","6.39007","0.02258"
"12.85000","6.41516","0.02275"
"12.90000","6.44018","0.02290"
"12.95000","6.46516","0.02312"
"13.00000","6.49017","0.02341"
"13.05000","6.51520","0.02343"
"13.10000","6.54027","0.02342"
"13.15000","6.56532","0.02357"
"13.20000","6.59032","0.02389"
"13.25000","6.61535","0.02406"
"13.30000","6.64030","0.02433"
"13.35000","6.66529","0.02426"
"13.40000","6.69025","0.02448"
"13.45000","6.71523","0.02336"
"13.50000","6.74017","0.02381"
"13.55000","6.76511","0.02411"
"13.60000","6.79001","0.02400"
"13.65000","6.81497","0.02402"
"13.70000","6.83990","0.02474"
"13.75000","6.86485","0.02482"
"13.80000","6.88980","0.02487"
"13.85000","6.91487","0.02496"
"13.90000","6.93999","0.02496"
"13.95000","6.96527","0.02513"
"14.00000","6.99034","0.02570"
"14.05000","7.01525","0.02586"
"14.10000","7.04020","0.02582"
"14.15000","7.06516","0.02536"
"14.20000","7.09016","0.02562"
"14.25000","7.11520","0.02558"
"14.30000","7.14022","0.02608"
"14.35000","7.16532","0.02604"
"14.40000","7.19034","0.02615"
"14.45000","7.21534","0.02652"
"14.50000","7.24039","0.02646"
"14.55000","7.26541","0.02660"
"14.60000","7.29048","0.02691"
"14.65000","7.31580","0.02720"
"14.70000","7.34232","0.02752"
"14.75000","7.36643","0.02721"
"14.80000","7.39084","0.02679"
"14.85000","7.41546","0.02710"
"14.90000","7.44031","0.02743"
"14.95000","7.46511","0.02758"
"15.00000","7.48997","0.02779"
"15.05000","7.51491","0.02788"
"15.10000","7.54003","0.02770"
"15.15000","7.56498","0.02840"
"15.20000","7.58999","0.02851"
"15.25000","7.61500","0.02879"
"15.30000","7.64007","0.02903"
"15.35000","7.66507","0.02897"
"15.40000","7.69006","0.02888"
"15.45000","7.71512","0.02940"
"15.50000","7.74020","0.02955"
"15.55000","7.76524","0.02981"
"15.60000","7.79025","0.02854"
"15.65000","7.81542","0.02868"
"15.70000","7.84054","0.02878"
"15.75000","7.86542","0.02897"
"15.80000","7.89041","0.02905"
"15.85000","7.91536","0.02954"
"15.90000","7.94037","0.02984"
"15.95000","7.96531","0.02960"
"16.00000","7.99030","0.02987"
"16.05000","8.01527","0.03039"
"16.10000","8.04018","0.03012"
"16.15000","8.06516","0.03073"
"16.20000","8.09007","0.03070"
"16.25000","8.11508","0.03095"
"16.30000","8.13995","0.03109"
"16.35000","8.16483","0.03129"
"16.40000","8.18984","0.03128"
"16.45000","8.21501","0.03176"
"16.50000","8.24024","0.03174"
"16.55000","8.26528","0.03180"
"16.60000","8.29016","0.03227"
"16.65000","8.31512","0.03230"
"16.70000","8.34021","0.03125"
"16.75000","8.36525","0.03069"
"16.80000","8.39023","0.03138"
"16.85000","8.41527","0.03147"
"16.90000","8.44022","0.03124"
"16.95000","8.46532","0.03147"
"17.00000","8.49041","0.03200"
"17.05000","8.51545","0.03210"
"17.10000","8.54043","0.03218"
"17.15000","8.56586","0.03230"
"17.20000","8.59219","0.03282"
"17.25000","8.61613","0.03271"
"17.30000","8.64068","0.03310"
"17.35000","8.66549","0.03270"
"17.40000","8.69025","0.03262"
"17.45000","8.71514","0.03267"
"17.50000","8.74010","0.03325"
"17.55000","8.76507","0.03309"
"17.60000","8.78994","0.03353"
"17.65000","8.81495","0.03371"
"17.70000","8.83983","0.03389"
"17.75000","8.86495","0.03420"
"17.80000","8.89004","0.03418"
"17.85000","8.91503","0.03404"
"17.90000","8.94003","0.03466"
"17.95000","8.96501","0.03473"
"18.00000","8.99004","0.03439"
"18.05000","9.01514","0.03445"
"18.10000","9.04035","0.03458"
"18.15000","9.06536","0.03449"
"18.20000","9.09032","0.03483"
"18.25000","9.11538","0.03506"
"18.30000","9.14030","0.03526"
"18.35000","9.16532","0.03531"
"18.40000","9.19031","0.03541"
"18.45000","9.21532","0.03556"
"18.50000","9.24031","0.03601"
"18.55000","9.26538","0.03607"
"18.60000","9.29047","0.03632"
"18.65000","9.31565","0.03644"
"18.70000","9.34047","0.03659"
"18.75000","9.36545","0.03642"
"18.80000","9.39010","0.03663"
"18.85000","9.41510","0.03685"
"18.90000","9.44009","0.03693"
"18.95000","9.46505","0.03715"
"19.00000","9.49018","0.03732"
"19.05000","9.51511","0.03784"
"19.10000","9.54011","0.03792"
"19.15000","9.56505","0.03791"
"19.20000","9.59001","0.03807"
"19.25000","9.61503","0.03786"
"19.30000","9.64012","0.03793"
"19.35000","9.66515","0.03856"
"19.40000","9.69017","0.03860"
"19.45000","9.71548","0.03819"
"19.50000","9.74068","0.03848"
"19.55000","9.76556","0.03902"
"19.60000","9.79041","0.03870"
"19.65000","9.81548","0.03881"
"19.70000","9.84052","0.03896"
"19.75000","9.86553","0.03926"
"19.80000","9.89059","0.03939"
"19.85000","9.91557","0.03951"
"19.90000","9.94044","0.03960"
"19.95000","9.96537","0.04024"
"20.00000","9.99030","0.03999"
"20.05000","10.01523","0.04053"
"20.10000","10.04025","0.04047"
"20.15000","10.06518","0.04053"
"20.20000","10.09016","0.03981"
"20.25000","10.11516","0.04046"
"20.30000","10.14029","0.04006"
"20.35000","10.16548","0.04012"
"20.40000","10.19147","0.03991"
"20.45000","10.21671","0.04077"
"20.50000","10.24096","0.04100"
"20.55000","10.26570","0.04114"
"20.60000","10.29038","0.04094"
"20.65000","10.31532","0.04159"
"20.70000","10.34028","0.04173"
"20.75000","10.36524","0.04187"
"20.80000","10.39028","0.04222"
"20.85000","10.41527","0.04214"
"20.90000","10.44049","0.04224"
"20.95000","10.46537","0.04261"
"21.00000","10.49036","0.04241"
"21.05000","10.51539","0.04244"
"21.10000","10.54034","0.04278"
"21.15000","10.56526","0.04278"
"21.20000","10.59015","0.04296"
"21.25000","10.61521","0.04340"
"21.30000","10.64017","0.04341"
"21.35000","10.66517","0.04325"
"21.40000","10.69015","0.04278"
"21.45000","10.71527","0.04324"
"21.50000","10.74059","0.04333"
"21.55000","10.76536","0.04320"
"21.60000","10.79018","0.04334"
"21.65000","10.81522","0.04362"
"21.70000","10.84033","0.04391"
"21.75000","10.86535","0.04416"
"21.80000","10.89006","0.04431"
"21.85000","10.91512","0.04431"
"21.90000","10.94019","0.04434"
"21.95000","10.96515","0.04458"
"22.00000","10.99012","0.04499"
"22.05000","11.01514","0.04429"
"22.10000","11.04019","0.04455"
"22.15000","11.06530","0.04459"
"22.20000","11.09033","0.04509"
"22.25000","11.11542","0.04501"
"22.30000","11.14050","0.04539"
"22.35000","11.16568","0.04557"
"22.40000","11.19063","0.04592"
"22.45000","11.21568","0.04577"
"22.50000","11.24043","0.04604"
"22.55000","11.26539","0.04581"
"22.60000","11.29099","0.04588"
"22.65000","11.31619","0.04638"
"22.70000","11.34047","0.04658"
"22.75000","11.36526","0.04650"
"22.80000","11.39017","0.04648"
"22.85000","11.41516","0.04685"
"22.90000","11.44031","0.04700"
"22.95000","11.46532","0.04711"
"23.00000","11.49029","0.04705"
"23.05000","11.51523","0.04704"
"23.10000","11.54028","0.04752"
"23.15000","11.56532","0.04783"
"23.20000","11.59029","0.04768"
"23.25000","11.61526","0.04805"
"23.30000","11.64029","0.04818"
"23.35000","11.66539","0.04836"
"23.40000","11.69049","0.04813"
"23.45000","11.71548","0.04776"
"23.50000","11.74050","0.04786"
"23.55000","11.76551","0.04824"
"23.60000","11.79055","0.04832"
"23.65000","11.81554","0.04875"
"23.70000","11.84042","0.04879"
"23.75000","11.86535","0.04889"
"23.80000","11.89034","0.04895"
"23.85000","11.91540","0.04958"
"23.90000","11.94050","0.04953"
"23.95000","11.96535","0.04966"
"24.00000","11.99030","0.04989"
"24.05000","12.01519","0.04964"
"24.10000","12.04018","0.04945"
"24.15000","12.06514","0.04996"
"24.20000","12.09025","0.04991"
"24.25000","12.11532","0.05018"
"24.30000","12.14034","0.05029"
"24.35000","12.16534","0.05048"
"24.40000","12.19029","0.05090"
"24.45000","12.21524","0.05126"
"24.50000","12.24028","0.05118"
"24.55000","12.26529","0.05127"
"24.60000","12.29034","0.05144"
"24.65000","12.31538","0.05152"
"24.70000","12.34036","0.05085"
"24.75000","12.36537","0.05121"
"24.80000","12.39044","0.05142"
"24.85000","12.41570","0.05160"
"24.90000","12.44052","0.05166"
"24.95000","12.46536","0.05156"
"25.00000","12.49170","0.05155"
"25.05000","12.51586","0.05150"
"25.10000","12.54038","0.05161"
"25.15000","12.56526","0.05216"
"25.20000","12.59017","0.05226"
"25.25000","12.61523","0.05233"
"25.30000","12.64023","0.05268"
"25.35000","12.66521","0.05279"
"25.40000","12.69017","0.05295"
"25.45000","12.71537","0.05324"
"25.50000","12.74032","0.05323"
"25.55000","12.76532","0.05338"
"25.60000","12.79046","0.05323"
"25.65000","12.81549","0.05320"
"25.70000","12.84038","0.05369"
"25.75000","12.86541","0.05367"
"25.80000","12.89043","0.05348"
"25.85000","12.91547","0.05376"
"25.90000","12.94060","0.05405"
"25.95000","12.96568","0.05419"
"26.00000","12.99067","0.05448"
"26.05000","13.01570","0.05453"
"26.10000","13.04043","0.05427"
"26.15000","13.06535","0.05415"
"26.20000","13.09027","0.05444"
"26.25000","13.11532","0.05440"
"26.30000","13.14030","0.05461"
"26.35000","13.16526","0.05460"
"26.40000","13.19030","0.05459"
"26.45000","13.21569","0.05507"
"26.50000","13.24040","0.05521"
"26.55000","13.26524","0.05534"
"26.60000","13.29010","0.05557"
"26.65000","13.31513","0.05528"
"26.70000","13.34020","0.05547"
"26.75000","13.36523","0.05560"
"26.80000","13.39031","0.05567"
"26.85000","13.41531","0.05601"
"26.90000","13.44030","0.05566"
"26.95000","13.46538","0.05526"
"27.00000","13.49044","0.05549"
"27.05000","13.51544","0.05560"
"27.10000","13.54050","0.05546"
"27.15000","13.56557","0.05630"
"27.20000","13.59168","0.05559"
"27.25000","13.61639","0.05550"
"27.30000","13.64070","0.05569"
"27.35000","13.66544","0.05577"
"27.40000","13.69026","0.05597"
"27.45000","13.71514","0.05616"
"27.50000","13.74007","0.05651"
"27.55000","13.76513","0.05641"
"27.60000","13.79013","0.05658"
"27.65000","13.81518","0.05682"
"27.70000","13.84016","0.05680"
"27.75000","13.86519","0.05678"
"27.80000","13.89028","0.05633"
"27.85000","13.91514","0.05644"
"27.90000","13.94019","0.05692"
"27.95000","13.96519","0.05675"
"28.00000","13.99027","0.05683"
"28.05000","14.01528","0.05715"
"28.10000","14.04042","0.05712"
"28.15000","14.06558","0.05742"
"28.20000","14.09055","0.05730"
"28.25000","14.11554","0.05761"
"28.30000","14.14044","0.05772"
"28.35000","14.16539","0.05771"
"28.40000","14.19039","0.05793"
"28.45000","14.21530","0.05825"
"28.50000","14.24028","0.05821"
"28.55000","14.26515","0.05764"
"28.60000","14.29013","0.05770"
"28.65000","14.31506","0.05807"
"28.70000","14.34006","0.05790"
"28.75000","14.36508","0.05832"
"28.80000","14.39016","0.05859"
"28.85000","14.41539","0.05844"
"28.90000","14.44041","0.05852"
"28.95000","14.46574","0.05864"
"29.00000","14.49099","0.05875"
"29.05000","14.51548","0.05898"
"29.10000","14.54021","0.05834"
"29.15000","14.56517","0.05851"
"29.20000","14.59020","0.05882"
"29.25000","14.61526","0.05865"
"29.30000","14.64034","0.05852"
"29.35000","14.66539","0.05889"
"29.40000","14.69037","0.05842"
"29.45000","14.71539","0.05847"
"29.50000","14.74039","0.05863"
"29.55000","14.76540","0.05871"
"29.60000","14.79039","0.05865"
"29.65000","14.81540","0.05870"
"29.70000","14.84043","0.05872"
"29.75000","14.86537","0.05856"
"29.80000","14.89033","0.05880"
"29.85000","14.91525","0.05855"
"29.90000","14.94021","0.05881"
"29.95000","14.96527","0.05880"
"30.00000","14.99032","0.05888"
"30.05000","15.01572","0.05919"
"30.10000","15.04057","0.05919"
"30.15000","15.06539","0.05919"
"30.20000","15.09027","0.05913"
"30.25000","15.11528","0.05898"
"30.30000","15.14152","0.05879"
"30.35000","15.16676","0.05891"
"30.40000","15.19068","0.05897"
"30.45000","15.21550","0.05884"
"30.50000","15.24033","0.05907"
"30.55000","15.26521","0.05896"
"30.60000","15.29015","0.05907"
"30.65000","15.31522","0.05938"
"30.70000","15.34029","0.05902"
"30.75000","15.36538","0.05899"
"30.80000","15.39047","0.05919"
"30.85000","15.41545","0.05923"
"30.90000","15.44044","0.05961"
"30.95000","15.46529","0.05928"
"31.00000","15.49032","0.05912"
"31.05000","15.51547","0.05914"
"31.10000","15.54048","0.05942"
"31.15000","15.56533","0.05913"
"31.20000","15.59016","0.05922"
"31.25000","15.61513","0.05923"
"31.30000","15.64007","0.05920"
"31.35000","15.66503","0.05933"
"31.40000","15.69000","0.05968"
"31.45000","15.71500","0.05917"
"31.50000","15.74000","0.05939"
"31.55000","15.76515","0.05930"
"31.60000","15.79021","0.05916"
"31.65000","15.81580","0.05937"
"31.70000","15.84058","0.05940"
"31.75000","15.86542","0.05945"
"31.80000","15.89023","0.05951"
"31.85000","15.91510","0.05942"
"31.90000","15.94016","0.05873"
"31.95000","15.96535","0.05899"
"32.00000","15.99042","0.05900"
"32.05000","16.01536","0.05891"
"32.10000","16.04036","0.05884"
"32.15000","16.06537","0.05893"
"32.20000","16.09037","0.05901"
"32.25000","16.11535","0.05914"
"32.30000","16.14040","0.05902"
"32.35000","16.16533","0.05919"
"32.40000","16.19043","0.05927"
"32.45000","16.21528","0.05897"
"32.50000","16.24021","0.05875"
"32.55000","16.26559","0.05910"
"32.60000","16.29064","0.05873"
"32.65000","16.31633","0.05884"
"32.70000","16.34069","0.05894"
"32.75000","16.36526","0.05846"
"32.80000","16.39017","0.05828"
"32.85000","16.41506","0.05857"
"32.90000","16.43997","0.05832"
"32.95000","16.46490","0.05845"
"33.00000","16.49002","0.05854"
"33.05000","16.51509","0.05869"
"33.10000","16.54017","0.05865"
"33.15000","16.56528","0.05873"
"33.20000","16.59040","0.05850"
"33.25000","16.61547","0.05873"
"33.30000","16.64053","0.05839"
"33.35000","16.66556","0.05869"
"33.40000","16.69052","0.05860"
"33.45000","16.71570","0.05851"
"33.50000","16.74070","0.05836"
"33.55000","16.76561","0.05851"
"33.60000","16.79051","0.05846"
"33.65000","16.81527","0.05841"
"33.70000","16.84018","0.05874"
"33.75000","16.86508","0.05785"
"33.80000","16.89001","0.05776"
"33.85000","16.91504","0.05816"
"33.90000","16.93993","0.05806"
"33.95000","16.96494","0.05804"
"34.00000","16.98986","0.05806"
"34.05000","17.01492","0.05805"
"34.10000","17.03995","0.05810"
"34.15000","17.06491","0.05814"
"34.20000","17.08984","0.05821"
"34.25000","17.11477","0.05745"
"34.30000","17.13983","0.05764"
"34.35000","17.16503","0.05737"
"34.40000","17.19078","0.05753"
"34.45000","17.21546","0.05726"
"34.50000","17.24049","0.05733"
"34.55000","17.26565","0.05739"
"34.60000","17.29060","0.05755"
"34.65000","17.31568","0.05733"
"34.70000","17.34095","0.05762"
"34.75000","17.36587","0.05734"
"34.80000","17.39063","0.05745"
"34.85000","17.41559","0.05755"
"34.90000","17.44065","0.05668"
"34.95000","17.46563","0.05618"
"35.00000","17.49053","0.05671"
"35.05000","17.51542","0.05638"
"35.10000","17.54028","0.05663"
"35.15000","17.56524","0.05666"
"35.20000","17.59016","0.05643"
"35.25000","17.61507","0.05630"
"35.30000","17.64002","0.05654"
"35.35000","17.66496","0.05617"
"35.40000","17.68998","0.05654"
"35.45000","17.71491","0.05605"
"35.50000","17.73996","0.05615"
"35.55000","17.76501","0.05627"
"35.60000","17.79008","0.05563"
"35.65000","17.81526","0.05539"
"35.70000","17.84027","0.05509"
"35.75000","17.86542","0.05533"
"35.80000","17.89050","0.05497"
"35.85000","17.91628","0.05514"
"35.90000","17.94098","0.05499"
"35.95000","17.96592","0.05470"
"36.00000","17.99097","0.05496"
"36.05000","18.01661","0.05460"
"36.10000","18.04195","0.05478"
"36.15000","18.06579","0.05483"
"36.20000","18.09055","0.05474"
"36.25000","18.11554","0.05447"
"36.30000","18.14033","0.05413"
"36.35000","18.16515","0.05430"
"36.40000","18.19007","0.05404"
"36.45000","18.21499","0.05415"
"36.50000","18.24001","0.05382"
"36.55000","18.26501","0.05408"
"36.60000","18.28999","0.05397"
"36.65000","18.31490","0.05422"
"36.70000","18.33984","0.05404"
"36.75000","18.36488","0.05446"
"36.80000","18.38992","0.05333"
"36.85000","18.41501","0.05350"
"36.90000","18.44016","0.05363"
"36.95000","18.46531","0.05376"
"37.00000","18.49060","0.05341"
"37.05000","18.51561","0.05360"
"37.10000","18.54055","0.05341"
"37.15000","18.56557","0.05325"
"37.20000","18.59060","0.05321"
"37.25000","18.61558","0.05335"
"37.30000","18.64062","0.05309"
"37.35000","18.66562","0.05310"
"37.40000","18.69061","0.05292"
"37.45000","18.71558","0.05330"
"37.50000","18.74074","0.05298"
"37.55000","18.76549","0.05279"
"37.60000","18.79029","0.05285"
"37.65000","18.81524","0.05307"
"37.70000","18.84018","0.05283"
"37.75000","18.86511","0.05330"
"37.80000","18.89006","0.05304"
"37.85000","18.91506","0.05315"
"37.90000","18.94013","0.05295"
"37.95000","18.96534","0.05251"
"38.00000","18.99024","0.05267"
"38.05000","19.01516","0.05274"
"38.10000","19.03987","0.05273"
"38.15000","19.06479","0.05253"
"38.20000","19.09003","0.05275"
"38.25000","19.11526","0.05271"
"38.30000","19.14028","0.05273"
"38.35000","19.16554","0.05273"
"38.40000","19.19064","0.05274"
"38.45000","19.21567","0.05236"
"38.50000","19.24067","0.05217"
"38.55000","19.26567","0.05226"
"38.60000","19.29067","0.05244"
"38.65000","19.31560","0.05205"
"38.70000","19.34053","0.05215"
"38.75000","19.36555","0.05193"
"38.80000","19.39050","0.05207"
"38.85000","19.41549","0.05203"
"38.90000","19.44031","0.05219"
"38.95000","19.46530","0.05178"
"39.00000","19.49034","0.05197"
"39.05000","19.51523","0.05174"
"39.10000","19.54023","0.05183"
"39.15000","19.56633","0.05143"
"39.20000","19.59108","0.05129"
"39.25000","19.61529","0.05089"
"39.30000","19.64007","0.05114"
"39.35000","19.66499","0.05099"
"39.40000","19.68996","0.05094"
"39.45000","19.71509","0.05088"
"39.50000","19.74025","0.05116"
"39.55000","19.76540","0.05080"
"39.60000","19.79054","0.05124"
"39.65000","19.81566","0.05112"
"39.70000","19.84078","0.05068"
"39.75000","19.86609","0.05056"
"39.80000","19.89116","0.05082"
"39.85000","19.91596","0.05021"
"39.90000","19.94086","0.05077"
"39.95000","19.96574","0.05062"
"40.00000","19.99064","0.05017"
"40.05000","20.01550","0.05027"
"40.10000","20.04036","0.05030"
"40.15000","20.06529","0.05054"
"40.20000","20.09022","0.05063"
"40.25000","20.11513","0.05079"
"40.30000","20.14002","0.05050"
"40.35000","20.16500","0.05043"
"40.40000","20.19026","0.05051"
"40.45000","20.21531","0.05063"
"40.50000","20.24028","0.05083"
"40.55000","20.26504","0.05088"
"40.60000","20.29001","0.05085"
"40.65000","20.31500","0.05092"
"40.70000","20.34007","0.05051"
"40.75000","20.36516","0.05090"
"40.80000","20.39019","0.05079"
"40.85000","20.41523","0.05095"
"40.90000","20.44044","0.05105"
"40.95000","20.46559","0.05132"
"41.00000","20.49212","0.05110"
"41.05000","20.51656","0.05117"
"41.10000","20.54104","0.05117"
"41.15000","20.56584","0.05124"
"41.20000","20.59067","0.05127"
"41.25000","20.61558","0.05158"
"41.30000","20.64041","0.05158"
"41.35000","20.66534","0.05184"
"41.40000","20.69063","0.05135"
"41.45000","20.71581","0.05163"
"41.50000","20.74024","0.05162"
"41.55000","20.76505","0.05165"
"41.60000","20.78992","0.05193"
"41.65000","20.81490","0.05230"
"41.70000","20.84000","0.05193"
"41.75000","20.86491","0.05206"
"41.80000","20.88993","0.05219"
"41.85000","20.91496","0.05228"
"41.90000","20.93996","0.05229"
"41.95000","20.96527","0.05235"
"42.00000","20.99026","0.05227"
"42.05000","21.01533","0.05206"
"42.10000","21.04025","0.05183"
"42.15000","21.06532","0.05213"
"42.20000","21.09047","0.05208"
"42.25000","21.11557","0.05224"
"42.30000","21.14069","0.05217"
"42.35000","21.16578","0.05248"
"42.40000","21.19078","0.05254"
"42.45000","21.21576","0.05222"
"42.50000","21.24082","0.05242"
"42.55000","21.26582","0.05242"
"42.60000","21.29063","0.05243"
"42.65000","21.31549","0.05258"
"42.70000","21.34033","0.05179"
"42.75000","21.36528","0.05122"
"42.80000","21.39021","0.05132"
"42.85000","21.41510","0.05108"
"42.90000","21.44009","0.05107"
"42.95000","21.46511","0.05113"
"43.00000","21.49011","0.05109"
"43.05000","21.51509","0.05086"
"43.10000","21.54002","0.05112"
"43.15000","21.56507","0.05102"
"43.20000","21.59026","0.05110"
"43.25000","21.61533","0.05111"
"43.30000","21.64162","0.05121"
"43.35000","21.66650","0.05108"
"43.40000","21.69078","0.05078"
"43.45000","21.71571","0.05060"
"43.50000","21.74077","0.05083"
"43.55000","21.76586","0.05069"
"43.60000","21.79079","0.05065"
"43.65000","21.81576","0.05084"
"43.70000","21.84072","0.05104"
"43.75000","21.86571","0.05095"
"43.80000","21.89062","0.05079"
"43.85000","21.91545","0.04962"
"43.90000","21.94040","0.04973"
"43.95000","21.96534","0.05003"
"44.00000","21.99049","0.04987"
"44.05000","22.01576","0.04977"
"44.10000","22.04027","0.04992"
"44.15000","22.06518","0.04999"
"44.20000","22.09017","0.04972"
"44.25000","22.11516","0.04983"
"44.30000","22.14014","0.05003"
"44.35000","22.16516","0.04971"
"44.40000","22.19013","0.04948"
"44.45000","22.21515","0.04944"
"44.50000","22.24026","0.04937"
"44.55000","22.26540","0.04929"
"44.60000","22.29050","0.04924"
"44.65000","22.31558","0.04824"
"44.70000","22.34070","0.04788"
"44.75000","22.36572","0.04584"
"44.80000","22.39067","0.04446"
"44.85000","22.41559","0.04422"
"44.90000","22.44090","0.04366"
"44.95000","22.46600","0.04136"
"45.00000","22.49062","0.03998"
"45.05000","22.51556","0.03853"
"45.10000","22.54051","0.03695"
"45.15000","22.56534","0.03649"
"45.20000","22.59020","0.03585"
"45.25000","22.61500","0.03529"
"45.30000","22.63990","0.03518"
"45.35000","22.66491","0.03440"
"45.40000","22.68993","0.03470"
"45.45000","22.71487","0.03454"
"45.50000","22.73991","0.03436"
"45.55000","22.76496","0.03355"
"45.60000","22.79006","0.03342"
"45.65000","22.81512","0.03315"
"45.70000","22.84013","0.03323"
"45.75000","22.86519","0.03310"
"45.80000","22.89025","0.03303"
"45.85000","22.91526","0.03298"
"45.90000","22.94033","0.03259"
"45.95000","22.96580","0.03235"
"46.00000","22.99261","0.03217"
"46.05000","23.01707","0.03138"
"46.10000","23.04119","0.03099"
"46.15000","23.06601","0.03108"
"46.20000","23.09086","0.03077"
"46.25000","23.11571","0.03071"
"46.30000","23.14061","0.03066"
"46.35000","23.16545","0.03046"
"46.40000","23.19026","0.03040"
"46.45000","23.21525","0.03013"
"46.50000","23.24018","0.02985"
"46.55000","23.26513","0.02990"
"46.60000","23.29010","0.02970"
"46.65000","23.31508","0.02937"
"46.70000","23.33996","0.02944"
"46.75000","23.36487","0.02943"
"46.80000","23.38993","0.02928"
"46.85000","23.41500","0.02928"
"46.90000","23.44020","0.02874"
"46.95000","23.46519","0.02829"
"47.00000","23.49013","0.02836"
"47.05000","23.51511","0.02811"
"47.10000","23.54013","0.02793"
"47.15000","23.56518","0.02803"
"47.20000","23.59026","0.02796"
"47.25000","23.61541","0.02746"
"47.30000","23.64049","0.02785"
"47.35000","23.66570","0.02761"
"47.40000","23.69088","0.02768"
"47.45000","23.71580","0.02759"
"47.50000","23.74071","0.02735"
"47.55000","23.76556","0.02717"
"47.60000","23.79026","0.02728"
"47.65000","23.81516","0.02703"
"47.70000","23.84003","0.02699"
"47.75000","23.86498","0.02562"
"47.80000","23.89002","0.02534"
"47.85000","23.91502","0.02551"
"47.90000","23.94003","0.02536"
"47.95000","23.96505","0.02528"
"48.00000","23.99009","0.02527"
"48.05000","24.01499","0.02522"
"48.10000","24.04154","0.02501"
"48.15000","24.06589","0.02483"
"48.20000","24.09026","0.02508"
"48.25000","24.11503","0.02470"
"48.30000","24.13998","0.02477"
"48.35000","24.16507","0.02418"
"48.40000","24.19012","0.02397"
"48.45000","24.21513","0.02374"
"48.50000","24.24030","0.02334"
"48.55000","24.26531","0.02302"
"48.60000","24.29033","0.02294"
"48.65000","24.31545","0.02223"
"48.70000","24.34054","0.02199"
"48.75000","24.36558","0.02177"
"48.80000","24.39058","0.02162"
"48.85000","24.41562","0.02147"
"48.90000","24.44048","0.02137"
"48.95000","24.46533","0.02114"
"49.00000","24.49031","0.02090"
"49.05000","24.51534","0.02070"
"49.10000","24.54032","0.02049"
"49.15000","24.56510","0.01963"
"49.20000","24.59000","0.01973"
"49.25000","24.61493","0.01957"
"49.30000","24.63988","0.01902"
"49.35000","24.66495","0.01876"
"49.40000","24.68995","0.01797"
"49.45000","24.71495","0.01792"
"49.50000","24.73998","0.01613"
"49.55000","24.76500","0.01439"
"49.60000","24.79017","0.01336"
"49.65000","24.81522","0.01198"
"49.70000","24.84031","0.01071"
"49.75000","24.86539","0.00894"
"49.80000","24.89044","0.00709"
"49.85000","24.91544","0.00463"
"49.90000","24.94049","-0.00344"
"49.95000","24.96561","-0.01024"
"50.00000","24.99071","-0.01033"
"50.05000","25.01682","-0.00984"
"50.10000","25.04131","-0.01017"
"50.15000","25.06643","-0.00992"
"50.20000","25.09059","-0.00953"
"50.25000","25.11525","-0.00985"
"50.30000","25.14008","-0.00959"
"50.35000","25.16505","-0.00959"
"50.40000","25.19007","-0.00993"
"50.45000","25.21502","-0.00956"
"50.50000","25.23992","-0.00975"
"50.55000","25.26493","-0.00969"
"50.60000","25.28999","-0.00984"
"50.65000","25.31508","-0.00992"
"50.70000","25.34019","-0.00979"
"50.75000","25.36519","-0.00983"
"50.80000","25.39019","-0.00983"
"50.85000","25.41526","-0.00945"
"50.90000","25.44046","-0.00944"
"50.95000","25.46583","-0.00912"
"51.00000","25.49051","-0.00941"
"51.05000","25.51539","-0.00960"
"51.10000","25.54046","-0.01002"
"51.15000","25.56551","-0.01043"
"51.20000","25.59060","-0.00975"
"51.25000","25.61565","-0.00988"
"51.30000","25.64059","-0.01025"
"51.35000","25.66554","-0.00973"
"51.40000","25.69041","-0.00960"
"51.45000","25.71539","-0.00962"
"51.50000","25.74028","-0.00938"
"51.55000","25.76526","-0.00985"
"51.60000","25.79036","-0.00946"
"51.65000","25.81534","-0.00933"
"51.70000","25.84049","-0.00935"
"51.75000","25.86541","-0.00992"
"51.80000","25.89038","-0.01041"
"51.85000","25.91521","-0.01041"
"51.90000","25.94008","-0.01002"
"51.95000","25.96512","-0.01025"
"52.00000","25.99008","-0.01014"
"52.05000","26.01516","-0.01011"
"52.10000","26.04027","-0.01004"
"52.15000","26.06530","-0.00997"
"52.20000","26.09033","-0.00966"
"52.25000","26.11541","-0.01030"
"52.30000","26.14046","-0.01046"
"52.35000","26.16554","-0.01013"
"52.40000","26.19054","-0.01025"
"52.45000","26.21567","-0.00960"
"52.50000","26.24066","-0.00972"
"52.55000","26.26576","-0.00980"
"52.60000","26.29091","-0.00973"
"52.65000","26.31624","-0.00999"
"52.70000","26.34255","-0.01021"
"52.75000","26.36662","-0.01018"
"52.80000","26.39075","-0.00970"
"52.85000","26.41541","-0.01011"
"52.90000","26.44021","-0.01027"
"52.95000","26.46508","-0.00992"
"53.00000","26.48998","-0.01019"
"53.05000","26.51502","-0.00917"
"53.10000","26.53980","-0.01005"
"53.15000","26.56502","-0.00990"
"53.20000","26.58995","-0.00966"
"53.25000","26.61483","-0.00978"
"53.30000","26.64039","-0.00923"
"53.35000","26.66523","-0.00930"
"53.40000","26.69014","-0.01013"
"53.45000","26.71538","-0.01022"
"53.50000","26.74039","-0.00957"
"53.55000","26.76585","-0.00977"
"53.60000","26.79167","-0.01003"
"53.65000","26.81594","-0.00976"
"53.70000","26.84066","-0.00979"
"53.75000","26.86557","-0.00952"
"53.80000","26.89058","-0.00945"
"53.85000","26.91542","-0.00967"
"53.90000","26.94044","-0.00990"
"53.95000","26.96529","-0.00963"
"54.00000","26.99031","-0.00981"
"54.05000","27.01529","-0.00970"
"54.10000","27.04020","-0.00977"
"54.15000","27.06513","-0.00991"
"54.20000","27.09007","-0.01040"
"54.25000","27.11507","-0.00981"
"54.30000","27.14060","-0.00992"
"54.35000","27.16537","-0.00997"
"54.40000","27.19036","-0.01011"
"54.45000","27.21532","-0.00978"
"54.50000","27.24030","-0.00987"
"54.55000","27.26528","-0.00962"
"54.60000","27.29031","-0.00971"
"54.65000","27.31529","-0.00952"
"54.70000","27.34030","-0.00968"
"54.75000","27.36536","-0.00974"
"54.80000","27.39042","-0.00943"
"54.85000","27.41546","-0.00955"
"54.90000","27.44054","-0.00961"
"54.93400","27.45764","-0.00969"