File: 10G1650/ST 10G1650_002.csv
Rate 1,"0.60000",mm/s
Start date,"9/3/2021"
Specimen label,""

Time,Extension,2 kg Beam Load Cell
(s),(mm),(N)
"0.00000","-0.00127","-0.00068"
"0.05000","-0.00092","-0.00015"
"0.10000","0.00568","0.00011"
"0.15000","0.02519","-0.00015"
"0.20000","0.05058","0.00024"
"0.25000","0.08002","-0.00002"
"0.30000","0.11070","0.00023"
"0.35000","0.14372","0.00055"
"0.40000","0.17498","0.00079"
"0.45000","0.20681","0.00080"
"0.50000","0.23905","0.00121"
"0.55000","0.27139","0.00111"
"0.60000","0.30369","0.00145"
"0.65000","0.33588","0.00177"
"0.70000","0.36809","0.00194"
"0.75000","0.40035","0.00235"
"0.80000","0.43224","0.00076"
"0.85000","0.46415","0.00016"
"0.90000","0.49592","0.00159"
"0.95000","0.52750","0.00100"
"1.00000","0.55912","0.00137"
"1.05000","0.59086","0.00165"
"1.10000","0.62237","0.00211"
"1.15000","0.65374","0.00213"
"1.20000","0.68515","0.00235"
"1.25000","0.71648","0.00268"
"1.30000","0.74775","0.00307"
"1.35000","0.77902","0.00297"
"1.40000","0.81020","0.00321"
"1.45000","0.84117","0.00319"
"1.50000","0.87214","0.00241"
"1.55000","0.90299","0.00278"
"1.60000","0.93368","0.00353"
"1.65000","0.96541","0.00301"
"1.70000","0.99590","0.00344"
"1.75000","1.02589","0.00362"
"1.80000","1.05623","0.00375"
"1.85000","1.08665","0.00437"
"1.90000","1.11700","0.00431"
"1.95000","1.14746","0.00450"
"2.00000","1.17818","0.00482"
"2.05000","1.20865","0.00485"
"2.10000","1.23904","0.00489"
"2.15000","1.26939","0.00481"
"2.20000","1.29991","0.00494"
"2.25000","1.33033","0.00541"
"2.30000","1.36078","0.00543"
"2.35000","1.39120","0.00567"
"2.40000","1.42177","0.00584"
"2.45000","1.45223","0.00607"
"2.50000","1.48236","0.00622"
"2.55000","1.51265","0.00665"
"2.60000","1.54290","0.00550"
"2.65000","1.57299","0.00598"
"2.70000","1.60307","0.00618"
"2.75000","1.63323","0.00622"
"2.80000","1.66337","0.00627"
"2.85000","1.69356","0.00678"
"2.90000","1.72379","0.00681"
"2.95000","1.75420","0.00737"
"3.00000","1.78399","0.00711"
"3.05000","1.81389","0.00754"
"3.10000","1.84401","0.00769"
"3.15000","1.87415","0.00814"
"3.20000","1.90423","0.00821"
"3.25000","1.93437","0.00787"
"3.30000","1.96460","0.00757"
"3.35000","1.99484","0.00854"
"3.40000","2.02501","0.00841"
"3.45000","2.05514","0.00871"
"3.50000","2.08529","0.00879"
"3.55000","2.11544","0.00899"
"3.60000","2.14552","0.00928"
"3.65000","2.17594","0.00971"
"3.70000","2.20661","0.00989"
"3.75000","2.23581","0.00955"
"3.80000","2.26552","0.00905"
"3.85000","2.29548","0.00985"
"3.90000","2.32538","0.00971"
"3.95000","2.35517","0.00958"
"4.00000","2.38510","0.01018"
"4.05000","2.41518","0.01042"
"4.10000","2.44524","0.01052"
"4.15000","2.47512","0.01076"
"4.20000","2.50509","0.01077"
"4.25000","2.53520","0.01112"
"4.30000","2.56527","0.01137"
"4.35000","2.59535","0.01132"
"4.40000","2.62536","0.01111"
"4.45000","2.65540","0.01138"
"4.50000","2.68553","0.01160"
"4.55000","2.71555","0.01201"
"4.60000","2.74565","0.01239"
"4.65000","2.77577","0.01199"
"4.70000","2.80575","0.01229"
"4.75000","2.83569","0.01251"
"4.80000","2.86571","0.01296"
"4.85000","2.89570","0.01322"
"4.90000","2.92563","0.01336"
"4.95000","2.95541","0.01357"
"5.00000","2.98535","0.01399"
"5.05000","3.01530","0.01393"
"5.10000","3.04533","0.01444"
"5.15000","3.07544","0.01473"
"5.20000","3.10545","0.01403"
"5.25000","3.13547","0.01391"
"5.30000","3.16552","0.01454"
"5.35000","3.19581","0.01426"
"5.40000","3.22551","0.01467"
"5.45000","3.25546","0.01507"
"5.50000","3.28548","0.01551"
"5.55000","3.31545","0.01532"
"5.60000","3.34543","0.01566"
"5.65000","3.37553","0.01570"
"5.70000","3.40553","0.01562"
"5.75000","3.43567","0.01581"
"5.80000","3.46575","0.01613"
"5.85000","3.49585","0.01615"
"5.90000","3.52583","0.01667"
"5.95000","3.55585","0.01685"
"6.00000","3.58584","0.01707"
"6.05000","3.61646","0.01687"
"6.10000","3.64621","0.01708"
"6.15000","3.67603","0.01719"
"6.20000","3.70567","0.01749"
"6.25000","3.73556","0.01775"
"6.30000","3.76554","0.01770"
"6.35000","3.79550","0.01796"
"6.40000","3.82565","0.01781"
"6.45000","3.85558","0.01828"
"6.50000","3.88561","0.01855"
"6.55000","3.91554","0.01877"
"6.60000","3.94553","0.01917"
"6.65000","3.97550","0.01941"
"6.70000","4.00554","0.01941"
"6.75000","4.03558","0.01990"
"6.80000","4.06565","0.02001"
"6.85000","4.09569","0.02030"
"6.90000","4.12582","0.02049"
"6.95000","4.15589","0.01982"
"7.00000","4.18623","0.02020"
"7.05000","4.21680","0.02057"
"7.10000","4.24653","0.02050"
"7.15000","4.27587","0.02099"
"7.20000","4.30568","0.02058"
"7.25000","4.33552","0.02116"
"7.30000","4.36544","0.02127"
"7.35000","4.39543","0.02172"
"7.40000","4.42547","0.02188"
"7.45000","4.45553","0.02231"
"7.50000","4.48544","0.02214"
"7.55000","4.51534","0.02261"
"7.60000","4.54536","0.02240"
"7.65000","4.57542","0.02263"
"7.70000","4.60540","0.02298"
"7.75000","4.63541","0.02246"
"7.80000","4.66554","0.02280"
"7.85000","4.69567","0.02344"
"7.90000","4.72619","0.02328"
"7.95000","4.75617","0.02370"
"8.00000","4.78588","0.02402"
"8.05000","4.81584","0.02387"
"8.10000","4.84566","0.02382"
"8.15000","4.87555","0.02439"
"8.20000","4.90555","0.02440"
"8.25000","4.93545","0.02446"
"8.30000","4.96547","0.02481"
"8.35000","4.99545","0.02502"
"8.40000","5.02541","0.02558"
"8.45000","5.05550","0.02546"
"8.50000","5.08555","0.02601"
"8.55000","5.11567","0.02600"
"8.60000","5.14578","0.02531"
"8.65000","5.17584","0.02570"
"8.70000","5.20692","0.02622"
"8.75000","5.23619","0.02617"
"8.80000","5.26588","0.02650"
"8.85000","5.29578","0.02654"
"8.90000","5.32578","0.02717"
"8.95000","5.35577","0.02711"
"9.00000","5.38588","0.02744"
"9.05000","5.41604","0.02755"
"9.10000","5.44603","0.02774"
"9.15000","5.47595","0.02773"
"9.20000","5.50568","0.02842"
"9.25000","5.53559","0.02817"
"9.30000","5.56556","0.02831"
"9.35000","5.59565","0.02881"
"9.40000","5.62570","0.02912"
"9.45000","5.65564","0.02931"
"9.50000","5.68572","0.02945"
"9.55000","5.71571","0.02922"
"9.60000","5.74567","0.03023"
"9.65000","5.77569","0.03036"
"9.70000","5.80565","0.03064"
"9.75000","5.83561","0.03085"
"9.80000","5.86553","0.03095"
"9.85000","5.89554","0.03048"
"9.90000","5.92563","0.03075"
"9.95000","5.95574","0.03120"
"10.00000","5.98576","0.03137"
"10.05000","6.01573","0.03114"
"10.10000","6.04578","0.03165"
"10.15000","6.07572","0.03150"
"10.20000","6.10573","0.03137"
"10.25000","6.13588","0.03190"
"10.30000","6.16583","0.03215"
"10.35000","6.19580","0.03223"
"10.40000","6.22568","0.03255"
"10.45000","6.25559","0.03277"
"10.50000","6.28555","0.03300"
"10.55000","6.31550","0.03336"
"10.60000","6.34551","0.03350"
"10.65000","6.37553","0.03371"
"10.70000","6.40562","0.03368"
"10.75000","6.43564","0.03363"
"10.80000","6.46566","0.03393"
"10.85000","6.49574","0.03388"
"10.90000","6.52583","0.03430"
"10.95000","6.55589","0.03456"
"11.00000","6.58615","0.03460"
"11.05000","6.61618","0.03473"
"11.10000","6.64624","0.03528"
"11.15000","6.67605","0.03564"
"11.20000","6.70592","0.03556"
"11.25000","6.73582","0.03562"
"11.30000","6.76567","0.03527"
"11.35000","6.79558","0.03597"
"11.40000","6.82555","0.03623"
"11.45000","6.85549","0.03623"
"11.50000","6.88543","0.03617"
"11.55000","6.91556","0.03626"
"11.60000","6.94559","0.03615"
"11.65000","6.97555","0.03702"
"11.70000","7.00553","0.03687"
"11.75000","7.03553","0.03702"
"11.80000","7.06562","0.03735"
"11.85000","7.09577","0.03764"
"11.90000","7.12571","0.03798"
"11.95000","7.15568","0.03832"
"12.00000","7.18569","0.03837"
"12.05000","7.21572","0.03840"
"12.10000","7.24570","0.03765"
"12.15000","7.27561","0.03815"
"12.20000","7.30548","0.03839"
"12.25000","7.33557","0.03851"
"12.30000","7.36789","0.03857"
"12.35000","7.39670","0.03932"
"12.40000","7.42611","0.03918"
"12.45000","7.45597","0.03946"
"12.50000","7.48571","0.03962"
"12.55000","7.51556","0.03950"
"12.60000","7.54554","0.03952"
"12.65000","7.57550","0.03972"
"12.70000","7.60555","0.03956"
"12.75000","7.63556","0.03999"
"12.80000","7.66564","0.04017"
"12.85000","7.69569","0.04027"
"12.90000","7.72582","0.04004"
"12.95000","7.75597","0.03963"
"13.00000","7.78585","0.04001"
"13.05000","7.81570","0.03997"
"13.10000","7.84561","0.04053"
"13.15000","7.87552","0.04108"
"13.20000","7.90549","0.04095"
"13.25000","7.93540","0.04085"
"13.30000","7.96535","0.04119"
"13.35000","7.99540","0.04134"
"13.40000","8.02538","0.04155"
"13.45000","8.05542","0.04148"
"13.50000","8.08552","0.04181"
"13.55000","8.11557","0.04183"
"13.60000","8.14556","0.04224"
"13.65000","8.17584","0.04230"
"13.70000","8.20652","0.04264"
"13.75000","8.23583","0.04243"
"13.80000","8.26571","0.04246"
"13.85000","8.29568","0.04266"
"13.90000","8.32565","0.04278"
"13.95000","8.35569","0.04293"
"14.00000","8.38574","0.04300"
"14.05000","8.41572","0.04313"
"14.10000","8.44567","0.04282"
"14.15000","8.47572","0.04298"
"14.20000","8.50598","0.04307"
"14.25000","8.53588","0.04303"
"14.30000","8.56564","0.04316"
"14.35000","8.59551","0.04343"
"14.40000","8.62545","0.04370"
"14.45000","8.65549","0.04380"
"14.50000","8.68548","0.04406"
"14.55000","8.71550","0.04410"
"14.60000","8.74549","0.04437"
"14.65000","8.77551","0.04432"
"14.70000","8.80548","0.04414"
"14.75000","8.83555","0.04442"
"14.80000","8.86565","0.04443"
"14.85000","8.89557","0.04457"
"14.90000","8.92555","0.04495"
"14.95000","8.95577","0.04482"
"15.00000","8.98616","0.04436"
"15.05000","9.01599","0.04491"
"15.10000","9.04592","0.04452"
"15.15000","9.07581","0.04476"
"15.20000","9.10573","0.04483"
"15.25000","9.13558","0.04508"
"15.30000","9.16547","0.04487"
"15.35000","9.19535","0.04525"
"15.40000","9.22538","0.04507"
"15.45000","9.25541","0.04551"
"15.50000","9.28546","0.04534"
"15.55000","9.31550","0.04481"
"15.60000","9.34561","0.04511"
"15.65000","9.37548","0.04537"
"15.70000","9.40556","0.04514"
"15.75000","9.43588","0.04550"
"15.80000","9.46707","0.04555"
"15.85000","9.49599","0.04606"
"15.90000","9.52566","0.04591"
"15.95000","9.55556","0.04596"
"16.00000","9.58556","0.04616"
"16.05000","9.61558","0.04571"
"16.10000","9.64579","0.04579"
"16.15000","9.67594","0.04640"
"16.20000","9.70591","0.04602"
"16.25000","9.73580","0.04610"
"16.30000","9.76564","0.04649"
"16.35000","9.79555","0.04686"
"16.40000","9.82548","0.04672"
"16.45000","9.85543","0.04648"
"16.50000","9.88552","0.04666"
"16.55000","9.91557","0.04695"
"16.60000","9.94546","0.04694"
"16.65000","9.97543","0.04730"
"16.70000","10.00533","0.04717"
"16.75000","10.03533","0.04709"
"16.80000","10.06523","0.04735"
"16.85000","10.09523","0.04771"
"16.90000","10.12567","0.04778"
"16.95000","10.15591","0.04804"
"17.00000","10.18560","0.04802"
"17.05000","10.21565","0.04794"
"17.10000","10.24571","0.04772"
"17.15000","10.27585","0.04770"
"17.20000","10.30589","0.04808"
"17.25000","10.33582","0.04828"
"17.30000","10.36581","0.04809"
"17.35000","10.39582","0.04795"
"17.40000","10.42574","0.04826"
"17.45000","10.45571","0.04826"
"17.50000","10.48576","0.04864"
"17.55000","10.51590","0.04856"
"17.60000","10.54598","0.04875"
"17.65000","10.57548","0.04893"
"17.70000","10.60514","0.04909"
"17.75000","10.63512","0.04878"
"17.80000","10.66513","0.04889"
"17.85000","10.69532","0.04900"
"17.90000","10.72524","0.04895"
"17.95000","10.75516","0.04897"
"18.00000","10.78521","0.04909"
"18.05000","10.81534","0.04914"
"18.10000","10.84550","0.04933"
"18.15000","10.87576","0.04937"
"18.20000","10.90594","0.04928"
"18.25000","10.93610","0.04893"
"18.30000","10.96616","0.04939"
"18.35000","10.99607","0.04938"
"18.40000","11.02612","0.04932"
"18.45000","11.05719","0.04949"
"18.50000","11.08694","0.04968"
"18.55000","11.11627","0.04980"
"18.60000","11.14601","0.05008"
"18.65000","11.17583","0.04981"
"18.70000","11.20569","0.04988"
"18.75000","11.23546","0.05005"
"18.80000","11.26531","0.05012"
"18.85000","11.29520","0.05010"
"18.90000","11.32525","0.04913"
"18.95000","11.35544","0.04862"
"19.00000","11.38561","0.04903"
"19.05000","11.41555","0.04847"
"19.10000","11.44561","0.04806"
"19.15000","11.47571","0.04823"
"19.20000","11.50582","0.04772"
"19.25000","11.53586","0.04774"
"19.30000","11.56603","0.04758"
"19.35000","11.59675","0.04771"
"19.40000","11.62647","0.04697"
"19.45000","11.65614","0.04701"
"19.50000","11.68605","0.04666"
"19.55000","11.71589","0.04685"
"19.60000","11.74590","0.04663"
"19.65000","11.77574","0.04688"
"19.70000","11.80565","0.04681"
"19.75000","11.83582","0.04626"
"19.80000","11.86576","0.04597"
"19.85000","11.89538","0.04625"
"19.90000","11.92530","0.04591"
"19.95000","11.95522","0.04649"
"20.00000","11.98526","0.04624"
"20.05000","12.01532","0.04641"
"20.10000","12.04534","0.04600"
"20.15000","12.07548","0.04615"
"20.20000","12.10566","0.04606"
"20.25000","12.13580","0.04564"
"20.30000","12.16595","0.04543"
"20.35000","12.19612","0.04571"
"20.40000","12.22618","0.04542"
"20.45000","12.25655","0.04554"
"20.50000","12.28789","0.04569"
"20.55000","12.31672","0.04547"
"20.60000","12.34621","0.04504"
"20.65000","12.37604","0.04519"
"20.70000","12.40579","0.04487"
"20.75000","12.43568","0.04484"
"20.80000","12.46560","0.04509"
"20.85000","12.49552","0.04494"
"20.90000","12.52559","0.04464"
"20.95000","12.55553","0.04473"
"21.00000","12.58535","0.04471"
"21.05000","12.61522","0.04473"
"21.10000","12.64523","0.04458"
"21.15000","12.67523","0.04453"
"21.20000","12.70529","0.04447"
"21.25000","12.73550","0.04402"
"21.30000","12.76573","0.04399"
"21.35000","12.79598","0.04390"
"21.40000","12.82630","0.04415"
"21.45000","12.85642","0.04387"
"21.50000","12.88633","0.04396"
"21.55000","12.91609","0.04365"
"21.60000","12.94605","0.04373"
"21.65000","12.97601","0.04346"
"21.70000","13.00593","0.04374"
"21.75000","13.03577","0.04368"
"21.80000","13.06573","0.04350"
"21.85000","13.09563","0.04327"
"21.90000","13.12559","0.04340"
"21.95000","13.15547","0.04328"
"22.00000","13.18561","0.04368"
"22.05000","13.21560","0.04322"
"22.10000","13.24545","0.04365"
"22.15000","13.27535","0.04342"
"22.20000","13.30542","0.04319"
"22.25000","13.33554","0.04344"
"22.30000","13.36579","0.04346"
"22.35000","13.39713","0.04296"
"22.40000","13.42632","0.04294"
"22.45000","13.45622","0.04280"
"22.50000","13.48618","0.04279"
"22.55000","13.51625","0.04297"
"22.60000","13.54622","0.04280"
"22.65000","13.57621","0.04282"
"22.70000","13.60644","0.04284"
"22.75000","13.63636","0.04237"
"22.80000","13.66606","0.04295"
"22.85000","13.69578","0.04273"
"22.90000","13.72556","0.04282"
"22.95000","13.75552","0.04300"
"23.00000","13.78538","0.04325"
"23.05000","13.81538","0.04278"
"23.10000","13.84539","0.04261"
"23.15000","13.87544","0.04267"
"23.20000","13.90597","0.04229"
"23.25000","13.93570","0.04272"
"23.30000","13.96560","0.04261"
"23.35000","13.99556","0.04266"
"23.40000","14.02558","0.04284"
"23.45000","14.05569","0.04290"
"23.50000","14.08594","0.04301"
"23.55000","14.11608","0.04297"
"23.60000","14.14620","0.04285"
"23.65000","14.17627","0.04323"
"23.70000","14.20693","0.04253"
"23.75000","14.23655","0.04268"
"23.80000","14.26630","0.04285"
"23.85000","14.29596","0.04295"
"23.90000","14.32572","0.04304"
"23.95000","14.35560","0.04321"
"24.00000","14.38551","0.04294"
"24.05000","14.41543","0.04344"
"24.10000","14.44542","0.04309"
"24.15000","14.47537","0.04355"
"24.20000","14.50532","0.04318"
"24.25000","14.53528","0.04224"
"24.30000","14.56532","0.04243"
"24.35000","14.59550","0.04289"
"24.40000","14.62578","0.04274"
"24.45000","14.65593","0.04267"
"24.50000","14.68613","0.04299"
"24.55000","14.71768","0.04331"
"24.60000","14.74669","0.04331"
"24.65000","14.77645","0.04347"
"24.70000","14.80640","0.04330"
"24.75000","14.83637","0.04328"
"24.80000","14.86625","0.04256"
"24.85000","14.89603","0.04300"
"24.90000","14.92586","0.04332"
"24.95000","14.95588","0.04316"
"25.00000","14.98582","0.04325"
"25.05000","15.01558","0.04349"
"25.10000","15.04548","0.04374"
"25.15000","15.07555","0.04393"
"25.20000","15.10568","0.04373"
"25.25000","15.13573","0.04427"
"25.30000","15.16547","0.04411"
"25.35000","15.19541","0.04310"
"25.40000","15.22544","0.04347"
"25.45000","15.25551","0.04363"
"25.50000","15.28568","0.04368"
"25.55000","15.31596","0.04379"
"25.60000","15.34605","0.04393"
"25.65000","15.37619","0.04429"
"25.70000","15.40622","0.04434"
"25.75000","15.43618","0.04412"
"25.80000","15.46618","0.04443"
"25.85000","15.49622","0.04448"
"25.90000","15.52695","0.04459"
"25.95000","15.55634","0.04426"
"26.00000","15.58590","0.04449"
"26.05000","15.61570","0.04438"
"26.10000","15.64562","0.04464"
"26.15000","15.67563","0.04456"
"26.20000","15.70550","0.04518"
"26.25000","15.73552","0.04444"
"26.30000","15.76545","0.04441"
"26.35000","15.79548","0.04490"
"26.40000","15.82563","0.04507"
"26.45000","15.85569","0.04479"
"26.50000","15.88575","0.04534"
"26.55000","15.91577","0.04522"
"26.60000","15.94592","0.04559"
"26.65000","15.97603","0.04487"
"26.70000","16.00616","0.04521"
"26.75000","16.03762","0.04503"
"26.80000","16.06729","0.04537"
"26.85000","16.09639","0.04534"
"26.90000","16.12613","0.04561"
"26.95000","16.15602","0.04547"
"27.00000","16.18566","0.04524"
"27.05000","16.21567","0.04559"
"27.10000","16.24554","0.04563"
"27.15000","16.27537","0.04566"
"27.20000","16.30533","0.04604"
"27.25000","16.33522","0.04602"
"27.30000","16.36522","0.04634"
"27.35000","16.39522","0.04635"
"27.40000","16.42540","0.04662"
"27.45000","16.45561","0.04663"
"27.50000","16.48580","0.04594"
"27.55000","16.51581","0.04624"
"27.60000","16.54572","0.04659"
"27.65000","16.57561","0.04659"
"27.70000","16.60581","0.04648"
"27.75000","16.63603","0.04697"
"27.80000","16.66619","0.04682"
"27.85000","16.69628","0.04722"
"27.90000","16.72636","0.04697"
"27.95000","16.75616","0.04676"
"28.00000","16.78608","0.04706"
"28.05000","16.81689","0.04689"
"28.10000","16.84632","0.04675"
"28.15000","16.87573","0.04706"
"28.20000","16.90554","0.04699"
"28.25000","16.93542","0.04727"
"28.30000","16.96531","0.04696"
"28.35000","16.99539","0.04722"
"28.40000","17.02541","0.04707"
"28.45000","17.05547","0.04744"
"28.50000","17.08555","0.04731"
"28.55000","17.11553","0.04774"
"28.60000","17.14548","0.04723"
"28.65000","17.17553","0.04726"
"28.70000","17.20561","0.04740"
"28.75000","17.23578","0.04767"
"28.80000","17.26583","0.04765"
"28.85000","17.29598","0.04811"
"28.90000","17.32610","0.04802"
"28.95000","17.35614","0.04838"
"29.00000","17.38596","0.04860"
"29.05000","17.41591","0.04860"
"29.10000","17.44572","0.04909"
"29.15000","17.47560","0.04906"
"29.20000","17.50576","0.04880"
"29.25000","17.53708","0.04820"
"29.30000","17.56658","0.04833"
"29.35000","17.59571","0.04858"
"29.40000","17.62553","0.04845"
"29.45000","17.65543","0.04851"
"29.50000","17.68536","0.04893"
"29.55000","17.71532","0.04900"
"29.60000","17.74532","0.04916"
"29.65000","17.77542","0.04939"
"29.70000","17.80554","0.04936"
"29.75000","17.83562","0.04951"
"29.80000","17.86576","0.04975"
"29.85000","17.89602","0.04981"
"29.90000","17.92597","0.05022"
"29.95000","17.95593","0.04999"
"30.00000","17.98602","0.04975"
"30.05000","18.01601","0.04929"
"30.10000","18.04603","0.04925"
"30.15000","18.07600","0.04958"
"30.20000","18.10579","0.04940"
"30.25000","18.13563","0.04929"
"30.30000","18.16544","0.04982"
"30.35000","18.19555","0.05003"
"30.40000","18.22552","0.04989"
"30.45000","18.25543","0.04989"
"30.50000","18.28537","0.05005"
"30.55000","18.31545","0.04989"
"30.60000","18.34540","0.05020"
"30.65000","18.37562","0.04923"
"30.70000","18.40624","0.04932"
"30.75000","18.43603","0.04925"
"30.80000","18.46556","0.04875"
"30.85000","18.49565","0.04857"
"30.90000","18.52581","0.04861"
"30.95000","18.55591","0.04810"
"31.00000","18.58607","0.04770"
"31.05000","18.61624","0.04667"
"31.10000","18.64616","0.04563"
"31.15000","18.67609","0.04482"
"31.20000","18.70606","0.04366"
"31.25000","18.73597","0.04277"
"31.30000","18.76585","0.04159"
"31.35000","18.79575","0.03916"
"31.40000","18.82567","0.03679"
"31.45000","18.85557","0.03602"
"31.50000","18.88549","0.03442"
"31.55000","18.91550","0.03272"
"31.60000","18.94643","0.03118"
"31.65000","18.97750","0.02986"
"31.70000","19.00635","0.02856"
"31.75000","19.03601","0.02661"
"31.80000","19.06590","0.02255"
"31.85000","19.09584","0.02014"
"31.90000","19.12588","0.01814"
"31.95000","19.15593","0.01602"
"32.00000","19.18601","0.01176"
"32.05000","19.21618","-0.01292"
"32.10000","19.24615","-0.01512"
"32.15000","19.27606","-0.01421"
"32.20000","19.30610","-0.01472"
"32.25000","19.33610","-0.01494"
"32.30000","19.36633","-0.01486"
"32.35000","19.39590","-0.01476"
"32.40000","19.42566","-0.01497"
"32.45000","19.45554","-0.01464"
"32.50000","19.48548","-0.01463"
"32.55000","19.51543","-0.01538"
"32.60000","19.54546","-0.01556"
"32.65000","19.57549","-0.01486"
"32.70000","19.60570","-0.01552"
"32.75000","19.63584","-0.01515"
"32.80000","19.66569","-0.01498"
"32.85000","19.69569","-0.01492"
"32.90000","19.72576","-0.01482"
"32.95000","19.75581","-0.01460"
"33.00000","19.78601","-0.01462"
"33.05000","19.81644","-0.01423"
"33.10000","19.84646","-0.01504"
"33.15000","19.87638","-0.01558"
"33.20000","19.90627","-0.01505"
"33.25000","19.93630","-0.01542"
"33.30000","19.96608","-0.01515"
"33.35000","19.99578","-0.01520"
"33.40000","20.02564","-0.01547"
"33.45000","20.05573","-0.01520"
"33.50000","20.08561","-0.01543"
"33.55000","20.11555","-0.01530"
"33.60000","20.14559","-0.01507"
"33.65000","20.17574","-0.01484"
"33.70000","20.20565","-0.01511"
"33.75000","20.23558","-0.01560"
"33.80000","20.26565","-0.01564"
"33.85000","20.29567","-0.01553"
"33.90000","20.32575","-0.01512"
"33.95000","20.35585","-0.01552"
"34.00000","20.38594","-0.01520"
"34.05000","20.41600","-0.01514"
"34.10000","20.44631","-0.01561"
"34.15000","20.47826","-0.01523"
"34.20000","20.50711","-0.01499"
"34.25000","20.53646","-0.01524"
"34.30000","20.56622","-0.01494"
"34.35000","20.59597","-0.01532"
"34.40000","20.62573","-0.01483"
"34.45000","20.65567","-0.01555"
"34.50000","20.68561","-0.01540"
"34.55000","20.71552","-0.01537"
"34.60000","20.74553","-0.01556"
"34.65000","20.77560","-0.01571"
"34.70000","20.80550","-0.01483"
"34.75000","20.83529","-0.01509"
"34.80000","20.86547","-0.01539"
"34.85000","20.89580","-0.01539"
"34.90000","20.92556","-0.01492"
"34.95000","20.95548","-0.01498"
"35.00000","20.98576","-0.01496"
"35.05000","21.01606","-0.01601"
"35.10000","21.04605","-0.01520"
"35.15000","21.07589","-0.01548"
"35.20000","21.10591","-0.01528"
"35.25000","21.13587","-0.01530"
"35.30000","21.16591","-0.01519"
"35.35000","21.19584","-0.01507"
"35.40000","21.22582","-0.01513"
"35.45000","21.25570","-0.01555"
"35.50000","21.28568","-0.01544"
"35.55000","21.31575","-0.01536"
"35.60000","21.34565","-0.01525"
"35.65000","21.37571","-0.01501"
"35.70000","21.40562","-0.01581"
"35.75000","21.43554","-0.01600"
"35.80000","21.46547","-0.01539"
"35.85000","21.49558","-0.01543"
"35.90000","21.52557","-0.01561"
"35.95000","21.55551","-0.01533"
"36.00000","21.58562","-0.01545"
"36.05000","21.61594","-0.01533"
"36.10000","21.64633","-0.01498"
"36.15000","21.67734","-0.01518"
"36.20000","21.70664","-0.01508"
"36.25000","21.73624","-0.01474"
"36.30000","21.76598","-0.01535"
"36.35000","21.79580","-0.01556"
"36.40000","21.82574","-0.01567"
"36.45000","21.85568","-0.01560"
"36.50000","21.88578","-0.01557"
"36.55000","21.91575","-0.01557"
"36.60000","21.94571","-0.01527"
"36.65000","21.97615","-0.01535"
"36.70000","22.00642","-0.01565"
"36.75000","22.03580","-0.01520"
"36.80000","22.06548","-0.01544"
"36.85000","22.09545","-0.01516"
"36.90000","22.12556","-0.01513"
"36.95000","22.15555","-0.01523"
"37.00000","22.18559","-0.01552"
"37.05000","22.21569","-0.01522"
"37.10000","22.24589","-0.01532"
"37.15000","22.27590","-0.01519"
"37.20000","22.30589","-0.01511"
"37.25000","22.33599","-0.01517"
"37.30000","22.36590","-0.01559"
"37.35000","22.39587","-0.01536"
"37.40000","22.42598","-0.01548"
"37.45000","22.45608","-0.01535"
"37.50000","22.48611","-0.01537"
"37.55000","22.51599","-0.01509"
"37.60000","22.54599","-0.01562"
"37.65000","22.57603","-0.01616"
"37.70000","22.60588","-0.01581"
"37.75000","22.63727","-0.01554"
"37.80000","22.66663","-0.01571"
"37.85000","22.69614","-0.01572"
"37.90000","22.72579","-0.01554"
"37.95000","22.75571","-0.01562"
"38.00000","22.78558","-0.01563"
"38.05000","22.81561","-0.01542"
"38.10000","22.84586","-0.01544"
"38.15000","22.87586","-0.01531"
"38.20000","22.90589","-0.01514"
"38.25000","22.93590","-0.01520"
"38.30000","22.96582","-0.01545"
"38.35000","22.99582","-0.01572"
"38.40000","23.02573","-0.01557"
"38.45000","23.05567","-0.01578"
"38.50000","23.08569","-0.01539"
"38.55000","23.11573","-0.01539"
"38.60000","23.14578","-0.01528"
"38.65000","23.17581","-0.01540"
"38.70000","23.20584","-0.01563"
"38.75000","23.23581","-0.01580"
"38.80000","23.26583","-0.01537"
"38.85000","23.29598","-0.01565"
"38.88100","23.31465","-0.01560"