File: 15G1652/ST 15G1652_00028.csv
Rate 1,"0.15000",mm/s
Start date,"9/25/2021"
Specimen label,""

Time,Extension,2 kg Beam Load Cell
(s),(mm),(N)
"0.00000","0.00000","0.00024"
"0.12500","0.00300","0.00043"
"0.25000","0.01875","0.00029"
"0.37500","0.03789","0.00056"
"0.50000","0.05808","0.00056"
"0.62500","0.07870","0.00084"
"0.75000","0.09918","0.00091"
"0.87500","0.11949","0.00080"
"1.00000","0.13950","0.00103"
"1.12500","0.15940","0.00120"
"1.25000","0.17887","0.00109"
"1.37500","0.19819","0.00137"
"1.50000","0.21757","0.00158"
"1.62500","0.23698","0.00186"
"1.75000","0.25626","0.00198"
"1.87500","0.27525","0.00208"
"2.00000","0.29443","0.00213"
"2.12500","0.31351","0.00200"
"2.25000","0.33255","0.00191"
"2.37500","0.35155","0.00223"
"2.50000","0.37051","0.00252"
"2.62500","0.38943","0.00239"
"2.75000","0.40823","0.00271"
"2.87500","0.42713","0.00271"
"3.00000","0.44690","0.00250"
"3.12500","0.46471","0.00284"
"3.25000","0.48346","0.00279"
"3.37500","0.50221","0.00287"
"3.50000","0.52098","0.00323"
"3.62500","0.53977","0.00325"
"3.75000","0.55846","0.00344"
"3.87500","0.57727","0.00358"
"4.00000","0.59609","0.00334"
"4.12500","0.61477","0.00373"
"4.25000","0.63352","0.00384"
"4.37500","0.65240","0.00374"
"4.50000","0.67115","0.00389"
"4.62500","0.68991","0.00413"
"4.75000","0.70870","0.00420"
"4.87500","0.72745","0.00431"
"5.00000","0.74612","0.00439"
"5.12500","0.76489","0.00440"
"5.25000","0.78360","0.00448"
"5.37500","0.80228","0.00455"
"5.50000","0.82106","0.00455"
"5.62500","0.83996","0.00439"
"5.75000","0.85876","0.00469"
"5.87500","0.87720","0.00480"
"6.00000","0.89597","0.00480"
"6.12500","0.91481","0.00498"
"6.25000","0.93354","0.00529"
"6.37500","0.95240","0.00540"
"6.50000","0.97123","0.00533"
"6.62500","0.99037","0.00549"
"6.75000","1.00872","0.00562"
"6.87500","1.02743","0.00558"
"7.00000","1.04611","0.00563"
"7.12500","1.06488","0.00580"
"7.25000","1.08367","0.00603"
"7.37500","1.10235","0.00602"
"7.50000","1.12115","0.00592"
"7.62500","1.13991","0.00605"
"7.75000","1.15868","0.00618"
"7.87500","1.17740","0.00627"
"8.00000","1.19621","0.00646"
"8.12500","1.21502","0.00660"
"8.25000","1.23376","0.00660"
"8.37500","1.25250","0.00676"
"8.50000","1.27121","0.00675"
"8.62500","1.28989","0.00699"
"8.75000","1.30864","0.00712"
"8.87500","1.32744","0.00700"
"9.00000","1.34612","0.00714"
"9.12500","1.36490","0.00745"
"9.25000","1.38370","0.00750"
"9.37500","1.40248","0.00762"
"9.50000","1.42125","0.00792"
"9.62500","1.44000","0.00779"
"9.75000","1.45872","0.00820"
"9.87500","1.47744","0.00815"
"10.00000","1.49621","0.00805"
"10.12500","1.51496","0.00817"
"10.25000","1.53366","0.00834"
"10.37500","1.55245","0.00840"
"10.50000","1.57126","0.00848"
"10.62500","1.58993","0.00849"
"10.75000","1.60869","0.00870"
"10.87500","1.62750","0.00893"
"11.00000","1.64631","0.00897"
"11.12500","1.66503","0.00903"
"11.25000","1.68380","0.00925"
"11.37500","1.70256","0.00921"
"11.50000","1.72204","0.00913"
"11.62500","1.74036","0.00949"
"11.75000","1.75877","0.00958"
"11.87500","1.77738","0.00960"
"12.00000","1.79609","0.00971"
"12.12500","1.81480","0.00974"
"12.25000","1.83351","0.00998"
"12.37500","1.85233","0.01017"
"12.50000","1.87116","0.01021"
"12.62500","1.88998","0.01041"
"12.75000","1.90876","0.01052"
"12.87500","1.92796","0.01043"
"13.00000","1.94632","0.01070"
"13.12500","1.96497","0.01072"
"13.25000","1.98371","0.01079"
"13.37500","2.00244","0.01082"
"13.50000","2.02118","0.01100"
"13.62500","2.03993","0.01095"
"13.75000","2.05872","0.01096"
"13.87500","2.07743","0.01116"
"14.00000","2.09617","0.01139"
"14.12500","2.11495","0.01142"
"14.25000","2.13376","0.01132"
"14.37500","2.15252","0.01172"
"14.50000","2.17140","0.01179"
"14.62500","2.19014","0.01184"
"14.75000","2.20888","0.01209"
"14.87500","2.22762","0.01217"
"15.00000","2.24635","0.01212"
"15.12500","2.26502","0.01245"
"15.25000","2.28378","0.01243"
"15.37500","2.30252","0.01262"
"15.50000","2.32123","0.01273"
"15.62500","2.34005","0.01278"
"15.75000","2.35891","0.01315"
"15.87500","2.37759","0.01313"
"16.00000","2.39632","0.01316"
"16.12500","2.41507","0.01318"
"16.25000","2.43381","0.01346"
"16.37500","2.45248","0.01328"
"16.50000","2.47124","0.01364"
"16.62500","2.48997","0.01356"
"16.75000","2.50874","0.01375"
"16.87500","2.52756","0.01414"
"17.00000","2.54634","0.01417"
"17.12500","2.56500","0.01449"
"17.25000","2.58372","0.01451"
"17.37500","2.60255","0.01447"
"17.50000","2.62132","0.01466"
"17.62500","2.64005","0.01481"
"17.75000","2.65883","0.01470"
"17.87500","2.67759","0.01493"
"18.00000","2.69632","0.01518"
"18.12500","2.71502","0.01520"
"18.25000","2.73377","0.01539"
"18.37500","2.75307","0.01542"
"18.50000","2.77119","0.01547"
"18.62500","2.78991","0.01571"
"18.75000","2.80861","0.01578"
"18.87500","2.82736","0.01602"
"19.00000","2.84613","0.01599"
"19.12500","2.86498","0.01610"
"19.25000","2.88372","0.01623"
"19.37500","2.90253","0.01642"
"19.50000","2.92132","0.01655"
"19.62500","2.93999","0.01669"
"19.75000","2.95875","0.01687"
"19.87500","2.97754","0.01704"
"20.00000","2.99623","0.01705"
"20.12500","3.01495","0.01732"
"20.25000","3.03370","0.01725"
"20.37500","3.05241","0.01733"
"20.50000","3.07121","0.01730"
"20.62500","3.08999","0.01727"
"20.75000","3.10871","0.01784"
"20.87500","3.12754","0.01775"
"21.00000","3.14634","0.01799"
"21.12500","3.16600","0.01844"
"21.25000","3.18386","0.01830"
"21.37500","3.20249","0.01840"
"21.50000","3.22118","0.01875"
"21.62500","3.23987","0.01869"
"21.75000","3.25865","0.01892"
"21.87500","3.27734","0.01896"
"22.00000","3.29608","0.01898"
"22.12500","3.31485","0.01922"
"22.25000","3.33366","0.01911"
"22.37500","3.35241","0.01933"
"22.50000","3.37122","0.01956"
"22.62500","3.39001","0.01969"
"22.75000","3.40876","0.01995"
"22.87500","3.42747","0.02001"
"23.00000","3.44632","0.02008"
"23.12500","3.46511","0.02023"
"23.25000","3.48376","0.02053"
"23.37500","3.50253","0.02042"
"23.50000","3.52124","0.02070"
"23.62500","3.53994","0.02077"
"23.75000","3.55870","0.02082"
"23.87500","3.57751","0.02129"
"24.00000","3.59634","0.02133"
"24.12500","3.61520","0.02147"
"24.25000","3.63389","0.02165"
"24.37500","3.65257","0.02142"
"24.50000","3.67132","0.02163"
"24.62500","3.69008","0.02161"
"24.75000","3.70883","0.02185"
"24.87500","3.72756","0.02186"
"25.00000","3.74625","0.02216"
"25.12500","3.76504","0.02239"
"25.25000","3.78378","0.02231"
"25.37500","3.80253","0.02247"
"25.50000","3.82131","0.02252"
"25.62500","3.84004","0.02291"
"25.75000","3.85880","0.02289"
"25.87500","3.87758","0.02289"
"26.00000","3.89628","0.02316"
"26.12500","3.91500","0.02337"
"26.25000","3.93374","0.02341"
"26.37500","3.95310","0.02354"
"26.50000","3.97156","0.02368"
"26.62500","3.98988","0.02373"
"26.75000","4.00856","0.02401"
"26.87500","4.02727","0.02387"
"27.00000","4.04611","0.02434"
"27.12500","4.06493","0.02450"
"27.25000","4.08378","0.02459"
"27.37500","4.10260","0.02459"
"27.50000","4.12140","0.02470"
"27.62500","4.14012","0.02482"
"27.75000","4.15888","0.02498"
"27.87500","4.17761","0.02540"
"28.00000","4.19633","0.02550"
"28.12500","4.21502","0.02568"
"28.25000","4.23376","0.02554"
"28.37500","4.25252","0.02594"
"28.50000","4.27123","0.02619"
"28.62500","4.28999","0.02609"
"28.75000","4.30878","0.02639"
"28.87500","4.32751","0.02647"
"29.00000","4.34630","0.02635"
"29.12500","4.36505","0.02665"
"29.25000","4.38378","0.02672"
"29.37500","4.40248","0.02678"
"29.50000","4.42125","0.02709"
"29.62500","4.43998","0.02699"
"29.75000","4.45913","0.02727"
"29.87500","4.47774","0.02738"
"30.00000","4.49615","0.02764"
"30.12500","4.51479","0.02767"
"30.25000","4.53357","0.02771"
"30.37500","4.55233","0.02786"
"30.50000","4.57113","0.02825"
"30.62500","4.58994","0.02812"
"30.75000","4.60871","0.02831"
"30.87500","4.62744","0.02860"
"31.00000","4.64620","0.02886"
"31.12500","4.66492","0.02881"
"31.25000","4.68366","0.02877"
"31.37500","4.70238","0.02907"
"31.50000","4.72115","0.02914"
"31.62500","4.73997","0.02955"
"31.75000","4.75869","0.02929"
"31.87500","4.77749","0.02962"
"32.00000","4.79629","0.02983"
"32.12500","4.81502","0.02981"
"32.25000","4.83381","0.02995"
"32.37500","4.85260","0.03044"
"32.50000","4.87130","0.03025"
"32.62500","4.89005","0.03058"
"32.75000","4.90884","0.03083"
"32.87500","4.92751","0.03070"
"33.00000","4.94622","0.03100"
"33.12500","4.96502","0.03110"
"33.25000","4.98396","0.03133"
"33.37500","5.00243","0.03142"
"33.50000","5.02120","0.03159"
"33.62500","5.04001","0.03150"
"33.75000","5.05879","0.03179"
"33.87500","5.07760","0.03181"
"34.00000","5.09636","0.03194"
"34.12500","5.11510","0.03220"
"34.25000","5.13387","0.03215"
"34.37500","5.15259","0.03232"
"34.50000","5.17126","0.03276"
"34.62500","5.18998","0.03285"
"34.75000","5.20870","0.03306"
"34.87500","5.22742","0.03319"
"35.00000","5.24614","0.03319"
"35.12500","5.26516","0.03340"
"35.25000","5.28424","0.03345"
"35.37500","5.30252","0.03355"
"35.50000","5.32122","0.03386"
"35.62500","5.33997","0.03390"
"35.75000","5.35876","0.03408"
"35.87500","5.37750","0.03406"
"36.00000","5.39620","0.03417"
"36.12500","5.41487","0.03440"
"36.25000","5.43360","0.03456"
"36.37500","5.45241","0.03472"
"36.50000","5.47114","0.03492"
"36.62500","5.48994","0.03507"
"36.75000","5.50871","0.03519"
"36.87500","5.52745","0.03530"
"37.00000","5.54629","0.03555"
"37.12500","5.56513","0.03547"
"37.25000","5.58381","0.03590"
"37.37500","5.60252","0.03586"
"37.50000","5.62177","0.03591"
"37.62500","5.64001","0.03631"
"37.75000","5.65869","0.03643"
"37.87500","5.67743","0.03652"
"38.00000","5.69615","0.03685"
"38.12500","5.71489","0.03690"
"38.25000","5.73363","0.03690"
"38.37500","5.75248","0.03702"
"38.50000","5.77130","0.03702"
"38.62500","5.79007","0.03735"
"38.75000","5.80882","0.03740"
"38.87500","5.82758","0.03741"
"39.00000","5.84632","0.03796"
"39.12500","5.86504","0.03790"
"39.25000","5.88371","0.03825"
"39.37500","5.90240","0.03860"
"39.50000","5.92116","0.03866"
"39.62500","5.94098","0.03876"
"39.75000","5.95869","0.03876"
"39.87500","5.97731","0.03889"
"40.00000","5.99613","0.03910"
"40.12500","6.01499","0.03907"
"40.25000","6.03379","0.03919"
"40.37500","6.05260","0.03967"
"40.50000","6.07132","0.03967"
"40.62500","6.09006","0.03981"
"40.75000","6.10878","0.04023"
"40.87500","6.12754","0.04022"
"41.00000","6.14621","0.04026"
"41.12500","6.16496","0.04030"
"41.25000","6.18372","0.04058"
"41.37500","6.20241","0.04084"
"41.50000","6.22118","0.04096"
"41.62500","6.23996","0.04102"
"41.75000","6.25871","0.04119"
"41.87500","6.27748","0.04163"
"42.00000","6.29628","0.04146"
"42.12500","6.31496","0.04174"
"42.25000","6.33368","0.04208"
"42.37500","6.35244","0.04187"
"42.50000","6.37121","0.04235"
"42.62500","6.38987","0.04237"
"42.75000","6.40866","0.04256"
"42.87500","6.42745","0.04268"
"43.00000","6.44623","0.04286"
"43.12500","6.46604","0.04305"
"43.25000","6.48375","0.04323"
"43.37500","6.50245","0.04315"
"43.50000","6.52116","0.04347"
"43.62500","6.53996","0.04385"
"43.75000","6.55878","0.04385"
"43.87500","6.57749","0.04412"
"44.00000","6.59631","0.04419"
"44.12500","6.61503","0.04422"
"44.25000","6.63367","0.04464"
"44.37500","6.65242","0.04464"
"44.50000","6.67120","0.04479"
"44.62500","6.68995","0.04481"
"44.75000","6.70870","0.04515"
"44.87500","6.72750","0.04524"
"45.00000","6.74628","0.04548"
"45.12500","6.76511","0.04563"
"45.25000","6.78386","0.04581"
"45.37500","6.80255","0.04607"
"45.50000","6.82128","0.04605"
"45.62500","6.84002","0.04627"
"45.75000","6.85874","0.04643"
"45.87500","6.87744","0.04645"
"46.00000","6.89619","0.04669"
"46.12500","6.91497","0.04693"
"46.25000","6.93403","0.04709"
"46.37500","6.95235","0.04738"
"46.50000","6.97116","0.04748"
"46.62500","6.98996","0.04780"
"46.75000","7.00875","0.04796"
"46.87500","7.02751","0.04814"
"47.00000","7.04630","0.04826"
"47.12500","7.06506","0.04846"
"47.25000","7.08380","0.04861"
"47.37500","7.10243","0.04853"
"47.50000","7.12116","0.04874"
"47.62500","7.13994","0.04878"
"47.75000","7.15870","0.04894"
"47.87500","7.17743","0.04919"
"48.00000","7.19719","0.04921"
"48.12500","7.21509","0.04967"
"48.25000","7.23374","0.04972"
"48.37500","7.25251","0.05003"
"48.50000","7.27132","0.05034"
"48.62500","7.29005","0.05017"
"48.75000","7.30880","0.05031"
"48.87500","7.32754","0.05065"
"49.00000","7.34621","0.05070"
"49.12500","7.36495","0.05100"
"49.25000","7.38375","0.05107"
"49.37500","7.40253","0.05099"
"49.50000","7.42118","0.05118"
"49.62500","7.43992","0.05161"
"49.75000","7.45879","0.05166"
"49.87500","7.47754","0.05188"
"50.00000","7.49628","0.05196"
"50.12500","7.51527","0.05219"
"50.25000","7.53375","0.05245"
"50.37500","7.55248","0.05250"
"50.50000","7.57128","0.05263"
"50.62500","7.58988","0.05291"
"50.75000","7.60860","0.05311"
"50.87500","7.62739","0.05316"
"51.00000","7.64614","0.05334"
"51.12500","7.66486","0.05370"
"51.25000","7.68365","0.05368"
"51.37500","7.70244","0.05387"
"51.50000","7.72122","0.05409"
"51.62500","7.74004","0.05422"
"51.75000","7.75877","0.05429"
"51.87500","7.77749","0.05443"
"52.00000","7.79630","0.05461"
"52.12500","7.81513","0.05477"
"52.25000","7.83495","0.05475"
"52.37500","7.85312","0.05508"
"52.50000","7.87117","0.05508"
"52.62500","7.88975","0.05531"
"52.75000","7.90849","0.05559"
"52.87500","7.92734","0.05594"
"53.00000","7.94613","0.05599"
"53.12500","7.96494","0.05619"
"53.25000","7.98371","0.05637"
"53.37500","8.00253","0.05654"
"53.50000","8.02125","0.05662"
"53.62500","8.03997","0.05675"
"53.75000","8.05867","0.05700"
"53.87500","8.07736","0.05735"
"54.00000","8.09613","0.05724"
"54.12500","8.11495","0.05751"
"54.25000","8.13365","0.05756"
"54.37500","8.15236","0.05770"
"54.50000","8.17114","0.05805"
"54.62500","8.18992","0.05813"
"54.75000","8.20867","0.05828"
"54.87500","8.22743","0.05842"
"55.00000","8.24625","0.05847"
"55.12500","8.26501","0.05890"
"55.25000","8.28425","0.05901"
"55.37500","8.30249","0.05903"
"55.50000","8.32110","0.05936"
"55.62500","8.33989","0.05944"
"55.75000","8.35870","0.05948"
"55.87500","8.37746","0.05965"
"56.00000","8.39616","0.05986"
"56.12500","8.41488","0.05975"
"56.25000","8.43364","0.06024"
"56.37500","8.45244","0.06019"
"56.50000","8.47123","0.06052"
"56.62500","8.48990","0.06063"
"56.75000","8.50865","0.06074"
"56.87500","8.52742","0.06099"
"57.00000","8.54617","0.06091"
"57.12500","8.56490","0.06098"
"57.25000","8.58371","0.06129"
"57.37500","8.60245","0.06150"
"57.50000","8.62117","0.06167"
"57.62500","8.63989","0.06205"
"57.75000","8.65866","0.06201"
"57.87500","8.67762","0.06229"
"58.00000","8.69625","0.06257"
"58.12500","8.71497","0.06245"
"58.25000","8.73378","0.06273"
"58.37500","8.75253","0.06281"
"58.50000","8.77129","0.06293"
"58.62500","8.79003","0.06312"
"58.75000","8.80869","0.06334"
"58.87500","8.82749","0.06337"
"59.00000","8.84627","0.06355"
"59.12500","8.86504","0.06388"
"59.25000","8.88382","0.06391"
"59.37500","8.90256","0.06395"
"59.50000","8.92132","0.06419"
"59.62500","8.94008","0.06441"
"59.75000","8.95883","0.06452"
"59.87500","8.97758","0.06458"
"60.00000","8.99634","0.06483"
"60.12500","9.01503","0.06515"
"60.25000","9.03377","0.06509"
"60.37500","9.05246","0.06545"
"60.50000","9.07121","0.06571"
"60.62500","9.08999","0.06573"
"60.75000","9.10876","0.06595"
"60.87500","9.12744","0.06602"
"61.00000","9.14630","0.06610"
"61.12500","9.16586","0.06636"
"61.25000","9.18365","0.06639"
"61.37500","9.20235","0.06666"
"61.50000","9.22117","0.06679"
"61.62500","9.23995","0.06688"
"61.75000","9.25867","0.06687"
"61.87500","9.27739","0.06710"
"62.00000","9.29612","0.06729"
"62.12500","9.31497","0.06741"
"62.25000","9.33365","0.06779"
"62.37500","9.35238","0.06784"
"62.50000","9.37110","0.06787"
"62.62500","9.38990","0.06803"
"62.75000","9.40873","0.06809"
"62.87500","9.42752","0.06825"
"63.00000","9.44625","0.06831"
"63.12500","9.46500","0.06862"
"63.25000","9.48383","0.06884"
"63.37500","9.50257","0.06883"
"63.50000","9.52127","0.06913"
"63.62500","9.53993","0.06949"
"63.75000","9.55872","0.06931"
"63.87500","9.57747","0.06958"
"64.00000","9.59623","0.06979"
"64.12500","9.61496","0.06970"
"64.25000","9.63373","0.06994"
"64.37500","9.65252","0.07005"
"64.50000","9.67125","0.07015"
"64.62500","9.68991","0.07030"
"64.75000","9.70871","0.07052"
"64.87500","9.72744","0.07060"
"65.00000","9.74619","0.07082"
"65.12500","9.76493","0.07096"
"65.25000","9.78380","0.07105"
"65.37500","9.80239","0.07138"
"65.50000","9.82109","0.07135"
"65.62500","9.83986","0.07149"
"65.75000","9.85861","0.07197"
"65.87500","9.87742","0.07194"
"66.00000","9.89625","0.07211"
"66.12500","9.91501","0.07230"
"66.25000","9.93381","0.07227"
"66.37500","9.95261","0.07239"
"66.50000","9.97123","0.07265"
"66.62500","9.98998","0.07282"
"66.75000","10.00870","0.07314"
"66.87500","10.02744","0.07317"
"67.00000","10.04619","0.07330"
"67.12500","10.06498","0.07359"
"67.25000","10.08373","0.07355"
"67.37500","10.10248","0.07352"
"67.50000","10.12128","0.07377"
"67.62500","10.14006","0.07388"
"67.75000","10.15884","0.07422"
"67.87500","10.17766","0.07427"
"68.00000","10.19639","0.07461"
"68.12500","10.21511","0.07488"
"68.25000","10.23387","0.07495"
"68.37500","10.25456","0.07501"
"68.50000","10.27146","0.07520"
"68.62500","10.28988","0.07544"
"68.75000","10.30865","0.07517"
"68.87500","10.32737","0.07550"
"69.00000","10.34609","0.07565"
"69.12500","10.36483","0.07571"
"69.25000","10.38360","0.07603"
"69.37500","10.40243","0.07610"
"69.50000","10.42122","0.07647"
"69.62500","10.43998","0.07651"
"69.75000","10.45870","0.07670"
"69.87500","10.47740","0.07677"
"70.00000","10.49614","0.07698"
"70.12500","10.51488","0.07717"
"70.25000","10.53363","0.07728"
"70.37500","10.55240","0.07729"
"70.50000","10.57114","0.07732"
"70.62500","10.58994","0.07770"
"70.75000","10.60878","0.07778"
"70.87500","10.62756","0.07783"
"71.00000","10.64632","0.07833"
"71.12500","10.66510","0.07835"
"71.25000","10.68390","0.07842"
"71.37500","10.70259","0.07854"
"71.50000","10.72150","0.07871"
"71.62500","10.74037","0.07887"
"71.75000","10.75878","0.07905"
"71.87500","10.77750","0.07906"
"72.00000","10.79628","0.07919"
"72.12500","10.81497","0.07928"
"72.25000","10.83372","0.07944"
"72.37500","10.85254","0.07971"
"72.50000","10.87135","0.07997"
"72.62500","10.89006","0.08010"
"72.75000","10.90882","0.08019"
"72.87500","10.92755","0.08046"
"73.00000","10.94626","0.08054"
"73.12500","10.96497","0.08074"
"73.25000","10.98369","0.08072"
"73.37500","11.00241","0.08094"
"73.50000","11.02116","0.08113"
"73.62500","11.03991","0.08109"
"73.75000","11.05866","0.08119"
"73.87500","11.07747","0.08144"
"74.00000","11.09619","0.08141"
"74.12500","11.11493","0.08165"
"74.25000","11.13369","0.08178"
"74.37500","11.15248","0.08192"
"74.50000","11.17126","0.08205"
"74.62500","11.18996","0.08244"
"74.75000","11.20875","0.08265"
"74.87500","11.22751","0.08275"
"75.00000","11.24623","0.08296"
"75.12500","11.26499","0.08296"
"75.25000","11.28375","0.08315"
"75.37500","11.30248","0.08311"
"75.50000","11.32129","0.08321"
"75.62500","11.34010","0.08342"
"75.75000","11.35912","0.08349"
"75.87500","11.37767","0.08353"
"76.00000","11.39638","0.08399"
"76.12500","11.41519","0.08399"
"76.25000","11.43387","0.08410"
"76.37500","11.45260","0.08445"
"76.50000","11.47135","0.08445"
"76.62500","11.49007","0.08456"
"76.75000","11.50883","0.08460"
"76.87500","11.52755","0.08458"
"77.00000","11.54626","0.08483"
"77.12500","11.56502","0.08479"
"77.25000","11.58380","0.08517"
"77.37500","11.60250","0.08551"
"77.50000","11.62123","0.08535"
"77.62500","11.64002","0.08573"
"77.75000","11.65873","0.08582"
"77.87500","11.67753","0.08607"
"78.00000","11.69634","0.08591"
"78.12500","11.71491","0.08631"
"78.25000","11.73482","0.08627"
"78.37500","11.75288","0.08649"
"78.50000","11.77117","0.08676"
"78.62500","11.78981","0.08665"
"78.75000","11.80858","0.08698"
"78.87500","11.82741","0.08687"
"79.00000","11.84621","0.08707"
"79.12500","11.86495","0.08742"
"79.25000","11.88374","0.08720"
"79.37500","11.90250","0.08726"
"79.50000","11.92130","0.08749"
"79.62500","11.94002","0.08746"
"79.75000","11.95872","0.08781"
"79.87500","11.97771","0.08777"
"80.00000","11.99625","0.08784"
"80.12500","12.01493","0.08809"
"80.25000","12.03368","0.08825"
"80.37500","12.05248","0.08798"
"80.50000","12.07128","0.08834"
"80.62500","12.09002","0.08840"
"80.75000","12.10878","0.08866"
"80.87500","12.12754","0.08877"
"81.00000","12.14633","0.08893"
"81.12500","12.16510","0.08889"
"81.25000","12.18381","0.08913"
"81.37500","12.20252","0.08917"
"81.50000","12.22116","0.08932"
"81.62500","12.23992","0.08943"
"81.75000","12.25865","0.08930"
"81.87500","12.27738","0.08965"
"82.00000","12.29616","0.08973"
"82.12500","12.31493","0.08972"
"82.25000","12.33369","0.09001"
"82.37500","12.35313","0.09001"
"82.50000","12.37118","0.08997"
"82.62500","12.38986","0.09050"
"82.75000","12.40863","0.09035"
"82.87500","12.42738","0.09038"
"83.00000","12.44612","0.09072"
"83.12500","12.46483","0.09061"
"83.25000","12.48366","0.09089"
"83.37500","12.50242","0.09109"
"83.50000","12.52119","0.09106"
"83.62500","12.54000","0.09126"
"83.75000","12.55880","0.09138"
"83.87500","12.57761","0.09150"
"84.00000","12.59637","0.09164"
"84.12500","12.61515","0.09162"
"84.25000","12.63388","0.09156"
"84.37500","12.65255","0.09176"
"84.50000","12.67131","0.09209"
"84.62500","12.69004","0.09211"
"84.75000","12.70875","0.09209"
"84.87500","12.72749","0.09214"
"85.00000","12.74622","0.09229"
"85.12500","12.76500","0.09263"
"85.25000","12.78385","0.09263"
"85.37500","12.80245","0.09295"
"85.50000","12.82117","0.09308"
"85.62500","12.83997","0.09303"
"85.75000","12.85877","0.09334"
"85.87500","12.87745","0.09321"
"86.00000","12.89620","0.09371"
"86.12500","12.91495","0.09368"
"86.25000","12.93368","0.09365"
"86.37500","12.95242","0.09365"
"86.50000","12.97120","0.09384"
"86.62500","12.98997","0.09372"
"86.75000","13.00997","0.09399"
"86.87500","13.02774","0.09403"
"87.00000","13.04616","0.09399"
"87.12500","13.06485","0.09418"
"87.25000","13.08366","0.09448"
"87.37500","13.10244","0.09450"
"87.50000","13.12124","0.09456"
"87.62500","13.14002","0.09465"
"87.75000","13.15873","0.09463"
"87.87500","13.17747","0.09466"
"88.00000","13.19624","0.09488"
"88.12500","13.21497","0.09512"
"88.25000","13.23374","0.09514"
"88.37500","13.25248","0.09504"
"88.50000","13.27125","0.09536"
"88.62500","13.28999","0.09540"
"88.75000","13.30879","0.09545"
"88.87500","13.32759","0.09568"
"89.00000","13.34642","0.09602"
"89.12500","13.36518","0.09589"
"89.25000","13.38384","0.09593"
"89.37500","13.40255","0.09605"
"89.50000","13.42123","0.09617"
"89.62500","13.44000","0.09630"
"89.75000","13.45875","0.09627"
"89.87500","13.47748","0.09647"
"90.00000","13.49621","0.09669"
"90.12500","13.51497","0.09659"
"90.25000","13.53375","0.09676"
"90.37500","13.55286","0.09691"
"90.50000","13.57130","0.09696"
"90.62500","13.59013","0.09701"
"90.75000","13.60882","0.09725"
"90.87500","13.62761","0.09735"
"91.00000","13.64629","0.09738"
"91.12500","13.66495","0.09766"
"91.25000","13.68366","0.09766"
"91.37500","13.70242","0.09768"
"91.50000","13.72117","0.09796"
"91.62500","13.73993","0.09783"
"91.75000","13.75872","0.09808"
"91.87500","13.77750","0.09799"
"92.00000","13.79627","0.09793"
"92.12500","13.81507","0.09835"
"92.25000","13.83388","0.09852"
"92.37500","13.85257","0.09856"
"92.50000","13.87128","0.09871"
"92.62500","13.89000","0.09883"
"92.75000","13.90876","0.09876"
"92.87500","13.92749","0.09901"
"93.00000","13.94630","0.09890"
"93.12500","13.96670","0.09922"
"93.25000","13.98397","0.09913"
"93.37500","14.00247","0.09900"
"93.50000","14.02121","0.09935"
"93.62500","14.03994","0.09945"
"93.75000","14.05879","0.09945"
"93.87500","14.07755","0.09982"
"94.00000","14.09627","0.09964"
"94.12500","14.11501","0.09987"
"94.25000","14.13378","0.10006"
"94.37500","14.15246","0.10010"
"94.50000","14.17114","0.10033"
"94.62500","14.18989","0.10031"
"94.75000","14.20864","0.10044"
"94.87500","14.22746","0.10053"
"95.00000","14.24623","0.10051"
"95.12500","14.26498","0.10058"
"95.25000","14.28375","0.10093"
"95.37500","14.30256","0.10082"
"95.50000","14.32138","0.10091"
"95.62500","14.34002","0.10121"
"95.75000","14.35873","0.10114"
"95.87500","14.37748","0.10120"
"96.00000","14.39623","0.10149"
"96.12500","14.41508","0.10152"
"96.25000","14.43367","0.10137"
"96.37500","14.45249","0.10160"
"96.50000","14.47115","0.10163"
"96.62500","14.48998","0.10182"
"96.75000","14.50874","0.10194"
"96.87500","14.52753","0.10201"
"97.00000","14.54630","0.10216"
"97.12500","14.56510","0.10227"
"97.25000","14.58379","0.10234"
"97.37500","14.60256","0.10230"
"97.50000","14.62133","0.10244"
"97.62500","14.64001","0.10270"
"97.75000","14.65873","0.10248"
"97.87500","14.67752","0.10281"
"98.00000","14.69627","0.10293"
"98.12500","14.71497","0.10309"
"98.25000","14.73374","0.10304"
"98.37500","14.75251","0.10309"
"98.50000","14.77126","0.10323"
"98.62500","14.79006","0.10314"
"98.75000","14.80882","0.10344"
"98.87500","14.82755","0.10356"
"99.00000","14.84627","0.10343"
"99.12500","14.86499","0.10364"
"99.25000","14.88369","0.10384"
"99.37500","14.90462","0.10391"
"99.50000","14.92139","0.10387"
"99.62500","14.93971","0.10376"
"99.75000","14.95849","0.10395"
"99.87500","14.97726","0.10390"
"100.00000","14.99614","0.10394"
"100.12500","15.01492","0.10418"
"100.25000","15.03377","0.10423"
"100.37500","15.05254","0.10433"
"100.50000","15.07124","0.10451"
"100.62500","15.08994","0.10483"
"100.75000","15.10868","0.10451"
"100.87500","15.12746","0.10467"
"101.00000","15.14621","0.10484"
"101.12500","15.16492","0.10454"
"101.25000","15.18365","0.10471"
"101.37500","15.20242","0.10485"
"101.50000","15.22118","0.10485"
"101.62500","15.23993","0.10492"
"101.75000","15.25875","0.10488"
"101.87500","15.27752","0.10492"
"102.00000","15.29627","0.10511"
"102.12500","15.31505","0.10501"
"102.25000","15.33377","0.10536"
"102.37500","15.35248","0.10549"
"102.50000","15.37128","0.10555"
"102.62500","15.39000","0.10561"
"102.75000","15.40871","0.10568"
"102.87500","15.42839","0.10568"
"103.00000","15.44607","0.10573"
"103.12500","15.46474","0.10577"
"103.25000","15.48357","0.10553"
"103.37500","15.50239","0.10579"
"103.50000","15.52123","0.10591"
"103.62500","15.53998","0.10590"
"103.75000","15.55869","0.10618"
"103.87500","15.57753","0.10598"
"104.00000","15.59620","0.10599"
"104.12500","15.61490","0.10617"
"104.25000","15.63362","0.10608"
"104.37500","15.65242","0.10618"
"104.50000","15.67125","0.10625"
"104.62500","15.69007","0.10621"
"104.75000","15.70874","0.10633"
"104.87500","15.72750","0.10619"
"105.00000","15.74629","0.10640"
"105.12500","15.76504","0.10646"
"105.25000","15.78376","0.10636"
"105.37500","15.80248","0.10635"
"105.50000","15.82125","0.10665"
"105.62500","15.84002","0.10627"
"105.75000","15.85875","0.10640"
"105.87500","15.87753","0.10663"
"106.00000","15.89626","0.10638"
"106.12500","15.91499","0.10646"
"106.25000","15.93380","0.10651"
"106.37500","15.95257","0.10611"
"106.50000","15.97133","0.10646"
"106.62500","15.99018","0.10638"
"106.75000","16.00899","0.10625"
"106.87500","16.02772","0.10653"
"107.00000","16.04627","0.10633"
"107.12500","16.06497","0.10634"
"107.25000","16.08372","0.10635"
"107.37500","16.10239","0.10614"
"107.50000","16.12111","0.10619"
"107.62500","16.13987","0.10616"
"107.75000","16.15859","0.10605"
"107.87500","16.17739","0.10599"
"108.00000","16.19621","0.10618"
"108.12500","16.21500","0.10621"
"108.25000","16.23381","0.10622"
"108.37500","16.25260","0.10619"
"108.50000","16.27130","0.10622"
"108.62500","16.29001","0.10625"
"108.75000","16.30877","0.10616"
"108.87500","16.32750","0.10611"
"109.00000","16.34622","0.10620"
"109.12500","16.36487","0.10596"
"109.25000","16.38364","0.10605"
"109.37500","16.40240","0.10588"
"109.50000","16.42119","0.10582"
"109.62500","16.44001","0.10587"
"109.75000","16.45881","0.10563"
"109.87500","16.47759","0.10581"
"110.00000","16.49640","0.10582"
"110.12500","16.51516","0.10585"
"110.25000","16.53389","0.10581"
"110.37500","16.55261","0.10608"
"110.50000","16.57132","0.10581"
"110.62500","16.58995","0.10571"
"110.75000","16.60870","0.10589"
"110.87500","16.62744","0.10556"
"111.00000","16.64613","0.10554"
"111.12500","16.66489","0.10568"
"111.25000","16.68372","0.10560"
"111.37500","16.70248","0.10549"
"111.50000","16.72229","0.10551"
"111.62500","16.74059","0.10546"
"111.75000","16.75861","0.10554"
"111.87500","16.77736","0.10536"
"112.00000","16.79612","0.10521"
"112.12500","16.81483","0.10531"
"112.25000","16.83353","0.10545"
"112.37500","16.85231","0.10544"
"112.50000","16.87105","0.10555"
"112.62500","16.88986","0.10529"
"112.75000","16.90868","0.10524"
"112.87500","16.92745","0.10519"
"113.00000","16.94622","0.10516"
"113.12500","16.96502","0.10540"
"113.25000","16.98381","0.10527"
"113.37500","17.00256","0.10538"
"113.50000","17.02137","0.10545"
"113.62500","17.04009","0.10555"
"113.75000","17.05878","0.10535"
"113.87500","17.07746","0.10544"
"114.00000","17.09625","0.10546"
"114.12500","17.11502","0.10511"
"114.25000","17.13375","0.10526"
"114.37500","17.15252","0.10544"
"114.50000","17.17132","0.10526"
"114.62500","17.19008","0.10530"
"114.75000","17.20885","0.10515"
"114.87500","17.22757","0.10520"
"115.00000","17.24621","0.10521"
"115.12500","17.26496","0.10516"
"115.25000","17.28369","0.10527"
"115.37500","17.30235","0.10541"
"115.50000","17.32110","0.10508"
"115.62500","17.33988","0.10512"
"115.75000","17.35866","0.10506"
"115.87500","17.37740","0.10504"
"116.00000","17.39619","0.10491"
"116.12500","17.41499","0.10519"
"116.25000","17.43374","0.10510"
"116.37500","17.45251","0.10515"
"116.50000","17.47308","0.10471"
"116.62500","17.49011","0.10484"
"116.75000","17.50851","0.10503"
"116.87500","17.52731","0.10501"
"117.00000","17.54609","0.10516"
"117.12500","17.56487","0.10508"
"117.25000","17.58364","0.10465"
"117.37500","17.60239","0.10499"
"117.50000","17.62115","0.10496"
"117.62500","17.63994","0.10501"
"117.75000","17.65868","0.10528"
"117.87500","17.67747","0.10510"
"118.00000","17.69627","0.10523"
"118.12500","17.71504","0.10530"
"118.25000","17.73379","0.10510"
"118.37500","17.75254","0.10522"
"118.50000","17.77125","0.10518"
"118.62500","17.78994","0.10519"
"118.75000","17.80864","0.10520"
"118.87500","17.82738","0.10511"
"119.00000","17.84611","0.10520"
"119.12500","17.86481","0.10502"
"119.25000","17.88363","0.10537"
"119.37500","17.90245","0.10528"
"119.50000","17.92122","0.10550"
"119.62500","17.93999","0.10559"
"119.75000","17.95877","0.10554"
"119.87500","17.97753","0.10561"
"120.00000","17.99630","0.10560"
"120.12500","18.01503","0.10551"
"120.25000","18.03380","0.10563"
"120.37500","18.05258","0.10546"
"120.50000","18.07095","0.10539"
"120.62500","18.08968","0.10550"
"120.75000","18.10850","0.10553"
"120.87500","18.12734","0.10571"
"121.00000","18.14617","0.10547"
"121.12500","18.16502","0.10564"
"121.25000","18.18398","0.10571"
"121.37500","18.20248","0.10569"
"121.50000","18.22120","0.10560"
"121.62500","18.23997","0.10560"
"121.75000","18.25874","0.10556"
"121.87500","18.27752","0.10551"
"122.00000","18.29647","0.10575"
"122.12500","18.31516","0.10542"
"122.25000","18.33379","0.10553"
"122.37500","18.35246","0.10556"
"122.50000","18.37126","0.10564"
"122.62500","18.39005","0.10554"
"122.75000","18.40879","0.10564"
"122.87500","18.42750","0.10538"
"123.00000","18.44625","0.10577"
"123.12500","18.46495","0.10555"
"123.25000","18.48370","0.10537"
"123.37500","18.50244","0.10553"
"123.50000","18.52118","0.10536"
"123.62500","18.53993","0.10524"
"123.75000","18.55869","0.10537"
"123.87500","18.57740","0.10539"
"124.00000","18.59614","0.10548"
"124.12500","18.61495","0.10562"
"124.25000","18.63385","0.10561"
"124.37500","18.65248","0.10576"
"124.50000","18.67125","0.10589"
"124.62500","18.69002","0.10585"
"124.75000","18.70872","0.10583"
"124.87500","18.72748","0.10568"
"125.00000","18.74623","0.10572"
"125.12500","18.76492","0.10578"
"125.25000","18.78369","0.10559"
"125.37500","18.80246","0.10559"
"125.50000","18.82143","0.10584"
"125.62500","18.84060","0.10588"
"125.75000","18.85868","0.10582"
"125.87500","18.87737","0.10576"
"126.00000","18.89615","0.10570"
"126.12500","18.91497","0.10588"
"126.25000","18.93375","0.10595"
"126.37500","18.95249","0.10576"
"126.50000","18.97126","0.10588"
"126.62500","18.99001","0.10586"
"126.75000","19.00868","0.10590"
"126.87500","19.02740","0.10602"
"127.00000","19.04622","0.10601"
"127.12500","19.06490","0.10597"
"127.25000","19.08361","0.10616"
"127.37500","19.10238","0.10585"
"127.50000","19.12115","0.10598"
"127.62500","19.13993","0.10616"
"127.75000","19.15878","0.10610"
"127.87500","19.17745","0.10623"
"128.00000","19.19617","0.10611"
"128.12500","19.21489","0.10583"
"128.25000","19.23359","0.10619"
"128.37500","19.25233","0.10596"
"128.50000","19.27110","0.10590"
"128.62500","19.28989","0.10600"
"128.75000","19.30865","0.10603"
"128.87500","19.32740","0.10600"
"129.00000","19.34618","0.10609"
"129.12500","19.36495","0.10621"
"129.25000","19.38370","0.10628"
"129.37500","19.40246","0.10625"
"129.50000","19.42119","0.10618"
"129.62500","19.43993","0.10604"
"129.75000","19.45876","0.10616"
"129.87500","19.47745","0.10586"
"130.00000","19.49622","0.10620"
"130.12500","19.51499","0.10630"
"130.25000","19.53374","0.10614"
"130.37500","19.55249","0.10637"
"130.50000","19.57124","0.10650"
"130.62500","19.59002","0.10644"
"130.75000","19.60881","0.10664"
"130.87500","19.62819","0.10661"
"131.00000","19.64641","0.10678"
"131.12500","19.66505","0.10663"
"131.25000","19.68382","0.10654"
"131.37500","19.70251","0.10668"
"131.50000","19.72120","0.10678"
"131.62500","19.73989","0.10668"
"131.75000","19.75870","0.10673"
"131.87500","19.77746","0.10687"
"132.00000","19.79605","0.10689"
"132.12500","19.81480","0.10692"
"132.25000","19.83366","0.10681"
"132.37500","19.85238","0.10698"
"132.50000","19.87113","0.10700"
"132.62500","19.88993","0.10715"
"132.75000","19.90869","0.10712"
"132.87500","19.92744","0.10718"
"133.00000","19.94622","0.10726"
"133.12500","19.96494","0.10742"
"133.25000","19.98365","0.10739"
"133.37500","20.00241","0.10752"
"133.50000","20.02116","0.10741"
"133.62500","20.03989","0.10763"
"133.75000","20.05881","0.10774"
"133.87500","20.07760","0.10771"
"134.00000","20.09631","0.10781"
"134.12500","20.11518","0.10750"
"134.25000","20.13396","0.10784"
"134.37500","20.15253","0.10761"
"134.50000","20.17126","0.10788"
"134.62500","20.19005","0.10787"
"134.75000","20.20914","0.10770"
"134.87500","20.22751","0.10799"
"135.00000","20.24622","0.10815"
"135.12500","20.26494","0.10796"
"135.25000","20.28369","0.10811"
"135.37500","20.30247","0.10846"
"135.50000","20.32129","0.10812"
"135.62500","20.34008","0.10830"
"135.75000","20.35884","0.10840"
"135.87500","20.37755","0.10837"
"136.00000","20.39625","0.10834"
"136.12500","20.41496","0.10830"
"136.25000","20.43368","0.10833"
"136.37500","20.45241","0.10848"
"136.50000","20.47113","0.10849"
"136.62500","20.48994","0.10853"
"136.75000","20.50862","0.10863"
"136.87500","20.52738","0.10879"
"137.00000","20.54615","0.10879"
"137.12500","20.56495","0.10911"
"137.25000","20.58370","0.10908"
"137.37500","20.60245","0.10903"
"137.50000","20.62119","0.10904"
"137.62500","20.63990","0.10892"
"137.75000","20.65865","0.10924"
"137.87500","20.67743","0.10922"
"138.00000","20.69621","0.10923"
"138.12500","20.71495","0.10951"
"138.25000","20.73372","0.10936"
"138.37500","20.75246","0.10961"
"138.50000","20.77122","0.10994"
"138.62500","20.79005","0.10949"
"138.75000","20.81058","0.10974"
"138.87500","20.82820","0.10979"
"139.00000","20.84618","0.10976"
"139.12500","20.86486","0.11005"
"139.25000","20.88365","0.11003"
"139.37500","20.90241","0.11013"
"139.50000","20.92112","0.11047"
"139.62500","20.93985","0.11028"
"139.75000","20.95859","0.11023"
"139.87500","20.97737","0.11035"
"140.00000","20.99610","0.11041"
"140.12500","21.01481","0.11037"
"140.25000","21.03361","0.11059"
"140.37500","21.05242","0.11078"
"140.50000","21.07122","0.11083"
"140.62500","21.08993","0.11090"
"140.75000","21.10862","0.11092"
"140.87500","21.12735","0.11113"
"141.00000","21.14612","0.11110"
"141.12500","21.16485","0.11117"
"141.25000","21.18358","0.11129"
"141.37500","21.20238","0.11148"
"141.50000","21.22104","0.11127"
"141.62500","21.24114","0.11145"
"141.75000","21.25846","0.11150"
"141.87500","21.27723","0.11155"
"142.00000","21.29597","0.11167"
"142.12500","21.31481","0.11169"
"142.25000","21.33372","0.11194"
"142.37500","21.35247","0.11188"
"142.50000","21.37123","0.11177"
"142.62500","21.38998","0.11207"
"142.75000","21.40881","0.11215"
"142.87500","21.42759","0.11216"
"143.00000","21.44636","0.11238"
"143.12500","21.46509","0.11241"
"143.25000","21.48385","0.11240"
"143.37500","21.50254","0.11265"
"143.50000","21.52131","0.11281"
"143.62500","21.54010","0.11254"
"143.75000","21.55895","0.11276"
"143.87500","21.57763","0.11276"
"144.00000","21.59747","0.11292"
"144.12500","21.61499","0.11275"
"144.25000","21.63360","0.11265"
"144.37500","21.65241","0.11316"
"144.50000","21.67119","0.11301"
"144.62500","21.68994","0.11293"
"144.75000","21.70872","0.11328"
"144.87500","21.72736","0.11314"
"145.00000","21.74610","0.11338"
"145.12500","21.76484","0.11354"
"145.25000","21.78363","0.11373"
"145.37500","21.80248","0.11359"
"145.50000","21.82118","0.11365"
"145.62500","21.83994","0.11365"
"145.75000","21.85866","0.11376"
"145.87500","21.87739","0.11390"
"146.00000","21.89617","0.11384"
"146.12500","21.91492","0.11404"
"146.25000","21.93365","0.11419"
"146.37500","21.95244","0.11421"
"146.50000","21.97126","0.11422"
"146.62500","21.99007","0.11429"
"146.75000","22.00878","0.11433"
"146.87500","22.02833","0.11439"
"147.00000","22.04640","0.11451"
"147.12500","22.06507","0.11439"
"147.25000","22.08386","0.11475"
"147.37500","22.10266","0.11460"
"147.50000","22.12143","0.11462"
"147.62500","22.14014","0.11477"
"147.75000","22.15886","0.11476"
"147.87500","22.17756","0.11513"
"148.00000","22.19633","0.11501"
"148.12500","22.21507","0.11510"
"148.25000","22.23380","0.11541"
"148.37500","22.25256","0.11510"
"148.50000","22.27131","0.11513"
"148.62500","22.29009","0.11516"
"148.75000","22.30889","0.11551"
"148.87500","22.32773","0.11551"
"149.00000","22.34636","0.11569"
"149.12500","22.36504","0.11565"
"149.25000","22.38388","0.11553"
"149.37500","22.40240","0.11574"
"149.50000","22.42114","0.11571"
"149.62500","22.43988","0.11599"
"149.75000","22.45864","0.11604"
"149.87500","22.47737","0.11610"
"150.00000","22.49612","0.11619"
"150.12500","22.51494","0.11630"
"150.25000","22.53367","0.11619"
"150.37500","22.55246","0.11630"
"150.50000","22.57125","0.11658"
"150.62500","22.58999","0.11654"
"150.75000","22.60873","0.11666"
"150.87500","22.62749","0.11664"
"151.00000","22.64625","0.11662"
"151.12500","22.66722","0.11676"
"151.25000","22.68374","0.11664"
"151.37500","22.70229","0.11682"
"151.50000","22.72108","0.11693"
"151.62500","22.73998","0.11664"
"151.75000","22.75872","0.11671"
"151.87500","22.77759","0.11695"
"152.00000","22.79637","0.11687"
"152.12500","22.81518","0.11712"
"152.25000","22.83384","0.11733"
"152.37500","22.85260","0.11703"
"152.50000","22.87132","0.11712"
"152.62500","22.88995","0.11738"
"152.75000","22.90871","0.11713"
"152.87500","22.92754","0.11730"
"153.00000","22.94625","0.11735"
"153.12500","22.96492","0.11739"
"153.25000","22.98389","0.11761"
"153.37500","23.00249","0.11744"
"153.50000","23.02119","0.11755"
"153.62500","23.03995","0.11774"
"153.75000","23.05867","0.11767"
"153.87500","23.07733","0.11758"
"154.00000","23.09611","0.11768"
"154.12500","23.11489","0.11769"
"154.25000","23.13360","0.11789"
"154.37500","23.15238","0.11778"
"154.50000","23.17116","0.11781"
"154.62500","23.18991","0.11812"
"154.75000","23.20867","0.11793"
"154.87500","23.22746","0.11797"
"155.00000","23.24614","0.11803"
"155.12500","23.26492","0.11805"
"155.25000","23.28373","0.11806"
"155.37500","23.30252","0.11827"
"155.50000","23.32125","0.11811"
"155.62500","23.34006","0.11823"
"155.75000","23.35889","0.11821"
"155.87500","23.37755","0.11816"
"156.00000","23.39637","0.11821"
"156.12500","23.41558","0.11820"
"156.25000","23.43400","0.11813"
"156.37500","23.45230","0.11819"
"156.50000","23.47105","0.11840"
"156.62500","23.48991","0.11826"
"156.75000","23.50875","0.11829"
"156.87500","23.52754","0.11851"
"157.00000","23.54623","0.11835"
"157.12500","23.56500","0.11856"
"157.25000","23.58373","0.11859"
"157.37500","23.60243","0.11849"
"157.50000","23.62117","0.11848"
"157.62500","23.63990","0.11855"
"157.75000","23.65865","0.11883"
"157.87500","23.67737","0.11878"
"158.00000","23.69605","0.11853"
"158.12500","23.71485","0.11880"
"158.25000","23.73366","0.11872"
"158.37500","23.75239","0.11877"
"158.50000","23.77117","0.11865"
"158.62500","23.78993","0.11873"
"158.75000","23.80861","0.11860"
"158.87500","23.82752","0.11862"
"159.00000","23.84617","0.11856"
"159.12500","23.86484","0.11863"
"159.25000","23.88366","0.11878"
"159.37500","23.90243","0.11848"
"159.50000","23.92113","0.11858"
"159.62500","23.93995","0.11875"
"159.75000","23.95879","0.11856"
"159.87500","23.97758","0.11842"
"160.00000","23.99702","0.11860"
"160.12500","24.01544","0.11864"
"160.25000","24.03366","0.11854"
"160.37500","24.05240","0.11866"
"160.50000","24.07128","0.11843"
"160.62500","24.09015","0.11834"
"160.75000","24.10885","0.11844"
"160.87500","24.12757","0.11819"
"161.00000","24.14628","0.11847"
"161.12500","24.16500","0.11813"
"161.25000","24.18377","0.11825"
"161.37500","24.20257","0.11845"
"161.50000","24.22127","0.11843"
"161.62500","24.23999","0.11831"
"161.75000","24.25875","0.11841"
"161.87500","24.27741","0.11842"
"162.00000","24.29628","0.11841"
"162.12500","24.31488","0.11821"
"162.25000","24.33360","0.11814"
"162.37500","24.35232","0.11818"
"162.50000","24.37114","0.11793"
"162.62500","24.38989","0.11794"
"162.75000","24.40856","0.11801"
"162.87500","24.42735","0.11769"
"163.00000","24.44658","0.11772"
"163.12500","24.46503","0.11785"
"163.25000","24.48360","0.11751"
"163.37500","24.50246","0.11754"
"163.50000","24.52122","0.11732"
"163.62500","24.53997","0.11736"
"163.75000","24.55879","0.11726"
"163.87500","24.57742","0.11700"
"164.00000","24.59611","0.11676"
"164.12500","24.61492","0.11697"
"164.25000","24.63368","0.11661"
"164.37500","24.65244","0.11683"
"164.50000","24.67148","0.11678"
"164.62500","24.69015","0.11664"
"164.75000","24.70893","0.11663"
"164.87500","24.72763","0.11669"
"165.00000","24.74645","0.11644"
"165.12500","24.76555","0.11620"
"165.25000","24.78393","0.11629"
"165.37500","24.80250","0.11574"
"165.50000","24.82116","0.11504"
"165.62500","24.83989","0.11486"
"165.75000","24.85866","0.11428"
"165.87500","24.87744","0.11409"
"166.00000","24.89626","0.11371"
"166.12500","24.91495","0.11344"
"166.25000","24.93367","0.11338"
"166.37500","24.95242","0.11308"
"166.50000","24.97119","0.11294"
"166.62500","24.98999","0.11284"
"166.75000","25.00877","0.11260"
"166.87500","25.02749","0.11243"
"167.00000","25.04623","0.11208"
"167.12500","25.06495","0.11184"
"167.25000","25.08370","0.11175"
"167.37500","25.10240","0.11126"
"167.50000","25.12116","0.11081"
"167.62500","25.13990","0.11061"
"167.75000","25.15870","0.11028"
"167.87500","25.17748","0.10979"
"168.00000","25.19624","0.10952"
"168.12500","25.21501","0.10872"
"168.25000","25.23384","0.10818"
"168.37500","25.25266","0.10774"
"168.50000","25.27139","0.10723"
"168.62500","25.29011","0.10664"
"168.75000","25.30881","0.10608"
"168.87500","25.32745","0.10541"
"169.00000","25.34629","0.10475"
"169.12500","25.36507","0.10420"
"169.25000","25.38384","0.10326"
"169.37500","25.40258","0.10252"
"169.50000","25.42138","0.10150"
"169.62500","25.44011","0.10005"
"169.75000","25.45885","0.09932"
"169.87500","25.47761","0.09849"
"170.00000","25.49633","0.09721"
"170.12500","25.51501","0.09627"
"170.25000","25.53400","0.09493"
"170.37500","25.55254","0.09392"
"170.50000","25.57121","0.09279"
"170.62500","25.58992","0.09131"
"170.75000","25.60868","0.08993"
"170.87500","25.62739","0.08811"
"171.00000","25.64615","0.08645"
"171.12500","25.66725","0.08437"
"171.25000","25.68381","0.08202"
"171.37500","25.70231","0.07844"
"171.50000","25.72102","0.07484"
"171.62500","25.73973","0.07081"
"171.75000","25.75857","0.06381"
"171.87500","25.77740","0.05061"
"172.00000","25.79613","-0.01424"
"172.12500","25.81489","-0.01325"
"172.25000","25.83365","-0.01318"
"172.37500","25.85247","-0.01329"
"172.50000","25.87120","-0.01342"
"172.62500","25.88994","-0.01317"
"172.75000","25.90883","-0.01340"
"172.87500","25.92761","-0.01330"
"173.00000","25.94638","-0.01321"
"173.12500","25.96662","-0.01349"
"173.25000","25.98390","-0.01332"
"173.37500","26.00253","-0.01335"
"173.50000","26.02130","-0.01351"
"173.62500","26.04003","-0.01326"
"173.75000","26.05877","-0.01331"
"173.87500","26.07752","-0.01310"
"174.00000","26.09619","-0.01297"
"174.12500","26.11507","-0.01328"
"174.25000","26.13375","-0.01308"
"174.37500","26.15241","-0.01309"
"174.50000","26.17117","-0.01336"
"174.62500","26.19018","-0.01312"
"174.75000","26.20884","-0.01307"
"174.87500","26.22768","-0.01332"
"175.00000","26.24619","-0.01328"
"175.12500","26.26495","-0.01347"
"175.25000","26.28357","-0.01321"
"175.37500","26.30248","-0.01336"
"175.50000","26.32127","-0.01319"
"175.62500","26.33993","-0.01314"
"175.75000","26.35890","-0.01302"
"175.87500","26.37749","-0.01342"
"176.00000","26.39615","-0.01345"
"176.12500","26.41500","-0.01328"
"176.25000","26.43383","-0.01351"
"176.37500","26.45256","-0.01337"
"176.50000","26.47136","-0.01321"
"176.62500","26.49047","-0.01330"
"176.75000","26.50900","-0.01320"
"176.87500","26.52738","-0.01327"
"177.00000","26.54615","-0.01338"
"177.12500","26.56493","-0.01309"
"177.25000","26.58375","-0.01318"
"177.37500","26.60246","-0.01337"
"177.50000","26.62123","-0.01341"
"177.62500","26.64004","-0.01351"
"177.75000","26.65886","-0.01347"
"177.87500","26.67755","-0.01339"
"178.00000","26.69629","-0.01343"
"178.12500","26.71508","-0.01344"
"178.25000","26.73382","-0.01329"
"178.37500","26.75249","-0.01339"
"178.50000","26.77112","-0.01335"
"178.62500","26.78983","-0.01342"
"178.75000","26.80857","-0.01340"
"178.87500","26.82733","-0.01323"
"179.00000","26.84608","-0.01326"
"179.12500","26.86487","-0.01347"
"179.25000","26.88364","-0.01342"
"179.37500","26.90234","-0.01307"
"179.50000","26.92140","-0.01349"
"179.62500","26.94162","-0.01339"
"179.75000","26.95866","-0.01349"
"179.87500","26.97727","-0.01344"
"180.00000","26.99604","-0.01345"
"180.12500","27.01474","-0.01327"
"180.25000","27.03360","-0.01328"
"180.37500","27.05237","-0.01332"
"180.50000","27.07113","-0.01348"
"180.62500","27.08994","-0.01351"
"180.75000","27.10871","-0.01345"
"180.87500","27.12747","-0.01344"
"180.96200","27.14063","-0.01309"