File: 15G1652/ST 15G1652_0046.csv
Rate 1,"1.60000",mm/s
Start date,"9/25/2021"
Specimen label,""

Time,Extension,2 kg Beam Load Cell
(s),(mm),(N)
"0.00000","-0.00254","-0.00074"
"0.02500","-0.00254","-0.00018"
"0.05000","-0.00193","0.00097"
"0.07500","0.00574","0.00063"
"0.10000","0.02320","0.00078"
"0.12500","0.04735","0.00100"
"0.15000","0.07617","0.00077"
"0.17500","0.10795","0.00077"
"0.20000","0.14224","0.00093"
"0.22500","0.17863","0.00167"
"0.25000","0.21608","0.00150"
"0.27500","0.25449","0.00221"
"0.30000","0.29386","0.00251"
"0.32500","0.33424","0.00292"
"0.35000","0.37532","0.00331"
"0.37500","0.41685","0.00364"
"0.40000","0.45890","0.00393"
"0.42500","0.50143","0.00442"
"0.45000","0.54397","0.00505"
"0.47500","0.58653","0.00539"
"0.50000","0.62916","0.00553"
"0.52500","0.67189","0.00627"
"0.55000","0.71460","0.00602"
"0.57500","0.75723","0.00707"
"0.60000","0.79978","0.00760"
"0.62500","0.84241","0.00755"
"0.65000","0.88537","0.00838"
"0.67500","0.92794","0.00854"
"0.70000","0.97046","0.00909"
"0.72500","1.01317","0.00930"
"0.75000","1.05600","0.00978"
"0.77500","1.09884","0.01016"
"0.80000","1.14167","0.01070"
"0.82500","1.18449","0.01103"
"0.85000","1.22726","0.01146"
"0.87500","1.26998","0.01193"
"0.90000","1.31300","0.01248"
"0.92500","1.35547","0.01274"
"0.95000","1.39765","0.01327"
"0.97500","1.43980","0.01384"
"1.00000","1.48197","0.01409"
"1.02500","1.52425","0.01452"
"1.05000","1.56661","0.01507"
"1.07500","1.60897","0.01526"
"1.10000","1.65134","0.01502"
"1.12500","1.69367","0.01718"
"1.15000","1.73600","0.01644"
"1.17500","1.77848","0.01716"
"1.20000","1.82132","0.01793"
"1.22500","1.86347","0.01767"
"1.25000","1.90560","0.01873"
"1.27500","1.94776","0.01900"
"1.30000","1.98956","0.01958"
"1.32500","2.03114","0.01953"
"1.35000","2.07277","0.01991"
"1.37500","2.11459","0.02054"
"1.40000","2.15655","0.02107"
"1.42500","2.19897","0.02162"
"1.45000","2.24085","0.02163"
"1.47500","2.28228","0.02231"
"1.50000","2.32389","0.02260"
"1.52500","2.36577","0.02331"
"1.55000","2.40768","0.02360"
"1.57500","2.44945","0.02426"
"1.60000","2.49113","0.02473"
"1.62500","2.53279","0.02479"
"1.65000","2.57434","0.02586"
"1.67500","2.61570","0.02598"
"1.70000","2.65749","0.02640"
"1.72500","2.69972","0.02676"
"1.75000","2.74147","0.02726"
"1.77500","2.78295","0.02788"
"1.80000","2.82450","0.02828"
"1.82500","2.86595","0.02885"
"1.85000","2.90732","0.02912"
"1.87500","2.94865","0.02966"
"1.90000","2.99034","0.02998"
"1.92500","3.03195","0.03030"
"1.95000","3.07306","0.03095"
"1.97500","3.11419","0.03143"
"2.00000","3.15539","0.03208"
"2.02500","3.19656","0.03264"
"2.05000","3.23709","0.03308"
"2.07500","3.27760","0.03341"
"2.10000","3.31861","0.03363"
"2.12500","3.35937","0.03442"
"2.15000","3.39965","0.03476"
"2.17500","3.43992","0.03529"
"2.20000","3.48020","0.03575"
"2.22500","3.52050","0.03614"
"2.25000","3.56078","0.03676"
"2.27500","3.60109","0.03731"
"2.30000","3.64145","0.03758"
"2.32500","3.68176","0.03794"
"2.35000","3.72223","0.03866"
"2.37500","3.76258","0.03914"
"2.40000","3.80261","0.03970"
"2.42500","3.84245","0.04004"
"2.45000","3.88231","0.04032"
"2.47500","3.92227","0.04110"
"2.50000","3.96255","0.04152"
"2.52500","4.00300","0.04198"
"2.55000","4.04269","0.04244"
"2.57500","4.08232","0.04285"
"2.60000","4.12211","0.04341"
"2.62500","4.16199","0.04387"
"2.65000","4.20191","0.04450"
"2.67500","4.24195","0.04469"
"2.70000","4.28193","0.04544"
"2.72500","4.32188","0.04596"
"2.75000","4.36185","0.04635"
"2.77500","4.40218","0.04674"
"2.80000","4.44221","0.04726"
"2.82500","4.48178","0.04775"
"2.85000","4.52162","0.04840"
"2.87500","4.56132","0.04889"
"2.90000","4.60102","0.04932"
"2.92500","4.64077","0.04995"
"2.95000","4.68080","0.05066"
"2.97500","4.72054","0.05084"
"3.00000","4.76020","0.05126"
"3.02500","4.79998","0.05195"
"3.05000","4.83989","0.05224"
"3.07500","4.87991","0.05314"
"3.10000","4.92046","0.05350"
"3.12500","4.96082","0.05415"
"3.15000","5.00062","0.05462"
"3.17500","5.04046","0.05513"
"3.20000","5.08014","0.05546"
"3.22500","5.11983","0.05586"
"3.25000","5.15968","0.05669"
"3.27500","5.19950","0.05730"
"3.30000","5.23927","0.05756"
"3.32500","5.27904","0.05868"
"3.35000","5.31887","0.05876"
"3.37500","5.35877","0.05946"
"3.40000","5.39883","0.05993"
"3.42500","5.43916","0.06069"
"3.45000","5.47904","0.06085"
"3.47500","5.51886","0.06148"
"3.50000","5.55874","0.06238"
"3.52500","5.59869","0.06257"
"3.55000","5.63864","0.06342"
"3.57500","5.67860","0.06380"
"3.60000","5.71862","0.06452"
"3.62500","5.75858","0.06521"
"3.65000","5.79845","0.06553"
"3.67500","5.83830","0.06598"
"3.70000","5.87852","0.06664"
"3.72500","5.91869","0.06721"
"3.75000","5.95837","0.06784"
"3.77500","5.99805","0.06849"
"3.80000","6.03797","0.06914"
"3.82500","6.07806","0.06955"
"3.85000","6.11806","0.07018"
"3.87500","6.15804","0.07077"
"3.90000","6.19805","0.07114"
"3.92500","6.23808","0.07202"
"3.95000","6.27821","0.07245"
"3.97500","6.31841","0.07308"
"4.00000","6.35898","0.07375"
"4.02500","6.39893","0.07424"
"4.05000","6.43852","0.07497"
"4.07500","6.47825","0.07554"
"4.10000","6.51811","0.07637"
"4.12500","6.55806","0.07668"
"4.15000","6.59800","0.07744"
"4.17500","6.63799","0.07816"
"4.20000","6.67801","0.07864"
"4.22500","6.71805","0.07947"
"4.25000","6.75810","0.07982"
"4.27500","6.79811","0.08012"
"4.30000","6.83814","0.08107"
"4.32500","6.87820","0.08170"
"4.35000","6.91831","0.08234"
"4.37500","6.95868","0.08292"
"4.40000","6.99947","0.08370"
"4.42500","7.03955","0.08405"
"4.45000","7.07928","0.08462"
"4.47500","7.11907","0.08545"
"4.50000","7.15898","0.08600"
"4.52500","7.19926","0.08652"
"4.55000","7.23943","0.08746"
"4.57500","7.27954","0.08815"
"4.60000","7.31962","0.08870"
"4.62500","7.35965","0.08923"
"4.65000","7.39968","0.08979"
"4.67500","7.43987","0.09065"
"4.70000","7.48005","0.09136"
"4.72500","7.52050","0.09191"
"4.75000","7.56106","0.09250"
"4.77500","7.60099","0.09329"
"4.80000","7.64082","0.09365"
"4.82500","7.68080","0.09435"
"4.85000","7.72084","0.09494"
"4.87500","7.76091","0.09582"
"4.90000","7.80103","0.09642"
"4.92500","7.84119","0.09740"
"4.95000","7.88131","0.09791"
"4.97500","7.92155","0.09845"
"5.00000","7.96177","0.09900"
"5.02500","8.00240","0.09961"
"5.05000","8.04325","0.10015"
"5.07500","8.08313","0.10111"
"5.10000","8.12290","0.10185"
"5.12500","8.16295","0.10231"
"5.15000","8.20312","0.10302"
"5.17500","8.24316","0.10372"
"5.20000","8.28312","0.10426"
"5.22500","8.32310","0.10491"
"5.25000","8.36304","0.10572"
"5.27500","8.40304","0.10636"
"5.30000","8.44312","0.10696"
"5.32500","8.48327","0.10782"
"5.35000","8.52340","0.10839"
"5.37500","8.56359","0.10918"
"5.40000","8.60442","0.10956"
"5.42500","8.64459","0.11016"
"5.45000","8.68435","0.11118"
"5.47500","8.72423","0.11177"
"5.50000","8.76422","0.11222"
"5.52500","8.80431","0.11289"
"5.55000","8.84425","0.11379"
"5.57500","8.88406","0.11422"
"5.60000","8.92389","0.11505"
"5.62500","8.96369","0.11557"
"5.65000","9.00358","0.11636"
"5.67500","9.04376","0.11716"
"5.70000","9.08418","0.11786"
"5.72500","9.12421","0.11834"
"5.75000","9.16407","0.11885"
"5.77500","9.20406","0.11977"
"5.80000","9.24413","0.12035"
"5.82500","9.28418","0.12103"
"5.85000","9.32424","0.12175"
"5.87500","9.36434","0.12235"
"5.90000","9.40436","0.12313"
"5.92500","9.44432","0.12362"
"5.95000","9.48427","0.12431"
"5.97500","9.52449","0.12489"
"6.00000","9.56537","0.12558"
"6.02500","9.60542","0.12652"
"6.05000","9.64502","0.12712"
"6.07500","9.68484","0.12776"
"6.10000","9.72493","0.12830"
"6.12500","9.76501","0.12909"
"6.15000","9.80501","0.12986"
"6.17500","9.84498","0.13024"
"6.20000","9.88498","0.13108"
"6.22500","9.92509","0.13175"
"6.25000","9.96508","0.13230"
"6.27500","10.00510","0.13309"
"6.30000","10.04508","0.13368"
"6.32500","10.08497","0.13439"
"6.35000","10.12479","0.13499"
"6.37500","10.16460","0.13590"
"6.40000","10.20446","0.13623"
"6.42500","10.24423","0.13695"
"6.45000","10.28412","0.13783"
"6.47500","10.32449","0.13835"
"6.50000","10.36467","0.13919"
"6.52500","10.40444","0.13988"
"6.55000","10.44423","0.14033"
"6.57500","10.48413","0.14104"
"6.60000","10.52406","0.14156"
"6.62500","10.56405","0.14261"
"6.65000","10.60406","0.14292"
"6.67500","10.64436","0.14381"
"6.70000","10.68458","0.14422"
"6.72500","10.72450","0.14502"
"6.75000","10.76430","0.14587"
"6.77500","10.80405","0.14621"
"6.80000","10.84391","0.14697"
"6.82500","10.88384","0.14757"
"6.85000","10.92385","0.14823"
"6.87500","10.96409","0.14895"
"6.90000","11.00458","0.14932"
"6.92500","11.04463","0.15038"
"6.95000","11.08437","0.15081"
"6.97500","11.12421","0.15156"
"7.00000","11.16413","0.15215"
"7.02500","11.20408","0.15260"
"7.05000","11.24398","0.15369"
"7.07500","11.28391","0.15424"
"7.10000","11.32393","0.15489"
"7.12500","11.36403","0.15556"
"7.15000","11.40406","0.15600"
"7.17500","11.44399","0.15693"
"7.20000","11.48383","0.15746"
"7.22500","11.52364","0.15811"
"7.25000","11.56348","0.15853"
"7.27500","11.60341","0.15917"
"7.30000","11.64350","0.16016"
"7.32500","11.68354","0.16067"
"7.35000","11.72368","0.16136"
"7.37500","11.76381","0.16187"
"7.40000","11.80440","0.16238"
"7.42500","11.84492","0.16317"
"7.45000","11.88468","0.16360"
"7.47500","11.92424","0.16433"
"7.50000","11.96392","0.16483"
"7.52500","12.00376","0.16552"
"7.55000","12.04377","0.16592"
"7.57500","12.08376","0.16672"
"7.60000","12.12370","0.16733"
"7.62500","12.16372","0.16784"
"7.65000","12.20367","0.16863"
"7.67500","12.24364","0.16906"
"7.70000","12.28359","0.16971"
"7.72500","12.32354","0.17038"
"7.75000","12.36351","0.17096"
"7.77500","12.40350","0.17162"
"7.80000","12.44356","0.17219"
"7.82500","12.48368","0.17281"
"7.85000","12.52429","0.17335"
"7.87500","12.56460","0.17388"
"7.90000","12.60432","0.17486"
"7.92500","12.64402","0.17527"
"7.95000","12.68389","0.17600"
"7.97500","12.72383","0.17648"
"8.00000","12.76387","0.17711"
"8.02500","12.80395","0.17756"
"8.05000","12.84405","0.17845"
"8.07500","12.88416","0.17889"
"8.10000","12.92443","0.17953"
"8.12500","12.96423","0.18037"
"8.15000","13.00403","0.18073"
"8.17500","13.04391","0.18129"
"8.20000","13.08383","0.18193"
"8.22500","13.12377","0.18267"
"8.25000","13.16391","0.18303"
"8.27500","13.20387","0.18372"
"8.30000","13.24373","0.18433"
"8.32500","13.28366","0.18481"
"8.35000","13.32360","0.18548"
"8.37500","13.36347","0.18594"
"8.40000","13.40344","0.18667"
"8.42500","13.44347","0.18718"
"8.45000","13.48348","0.18761"
"8.47500","13.52351","0.18812"
"8.50000","13.56400","0.18869"
"8.52500","13.60474","0.18935"
"8.55000","13.64481","0.18966"
"8.57500","13.68448","0.19046"
"8.60000","13.72422","0.19085"
"8.62500","13.76408","0.19114"
"8.65000","13.80405","0.19201"
"8.67500","13.84404","0.19249"
"8.70000","13.88408","0.19296"
"8.72500","13.92454","0.19345"
"8.75000","13.96451","0.19399"
"8.77500","14.00422","0.19464"
"8.80000","14.04394","0.19525"
"8.82500","14.08369","0.19554"
"8.85000","14.12357","0.19600"
"8.87500","14.16350","0.19660"
"8.90000","14.20345","0.19732"
"8.92500","14.24354","0.19746"
"8.95000","14.28369","0.19797"
"8.97500","14.32368","0.19865"
"9.00000","14.36357","0.19894"
"9.02500","14.40349","0.19960"
"9.05000","14.44342","0.19980"
"9.07500","14.48339","0.20025"
"9.10000","14.52347","0.20083"
"9.12500","14.56369","0.20130"
"9.15000","14.60397","0.20148"
"9.17500","14.64410","0.20219"
"9.20000","14.68474","0.20258"
"9.22500","14.72511","0.20279"
"9.25000","14.76466","0.20332"
"9.27500","14.80424","0.20387"
"9.30000","14.84410","0.20399"
"9.32500","14.88410","0.20458"
"9.35000","14.92413","0.20500"
"9.37500","14.96412","0.20526"
"9.40000","15.00432","0.20587"
"9.42500","15.04447","0.20625"
"9.45000","15.08435","0.20661"
"9.47500","15.12433","0.20705"
"9.50000","15.16438","0.20745"
"9.52500","15.20444","0.20784"
"9.55000","15.24430","0.20824"
"9.57500","15.28411","0.20887"
"9.60000","15.32401","0.20893"
"9.62500","15.36401","0.20936"
"9.65000","15.40388","0.20976"
"9.67500","15.44436","0.21000"
"9.70000","15.48447","0.21041"
"9.72500","15.52416","0.21069"
"9.75000","15.56393","0.21093"
"9.77500","15.60385","0.21112"
"9.80000","15.64387","0.21171"
"9.82500","15.68407","0.21176"
"9.85000","15.72419","0.21235"
"9.87500","15.76419","0.21279"
"9.90000","15.80422","0.21315"
"9.92500","15.84427","0.21354"
"9.95000","15.88430","0.21389"
"9.97500","15.92426","0.21416"
"10.00000","15.96417","0.21450"
"10.02500","16.00436","0.21481"
"10.05000","16.04401","0.21555"
"10.07500","16.08364","0.21583"
"10.10000","16.12349","0.21616"
"10.12500","16.16350","0.21647"
"10.15000","16.20350","0.21679"
"10.17500","16.24352","0.21741"
"10.20000","16.28360","0.21716"
"10.22500","16.32375","0.21786"
"10.25000","16.36390","0.21819"
"10.27500","16.40406","0.21837"
"10.30000","16.44416","0.21877"
"10.32500","16.48402","0.21898"
"10.35000","16.52379","0.21976"
"10.37500","16.56354","0.21971"
"10.40000","16.60332","0.22001"
"10.42500","16.64315","0.22031"
"10.45000","16.68363","0.22061"
"10.47500","16.72438","0.22118"
"10.50000","16.76428","0.22111"
"10.52500","16.80398","0.22143"
"10.55000","16.84384","0.22165"
"10.57500","16.88395","0.22185"
"10.60000","16.92412","0.22230"
"10.62500","16.96428","0.22244"
"10.65000","17.00446","0.22311"
"10.67500","17.04451","0.22297"
"10.70000","17.08452","0.22353"
"10.72500","17.12457","0.22376"
"10.75000","17.16449","0.22375"
"10.77500","17.20431","0.22443"
"10.80000","17.24444","0.22445"
"10.82500","17.28478","0.22491"
"10.85000","17.32452","0.22512"
"10.87500","17.36425","0.22539"
"10.90000","17.40416","0.22579"
"10.92500","17.44412","0.22561"
"10.95000","17.48421","0.22633"
"10.97500","17.52427","0.22621"
"11.00000","17.56432","0.22675"
"11.02500","17.60446","0.22711"
"11.05000","17.64464","0.22698"
"11.07500","17.68476","0.22737"
"11.10000","17.72484","0.22761"
"11.12500","17.76479","0.22794"
"11.15000","17.80462","0.22813"
"11.17500","17.84441","0.22838"
"11.20000","17.88419","0.22868"
"11.22500","17.92397","0.22890"
"11.25000","17.96377","0.22931"
"11.27500","18.00360","0.22910"
"11.30000","18.04356","0.22943"
"11.32500","18.08378","0.23004"
"11.35000","18.12424","0.23002"
"11.37500","18.16447","0.23032"
"11.40000","18.20451","0.23036"
"11.42500","18.24454","0.23064"
"11.45000","18.28460","0.23079"
"11.47500","18.32463","0.23132"
"11.50000","18.36539","0.23157"
"11.52500","18.40607","0.23165"
"11.55000","18.44597","0.23217"
"11.57500","18.48553","0.23223"
"11.60000","18.52509","0.23253"
"11.62500","18.56498","0.23299"
"11.65000","18.60480","0.23289"
"11.67500","18.64457","0.23323"
"11.70000","18.68443","0.23348"
"11.72500","18.72437","0.23380"
"11.75000","18.76457","0.23379"
"11.77500","18.80463","0.23414"
"11.80000","18.84458","0.23425"
"11.82500","18.88453","0.23438"
"11.85000","18.92457","0.23496"
"11.87500","18.96469","0.23496"
"11.90000","19.00478","0.23533"
"11.92500","19.04497","0.23570"
"11.95000","19.08513","0.23572"
"11.97500","19.12553","0.23567"
"12.00000","19.16528","0.23603"
"12.02500","19.20488","0.23627"
"12.05000","19.24467","0.23645"
"12.07500","19.28455","0.23692"
"12.10000","19.32448","0.23691"
"12.12500","19.36443","0.23689"
"12.15000","19.40445","0.23713"
"12.17500","19.44445","0.23757"
"12.20000","19.48446","0.23752"
"12.22500","19.52442","0.23784"
"12.25000","19.56447","0.23775"
"12.27500","19.60469","0.23773"
"12.30000","19.64504","0.23816"
"12.32500","19.68538","0.23820"
"12.35000","19.72581","0.23835"
"12.37500","19.76583","0.23843"
"12.40000","19.80541","0.23895"
"12.42500","19.84518","0.23888"
"12.45000","19.88509","0.23906"
"12.47500","19.92509","0.23939"
"12.50000","19.96497","0.23953"
"12.52500","20.00488","0.23957"
"12.55000","20.04484","0.23982"
"12.57500","20.08487","0.23980"
"12.60000","20.12487","0.24014"
"12.62500","20.16489","0.24037"
"12.65000","20.20517","0.24068"
"12.67500","20.24539","0.24051"
"12.70000","20.28549","0.24097"
"12.72500","20.32551","0.24072"
"12.75000","20.36546","0.24104"
"12.77500","20.40535","0.24148"
"12.80000","20.44526","0.24138"
"12.82500","20.48528","0.24145"
"12.85000","20.52522","0.24150"
"12.87500","20.56515","0.24187"
"12.90000","20.60504","0.24196"
"12.92500","20.64490","0.24234"
"12.95000","20.68484","0.24218"
"12.97500","20.72490","0.24238"
"13.00000","20.76499","0.24266"
"13.02500","20.80519","0.24256"
"13.05000","20.84558","0.24257"
"13.07500","20.88576","0.24265"
"13.10000","20.92655","0.24267"
"13.12500","20.96696","0.24286"
"13.15000","21.00655","0.24285"
"13.17500","21.04602","0.24305"
"13.20000","21.08579","0.24310"
"13.22500","21.12576","0.24321"
"13.25000","21.16573","0.24330"
"13.27500","21.20564","0.24338"
"13.30000","21.24558","0.24391"
"13.32500","21.28552","0.24380"
"13.35000","21.32547","0.24406"
"13.37500","21.36556","0.24422"
"13.40000","21.40566","0.24394"
"13.42500","21.44608","0.24378"
"13.45000","21.48630","0.24400"
"13.47500","21.52617","0.24433"
"13.50000","21.56621","0.24431"
"13.52500","21.60611","0.24460"
"13.55000","21.64590","0.24460"
"13.57500","21.68572","0.24473"
"13.60000","21.72554","0.24501"
"13.62500","21.76545","0.24515"
"13.65000","21.80545","0.24516"
"13.67500","21.84551","0.24571"
"13.70000","21.88567","0.24571"
"13.72500","21.92591","0.24593"
"13.75000","21.96587","0.24627"
"13.77500","22.00564","0.24645"
"13.80000","22.04552","0.24655"
"13.82500","22.08550","0.24668"
"13.85000","22.12553","0.24697"
"13.87500","22.16552","0.24712"
"13.90000","22.20545","0.24730"
"13.92500","22.24538","0.24751"
"13.95000","22.28544","0.24770"
"13.97500","22.32558","0.24790"
"14.00000","22.36570","0.24803"
"14.02500","22.40623","0.24829"
"14.05000","22.44658","0.24844"
"14.07500","22.48635","0.24895"
"14.10000","22.52601","0.24876"
"14.12500","22.56593","0.24891"
"14.15000","22.60594","0.24930"
"14.17500","22.64601","0.24904"
"14.20000","22.68603","0.24947"
"14.22500","22.72603","0.24928"
"14.25000","22.76613","0.24940"
"14.27500","22.80623","0.24938"
"14.30000","22.84634","0.24945"
"14.32500","22.88627","0.24942"
"14.35000","22.92606","0.24953"
"14.37500","22.96595","0.24944"
"14.40000","23.00584","0.24897"
"14.42500","23.04569","0.24904"
"14.45000","23.08557","0.24864"
"14.47500","23.12547","0.24834"
"14.50000","23.16545","0.24822"
"14.52500","23.20547","0.24804"
"14.55000","23.24548","0.24817"
"14.57500","23.28563","0.24795"
"14.60000","23.32581","0.24794"
"14.62500","23.36624","0.24775"
"14.65000","23.40664","0.24758"
"14.67500","23.44631","0.24763"
"14.70000","23.48595","0.24747"
"14.72500","23.52570","0.24767"
"14.75000","23.56550","0.24767"
"14.77500","23.60535","0.24731"
"14.80000","23.64526","0.24740"
"14.82500","23.68518","0.24692"
"14.85000","23.72514","0.24676"
"14.87500","23.76510","0.24652"
"14.90000","23.80512","0.24690"
"14.92500","23.84517","0.24695"
"14.95000","23.88515","0.24674"
"14.97500","23.92508","0.24688"
"15.00000","23.96504","0.24633"
"15.02500","24.00489","0.24680"
"15.05000","24.04484","0.24671"
"15.07500","24.08516","0.24656"
"15.10000","24.12601","0.24677"
"15.12500","24.16624","0.24667"
"15.15000","24.20583","0.24672"
"15.17500","24.24541","0.24626"
"15.20000","24.28521","0.24626"
"15.22500","24.32513","0.24626"
"15.25000","24.36505","0.24601"
"15.27500","24.40502","0.24624"
"15.30000","24.44507","0.24602"
"15.32500","24.48511","0.24631"
"15.35000","24.52520","0.24615"
"15.37500","24.56522","0.24606"
"15.40000","24.60520","0.24612"
"15.42500","24.64516","0.24622"
"15.45000","24.68503","0.24629"
"15.47500","24.72496","0.24611"
"15.50000","24.76492","0.24626"
"15.52500","24.80485","0.24650"
"15.55000","24.84476","0.24621"
"15.57500","24.88469","0.24634"
"15.60000","24.92463","0.24623"
"15.62500","24.96454","0.24605"
"15.65000","25.00446","0.24619"
"15.67500","25.04448","0.24604"
"15.70000","25.08472","0.24616"
"15.72500","25.12536","0.24604"
"15.75000","25.16600","0.24607"
"15.77500","25.20589","0.24597"
"15.80000","25.24540","0.24579"
"15.82500","25.28505","0.24594"
"15.85000","25.32488","0.24533"
"15.87500","25.36470","0.24571"
"15.90000","25.40454","0.24537"
"15.92500","25.44439","0.24551"
"15.95000","25.48437","0.24540"
"15.97500","25.52443","0.24476"
"16.00000","25.56442","0.24469"
"16.02500","25.60434","0.24457"
"16.05000","25.64432","0.24502"
"16.07500","25.68427","0.24486"
"16.10000","25.72427","0.24485"
"16.12500","25.76424","0.24497"
"16.15000","25.80432","0.24489"
"16.17500","25.84442","0.24522"
"16.20000","25.88446","0.24535"
"16.22500","25.92445","0.24529"
"16.25000","25.96434","0.24554"
"16.27500","26.00429","0.24567"
"16.30000","26.04449","0.24553"
"16.32500","26.08424","0.24532"
"16.35000","26.12429","0.24523"
"16.37500","26.16431","0.24514"
"16.40000","26.20404","0.24503"
"16.42500","26.24380","0.24537"
"16.45000","26.28371","0.24504"
"16.47500","26.32384","0.24541"
"16.50000","26.36416","0.24558"
"16.52500","26.40458","0.24559"
"16.55000","26.44519","0.24594"
"16.57500","26.48568","0.24592"
"16.60000","26.52551","0.24650"
"16.62500","26.56507","0.24627"
"16.65000","26.60490","0.24664"
"16.67500","26.64473","0.24677"
"16.70000","26.68448","0.24648"
"16.72500","26.72424","0.24711"
"16.75000","26.76404","0.24689"
"16.77500","26.80376","0.24724"
"16.80000","26.84355","0.24758"
"16.82500","26.88340","0.24749"
"16.85000","26.92334","0.24754"
"16.87500","26.96346","0.24760"
"16.90000","27.00380","0.24799"
"16.92500","27.04420","0.24794"
"16.95000","27.08446","0.24818"
"16.97500","27.12457","0.24845"
"17.00000","27.16457","0.24845"
"17.02500","27.20454","0.24873"
"17.05000","27.24442","0.24876"
"17.07500","27.28431","0.24883"
"17.10000","27.32416","0.24929"
"17.12500","27.36397","0.24944"
"17.15000","27.40376","0.24960"
"17.17500","27.44349","0.24980"
"17.20000","27.48336","0.24993"
"17.22500","27.52340","0.25010"
"17.25000","27.56345","0.25018"
"17.27500","27.60374","0.25049"
"17.30000","27.64419","0.25050"
"17.32500","27.68459","0.25084"
"17.35000","27.72462","0.25097"
"17.37500","27.76461","0.25092"
"17.40000","27.80464","0.25094"
"17.42500","27.84470","0.25115"
"17.45000","27.88470","0.25123"
"17.47500","27.92458","0.25152"
"17.50000","27.96435","0.25150"
"17.52500","28.00411","0.25178"
"17.55000","28.04389","0.25213"
"17.57500","28.08368","0.25247"
"17.60000","28.12356","0.25213"
"17.62500","28.16357","0.25227"
"17.65000","28.20383","0.25258"
"17.67500","28.24435","0.25281"
"17.70000","28.28527","0.25314"
"17.72500","28.32582","0.25301"
"17.75000","28.36558","0.25345"
"17.77500","28.40539","0.25349"
"17.80000","28.44533","0.25378"
"17.82500","28.48531","0.25368"
"17.85000","28.52529","0.25388"
"17.87500","28.56516","0.25437"
"17.90000","28.60506","0.25431"
"17.92500","28.64477","0.25464"
"17.95000","28.68443","0.25460"
"17.97500","28.72418","0.25448"
"18.00000","28.76406","0.25468"
"18.02500","28.80389","0.25476"
"18.05000","28.84376","0.25470"
"18.07500","28.88381","0.25469"
"18.10000","28.92402","0.25499"
"18.12500","28.96426","0.25498"
"18.15000","29.00437","0.25517"
"18.17500","29.04441","0.25492"
"18.20000","29.08443","0.25484"
"18.22500","29.12442","0.25478"
"18.25000","29.16442","0.25493"
"18.27500","29.20446","0.25451"
"18.30000","29.24438","0.25435"
"18.32500","29.28444","0.25408"
"18.35000","29.32428","0.25389"
"18.37500","29.36399","0.25358"
"18.40000","29.40368","0.25327"
"18.42500","29.44352","0.25299"
"18.45000","29.48347","0.25271"
"18.47500","29.52349","0.25255"
"18.50000","29.56372","0.25229"
"18.52500","29.60396","0.25179"
"18.55000","29.64422","0.25157"
"18.57500","29.68444","0.25119"
"18.60000","29.72458","0.25017"
"18.62500","29.76463","0.24965"
"18.65000","29.80453","0.24840"
"18.67500","29.84436","0.24756"
"18.70000","29.88415","0.24618"
"18.72500","29.92411","0.24447"
"18.75000","29.96411","0.24301"
"18.77500","30.00422","0.24205"
"18.80000","30.04419","0.24119"
"18.82500","30.08474","0.23999"
"18.85000","30.12527","0.23896"
"18.87500","30.16499","0.23743"
"18.90000","30.20460","0.23628"
"18.92500","30.24462","0.23502"
"18.95000","30.28482","0.23364"
"18.97500","30.32499","0.23186"
"19.00000","30.36495","0.22905"
"19.02500","30.40489","0.22664"
"19.05000","30.44481","0.22447"
"19.07500","30.48480","0.22259"
"19.10000","30.52470","0.22025"
"19.12500","30.56445","0.21666"
"19.15000","30.60423","0.21359"
"19.17500","30.64403","0.21025"
"19.20000","30.68375","0.20510"
"19.22500","30.72359","0.19905"
"19.25000","30.76350","0.19326"
"19.27500","30.80353","0.18790"
"19.30000","30.84377","0.18284"
"19.32500","30.88416","0.17806"
"19.35000","30.92436","0.17335"
"19.37500","30.96446","0.16905"
"19.40000","31.00452","0.16477"
"19.42500","31.04454","0.16000"
"19.45000","31.08443","0.15486"
"19.47500","31.12422","0.14923"
"19.50000","31.16403","0.14427"
"19.52500","31.20391","0.14023"
"19.55000","31.24416","0.13680"
"19.57500","31.28450","0.13360"
"19.60000","31.32458","0.13019"
"19.62500","31.36465","0.12680"
"19.65000","31.40488","0.12282"
"19.67500","31.44495","0.11796"
"19.70000","31.48478","0.11313"
"19.72500","31.52488","0.10902"
"19.75000","31.56506","0.10543"
"19.77500","31.60519","0.10152"
"19.80000","31.64536","0.09785"
"19.82500","31.68539","0.09444"
"19.85000","31.72521","0.09151"
"19.87500","31.76498","0.08820"
"19.90000","31.80476","0.08556"
"19.92500","31.84458","0.08269"
"19.95000","31.88444","0.07934"
"19.97500","31.92447","0.07597"
"20.00000","31.96445","0.07208"
"20.02500","32.00445","0.06769"
"20.05000","32.04464","0.06167"
"20.07500","32.08482","0.05554"
"20.10000","32.12491","0.04643"
"20.12500","32.16491","0.01129"
"20.15000","32.20486","-0.01334"
"20.17500","32.24485","-0.01732"
"20.20000","32.28485","-0.01578"
"20.22500","32.32477","-0.01441"
"20.25000","32.36463","-0.01400"
"20.27500","32.40439","-0.01406"
"20.30000","32.44403","-0.01425"
"20.32500","32.48376","-0.01470"
"20.35000","32.52360","-0.01498"
"20.37500","32.56354","-0.01423"
"20.40000","32.60372","-0.01413"
"20.42500","32.64381","-0.01414"
"20.45000","32.68379","-0.01442"
"20.47500","32.72393","-0.01488"
"20.50000","32.76414","-0.01462"
"20.52500","32.80486","-0.01428"
"20.55000","32.84583","-0.01417"
"20.57500","32.88595","-0.01422"
"20.60000","32.92554","-0.01451"
"20.62500","32.96532","-0.01468"
"20.65000","33.00509","-0.01451"
"20.67500","33.04482","-0.01415"
"20.70000","33.08457","-0.01425"
"20.72500","33.12442","-0.01458"
"20.75000","33.16433","-0.01466"
"20.77500","33.20415","-0.01465"
"20.80000","33.24395","-0.01432"
"20.82500","33.28384","-0.01435"
"20.85000","33.32401","-0.01428"
"20.87500","33.36429","-0.01439"
"20.90000","33.40425","-0.01432"
"20.92500","33.44426","-0.01445"
"20.95000","33.48435","-0.01464"
"20.97500","33.52437","-0.01415"
"21.00000","33.56423","-0.01413"
"21.02500","33.60406","-0.01448"
"21.05000","33.64382","-0.01454"
"21.07500","33.68366","-0.01443"
"21.10000","33.72376","-0.01451"
"21.12500","33.76368","-0.01420"
"21.15000","33.80342","-0.01456"
"21.17500","33.84374","-0.01459"
"21.20000","33.88445","-0.01448"
"21.22500","33.92457","-0.01415"
"21.25000","33.96413","-0.01436"
"21.27500","34.00374","-0.01453"
"21.30000","34.04374","-0.01409"
"21.32500","34.08397","-0.01483"
"21.35000","34.12419","-0.01435"
"21.37500","34.16428","-0.01422"
"21.40000","34.20433","-0.01447"
"21.42500","34.24442","-0.01418"
"21.45000","34.28416","-0.01455"
"21.47500","34.32381","-0.01452"
"21.50000","34.36355","-0.01454"
"21.52500","34.40337","-0.01447"
"21.55000","34.44330","-0.01430"
"21.57500","34.48319","-0.01436"
"21.60000","34.52304","-0.01408"
"21.62500","34.56305","-0.01467"
"21.65000","34.60316","-0.01440"
"21.67500","34.64347","-0.01453"
"21.70000","34.68398","-0.01456"
"21.72500","34.72474","-0.01456"
"21.75000","34.76518","-0.01439"
"21.77500","34.80488","-0.01426"
"21.80000","34.84464","-0.01455"
"21.82500","34.88460","-0.01435"
"21.85000","34.92443","-0.01443"
"21.87500","34.96423","-0.01450"
"21.90000","35.00420","-0.01431"
"21.92500","35.04424","-0.01470"
"21.95000","35.08415","-0.01438"
"21.97500","35.12398","-0.01420"
"22.00000","35.16385","-0.01457"
"22.02500","35.20382","-0.01446"
"22.05000","35.24382","-0.01452"
"22.07500","35.28391","-0.01417"
"22.10000","35.32408","-0.01464"
"22.12500","35.36432","-0.01465"
"22.15000","35.40495","-0.01417"
"22.17500","35.44521","-0.01420"
"22.20000","35.48486","-0.01406"
"22.22500","35.52462","-0.01468"
"22.25000","35.56469","-0.01444"
"22.27500","35.60502","-0.01448"
"22.30000","35.64490","-0.01403"
"22.32500","35.68451","-0.01412"
"22.35000","35.72423","-0.01454"
"22.37500","35.76403","-0.01422"
"22.40000","35.80396","-0.01475"
"22.42500","35.84408","-0.01424"
"22.45000","35.88418","-0.01438"
"22.47500","35.92428","-0.01454"
"22.50000","35.96441","-0.01432"
"22.52500","36.00468","-0.01437"
"22.55000","36.04500","-0.01426"
"22.57500","36.08515","-0.01439"
"22.60000","36.12499","-0.01446"
"22.62500","36.16529","-0.01439"
"22.65000","36.20589","-0.01430"
"22.67500","36.24603","-0.01417"
"22.70000","36.28557","-0.01433"
"22.72500","36.32508","-0.01438"
"22.75000","36.36482","-0.01407"
"22.77500","36.40467","-0.01455"
"22.80000","36.44482","-0.01434"
"22.82500","36.48486","-0.01448"
"22.85000","36.52478","-0.01418"
"22.87500","36.56478","-0.01421"
"22.90000","36.60481","-0.01445"
"22.92500","36.64500","-0.01430"
"22.95000","36.68513","-0.01449"
"22.97500","36.72509","-0.01424"
"23.00000","36.76497","-0.01450"
"23.02500","36.80487","-0.01431"
"23.05000","36.84469","-0.01413"
"23.07500","36.88452","-0.01445"
"23.10000","36.92436","-0.01416"
"23.12500","36.96426","-0.01418"
"23.15000","37.00424","-0.01451"
"23.17500","37.04420","-0.01431"
"23.20000","37.08416","-0.01441"
"23.22500","37.12416","-0.01409"
"23.25000","37.16415","-0.01446"
"23.27500","37.20433","-0.01421"
"23.30000","37.24487","-0.01445"
"23.32500","37.28482","-0.01428"
"23.35000","37.32454","-0.01420"
"23.37500","37.36486","-0.01465"
"23.40000","37.40593","-0.01442"
"23.42500","37.44620","-0.01411"
"23.45000","37.48577","-0.01419"
"23.47500","37.52526","-0.01435"
"23.50000","37.56488","-0.01443"
"23.52500","37.60480","-0.01431"
"23.55000","37.64482","-0.01439"
"23.57500","37.68469","-0.01422"
"23.60000","37.72455","-0.01419"
"23.62500","37.76444","-0.01447"
"23.65000","37.80452","-0.01404"
"23.67500","37.84488","-0.01435"
"23.70000","37.88482","-0.01431"
"23.72500","37.92460","-0.01426"
"23.75000","37.96455","-0.01439"
"23.77500","38.00459","-0.01439"
"23.80000","38.04469","-0.01420"
"23.82500","38.08480","-0.01424"
"23.85000","38.12475","-0.01430"
"23.87200","38.15978","-0.01423"