File: 20G1650/ST 20G1650_0077.csv
Rate 1,"1.60000",mm/s
Start date,"9/27/2021"
Specimen label,""

Time,Extension,2 kg Beam Load Cell
(s),(mm),(N)
"0.00000","0.00127","-0.00050"
"0.02500","0.00127","0.00002"
"0.05000","0.00335","0.00134"
"0.07500","0.01369","0.00155"
"0.10000","0.03120","0.00228"
"0.12500","0.05428","0.00344"
"0.15000","0.08213","0.00457"
"0.17500","0.11345","0.00557"
"0.20000","0.14712","0.00729"
"0.22500","0.18271","0.00925"
"0.25000","0.21992","0.01079"
"0.27500","0.25838","0.01295"
"0.30000","0.29797","0.01484"
"0.32500","0.33869","0.01648"
"0.35000","0.38009","0.01879"
"0.37500","0.42198","0.02096"
"0.40000","0.46469","0.02293"
"0.42500","0.50699","0.02486"
"0.45000","0.54903","0.02736"
"0.47500","0.59121","0.02937"
"0.50000","0.63384","0.03147"
"0.52500","0.67661","0.03372"
"0.55000","0.71941","0.03571"
"0.57500","0.76234","0.03820"
"0.60000","0.80529","0.04048"
"0.62500","0.84826","0.04263"
"0.65000","0.89160","0.04461"
"0.67500","0.93456","0.04673"
"0.70000","0.97758","0.04924"
"0.72500","1.02072","0.05122"
"0.75000","1.06381","0.05386"
"0.77500","1.10685","0.05577"
"0.80000","1.14952","0.05792"
"0.82500","1.19219","0.06050"
"0.85000","1.23484","0.06247"
"0.87500","1.27750","0.06497"
"0.90000","1.32026","0.06706"
"0.92500","1.36336","0.06921"
"0.95000","1.40605","0.07169"
"0.97500","1.44837","0.07424"
"1.00000","1.49074","0.07645"
"1.02500","1.53331","0.07849"
"1.05000","1.57598","0.08122"
"1.07500","1.61863","0.08332"
"1.10000","1.66128","0.08532"
"1.12500","1.70378","0.08750"
"1.15000","1.74592","0.09062"
"1.17500","1.78793","0.09241"
"1.20000","1.83002","0.09577"
"1.22500","1.87210","0.09716"
"1.25000","1.91409","0.09954"
"1.27500","1.95664","0.10189"
"1.30000","1.99897","0.10439"
"1.32500","2.04064","0.10678"
"1.35000","2.08234","0.10905"
"1.37500","2.12477","0.11174"
"1.40000","2.16753","0.11379"
"1.42500","2.21001","0.11672"
"1.45000","2.25226","0.11912"
"1.47500","2.29450","0.12130"
"1.50000","2.33667","0.12362"
"1.52500","2.37882","0.12595"
"1.55000","2.42067","0.12845"
"1.57500","2.46233","0.13117"
"1.60000","2.50395","0.13385"
"1.62500","2.54550","0.13611"
"1.65000","2.58704","0.13864"
"1.67500","2.62854","0.14098"
"1.70000","2.67005","0.14321"
"1.72500","2.71157","0.14592"
"1.75000","2.75305","0.14853"
"1.77500","2.79513","0.15105"
"1.80000","2.83667","0.15338"
"1.82500","2.87745","0.15586"
"1.85000","2.91799","0.15832"
"1.87500","2.95843","0.16086"
"1.90000","2.99876","0.16345"
"1.92500","3.03899","0.16568"
"1.95000","3.07906","0.16838"
"1.97500","3.11907","0.17080"
"2.00000","3.15906","0.17320"
"2.02500","3.19906","0.17587"
"2.05000","3.23912","0.17844"
"2.07500","3.27916","0.18074"
"2.10000","3.31918","0.18325"
"2.12500","3.35938","0.18572"
"2.15000","3.40000","0.18814"
"2.17500","3.44037","0.19085"
"2.20000","3.48044","0.19347"
"2.22500","3.52049","0.19588"
"2.25000","3.56055","0.19831"
"2.27500","3.60083","0.20105"
"2.30000","3.64108","0.20349"
"2.32500","3.68169","0.20598"
"2.35000","3.72197","0.20887"
"2.37500","3.76178","0.21130"
"2.40000","3.80158","0.21382"
"2.42500","3.84162","0.21667"
"2.45000","3.88185","0.21911"
"2.47500","3.92167","0.22148"
"2.50000","3.96142","0.22439"
"2.52500","4.00143","0.22660"
"2.55000","4.04172","0.22912"
"2.57500","4.08200","0.23182"
"2.60000","4.12226","0.23441"
"2.62500","4.16246","0.23716"
"2.65000","4.20272","0.23957"
"2.67500","4.24292","0.24210"
"2.70000","4.28301","0.24474"
"2.72500","4.32303","0.24759"
"2.75000","4.36312","0.25016"
"2.77500","4.40421","0.25264"
"2.80000","4.44467","0.25550"
"2.82500","4.48437","0.25808"
"2.85000","4.52404","0.26078"
"2.87500","4.56382","0.26363"
"2.90000","4.60376","0.26608"
"2.92500","4.64399","0.26886"
"2.95000","4.68426","0.27119"
"2.97500","4.72436","0.27424"
"3.00000","4.76454","0.27660"
"3.02500","4.80470","0.27972"
"3.05000","4.84491","0.28207"
"3.07500","4.88507","0.28445"
"3.10000","4.92520","0.28775"
"3.12500","4.96548","0.29006"
"3.15000","5.00575","0.29315"
"3.17500","5.04619","0.29567"
"3.20000","5.08619","0.29870"
"3.22500","5.12583","0.30144"
"3.25000","5.16546","0.30419"
"3.27500","5.20525","0.30689"
"3.30000","5.24520","0.30959"
"3.32500","5.28537","0.31261"
"3.35000","5.32617","0.31568"
"3.37500","5.36637","0.31815"
"3.40000","5.40614","0.32141"
"3.42500","5.44603","0.32405"
"3.45000","5.48613","0.32689"
"3.47500","5.52637","0.32990"
"3.50000","5.56646","0.33272"
"3.52500","5.60640","0.33567"
"3.55000","5.64625","0.33843"
"3.57500","5.68610","0.34184"
"3.60000","5.72591","0.34461"
"3.62500","5.76578","0.34733"
"3.65000","5.80578","0.35072"
"3.67500","5.84580","0.35321"
"3.70000","5.88594","0.35659"
"3.72500","5.92686","0.35921"
"3.75000","5.96735","0.36243"
"3.77500","6.00708","0.36529"
"3.80000","6.04688","0.36843"
"3.82500","6.08694","0.37130"
"3.85000","6.12704","0.37422"
"3.87500","6.16710","0.37744"
"3.90000","6.20715","0.38031"
"3.92500","6.24708","0.38334"
"3.95000","6.28687","0.38643"
"3.97500","6.32664","0.38920"
"4.00000","6.36643","0.39267"
"4.02500","6.40646","0.39562"
"4.05000","6.44684","0.39871"
"4.07500","6.48679","0.40185"
"4.10000","6.52672","0.40488"
"4.12500","6.56685","0.40804"
"4.15000","6.60735","0.41071"
"4.17500","6.64771","0.41433"
"4.20000","6.68758","0.41716"
"4.22500","6.72745","0.42043"
"4.25000","6.76756","0.42358"
"4.27500","6.80780","0.42645"
"4.30000","6.84789","0.42979"
"4.32500","6.88801","0.43260"
"4.35000","6.92797","0.43582"
"4.37500","6.96765","0.43880"
"4.40000","7.00733","0.44222"
"4.42500","7.04712","0.44518"
"4.45000","7.08696","0.44815"
"4.47500","7.12697","0.45160"
"4.50000","7.16748","0.45443"
"4.52500","7.20758","0.45758"
"4.55000","7.24748","0.46074"
"4.57500","7.28736","0.46383"
"4.60000","7.32736","0.46740"
"4.62500","7.36747","0.47017"
"4.65000","7.40766","0.47334"
"4.67500","7.44772","0.47616"
"4.70000","7.48837","0.47930"
"4.72500","7.52870","0.48268"
"4.75000","7.56821","0.48538"
"4.77500","7.60760","0.48885"
"4.80000","7.64719","0.49167"
"4.82500","7.68691","0.49482"
"4.85000","7.72674","0.49791"
"4.87500","7.76663","0.50098"
"4.90000","7.80706","0.50409"
"4.92500","7.84718","0.50736"
"4.95000","7.88699","0.51058"
"4.97500","7.92686","0.51396"
"5.00000","7.96678","0.51700"
"5.02500","8.00677","0.52026"
"5.05000","8.04678","0.52309"
"5.07500","8.08682","0.52677"
"5.10000","8.12706","0.52969"
"5.12500","8.16722","0.53297"
"5.15000","8.20694","0.53641"
"5.17500","8.24657","0.53961"
"5.20000","8.28627","0.54261"
"5.22500","8.32623","0.54581"
"5.25000","8.36719","0.54894"
"5.27500","8.40720","0.55222"
"5.30000","8.44676","0.55537"
"5.32500","8.48650","0.55881"
"5.35000","8.52648","0.56182"
"5.37500","8.56657","0.56522"
"5.40000","8.60679","0.56829"
"5.42500","8.64698","0.57145"
"5.45000","8.68711","0.57460"
"5.47500","8.72722","0.57810"
"5.50000","8.76725","0.58117"
"5.52500","8.80720","0.58433"
"5.55000","8.84708","0.58777"
"5.57500","8.88718","0.59071"
"5.60000","8.92748","0.59416"
"5.62500","8.96742","0.59740"
"5.65000","9.00708","0.60062"
"5.67500","9.04685","0.60367"
"5.70000","9.08678","0.60719"
"5.72500","9.12681","0.61029"
"5.75000","9.16689","0.61355"
"5.77500","9.20701","0.61681"
"5.80000","9.24716","0.61988"
"5.82500","9.28734","0.62309"
"5.85000","9.32750","0.62645"
"5.87500","9.36759","0.62961"
"5.90000","9.40818","0.63251"
"5.92500","9.44830","0.63599"
"5.95000","9.48790","0.63903"
"5.97500","9.52752","0.64224"
"6.00000","9.56725","0.64532"
"6.02500","9.60715","0.64809"
"6.05000","9.64717","0.65131"
"6.07500","9.68722","0.65472"
"6.10000","9.72741","0.65761"
"6.12500","9.76744","0.66088"
"6.15000","9.80733","0.66410"
"6.17500","9.84734","0.66726"
"6.20000","9.88736","0.67029"
"6.22500","9.92744","0.67337"
"6.25000","9.96759","0.67639"
"6.27500","10.00768","0.67956"
"6.30000","10.04767","0.68251"
"6.32500","10.08756","0.68554"
"6.35000","10.12739","0.68867"
"6.37500","10.16719","0.69182"
"6.40000","10.20693","0.69486"
"6.42500","10.24689","0.69798"
"6.45000","10.28693","0.70099"
"6.47500","10.32721","0.70429"
"6.50000","10.36786","0.70709"
"6.52500","10.40801","0.71037"
"6.55000","10.44779","0.71329"
"6.57500","10.48762","0.71625"
"6.60000","10.52757","0.71935"
"6.62500","10.56759","0.72240"
"6.65000","10.60755","0.72556"
"6.67500","10.64784","0.72846"
"6.70000","10.68815","0.73161"
"6.72500","10.72797","0.73442"
"6.75000","10.76760","0.73754"
"6.77500","10.80729","0.74079"
"6.80000","10.84704","0.74339"
"6.82500","10.88690","0.74683"
"6.85000","10.92673","0.74973"
"6.87500","10.96669","0.75268"
"6.90000","11.00725","0.75591"
"6.92500","11.04779","0.75897"
"6.95000","11.08768","0.76211"
"6.97500","11.12743","0.76477"
"7.00000","11.16732","0.76817"
"7.02500","11.20736","0.77091"
"7.05000","11.24743","0.77398"
"7.07500","11.28780","0.77724"
"7.10000","11.32814","0.78007"
"7.12500","11.36788","0.78323"
"7.15000","11.40751","0.78613"
"7.17500","11.44728","0.78917"
"7.20000","11.48714","0.79189"
"7.22500","11.52708","0.79505"
"7.25000","11.56702","0.79824"
"7.27500","11.60697","0.80096"
"7.30000","11.64697","0.80433"
"7.32500","11.68701","0.80706"
"7.35000","11.72762","0.81017"
"7.37500","11.76775","0.81338"
"7.40000","11.80754","0.81599"
"7.42500","11.84743","0.81918"
"7.45000","11.88739","0.82172"
"7.47500","11.92738","0.82492"
"7.50000","11.96726","0.82765"
"7.52500","12.00709","0.83069"
"7.55000","12.04695","0.83383"
"7.57500","12.08684","0.83620"
"7.60000","12.12718","0.83985"
"7.62500","12.16733","0.84221"
"7.65000","12.20711","0.84548"
"7.67500","12.24683","0.84833"
"7.70000","12.28671","0.85098"
"7.72500","12.32674","0.85397"
"7.75000","12.36677","0.85656"
"7.77500","12.40683","0.85948"
"7.80000","12.44694","0.86229"
"7.82500","12.48712","0.86517"
"7.85000","12.52721","0.86814"
"7.87500","12.56711","0.87067"
"7.90000","12.60692","0.87374"
"7.92500","12.64668","0.87620"
"7.95000","12.68652","0.87873"
"7.97500","12.72691","0.88172"
"8.00000","12.76779","0.88412"
"8.02500","12.80851","0.88726"
"8.05000","12.84851","0.88922"
"8.07500","12.88810","0.89234"
"8.10000","12.92775","0.89443"
"8.12500","12.96756","0.89712"
"8.15000","13.00762","0.89985"
"8.17500","13.04766","0.90205"
"8.20000","13.08760","0.90499"
"8.22500","13.12749","0.90739"
"8.25000","13.16740","0.90987"
"8.27500","13.20731","0.91247"
"8.30000","13.24723","0.91523"
"8.32500","13.28723","0.91774"
"8.35000","13.32776","0.92013"
"8.37500","13.36774","0.92304"
"8.40000","13.40754","0.92544"
"8.42500","13.44744","0.92803"
"8.45000","13.48742","0.93081"
"8.47500","13.52748","0.93326"
"8.50000","13.56742","0.93612"
"8.52500","13.60734","0.93865"
"8.55000","13.64727","0.94104"
"8.57500","13.68741","0.94353"
"8.60000","13.72824","0.94580"
"8.62500","13.76819","0.94823"
"8.65000","13.80780","0.95023"
"8.67500","13.84758","0.95305"
"8.70000","13.88752","0.95551"
"8.72500","13.92757","0.95805"
"8.75000","13.96747","0.96051"
"8.77500","14.00743","0.96269"
"8.80000","14.04750","0.96509"
"8.82500","14.08762","0.96775"
"8.85000","14.12799","0.97020"
"8.87500","14.16853","0.97280"
"8.90000","14.20844","0.97525"
"8.92500","14.24820","0.97759"
"8.95000","14.28811","0.97999"
"8.97500","14.32813","0.98229"
"9.00000","14.36813","0.98493"
"9.02500","14.40814","0.98707"
"9.05000","14.44817","0.98981"
"9.07500","14.48812","0.99189"
"9.10000","14.52795","0.99447"
"9.12500","14.56798","0.99669"
"9.15000","14.60852","0.99898"
"9.17500","14.64872","1.00125"
"9.20000","14.68915","1.00351"
"9.22500","14.72909","1.00599"
"9.25000","14.76880","1.00820"
"9.27500","14.80864","1.01072"
"9.30000","14.84863","1.01284"
"9.32500","14.88872","1.01503"
"9.35000","14.92867","1.01746"
"9.37500","14.96865","1.01973"
"9.40000","15.00856","1.02207"
"9.42500","15.04844","1.02444"
"9.45000","15.08829","1.02683"
"9.47500","15.12815","1.02918"
"9.50000","15.16797","1.03153"
"9.52500","15.20793","1.03398"
"9.55000","15.24883","1.03601"
"9.57500","15.28912","1.03850"
"9.60000","15.32883","1.04062"
"9.62500","15.36868","1.04290"
"9.65000","15.40866","1.04541"
"9.67500","15.44871","1.04759"
"9.70000","15.48881","1.05000"
"9.72500","15.52878","1.05228"
"9.75000","15.56875","1.05460"
"9.77500","15.60870","1.05677"
"9.80000","15.64874","1.05919"
"9.82500","15.68871","1.06150"
"9.85000","15.72877","1.06366"
"9.87500","15.76884","1.06614"
"9.90000","15.80849","1.06831"
"9.92500","15.84827","1.07045"
"9.95000","15.88825","1.07288"
"9.97500","15.92838","1.07498"
"10.00000","15.96846","1.07721"
"10.02500","16.00864","1.07940"
"10.05000","16.04863","1.08180"
"10.07500","16.08853","1.08392"
"10.10000","16.12845","1.08615"
"10.12500","16.16842","1.08826"
"10.15000","16.20845","1.09051"
"10.17500","16.24851","1.09280"
"10.20000","16.28841","1.09495"
"10.22500","16.32817","1.09706"
"10.25000","16.36795","1.09904"
"10.27500","16.40782","1.10146"
"10.30000","16.44764","1.10335"
"10.32500","16.48751","1.10528"
"10.35000","16.52799","1.10753"
"10.37500","16.56851","1.10939"
"10.40000","16.60859","1.11175"
"10.42500","16.64831","1.11364"
"10.45000","16.68809","1.11551"
"10.47500","16.72794","1.11734"
"10.50000","16.76785","1.11945"
"10.52500","16.80781","1.12155"
"10.55000","16.84793","1.12355"
"10.57500","16.88807","1.12581"
"10.60000","16.92828","1.12756"
"10.62500","16.96832","1.12918"
"10.65000","17.00799","1.13117"
"10.67500","17.04765","1.13304"
"10.70000","17.08751","1.13460"
"10.72500","17.12739","1.13686"
"10.75000","17.16727","1.13869"
"10.77500","17.20717","1.14057"
"10.80000","17.24715","1.14241"
"10.82500","17.28740","1.14413"
"10.85000","17.32784","1.14571"
"10.87500","17.36778","1.14726"
"10.90000","17.40757","1.14860"
"10.92500","17.44736","1.15030"
"10.95000","17.48732","1.15199"
"10.97500","17.52728","1.15311"
"11.00000","17.56721","1.15452"
"11.02500","17.60720","1.15630"
"11.05000","17.64721","1.15742"
"11.07500","17.68705","1.15915"
"11.10000","17.72688","1.16062"
"11.12500","17.76676","1.16184"
"11.15000","17.80680","1.16290"
"11.17500","17.84707","1.16399"
"11.20000","17.88762","1.16577"
"11.22500","17.92761","1.16684"
"11.25000","17.96741","1.16880"
"11.27500","18.00723","1.17029"
"11.30000","18.04710","1.17162"
"11.32500","18.08695","1.17314"
"11.35000","18.12678","1.17483"
"11.37500","18.16661","1.17605"
"11.40000","18.20646","1.17739"
"11.42500","18.24647","1.17904"
"11.45000","18.28684","1.18029"
"11.47500","18.32698","1.18164"
"11.50000","18.36760","1.18302"
"11.52500","18.40802","1.18395"
"11.55000","18.44773","1.18516"
"11.57500","18.48741","1.18637"
"11.60000","18.52728","1.18689"
"11.62500","18.56726","1.18807"
"11.65000","18.60722","1.18881"
"11.67500","18.64722","1.18979"
"11.70000","18.68716","1.19097"
"11.72500","18.72710","1.19225"
"11.75000","18.76714","1.19345"
"11.77500","18.80716","1.19435"
"11.80000","18.84772","1.19585"
"11.82500","18.88793","1.19708"
"11.85000","18.92772","1.19849"
"11.87500","18.96755","1.19972"
"11.90000","19.00747","1.20075"
"11.92500","19.04741","1.20184"
"11.95000","19.08734","1.20307"
"11.97500","19.12727","1.20363"
"12.00000","19.16728","1.20450"
"12.02500","19.20731","1.20543"
"12.05000","19.24729","1.20662"
"12.07500","19.28723","1.20754"
"12.10000","19.32721","1.20875"
"12.12500","19.36727","1.20963"
"12.15000","19.40725","1.21070"
"12.17500","19.44784","1.21217"
"12.20000","19.48799","1.21310"
"12.22500","19.52772","1.21441"
"12.25000","19.56749","1.21530"
"12.27500","19.60737","1.21645"
"12.30000","19.64734","1.21746"
"12.32500","19.68723","1.21849"
"12.35000","19.72726","1.21963"
"12.37500","19.76735","1.22045"
"12.40000","19.80729","1.22166"
"12.42500","19.84721","1.22279"
"12.45000","19.88718","1.22361"
"12.47500","19.92721","1.22520"
"12.50000","19.96724","1.22598"
"12.52500","20.00718","1.22745"
"12.55000","20.04715","1.22851"
"12.57500","20.08718","1.22962"
"12.60000","20.12726","1.23054"
"12.62500","20.16731","1.23172"
"12.65000","20.20721","1.23291"
"12.67500","20.24702","1.23344"
"12.70000","20.28741","1.23444"
"12.72500","20.32789","1.23526"
"12.75000","20.36776","1.23622"
"12.77500","20.40747","1.23734"
"12.80000","20.44733","1.23815"
"12.82500","20.48727","1.23912"
"12.85000","20.52720","1.24010"
"12.87500","20.56717","1.24108"
"12.90000","20.60719","1.24194"
"12.92500","20.64722","1.24294"
"12.95000","20.68725","1.24402"
"12.97500","20.72736","1.24485"
"13.00000","20.76746","1.24580"
"13.02500","20.80748","1.24689"
"13.05000","20.84752","1.24777"
"13.07500","20.88767","1.24899"
"13.10000","20.92835","1.24990"
"13.12500","20.96856","1.25095"
"13.15000","21.00815","1.25171"
"13.17500","21.04778","1.25284"
"13.20000","21.08765","1.25380"
"13.22500","21.12768","1.25466"
"13.25000","21.16780","1.25590"
"13.27500","21.20782","1.25668"
"13.30000","21.24787","1.25804"
"13.32500","21.28790","1.25896"
"13.35000","21.32793","1.25979"
"13.37500","21.36795","1.26093"
"13.40000","21.40797","1.26199"
"13.42500","21.44791","1.26288"
"13.45000","21.48777","1.26372"
"13.47500","21.52756","1.26497"
"13.50000","21.56736","1.26588"
"13.52500","21.60713","1.26685"
"13.55000","21.64719","1.26771"
"13.57500","21.68736","1.26877"
"13.60000","21.72759","1.26985"
"13.62500","21.76804","1.27098"
"13.65000","21.80796","1.27174"
"13.67500","21.84767","1.27278"
"13.70000","21.88749","1.27397"
"13.72500","21.92748","1.27484"
"13.75000","21.96757","1.27603"
"13.77500","22.00766","1.27707"
"13.80000","22.04777","1.27784"
"13.82500","22.08784","1.27871"
"13.85000","22.12776","1.27987"
"13.87500","22.16795","1.28076"
"13.90000","22.20767","1.28170"
"13.92500","22.24726","1.28278"
"13.95000","22.28692","1.28375"
"13.97500","22.32681","1.28475"
"14.00000","22.36680","1.28584"
"14.02500","22.40685","1.28648"
"14.05000","22.44699","1.28764"
"14.07500","22.48719","1.28767"
"14.10000","22.52747","1.28685"
"14.12500","22.56769","1.28667"
"14.15000","22.60783","1.28757"
"14.17500","22.64820","1.28818"
"14.20000","22.68806","1.28897"
"14.22500","22.72769","1.28964"
"14.25000","22.76750","1.29025"
"14.27500","22.80730","1.29105"
"14.30000","22.84706","1.29177"
"14.32500","22.88685","1.29254"
"14.35000","22.92669","1.29272"
"14.37500","22.96662","1.29355"
"14.40000","23.00661","1.29415"
"14.42500","23.04685","1.29469"
"14.45000","23.08717","1.29560"
"14.47500","23.12753","1.29620"
"14.50000","23.16768","1.29658"
"14.52500","23.20778","1.29738"
"14.55000","23.24785","1.29805"
"14.57500","23.28790","1.29857"
"14.60000","23.32789","1.29930"
"14.62500","23.36778","1.30000"
"14.65000","23.40755","1.30074"
"14.67500","23.44730","1.30147"
"14.70000","23.48719","1.30219"
"14.72500","23.52739","1.30259"
"14.75000","23.56834","1.30353"
"14.77500","23.60893","1.30432"
"14.80000","23.64884","1.30475"
"14.82500","23.68853","1.30552"
"14.85000","23.72848","1.30640"
"14.87500","23.76858","1.30695"
"14.90000","23.80877","1.30777"
"14.92500","23.84894","1.30841"
"14.95000","23.88902","1.30909"
"14.97500","23.92896","1.30979"
"15.00000","23.96881","1.31068"
"15.02500","24.00873","1.31121"
"15.05000","24.04867","1.31225"
"15.07500","24.08847","1.31287"
"15.10000","24.12820","1.31366"
"15.12500","24.16800","1.31441"
"15.15000","24.20788","1.31516"
"15.17500","24.24790","1.31598"
"15.20000","24.28827","1.31674"
"15.22500","24.32941","1.31735"
"15.25000","24.36962","1.31829"
"15.27500","24.40941","1.31906"
"15.30000","24.44927","1.32001"
"15.32500","24.48920","1.32043"
"15.35000","24.52917","1.32154"
"15.37500","24.56912","1.32211"
"15.40000","24.60911","1.32296"
"15.42500","24.64899","1.32375"
"15.45000","24.68877","1.32480"
"15.47500","24.72860","1.32574"
"15.50000","24.76854","1.32646"
"15.52500","24.80849","1.32728"
"15.55000","24.84846","1.32786"
"15.57500","24.88857","1.32873"
"15.60000","24.92843","1.32977"
"15.62500","24.96835","1.33036"
"15.65000","25.00831","1.33128"
"15.67500","25.04827","1.33211"
"15.70000","25.08824","1.33287"
"15.72500","25.12831","1.33386"
"15.75000","25.16840","1.33437"
"15.77500","25.20846","1.33525"
"15.80000","25.24869","1.33602"
"15.82500","25.28889","1.33726"
"15.85000","25.32889","1.33800"
"15.87500","25.36876","1.33848"
"15.90000","25.40859","1.33938"
"15.92500","25.44841","1.34010"
"15.95000","25.48833","1.34103"
"15.97500","25.52826","1.34187"
"16.00000","25.56823","1.34267"
"16.02500","25.60826","1.34351"
"16.05000","25.64830","1.34448"
"16.07500","25.68830","1.34509"
"16.10000","25.72833","1.34588"
"16.12500","25.76837","1.34677"
"16.15000","25.80849","1.34754"
"16.17500","25.84873","1.34826"
"16.20000","25.88891","1.34947"
"16.22500","25.92889","1.35006"
"16.25000","25.96882","1.35075"
"16.27500","26.00900","1.35153"
"16.30000","26.04918","1.35219"
"16.32500","26.09000","1.35306"
"16.35000","26.13037","1.35386"
"16.37500","26.17001","1.35472"
"16.40000","26.20966","1.35517"
"16.42500","26.24957","1.35594"
"16.45000","26.28961","1.35580"
"16.47500","26.32960","1.35524"
"16.50000","26.36953","1.35580"
"16.52500","26.40956","1.35628"
"16.55000","26.44973","1.35669"
"16.57500","26.48977","1.35732"
"16.60000","26.52963","1.35785"
"16.62500","26.56947","1.35804"
"16.65000","26.60933","1.35853"
"16.67500","26.64939","1.35926"
"16.70000","26.68958","1.35977"
"16.72500","26.72960","1.36033"
"16.75000","26.76947","1.36110"
"16.77500","26.80927","1.36130"
"16.80000","26.84914","1.36215"
"16.82500","26.88922","1.36234"
"16.85000","26.92976","1.36273"
"16.87500","26.96978","1.36343"
"16.90000","27.00965","1.36403"
"16.92500","27.04968","1.36478"
"16.95000","27.08970","1.36527"
"16.97500","27.12970","1.36595"
"17.00000","27.16963","1.36585"
"17.02500","27.20941","1.36609"
"17.05000","27.24930","1.36600"
"17.07500","27.28927","1.36499"
"17.10000","27.32922","1.36493"
"17.12500","27.36919","1.36529"
"17.15000","27.40936","1.36537"
"17.17500","27.44948","1.36561"
"17.20000","27.48948","1.36586"
"17.22500","27.52944","1.36569"
"17.25000","27.56937","1.36292"
"17.27500","27.60932","1.36179"
"17.30000","27.64937","1.36142"
"17.32500","27.68952","1.36167"
"17.35000","27.72971","1.36242"
"17.37500","27.76985","1.36243"
"17.40000","27.80988","1.36292"
"17.42500","27.84968","1.36329"
"17.45000","27.88946","1.36394"
"17.47500","27.92928","1.36442"
"17.50000","27.96925","1.36482"
"17.52500","28.00950","1.36549"
"17.55000","28.04979","1.36559"
"17.57500","28.08982","1.36651"
"17.60000","28.13040","1.36686"
"17.62500","28.17094","1.36752"
"17.65000","28.21061","1.36825"
"17.67500","28.25024","1.36872"
"17.70000","28.29016","1.36930"
"17.72500","28.33018","1.36954"
"17.75000","28.37015","1.37037"
"17.77500","28.41003","1.37067"
"17.80000","28.44984","1.37136"
"17.82500","28.48969","1.37208"
"17.85000","28.52970","1.37222"
"17.87500","28.56977","1.37308"
"17.90000","28.61000","1.37362"
"17.92500","28.65001","1.37416"
"17.95000","28.68979","1.37469"
"17.97500","28.72974","1.37507"
"18.00000","28.76972","1.37567"
"18.02500","28.80971","1.37646"
"18.05000","28.84973","1.37681"
"18.07500","28.88973","1.37702"
"18.10000","28.92976","1.37711"
"18.12500","28.96991","1.37782"
"18.15000","29.01021","1.37789"
"18.17500","29.05025","1.37877"
"18.20000","29.09008","1.37940"
"18.22500","29.13013","1.37954"
"18.25000","29.17055","1.38050"
"18.27500","29.21038","1.38079"
"18.30000","29.24999","1.38158"
"18.32500","29.28977","1.38191"
"18.35000","29.32971","1.38269"
"18.37500","29.36966","1.38329"
"18.40000","29.40961","1.38367"
"18.42500","29.44963","1.38465"
"18.45000","29.48963","1.38485"
"18.47500","29.52967","1.38556"
"18.50000","29.56978","1.38624"
"18.52500","29.60967","1.38662"
"18.55000","29.64935","1.38733"
"18.57500","29.68911","1.38791"
"18.60000","29.72898","1.38846"
"18.62500","29.76888","1.38859"
"18.65000","29.80887","1.38935"
"18.67500","29.84899","1.38965"
"18.70000","29.88962","1.38969"
"18.72500","29.93000","1.39009"
"18.75000","29.96991","1.38955"
"18.77500","30.00964","1.38961"
"18.80000","30.04947","1.38914"
"18.82500","30.08941","1.38933"
"18.85000","30.12940","1.38946"
"18.87500","30.16929","1.38935"
"18.90000","30.20919","1.38944"
"18.92500","30.24906","1.38962"
"18.95000","30.28886","1.38993"
"18.97500","30.32881","1.38997"
"19.00000","30.36886","1.39022"
"19.02500","30.40888","1.39042"
"19.05000","30.44893","1.39079"
"19.07500","30.48884","1.39092"
"19.10000","30.52874","1.39116"
"19.12500","30.56866","1.39163"
"19.15000","30.60859","1.39152"
"19.17500","30.64861","1.39206"
"19.20000","30.68868","1.39238"
"19.22500","30.72878","1.39254"
"19.25000","30.76881","1.39295"
"19.27500","30.80881","1.39336"
"19.30000","30.84883","1.39339"
"19.32500","30.88924","1.39371"
"19.35000","30.92923","1.39419"
"19.37500","30.96930","1.39430"
"19.40000","31.00986","1.39496"
"19.42500","31.04993","1.39530"
"19.45000","31.08973","1.39568"
"19.47500","31.12934","1.39580"
"19.50000","31.16910","1.39629"
"19.52500","31.20896","1.39636"
"19.55000","31.24886","1.39695"
"19.57500","31.28891","1.39719"
"19.60000","31.32899","1.39752"
"19.62500","31.36903","1.39770"
"19.65000","31.40914","1.39834"
"19.67500","31.44923","1.39816"
"19.70000","31.48919","1.39864"
"19.72500","31.52901","1.39884"
"19.75000","31.56882","1.39910"
"19.77500","31.60873","1.39950"
"19.80000","31.64866","1.39974"
"19.82500","31.68860","1.40030"
"19.85000","31.72848","1.40050"
"19.87500","31.76842","1.40098"
"19.90000","31.80833","1.40085"
"19.92500","31.84822","1.40126"
"19.95000","31.88815","1.40160"
"19.97500","31.92823","1.40155"
"20.00000","31.96828","1.40219"
"20.02500","32.00825","1.40234"
"20.05000","32.04829","1.40258"
"20.07500","32.08840","1.40280"
"20.10000","32.12856","1.40308"
"20.12500","32.16843","1.40328"
"20.15000","32.20862","1.40312"
"20.17500","32.24911","1.40381"
"20.20000","32.28917","1.40365"
"20.22500","32.32870","1.40393"
"20.25000","32.36839","1.40409"
"20.27500","32.40822","1.40407"
"20.30000","32.44815","1.40440"
"20.32500","32.48817","1.40450"
"20.35000","32.52826","1.40458"
"20.37500","32.56839","1.40454"
"20.40000","32.60851","1.40497"
"20.42500","32.64869","1.40478"
"20.45000","32.68873","1.40499"
"20.47500","32.72866","1.40526"
"20.50000","32.76856","1.40531"
"20.52500","32.80843","1.40510"
"20.55000","32.84828","1.40529"
"20.57500","32.88813","1.40537"
"20.60000","32.92793","1.40525"
"20.62500","32.96775","1.40535"
"20.65000","33.00771","1.40514"
"20.67500","33.04778","1.40522"
"20.70000","33.08779","1.40551"
"20.72500","33.12767","1.40512"
"20.75000","33.16759","1.40515"
"20.77500","33.20758","1.40464"
"20.80000","33.24778","1.40484"
"20.82500","33.28815","1.40470"
"20.85000","33.32835","1.40491"
"20.87500","33.36829","1.40441"
"20.90000","33.40818","1.40396"
"20.92500","33.44810","1.40407"
"20.95000","33.48791","1.40364"
"20.97500","33.52767","1.40332"
"21.00000","33.56736","1.40316"
"21.02500","33.60709","1.40292"
"21.05000","33.64685","1.40243"
"21.07500","33.68672","1.40234"
"21.10000","33.72670","1.40193"
"21.12500","33.76675","1.40132"
"21.15000","33.80684","1.40072"
"21.17500","33.84703","1.40043"
"21.20000","33.88736","1.39983"
"21.22500","33.92810","1.39954"
"21.25000","33.96875","1.39892"
"21.27500","34.00935","1.39819"
"21.30000","34.04976","1.39778"
"21.32500","34.08936","1.39690"
"21.35000","34.12893","1.39631"
"21.37500","34.16865","1.39544"
"21.40000","34.20840","1.39494"
"21.42500","34.24821","1.39411"
"21.45000","34.28804","1.39323"
"21.47500","34.32793","1.39250"
"21.50000","34.36781","1.39123"
"21.52500","34.40783","1.39064"
"21.55000","34.44801","1.38952"
"21.57500","34.48824","1.38803"
"21.60000","34.52834","1.38720"
"21.62500","34.56839","1.38606"
"21.65000","34.60851","1.38475"
"21.67500","34.64857","1.38347"
"21.70000","34.68854","1.38227"
"21.72500","34.72849","1.38059"
"21.75000","34.76841","1.37890"
"21.77500","34.80836","1.37767"
"21.80000","34.84813","1.37570"
"21.82500","34.88799","1.37402"
"21.85000","34.92798","1.37190"
"21.87500","34.96771","1.36961"
"21.90000","35.00746","1.36746"
"21.92500","35.04736","1.36467"
"21.95000","35.08734","1.36168"
"21.97500","35.12747","1.35675"
"22.00000","35.16768","1.32215"
"22.02500","35.20788","1.25977"
"22.05000","35.24800","1.22593"
"22.07500","35.28814","1.21335"
"22.10000","35.32830","1.20544"
"22.12500","35.36843","1.19756"
"22.15000","35.40841","1.19002"
"22.17500","35.44836","1.18238"
"22.20000","35.48849","1.17518"
"22.22500","35.52824","1.16830"
"22.25000","35.56770","1.16135"
"22.27500","35.60731","1.15457"
"22.30000","35.64710","1.14800"
"22.32500","35.68709","1.14137"
"22.35000","35.72722","1.13449"
"22.37500","35.76741","1.12833"
"22.40000","35.80766","1.12141"
"22.42500","35.84797","1.11487"
"22.45000","35.88828","1.10818"
"22.47500","35.92862","1.10084"
"22.50000","35.96880","1.09366"
"22.52500","36.00872","1.08624"
"22.55000","36.04860","1.07880"
"22.57500","36.08835","1.07092"
"22.60000","36.12803","1.06276"
"22.62500","36.16781","1.05398"
"22.65000","36.20766","1.04467"
"22.67500","36.24749","0.97496"
"22.70000","36.28735","0.84524"
"22.72500","36.32732","0.78860"
"22.75000","36.36738","0.76737"
"22.77500","36.40771","0.74541"
"22.80000","36.44822","0.71599"
"22.82500","36.48866","0.52458"
"22.85000","36.52918","0.10068"
"22.87500","36.56923","-0.03575"
"22.90000","36.60891","-0.02971"
"22.92500","36.64864","-0.01286"
"22.95000","36.68839","-0.00914"
"22.97500","36.72809","-0.00950"
"23.00000","36.76784","-0.01030"
"23.02500","36.80771","-0.01050"
"23.05000","36.84760","-0.01029"
"23.07500","36.88742","-0.01062"
"23.10000","36.92732","-0.01052"
"23.12500","36.96751","-0.01058"
"23.15000","37.00766","-0.01054"
"23.17500","37.04772","-0.01042"
"23.20000","37.08799","-0.01067"
"23.22500","37.12839","-0.01056"
"23.25000","37.16871","-0.01088"
"23.27500","37.20874","-0.01056"
"23.30000","37.24866","-0.01058"
"23.32500","37.28849","-0.01069"
"23.35000","37.32821","-0.01076"
"23.37500","37.36797","-0.01091"
"23.40000","37.40790","-0.01060"
"23.42500","37.44781","-0.01076"
"23.45000","37.48765","-0.01072"
"23.47500","37.52748","-0.01093"
"23.50000","37.56744","-0.01088"
"23.52500","37.60756","-0.01057"
"23.55000","37.64780","-0.01103"
"23.57500","37.68813","-0.01072"
"23.60000","37.72845","-0.01090"
"23.62500","37.76875","-0.01100"
"23.65000","37.80890","-0.01090"
"23.67500","37.84951","-0.01085"
"23.70000","37.89000","-0.01084"
"23.72500","37.92987","-0.01108"
"23.75000","37.96935","-0.01069"
"23.77500","38.00907","-0.01065"
"23.80000","38.04883","-0.01103"
"23.82500","38.08864","-0.01084"
"23.85000","38.12845","-0.01113"
"23.87500","38.16825","-0.01120"
"23.90000","38.20828","-0.01096"
"23.92500","38.24841","-0.01106"
"23.95000","38.28878","-0.01093"
"23.97500","38.32893","-0.01085"
"24.00000","38.36895","-0.01070"
"24.02500","38.40890","-0.01086"
"24.05000","38.44882","-0.01108"
"24.07500","38.48878","-0.01116"
"24.10000","38.52867","-0.01140"
"24.12500","38.56844","-0.01084"
"24.15000","38.60809","-0.01090"
"24.17500","38.64780","-0.01099"
"24.20000","38.68756","-0.01101"
"24.22500","38.72744","-0.01121"
"24.25000","38.76752","-0.01099"
"24.27500","38.80787","-0.01122"
"24.30000","38.84790","-0.01094"
"24.32500","38.88784","-0.01125"
"24.35000","38.92866","-0.01122"
"24.37500","38.96906","-0.01090"
"24.40000","39.00886","-0.01121"
"24.42500","39.04888","-0.01111"
"24.45000","39.08897","-0.01120"
"24.47500","39.12903","-0.01120"
"24.50000","39.16898","-0.01111"
"24.52500","39.20873","-0.01095"
"24.55000","39.24850","-0.01113"
"24.57500","39.28828","-0.01111"
"24.60000","39.32825","-0.01104"
"24.62500","39.36839","-0.01104"
"24.65000","39.40920","-0.01123"
"24.67500","39.44929","-0.01106"
"24.70000","39.48875","-0.01144"
"24.72500","39.52842","-0.01104"
"24.75000","39.56830","-0.01106"
"24.77500","39.60828","-0.01132"
"24.80000","39.64849","-0.01137"
"24.82500","39.68901","-0.01161"
"24.85000","39.72910","-0.01110"
"24.87500","39.76881","-0.01060"
"24.90000","39.80834","-0.01119"
"24.92500","39.84797","-0.01084"
"24.95000","39.88776","-0.01172"
"24.97500","39.92766","-0.01106"
"25.00000","39.96756","-0.01117"
"25.02500","40.00742","-0.01110"
"25.05000","40.04714","-0.01103"
"25.07500","40.08688","-0.01154"
"25.10000","40.12684","-0.01117"
"25.12500","40.16714","-0.01108"
"25.15000","40.20726","-0.01101"
"25.17500","40.24727","-0.01144"
"25.20000","40.28735","-0.01142"
"25.22500","40.32754","-0.01120"
"25.25000","40.36764","-0.01126"
"25.27500","40.40760","-0.01107"
"25.30000","40.44754","-0.01136"
"25.32500","40.48755","-0.01138"
"25.35000","40.52781","-0.01117"
"25.37500","40.56813","-0.01126"
"25.40000","40.60765","-0.01118"
"25.42500","40.64703","-0.01125"
"25.45000","40.68678","-0.01128"
"25.47500","40.72670","-0.01122"
"25.50000","40.76664","-0.01131"
"25.52500","40.80668","-0.01119"
"25.55000","40.84684","-0.01144"
"25.57500","40.88715","-0.01125"
"25.60000","40.92739","-0.01098"
"25.62500","40.96761","-0.01137"
"25.65000","41.00791","-0.01127"
"25.67500","41.04789","-0.01151"
"25.70000","41.08779","-0.01125"
"25.72500","41.12765","-0.01107"
"25.75000","41.16747","-0.01142"
"25.77500","41.20729","-0.01116"
"25.80000","41.24705","-0.01148"
"25.82500","41.28699","-0.01101"
"25.85000","41.32709","-0.01150"
"25.87500","41.36719","-0.01113"
"25.90000","41.40726","-0.01130"
"25.92500","41.44746","-0.01159"
"25.95000","41.48761","-0.01123"
"25.97500","41.52777","-0.01119"
"26.00000","41.56807","-0.01134"
"26.02500","41.60849","-0.01145"
"26.05000","41.64841","-0.01124"
"26.07500","41.68814","-0.01137"
"26.10000","41.72799","-0.01124"
"26.12500","41.76787","-0.01120"
"26.15000","41.80774","-0.01141"
"26.17500","41.84761","-0.01132"
"26.20000","41.88743","-0.01121"
"26.22500","41.92730","-0.01145"
"26.25000","41.96760","-0.01126"
"26.27500","42.00770","-0.01141"
"26.30000","42.04785","-0.01138"
"26.32500","42.08790","-0.01129"
"26.35000","42.12833","-0.01126"
"26.37500","42.16918","-0.01134"
"26.40000","42.20967","-0.01143"
"26.42500","42.24951","-0.01113"
"26.45000","42.28926","-0.01146"
"26.47500","42.32900","-0.01130"
"26.50000","42.36888","-0.01137"
"26.52500","42.40896","-0.01134"
"26.55000","42.44875","-0.01130"
"26.57500","42.48844","-0.01126"
"26.60000","42.52822","-0.01149"
"26.61500","42.55215","-0.01151"