File: 20G1650/ST 20G1650_00018.csv
Rate 1,"0.12000",mm/s
Start date,"9/28/2021"
Specimen label,""

Time,Extension,2 kg Beam Load Cell
(s),(mm),(N)
"0.00000","0.00127","-0.00225"
"0.20000","0.00621","-0.00190"
"0.40000","0.03255","-0.00174"
"0.60000","0.05928","-0.00130"
"0.80000","0.08570","-0.00094"
"1.00000","0.11168","-0.00026"
"1.20000","0.13731","0.00016"
"1.40000","0.16242","0.00034"
"1.60000","0.18732","0.00034"
"1.80000","0.21212","0.00128"
"2.00000","0.23652","0.00145"
"2.20000","0.26098","0.00189"
"2.40000","0.28543","0.00215"
"2.60000","0.31015","0.00259"
"2.80000","0.33390","0.00278"
"3.00000","0.35754","0.00323"
"3.20000","0.38164","0.00381"
"3.40000","0.40581","0.00398"
"3.60000","0.42989","0.00435"
"3.80000","0.45389","0.00487"
"4.00000","0.47792","0.00503"
"4.20000","0.50201","0.00526"
"4.40000","0.52599","0.00575"
"4.60000","0.55005","0.00639"
"4.80000","0.57407","0.00638"
"5.00000","0.59797","0.00724"
"5.20000","0.62207","0.00748"
"5.40000","0.64607","0.00772"
"5.60000","0.67011","0.00803"
"5.80000","0.69420","0.00861"
"6.00000","0.71818","0.00878"
"6.20000","0.74212","0.00931"
"6.40000","0.76614","0.00976"
"6.60000","0.79022","0.01003"
"6.80000","0.81424","0.01033"
"7.00000","0.83817","0.01059"
"7.20000","0.86214","0.01097"
"7.40000","0.88609","0.01138"
"7.60000","0.91007","0.01179"
"7.80000","0.93418","0.01222"
"8.00000","0.95821","0.01238"
"8.20000","0.98219","0.01287"
"8.40000","1.00609","0.01348"
"8.60000","1.03017","0.01354"
"8.80000","1.05422","0.01398"
"9.00000","1.07822","0.01452"
"9.20000","1.10216","0.01449"
"9.40000","1.12608","0.01530"
"9.60000","1.15007","0.01559"
"9.80000","1.17408","0.01558"
"10.00000","1.19813","0.01629"
"10.20000","1.22218","0.01665"
"10.40000","1.24610","0.01670"
"10.60000","1.27004","0.01743"
"10.80000","1.29418","0.01768"
"11.00000","1.31853","0.01785"
"11.20000","1.34211","0.01826"
"11.40000","1.36610","0.01890"
"11.60000","1.39010","0.01881"
"11.80000","1.41415","0.01930"
"12.00000","1.43822","0.01987"
"12.20000","1.46231","0.01983"
"12.40000","1.48631","0.02028"
"12.60000","1.51027","0.02105"
"12.80000","1.53422","0.02087"
"13.00000","1.55828","0.02168"
"13.20000","1.58228","0.02184"
"13.40000","1.60629","0.02223"
"13.60000","1.63025","0.02270"
"13.80000","1.65421","0.02287"
"14.00000","1.67814","0.02334"
"14.20000","1.70218","0.02405"
"14.40000","1.72630","0.02390"
"14.60000","1.75026","0.02475"
"14.80000","1.77418","0.02486"
"15.00000","1.79808","0.02519"
"15.20000","1.82215","0.02550"
"15.40000","1.84623","0.02605"
"15.60000","1.87028","0.02607"
"15.80000","1.89425","0.02650"
"16.00000","1.91819","0.02693"
"16.20000","1.94217","0.02736"
"16.40000","1.96616","0.02773"
"16.60000","1.99029","0.02803"
"16.80000","2.01589","0.02851"
"17.00000","2.03825","0.02903"
"17.20000","2.06211","0.02932"
"17.40000","2.08619","0.02989"
"17.60000","2.11017","0.03000"
"17.80000","2.13431","0.03048"
"18.00000","2.15832","0.03125"
"18.20000","2.18229","0.03109"
"18.40000","2.20627","0.03161"
"18.60000","2.23025","0.03243"
"18.80000","2.25430","0.03236"
"19.00000","2.27831","0.03286"
"19.20000","2.30226","0.03361"
"19.40000","2.32617","0.03349"
"19.60000","2.35019","0.03431"
"19.80000","2.37421","0.03458"
"20.00000","2.39821","0.03486"
"20.20000","2.42227","0.03546"
"20.40000","2.44625","0.03580"
"20.60000","2.47016","0.03603"
"20.80000","2.49419","0.03671"
"21.00000","2.51826","0.03711"
"21.20000","2.54231","0.03758"
"21.40000","2.56668","0.03785"
"21.60000","2.59027","0.03847"
"21.80000","2.61412","0.03857"
"22.00000","2.63815","0.03916"
"22.20000","2.66231","0.03975"
"22.40000","2.68626","0.03997"
"22.60000","2.71019","0.04043"
"22.80000","2.73422","0.04102"
"23.00000","2.75823","0.04120"
"23.20000","2.78232","0.04165"
"23.40000","2.80636","0.04231"
"23.60000","2.83033","0.04239"
"23.80000","2.85427","0.04290"
"24.00000","2.87828","0.04356"
"24.20000","2.90222","0.04366"
"24.40000","2.92628","0.04424"
"24.60000","2.95036","0.04480"
"24.80000","2.97591","0.04517"
"25.00000","2.99809","0.04536"
"25.20000","3.02205","0.04605"
"25.40000","3.04611","0.04640"
"25.60000","3.07012","0.04684"
"25.80000","3.09413","0.04739"
"26.00000","3.11811","0.04764"
"26.20000","3.14217","0.04789"
"26.40000","3.16614","0.04856"
"26.60000","3.19022","0.04895"
"26.80000","3.21427","0.04915"
"27.00000","3.23825","0.04993"
"27.20000","3.26215","0.04992"
"27.40000","3.28623","0.05048"
"27.60000","3.31029","0.05114"
"27.80000","3.33439","0.05126"
"28.00000","3.35830","0.05189"
"28.20000","3.38216","0.05246"
"28.40000","3.40624","0.05271"
"28.60000","3.43026","0.05331"
"28.80000","3.45428","0.05348"
"29.00000","3.47831","0.05420"
"29.20000","3.50223","0.05446"
"29.40000","3.52613","0.05503"
"29.60000","3.55021","0.05540"
"29.80000","3.57420","0.05556"
"30.00000","3.59824","0.05629"
"30.20000","3.62217","0.05657"
"30.40000","3.64609","0.05677"
"30.60000","3.67013","0.05759"
"30.80000","3.69412","0.05781"
"31.00000","3.71821","0.05817"
"31.20000","3.74363","0.05861"
"31.40000","3.76615","0.05903"
"31.60000","3.78996","0.05947"
"31.80000","3.81408","0.05987"
"32.00000","3.83817","0.06034"
"32.20000","3.86218","0.06064"
"32.40000","3.88625","0.06129"
"32.60000","3.91016","0.06167"
"32.80000","3.93419","0.06200"
"33.00000","3.95812","0.06247"
"33.20000","3.98226","0.06304"
"33.40000","4.00625","0.06357"
"33.60000","4.03021","0.06402"
"33.80000","4.05423","0.06458"
"34.00000","4.07830","0.06510"
"34.20000","4.10237","0.06523"
"34.40000","4.12643","0.06583"
"34.60000","4.15032","0.06622"
"34.80000","4.17423","0.06652"
"35.00000","4.19822","0.06731"
"35.20000","4.22293","0.06761"
"35.40000","4.24615","0.06806"
"35.60000","4.27018","0.06852"
"35.80000","4.29407","0.06893"
"36.00000","4.31803","0.06955"
"36.20000","4.34210","0.07009"
"36.40000","4.36615","0.07058"
"36.60000","4.39020","0.07113"
"36.80000","4.41420","0.07134"
"37.00000","4.43820","0.07212"
"37.20000","4.46222","0.07251"
"37.40000","4.48612","0.07279"
"37.60000","4.51023","0.07372"
"37.80000","4.53432","0.07376"
"38.00000","4.55819","0.07429"
"38.20000","4.58217","0.07521"
"38.40000","4.60621","0.07531"
"38.60000","4.63024","0.07583"
"38.80000","4.65435","0.07643"
"39.00000","4.67941","0.07708"
"39.20000","4.70213","0.07718"
"39.40000","4.72608","0.07793"
"39.60000","4.75009","0.07823"
"39.80000","4.77420","0.07870"
"40.00000","4.79816","0.07938"
"40.20000","4.82214","0.07993"
"40.40000","4.84610","0.08030"
"40.60000","4.87009","0.08096"
"40.80000","4.89416","0.08124"
"41.00000","4.91815","0.08191"
"41.20000","4.94217","0.08258"
"41.40000","4.96609","0.08275"
"41.60000","4.98996","0.08336"
"41.80000","5.01402","0.08398"
"42.00000","5.03811","0.08452"
"42.20000","5.06222","0.08491"
"42.40000","5.08616","0.08559"
"42.60000","5.11020","0.08615"
"42.80000","5.13415","0.08647"
"43.00000","5.15811","0.08727"
"43.20000","5.18221","0.08767"
"43.40000","5.20627","0.08813"
"43.60000","5.23020","0.08879"
"43.80000","5.25417","0.08921"
"44.00000","5.27817","0.08984"
"44.20000","5.30224","0.09029"
"44.40000","5.32626","0.09095"
"44.60000","5.35019","0.09152"
"44.80000","5.37414","0.09182"
"45.00000","5.39827","0.09285"
"45.20000","5.42328","0.09308"
"45.40000","5.44623","0.09340"
"45.60000","5.47017","0.09435"
"45.80000","5.49410","0.09466"
"46.00000","5.51802","0.09505"
"46.20000","5.54203","0.09593"
"46.40000","5.56614","0.09627"
"46.60000","5.59013","0.09673"
"46.80000","5.61411","0.09751"
"47.00000","5.63805","0.09786"
"47.20000","5.66209","0.09836"
"47.40000","5.68613","0.09915"
"47.60000","5.71021","0.09967"
"47.80000","5.73424","0.10004"
"48.00000","5.75814","0.10094"
"48.20000","5.78206","0.10137"
"48.40000","5.80612","0.10193"
"48.60000","5.83017","0.10257"
"48.80000","5.85422","0.10303"
"49.00000","5.87817","0.10379"
"49.20000","5.90212","0.10409"
"49.40000","5.92621","0.10491"
"49.60000","5.95020","0.10539"
"49.80000","5.97429","0.10577"
"50.00000","5.99838","0.10674"
"50.20000","6.02225","0.10708"
"50.40000","6.04614","0.10783"
"50.60000","6.07019","0.10838"
"50.80000","6.09422","0.10863"
"51.00000","6.11823","0.10947"
"51.20000","6.14222","0.11007"
"51.40000","6.16627","0.11047"
"51.60000","6.19025","0.11106"
"51.80000","6.21505","0.11179"
"52.00000","6.23809","0.11227"
"52.20000","6.26211","0.11282"
"52.40000","6.28604","0.11364"
"52.60000","6.31000","0.11404"
"52.80000","6.33413","0.11442"
"53.00000","6.35822","0.11554"
"53.20000","6.38225","0.11578"
"53.40000","6.40624","0.11660"
"53.60000","6.43020","0.11715"
"53.80000","6.45424","0.11753"
"54.00000","6.47821","0.11824"
"54.20000","6.50227","0.11900"
"54.40000","6.52635","0.11925"
"54.60000","6.55026","0.12001"
"54.80000","6.57415","0.12066"
"55.00000","6.59825","0.12131"
"55.20000","6.62231","0.12170"
"55.40000","6.64631","0.12257"
"55.60000","6.67035","0.12342"
"55.80000","6.69422","0.12346"
"56.00000","6.71824","0.12486"
"56.20000","6.74218","0.12511"
"56.40000","6.76628","0.12568"
"56.60000","6.79032","0.12652"
"56.80000","6.81424","0.12681"
"57.00000","6.83906","0.12752"
"57.20000","6.86200","0.12821"
"57.40000","6.88606","0.12870"
"57.60000","6.91013","0.12937"
"57.80000","6.93416","0.13020"
"58.00000","6.95807","0.13067"
"58.20000","6.98208","0.13110"
"58.40000","7.00617","0.13190"
"58.60000","7.03020","0.13259"
"58.80000","7.05423","0.13305"
"59.00000","7.07819","0.13376"
"59.20000","7.10212","0.13453"
"59.40000","7.12621","0.13498"
"59.60000","7.15023","0.13602"
"59.80000","7.17429","0.13646"
"60.00000","7.19822","0.13693"
"60.20000","7.22224","0.13789"
"60.40000","7.24623","0.13864"
"60.60000","7.27020","0.13920"
"60.80000","7.29429","0.13975"
"61.00000","7.31832","0.14052"
"61.20000","7.34220","0.14100"
"61.40000","7.36613","0.14178"
"61.60000","7.39017","0.14242"
"61.80000","7.41425","0.14309"
"62.00000","7.43820","0.14370"
"62.20000","7.46219","0.14460"
"62.40000","7.48614","0.14490"
"62.60000","7.51009","0.14589"
"62.80000","7.53414","0.14662"
"63.00000","7.55817","0.14689"
"63.20000","7.58221","0.14796"
"63.40000","7.60623","0.14867"
"63.60000","7.63009","0.14928"
"63.80000","7.65415","0.15006"
"64.00000","7.67816","0.15067"
"64.20000","7.70224","0.15139"
"64.40000","7.72626","0.15206"
"64.60000","7.75020","0.15286"
"64.80000","7.77423","0.15361"
"65.00000","7.79956","0.15433"
"65.20000","7.82221","0.15516"
"65.40000","7.84618","0.15558"
"65.60000","7.87011","0.15636"
"65.80000","7.89410","0.15708"
"66.00000","7.91811","0.15782"
"66.20000","7.94213","0.15844"
"66.40000","7.96621","0.15924"
"66.60000","7.99019","0.16030"
"66.80000","8.01411","0.16047"
"67.00000","8.03809","0.16148"
"67.20000","8.06206","0.16235"
"67.40000","8.08615","0.16265"
"67.60000","8.11019","0.16383"
"67.80000","8.13415","0.16446"
"68.00000","8.15844","0.16519"
"68.20000","8.18199","0.16591"
"68.40000","8.20609","0.16681"
"68.60000","8.23011","0.16756"
"68.80000","8.25412","0.16808"
"69.00000","8.27812","0.16918"
"69.20000","8.30208","0.16975"
"69.40000","8.32609","0.17013"
"69.60000","8.35022","0.17145"
"69.80000","8.37425","0.17204"
"70.00000","8.39817","0.17272"
"70.20000","8.42216","0.17356"
"70.40000","8.44618","0.17435"
"70.60000","8.47022","0.17503"
"70.80000","8.49441","0.17578"
"71.00000","8.51825","0.17643"
"71.20000","8.54215","0.17735"
"71.40000","8.56610","0.17794"
"71.60000","8.59010","0.17915"
"71.80000","8.61419","0.17941"
"72.00000","8.63818","0.18029"
"72.20000","8.66214","0.18133"
"72.40000","8.68613","0.18175"
"72.60000","8.71018","0.18288"
"72.80000","8.73412","0.18353"
"73.00000","8.75815","0.18429"
"73.20000","8.78220","0.18503"
"73.40000","8.80615","0.18588"
"73.60000","8.83013","0.18674"
"73.80000","8.85413","0.18735"
"74.00000","8.87816","0.18832"
"74.20000","8.90221","0.18905"
"74.40000","8.92617","0.18973"
"74.60000","8.95012","0.19057"
"74.80000","8.97413","0.19127"
"75.00000","8.99815","0.19199"
"75.20000","9.02225","0.19311"
"75.40000","9.04630","0.19348"
"75.60000","9.07019","0.19453"
"75.80000","9.09410","0.19520"
"76.00000","9.11818","0.19615"
"76.20000","9.14220","0.19696"
"76.40000","9.16622","0.19760"
"76.60000","9.19021","0.19843"
"76.80000","9.21419","0.19909"
"77.00000","9.23822","0.20007"
"77.20000","9.26214","0.20090"
"77.40000","9.28621","0.20132"
"77.60000","9.31024","0.20262"
"77.80000","9.33417","0.20313"
"78.00000","9.35808","0.20390"
"78.20000","9.38211","0.20487"
"78.40000","9.40620","0.20545"
"78.60000","9.43023","0.20630"
"78.80000","9.45590","0.20723"
"79.00000","9.47814","0.20802"
"79.20000","9.50200","0.20862"
"79.40000","9.52601","0.20966"
"79.60000","9.55011","0.21029"
"79.80000","9.57417","0.21121"
"80.00000","9.59806","0.21211"
"80.20000","9.62202","0.21294"
"80.40000","9.64609","0.21373"
"80.60000","9.67012","0.21472"
"80.80000","9.69421","0.21566"
"81.00000","9.71815","0.21598"
"81.20000","9.74211","0.21710"
"81.40000","9.76615","0.21783"
"81.60000","9.79014","0.21869"
"81.80000","9.81426","0.21948"
"82.00000","9.83832","0.22040"
"82.20000","9.86218","0.22117"
"82.40000","9.88607","0.22201"
"82.60000","9.91014","0.22293"
"82.80000","9.93411","0.22373"
"83.00000","9.95815","0.22468"
"83.20000","9.98211","0.22565"
"83.40000","10.00604","0.22615"
"83.60000","10.03001","0.22728"
"83.80000","10.05404","0.22826"
"84.00000","10.07815","0.22899"
"84.20000","10.10222","0.23008"
"84.40000","10.12613","0.23078"
"84.60000","10.15020","0.23172"
"84.80000","10.17420","0.23281"
"85.00000","10.19820","0.23349"
"85.20000","10.22221","0.23441"
"85.40000","10.24622","0.23533"
"85.60000","10.27013","0.23613"
"85.80000","10.29502","0.23731"
"86.00000","10.31814","0.23774"
"86.20000","10.34217","0.23888"
"86.40000","10.36617","0.23975"
"86.60000","10.39011","0.24058"
"86.80000","10.41411","0.24178"
"87.00000","10.43815","0.24237"
"87.20000","10.46212","0.24346"
"87.40000","10.48615","0.24423"
"87.60000","10.51013","0.24537"
"87.80000","10.53413","0.24593"
"88.00000","10.55810","0.24689"
"88.20000","10.58218","0.24810"
"88.40000","10.60611","0.24844"
"88.60000","10.63023","0.24967"
"88.80000","10.65412","0.25053"
"89.00000","10.67805","0.25123"
"89.20000","10.70212","0.25227"
"89.40000","10.72619","0.25313"
"89.60000","10.75025","0.25394"
"89.80000","10.77428","0.25470"
"90.00000","10.79819","0.25567"
"90.20000","10.82210","0.25667"
"90.40000","10.84617","0.25769"
"90.60000","10.87024","0.25849"
"90.80000","10.89426","0.25964"
"91.00000","10.91816","0.26016"
"91.20000","10.94210","0.26136"
"91.40000","10.96612","0.26241"
"91.60000","10.99012","0.26317"
"91.80000","11.01417","0.26413"
"92.00000","11.03819","0.26487"
"92.20000","11.06219","0.26599"
"92.40000","11.08624","0.26658"
"92.60000","11.11017","0.26770"
"92.80000","11.13454","0.26855"
"93.00000","11.15818","0.26924"
"93.20000","11.18207","0.27041"
"93.40000","11.20604","0.27104"
"93.60000","11.23005","0.27210"
"93.80000","11.25410","0.27302"
"94.00000","11.27818","0.27386"
"94.20000","11.30219","0.27491"
"94.40000","11.32618","0.27556"
"94.60000","11.35013","0.27652"
"94.80000","11.37417","0.27751"
"95.00000","11.39824","0.27819"
"95.20000","11.42227","0.27931"
"95.40000","11.44617","0.27994"
"95.60000","11.47021","0.28098"
"95.80000","11.49416","0.28181"
"96.00000","11.51813","0.28261"
"96.20000","11.54220","0.28363"
"96.40000","11.56624","0.28449"
"96.60000","11.59016","0.28523"
"96.80000","11.61410","0.28628"
"97.00000","11.63814","0.28698"
"97.20000","11.66232","0.28783"
"97.40000","11.68627","0.28882"
"97.60000","11.71016","0.28957"
"97.80000","11.73411","0.29049"
"98.00000","11.75816","0.29135"
"98.20000","11.78218","0.29214"
"98.40000","11.80622","0.29306"
"98.60000","11.83021","0.29406"
"98.80000","11.85413","0.29490"
"99.00000","11.87805","0.29543"
"99.20000","11.90211","0.29688"
"99.40000","11.92626","0.29731"
"99.60000","11.95144","0.29808"
"99.80000","11.97416","0.29918"
"100.00000","11.99803","0.29994"
"100.20000","12.02208","0.30079"
"100.40000","12.04612","0.30173"
"100.60000","12.07018","0.30255"
"100.80000","12.09421","0.30336"
"101.00000","12.11815","0.30409"
"101.20000","12.14205","0.30516"
"101.40000","12.16612","0.30581"
"101.60000","12.19017","0.30681"
"101.80000","12.21420","0.30780"
"102.00000","12.23823","0.30854"
"102.20000","12.26211","0.30931"
"102.40000","12.28616","0.31046"
"102.60000","12.31014","0.31104"
"102.80000","12.33418","0.31205"
"103.00000","12.35821","0.31296"
"103.20000","12.38210","0.31350"
"103.40000","12.40603","0.31463"
"103.60000","12.43011","0.31550"
"103.80000","12.45477","0.31622"
"104.00000","12.47811","0.31704"
"104.20000","12.50205","0.31792"
"104.40000","12.52603","0.31878"
"104.60000","12.55006","0.31965"
"104.80000","12.57413","0.32061"
"105.00000","12.59823","0.32124"
"105.20000","12.62224","0.32223"
"105.40000","12.64617","0.32299"
"105.60000","12.67007","0.32394"
"105.80000","12.69416","0.32449"
"106.00000","12.71825","0.32542"
"106.20000","12.74222","0.32642"
"106.40000","12.76622","0.32678"
"106.60000","12.79012","0.32799"
"106.80000","12.81415","0.32891"
"107.00000","12.83814","0.32937"
"107.20000","12.86226","0.33032"
"107.40000","12.88626","0.33128"
"107.60000","12.91021","0.33182"
"107.80000","12.93431","0.33287"
"108.00000","12.95821","0.33358"
"108.20000","12.98216","0.33440"
"108.40000","13.00621","0.33525"
"108.60000","13.03014","0.33616"
"108.80000","13.05410","0.33692"
"109.00000","13.07809","0.33760"
"109.20000","13.10207","0.33875"
"109.40000","13.12615","0.33942"
"109.60000","13.15010","0.34035"
"109.80000","13.17411","0.34147"
"110.00000","13.19807","0.34196"
"110.20000","13.22215","0.34299"
"110.40000","13.24622","0.34370"
"110.60000","13.27029","0.34479"
"110.80000","13.29426","0.34556"
"111.00000","13.31817","0.34618"
"111.20000","13.34214","0.34704"
"111.40000","13.36618","0.34770"
"111.60000","13.39158","0.34866"
"111.80000","13.41420","0.34938"
"112.00000","13.43816","0.34996"
"112.20000","13.46211","0.35122"
"112.40000","13.48617","0.35205"
"112.60000","13.51018","0.35286"
"112.80000","13.53422","0.35378"
"113.00000","13.55826","0.35454"
"113.20000","13.58221","0.35540"
"113.40000","13.60614","0.35649"
"113.60000","13.63013","0.35750"
"113.80000","13.65418","0.35823"
"114.00000","13.67818","0.35904"
"114.20000","13.70214","0.36016"
"114.40000","13.72602","0.36080"
"114.60000","13.75012","0.36190"
"114.80000","13.77409","0.36272"
"115.00000","13.79814","0.36351"
"115.20000","13.82216","0.36459"
"115.40000","13.84671","0.36540"
"115.60000","13.87001","0.36597"
"115.80000","13.89410","0.36734"
"116.00000","13.91823","0.36789"
"116.20000","13.94222","0.36875"
"116.40000","13.96617","0.36980"
"116.60000","13.99010","0.37044"
"116.80000","14.01416","0.37145"
"117.00000","14.03821","0.37231"
"117.20000","14.06219","0.37339"
"117.40000","14.08625","0.37397"
"117.60000","14.11020","0.37495"
"117.80000","14.13410","0.37600"
"118.00000","14.15816","0.37648"
"118.20000","14.18223","0.37751"
"118.40000","14.20631","0.37829"
"118.60000","14.23025","0.37905"
"118.80000","14.25417","0.37994"
"119.00000","14.27818","0.38070"
"119.20000","14.30222","0.38142"
"119.40000","14.32621","0.38213"
"119.60000","14.35019","0.38290"
"119.80000","14.37415","0.38388"
"120.00000","14.39809","0.38439"
"120.20000","14.42212","0.38533"
"120.40000","14.44673","0.38585"
"120.60000","14.47022","0.38652"
"120.80000","14.49410","0.38745"
"121.00000","14.51808","0.38815"
"121.20000","14.54205","0.38893"
"121.40000","14.56613","0.38958"
"121.60000","14.59022","0.39050"
"121.80000","14.61432","0.39137"
"122.00000","14.63817","0.39204"
"122.20000","14.66207","0.39274"
"122.40000","14.68615","0.39355"
"122.60000","14.71022","0.39458"
"122.80000","14.73428","0.39523"
"123.00000","14.75816","0.39567"
"123.20000","14.78215","0.39675"
"123.40000","14.80619","0.39745"
"123.60000","14.83011","0.39800"
"123.80000","14.85422","0.39914"
"124.00000","14.87828","0.39962"
"124.20000","14.90223","0.40042"
"124.40000","14.92615","0.40123"
"124.60000","14.95016","0.40190"
"124.80000","14.97423","0.40272"
"125.00000","14.99820","0.40344"
"125.20000","15.02212","0.40420"
"125.40000","15.04610","0.40496"
"125.60000","15.07012","0.40602"
"125.80000","15.09411","0.40655"
"126.00000","15.11826","0.40728"
"126.20000","15.14252","0.40815"
"126.40000","15.16605","0.40852"
"126.60000","15.19001","0.40943"
"126.80000","15.21402","0.41014"
"127.00000","15.23821","0.41066"
"127.20000","15.26222","0.41138"
"127.40000","15.28618","0.41223"
"127.60000","15.31017","0.41264"
"127.80000","15.33410","0.41338"
"128.00000","15.35810","0.41373"
"128.20000","15.38218","0.41442"
"128.40000","15.40621","0.41476"
"128.60000","15.43015","0.41559"
"128.80000","15.45414","0.41605"
"129.00000","15.47804","0.41628"
"129.20000","15.50210","0.41695"
"129.40000","15.52614","0.41728"
"129.60000","15.55014","0.41820"
"129.80000","15.57411","0.41855"
"130.00000","15.59811","0.41867"
"130.20000","15.62213","0.41980"
"130.40000","15.64620","0.42013"
"130.60000","15.67020","0.42064"
"130.80000","15.69412","0.42141"
"131.00000","15.71807","0.42192"
"131.20000","15.74210","0.42235"
"131.40000","15.76619","0.42328"
"131.60000","15.79026","0.42382"
"131.80000","15.81420","0.42436"
"132.00000","15.83836","0.42485"
"132.20000","15.86207","0.42561"
"132.40000","15.88604","0.42604"
"132.60000","15.91016","0.42705"
"132.80000","15.93422","0.42763"
"133.00000","15.95815","0.42803"
"133.20000","15.98211","0.42870"
"133.40000","16.00620","0.42942"
"133.60000","16.03019","0.42996"
"133.80000","16.05416","0.43080"
"134.00000","16.07849","0.43145"
"134.20000","16.10200","0.43204"
"134.40000","16.12607","0.43258"
"134.60000","16.15005","0.43343"
"134.80000","16.17419","0.43390"
"135.00000","16.19819","0.43455"
"135.20000","16.22216","0.43536"
"135.40000","16.24612","0.43600"
"135.60000","16.27017","0.43661"
"135.80000","16.29418","0.43739"
"136.00000","16.31822","0.43796"
"136.20000","16.34220","0.43856"
"136.40000","16.36619","0.43944"
"136.60000","16.39017","0.43988"
"136.80000","16.41410","0.44067"
"137.00000","16.43824","0.44142"
"137.20000","16.46223","0.44176"
"137.40000","16.48615","0.44248"
"137.60000","16.51021","0.44315"
"137.80000","16.53417","0.44357"
"138.00000","16.55813","0.44417"
"138.20000","16.58217","0.44531"
"138.40000","16.60622","0.44533"
"138.60000","16.63019","0.44628"
"138.80000","16.65411","0.44702"
"139.00000","16.67814","0.44714"
"139.20000","16.70226","0.44810"
"139.40000","16.72625","0.44901"
"139.60000","16.75015","0.44915"
"139.80000","16.77406","0.45020"
"140.00000","16.79814","0.45081"
"140.20000","16.82217","0.45139"
"140.40000","16.84622","0.45240"
"140.60000","16.87023","0.45278"
"140.80000","16.89421","0.45344"
"141.00000","16.91886","0.45419"
"141.20000","16.94200","0.45485"
"141.40000","16.96611","0.45548"
"141.60000","16.99019","0.45626"
"141.80000","17.01412","0.45700"
"142.00000","17.03804","0.45764"
"142.20000","17.06213","0.45824"
"142.40000","17.08615","0.45887"
"142.60000","17.11017","0.45952"
"142.80000","17.13421","0.46027"
"143.00000","17.15818","0.46092"
"143.20000","17.18207","0.46174"
"143.40000","17.20609","0.46195"
"143.60000","17.23018","0.46285"
"143.80000","17.25417","0.46373"
"144.00000","17.27810","0.46405"
"144.20000","17.30212","0.46498"
"144.40000","17.32617","0.46577"
"144.60000","17.35030","0.46590"
"144.80000","17.37408","0.46674"
"145.00000","17.39821","0.46754"
"145.20000","17.42214","0.46786"
"145.40000","17.44609","0.46861"
"145.60000","17.47020","0.46934"
"145.80000","17.49422","0.46971"
"146.00000","17.51819","0.47049"
"146.20000","17.54215","0.47141"
"146.40000","17.56608","0.47162"
"146.60000","17.59009","0.47248"
"146.80000","17.61413","0.47310"
"147.00000","17.63821","0.47330"
"147.20000","17.66226","0.47354"
"147.40000","17.68612","0.47431"
"147.60000","17.71006","0.47455"
"147.80000","17.73405","0.47537"
"148.00000","17.75816","0.47595"
"148.20000","17.78219","0.47638"
"148.40000","17.80614","0.47703"
"148.60000","17.83011","0.47728"
"148.80000","17.85411","0.47795"
"149.00000","17.87822","0.47849"
"149.20000","17.90221","0.47904"
"149.40000","17.92627","0.47950"
"149.60000","17.95033","0.48019"
"149.80000","17.97407","0.48062"
"150.00000","17.99814","0.48114"
"150.20000","18.02221","0.48174"
"150.40000","18.04627","0.48213"
"150.60000","18.07022","0.48270"
"150.80000","18.09417","0.48321"
"151.00000","18.11823","0.48331"
"151.20000","18.14224","0.48381"
"151.40000","18.16625","0.48424"
"151.60000","18.19022","0.48450"
"151.80000","18.21414","0.48507"
"152.00000","18.23813","0.48540"
"152.20000","18.26219","0.48590"
"152.40000","18.28626","0.48631"
"152.60000","18.31075","0.48675"
"152.80000","18.33400","0.48709"
"153.00000","18.35802","0.48764"
"153.20000","18.38207","0.48831"
"153.40000","18.40605","0.48852"
"153.60000","18.43009","0.48904"
"153.80000","18.45421","0.48956"
"154.00000","18.47817","0.48977"
"154.20000","18.50212","0.49053"
"154.40000","18.52615","0.49107"
"154.60000","18.55023","0.49117"
"154.80000","18.57422","0.49181"
"155.00000","18.59816","0.49227"
"155.20000","18.62217","0.49252"
"155.40000","18.64640","0.49280"
"155.60000","18.67015","0.49313"
"155.80000","18.69419","0.49349"
"156.00000","18.71819","0.49382"
"156.20000","18.74220","0.49450"
"156.40000","18.76610","0.49466"
"156.60000","18.79010","0.49532"
"156.80000","18.81415","0.49589"
"157.00000","18.83822","0.49580"
"157.20000","18.86218","0.49648"
"157.40000","18.88610","0.49693"
"157.60000","18.91131","0.49701"
"157.80000","18.93389","0.49764"
"158.00000","18.95801","0.49794"
"158.20000","18.98212","0.49823"
"158.40000","19.00612","0.49833"
"158.60000","19.03015","0.49874"
"158.80000","19.05422","0.49922"
"159.00000","19.07831","0.49916"
"159.20000","19.10223","0.49991"
"159.40000","19.12624","0.50011"
"159.60000","19.15011","0.50015"
"159.80000","19.17411","0.50082"
"160.00000","19.19812","0.50130"
"160.20000","19.22228","0.50131"
"160.40000","19.24623","0.50160"
"160.60000","19.27019","0.50229"
"160.80000","19.29412","0.50248"
"161.00000","19.31822","0.50289"
"161.20000","19.34233","0.50340"
"161.40000","19.36631","0.50352"
"161.60000","19.39029","0.50399"
"161.80000","19.41426","0.50483"
"162.00000","19.43818","0.50458"
"162.20000","19.46213","0.50526"
"162.40000","19.48616","0.50570"
"162.60000","19.51024","0.50612"
"162.80000","19.53415","0.50644"
"163.00000","19.55810","0.50653"
"163.20000","19.58204","0.50740"
"163.40000","19.60610","0.50766"
"163.60000","19.63015","0.50767"
"163.80000","19.65419","0.50847"
"164.00000","19.67818","0.50871"
"164.20000","19.70215","0.50919"
"164.40000","19.72613","0.50961"
"164.60000","19.75020","0.50981"
"164.80000","19.77432","0.51054"
"165.00000","19.79821","0.51066"
"165.20000","19.82219","0.51123"
"165.40000","19.84628","0.51150"
"165.60000","19.87025","0.51185"
"165.80000","19.89437","0.51232"
"166.00000","19.91823","0.51260"
"166.20000","19.94227","0.51318"
"166.40000","19.96623","0.51335"
"166.60000","19.99016","0.51363"
"166.80000","20.01427","0.51418"
"167.00000","20.03824","0.51461"
"167.20000","20.06217","0.51505"
"167.40000","20.08613","0.51518"
"167.60000","20.11011","0.51564"
"167.80000","20.13416","0.51585"
"168.00000","20.15823","0.51632"
"168.20000","20.18225","0.51690"
"168.40000","20.20617","0.51697"
"168.60000","20.23010","0.51753"
"168.80000","20.25412","0.51828"
"169.00000","20.27826","0.51830"
"169.20000","20.30223","0.51894"
"169.40000","20.32615","0.51939"
"169.60000","20.35011","0.51974"
"169.80000","20.37420","0.52008"
"170.00000","20.39826","0.52056"
"170.20000","20.42321","0.52060"
"170.40000","20.44630","0.52089"
"170.60000","20.47014","0.52162"
"170.80000","20.49414","0.52171"
"171.00000","20.51820","0.52201"
"171.20000","20.54227","0.52290"
"171.40000","20.56630","0.52277"
"171.60000","20.59022","0.52334"
"171.80000","20.61416","0.52378"
"172.00000","20.63818","0.52418"
"172.20000","20.66220","0.52448"
"172.40000","20.68624","0.52506"
"172.60000","20.71026","0.52547"
"172.80000","20.73415","0.52591"
"173.00000","20.75808","0.52642"
"173.20000","20.78209","0.52672"
"173.40000","20.80612","0.52692"
"173.60000","20.83021","0.52775"
"173.80000","20.85411","0.52801"
"174.00000","20.87823","0.52819"
"174.20000","20.90208","0.52896"
"174.40000","20.92615","0.52933"
"174.60000","20.95016","0.52965"
"174.80000","20.97421","0.53039"
"175.00000","20.99818","0.53075"
"175.20000","21.02207","0.53116"
"175.40000","21.04619","0.53155"
"175.60000","21.07025","0.53210"
"175.80000","21.09428","0.53265"
"176.00000","21.11822","0.53285"
"176.20000","21.14217","0.53369"
"176.40000","21.16623","0.53382"
"176.60000","21.19131","0.53436"
"176.80000","21.21425","0.53497"
"177.00000","21.23812","0.53510"
"177.20000","21.26209","0.53578"
"177.40000","21.28607","0.53611"
"177.60000","21.31008","0.53652"
"177.80000","21.33409","0.53687"
"178.00000","21.35816","0.53739"
"178.20000","21.38211","0.53780"
"178.40000","21.40608","0.53823"
"178.60000","21.43010","0.53882"
"178.80000","21.45406","0.53917"
"179.00000","21.47813","0.53946"
"179.20000","21.50217","0.54028"
"179.40000","21.52608","0.54056"
"179.60000","21.55007","0.54083"
"179.80000","21.57410","0.54150"
"180.00000","21.59822","0.54183"
"180.20000","21.62239","0.54208"
"180.40000","21.64647","0.54269"
"180.60000","21.67007","0.54299"
"180.80000","21.69408","0.54346"
"181.00000","21.71810","0.54402"
"181.20000","21.74223","0.54445"
"181.40000","21.76626","0.54448"
"181.60000","21.79020","0.54494"
"181.80000","21.81414","0.54528"
"182.00000","21.83821","0.54536"
"182.20000","21.86227","0.54600"
"182.40000","21.88626","0.54622"
"182.60000","21.91018","0.54643"
"182.80000","21.93415","0.54713"
"183.00000","21.95817","0.54720"
"183.20000","21.98211","0.54763"
"183.40000","22.00622","0.54777"
"183.60000","22.03025","0.54732"
"183.80000","22.05415","0.54728"
"184.00000","22.07809","0.54773"
"184.20000","22.10216","0.54788"
"184.40000","22.12806","0.54786"
"184.60000","22.15017","0.54824"
"184.80000","22.17400","0.54849"
"185.00000","22.19797","0.54827"
"185.20000","22.22199","0.54894"
"185.40000","22.24600","0.54911"
"185.60000","22.27018","0.54919"
"185.80000","22.29424","0.54981"
"186.00000","22.31816","0.54963"
"186.20000","22.34208","0.54994"
"186.40000","22.36615","0.55028"
"186.60000","22.39020","0.55056"
"186.80000","22.41421","0.55070"
"187.00000","22.43820","0.55113"
"187.20000","22.46219","0.55127"
"187.40000","22.48619","0.55134"
"187.60000","22.51018","0.55179"
"187.80000","22.53424","0.55209"
"188.00000","22.55822","0.55210"
"188.20000","22.58213","0.55273"
"188.40000","22.60609","0.55292"
"188.60000","22.63009","0.55307"
"188.80000","22.65409","0.55362"
"189.00000","22.67817","0.55369"
"189.20000","22.70217","0.55423"
"189.40000","22.72617","0.55438"
"189.60000","22.75019","0.55470"
"189.80000","22.77409","0.55494"
"190.00000","22.79815","0.55502"
"190.20000","22.82224","0.55539"
"190.40000","22.84618","0.55574"
"190.60000","22.87008","0.55583"
"190.80000","22.89412","0.55656"
"191.00000","22.91818","0.55648"
"191.20000","22.94224","0.55686"
"191.40000","22.96620","0.55721"
"191.60000","22.99018","0.55755"
"191.80000","23.01411","0.55779"
"192.00000","23.03815","0.55813"
"192.20000","23.06251","0.55859"
"192.40000","23.08626","0.55894"
"192.60000","23.11074","0.55895"
"192.80000","23.13399","0.55955"
"193.00000","23.15808","0.55928"
"193.20000","23.18214","0.55968"
"193.40000","23.20622","0.56009"
"193.60000","23.23020","0.56000"
"193.80000","23.25415","0.56050"
"194.00000","23.27811","0.56075"
"194.20000","23.30234","0.56082"
"194.40000","23.32612","0.56117"
"194.60000","23.35017","0.56152"
"194.80000","23.37408","0.56168"
"195.00000","23.39803","0.56161"
"195.20000","23.42212","0.56201"
"195.40000","23.44620","0.56208"
"195.60000","23.47017","0.56201"
"195.80000","23.49416","0.56241"
"196.00000","23.51811","0.56233"
"196.20000","23.54205","0.56278"
"196.40000","23.56608","0.56265"
"196.60000","23.59022","0.56304"
"196.80000","23.61427","0.56273"
"197.00000","23.63822","0.56225"
"197.20000","23.66215","0.56272"
"197.40000","23.68619","0.56082"
"197.60000","23.71016","0.56038"
"197.80000","23.73423","0.56068"
"198.00000","23.75827","0.56019"
"198.20000","23.78219","0.56040"
"198.40000","23.80617","0.56075"
"198.60000","23.83016","0.56027"
"198.80000","23.85424","0.56052"
"199.00000","23.87829","0.56091"
"199.20000","23.90212","0.56080"
"199.40000","23.92613","0.56077"
"199.60000","23.95167","0.56098"
"199.80000","23.97408","0.56083"
"200.00000","23.99801","0.56073"
"200.20000","24.02208","0.56103"
"200.40000","24.04608","0.56114"
"200.60000","24.07005","0.56106"
"200.80000","24.09413","0.56130"
"201.00000","24.11826","0.56120"
"201.20000","24.14219","0.56107"
"201.40000","24.16618","0.56105"
"201.60000","24.19014","0.56145"
"201.80000","24.21414","0.56093"
"202.00000","24.23817","0.56134"
"202.20000","24.26220","0.56114"
"202.40000","24.28629","0.56071"
"202.60000","24.31026","0.56098"
"202.80000","24.33414","0.56078"
"203.00000","24.35819","0.56051"
"203.20000","24.38226","0.56059"
"203.40000","24.40624","0.56026"
"203.60000","24.43020","0.56025"
"203.80000","24.45417","0.56001"
"204.00000","24.47817","0.55969"
"204.20000","24.50216","0.55914"
"204.40000","24.52621","0.55845"
"204.60000","24.55018","0.55818"
"204.80000","24.57417","0.55803"
"205.00000","24.59824","0.55729"
"205.20000","24.62209","0.55702"
"205.40000","24.64602","0.55657"
"205.60000","24.67012","0.55628"
"205.80000","24.69417","0.55621"
"206.00000","24.71811","0.55587"
"206.20000","24.74210","0.55552"
"206.40000","24.76611","0.55533"
"206.60000","24.79016","0.55518"
"206.80000","24.81437","0.55499"
"207.00000","24.83817","0.55463"
"207.20000","24.86201","0.55443"
"207.40000","24.88614","0.55429"
"207.60000","24.91023","0.55420"
"207.80000","24.93424","0.55377"
"208.00000","24.95821","0.55373"
"208.20000","24.98219","0.55338"
"208.40000","25.00621","0.55320"
"208.60000","25.03019","0.55296"
"208.80000","25.05434","0.55275"
"209.00000","25.07835","0.55253"
"209.20000","25.10224","0.55265"
"209.40000","25.12618","0.55188"
"209.60000","25.15020","0.55187"
"209.80000","25.17437","0.55181"
"210.00000","25.19823","0.55146"
"210.20000","25.22212","0.55152"
"210.40000","25.24611","0.55134"
"210.60000","25.27007","0.55105"
"210.80000","25.29406","0.55103"
"211.00000","25.31819","0.55076"
"211.20000","25.34228","0.55081"
"211.40000","25.36620","0.55051"
"211.60000","25.39011","0.55059"
"211.80000","25.41419","0.55019"
"212.00000","25.43823","0.55012"
"212.20000","25.46223","0.55020"
"212.40000","25.48621","0.55006"
"212.60000","25.51019","0.54995"
"212.80000","25.53415","0.54969"
"213.00000","25.55828","0.54969"
"213.20000","25.58257","0.54929"
"213.40000","25.60608","0.54928"
"213.60000","25.63006","0.54916"
"213.80000","25.65404","0.54887"
"214.00000","25.67815","0.54867"
"214.20000","25.70217","0.54874"
"214.40000","25.72619","0.54804"
"214.60000","25.75018","0.54816"
"214.80000","25.77412","0.54815"
"215.00000","25.79807","0.54775"
"215.20000","25.82201","0.54756"
"215.40000","25.84620","0.54769"
"215.60000","25.87021","0.54749"
"215.80000","25.89414","0.54730"
"216.00000","25.91811","0.54745"
"216.20000","25.94217","0.54712"
"216.40000","25.96617","0.54673"
"216.60000","25.99019","0.54704"
"216.80000","26.01419","0.54654"
"217.00000","26.03812","0.54611"
"217.20000","26.06207","0.54622"
"217.40000","26.08611","0.54564"
"217.60000","26.11027","0.54595"
"217.80000","26.13434","0.54571"
"218.00000","26.15820","0.54548"
"218.20000","26.18214","0.54556"
"218.40000","26.20621","0.54542"
"218.60000","26.23018","0.54532"
"218.80000","26.25425","0.54527"
"219.00000","26.27823","0.54516"
"219.20000","26.30270","0.54516"
"219.40000","26.32604","0.54493"
"219.60000","26.35013","0.54516"
"219.80000","26.37423","0.54505"
"220.00000","26.39819","0.54491"
"220.20000","26.42211","0.54507"
"220.40000","26.44610","0.54478"
"220.60000","26.47011","0.54441"
"220.80000","26.49409","0.54450"
"221.00000","26.51818","0.54453"
"221.20000","26.54221","0.54398"
"221.40000","26.56617","0.54425"
"221.60000","26.59018","0.54429"
"221.80000","26.61413","0.54380"
"222.00000","26.63823","0.54402"
"222.20000","26.66227","0.54393"
"222.40000","26.68619","0.54368"
"222.60000","26.71010","0.54395"
"222.80000","26.73413","0.54364"
"223.00000","26.75818","0.54349"
"223.20000","26.78436","0.54366"
"223.40000","26.80619","0.54322"
"223.60000","26.83004","0.54323"
"223.80000","26.85405","0.54315"
"224.00000","26.87808","0.54304"
"224.20000","26.90216","0.54246"
"224.40000","26.92620","0.54281"
"224.60000","26.95013","0.54266"
"224.80000","26.97403","0.54243"
"225.00000","26.99808","0.54281"
"225.20000","27.02205","0.54222"
"225.40000","27.04613","0.54223"
"225.60000","27.07015","0.54255"
"225.80000","27.09415","0.54206"
"226.00000","27.11809","0.54195"
"226.20000","27.14209","0.54213"
"226.40000","27.16615","0.54193"
"226.60000","27.19012","0.54206"
"226.80000","27.21413","0.54218"
"227.00000","27.23810","0.54192"
"227.20000","27.26212","0.54205"
"227.40000","27.28614","0.54252"
"227.60000","27.31020","0.54227"
"227.80000","27.33422","0.54250"
"228.00000","27.35812","0.54253"
"228.20000","27.38208","0.54252"
"228.40000","27.40613","0.54245"
"228.60000","27.43022","0.54267"
"228.80000","27.45432","0.54283"
"229.00000","27.47821","0.54293"
"229.20000","27.50220","0.54297"
"229.40000","27.52619","0.54320"
"229.60000","27.55010","0.54308"
"229.80000","27.57421","0.54308"
"230.00000","27.59821","0.54354"
"230.20000","27.62223","0.54352"
"230.40000","27.64594","0.54348"
"230.60000","27.66993","0.54379"
"230.80000","27.69407","0.54374"
"231.00000","27.71809","0.54371"
"231.20000","27.74212","0.54446"
"231.40000","27.76611","0.54421"
"231.60000","27.79012","0.54425"
"231.80000","27.81411","0.54446"
"232.00000","27.83819","0.54475"
"232.20000","27.86218","0.54468"
"232.40000","27.88613","0.54481"
"232.60000","27.91006","0.54539"
"232.80000","27.93413","0.54523"
"233.00000","27.95819","0.54562"
"233.20000","27.98228","0.54558"
"233.40000","28.00614","0.54556"
"233.60000","28.03007","0.54590"
"233.80000","28.05418","0.54594"
"234.00000","28.07820","0.54607"
"234.20000","28.10228","0.54645"
"234.40000","28.12629","0.54660"
"234.60000","28.15023","0.54690"
"234.80000","28.17412","0.54704"
"235.00000","28.19816","0.54730"
"235.20000","28.22222","0.54719"
"235.40000","28.24617","0.54752"
"235.60000","28.27009","0.54774"
"235.80000","28.29412","0.54770"
"236.00000","28.31809","0.54809"
"236.20000","28.34210","0.54822"
"236.40000","28.36622","0.54831"
"236.60000","28.39025","0.54861"
"236.80000","28.41420","0.54885"
"237.00000","28.43808","0.54899"
"237.20000","28.46224","0.54917"
"237.40000","28.48620","0.54944"
"237.60000","28.51022","0.54966"
"237.80000","28.53421","0.54964"
"238.00000","28.55814","0.55023"
"238.20000","28.58205","0.55018"
"238.40000","28.60611","0.55060"
"238.60000","28.63021","0.55090"
"238.80000","28.65432","0.55106"
"239.00000","28.67823","0.55154"
"239.20000","28.70214","0.55140"
"239.40000","28.72622","0.55185"
"239.60000","28.75024","0.55181"
"239.80000","28.77425","0.55212"
"240.00000","28.79827","0.55251"
"240.20000","28.82218","0.55250"
"240.40000","28.84617","0.55249"
"240.60000","28.87013","0.55298"
"240.80000","28.89430","0.55283"
"241.00000","28.91899","0.55324"
"241.20000","28.94194","0.55349"
"241.40000","28.96588","0.55369"
"241.60000","28.98996","0.55383"
"241.80000","29.01406","0.55423"
"242.00000","29.03804","0.55440"
"242.20000","29.06207","0.55453"
"242.40000","29.08610","0.55512"
"242.60000","29.11000","0.55518"
"242.80000","29.13412","0.55530"
"243.00000","29.15816","0.55590"
"243.20000","29.18224","0.55595"
"243.40000","29.20610","0.55615"
"243.60000","29.23006","0.55644"
"243.80000","29.25414","0.55658"
"244.00000","29.27808","0.55677"
"244.20000","29.30212","0.55708"
"244.40000","29.32641","0.55758"
"244.60000","29.35014","0.55751"
"244.80000","29.37416","0.55769"
"245.00000","29.39832","0.55815"
"245.20000","29.42224","0.55801"
"245.40000","29.44629","0.55830"
"245.60000","29.47020","0.55850"
"245.80000","29.49415","0.55883"
"246.00000","29.51810","0.55875"
"246.20000","29.54212","0.55923"
"246.40000","29.56613","0.55935"
"246.60000","29.59017","0.55962"
"246.80000","29.61411","0.56002"
"247.00000","29.63833","0.56014"
"247.20000","29.66207","0.56023"
"247.40000","29.68608","0.56060"
"247.60000","29.71010","0.56085"
"247.80000","29.73413","0.56099"
"248.00000","29.75806","0.56111"
"248.20000","29.78215","0.56147"
"248.40000","29.80613","0.56165"
"248.60000","29.83016","0.56185"
"248.80000","29.85424","0.56213"
"249.00000","29.87816","0.56228"
"249.20000","29.90214","0.56228"
"249.40000","29.92618","0.56267"
"249.60000","29.95031","0.56273"
"249.80000","29.97435","0.56286"
"250.00000","29.99829","0.56336"
"250.20000","30.02243","0.56337"
"250.40000","30.04618","0.56347"
"250.60000","30.07003","0.56386"
"250.80000","30.09416","0.56395"
"251.00000","30.11818","0.56429"
"251.20000","30.14218","0.56447"
"251.40000","30.16605","0.56466"
"251.60000","30.19006","0.56470"
"251.80000","30.21408","0.56499"
"252.00000","30.23819","0.56527"
"252.20000","30.26207","0.56538"
"252.40000","30.28605","0.56564"
"252.60000","30.31006","0.56598"
"252.80000","30.33410","0.56571"
"253.00000","30.35804","0.56609"
"253.20000","30.38218","0.56656"
"253.40000","30.40613","0.56637"
"253.60000","30.43005","0.56704"
"253.80000","30.45410","0.56708"
"254.00000","30.47826","0.56714"
"254.20000","30.50226","0.56762"
"254.40000","30.52615","0.56762"
"254.60000","30.55016","0.56794"
"254.80000","30.57425","0.56823"
"255.00000","30.59827","0.56831"
"255.20000","30.62234","0.56863"
"255.40000","30.64633","0.56883"
"255.60000","30.67028","0.56880"
"255.80000","30.69422","0.56900"
"256.00000","30.71926","0.56952"
"256.20000","30.74215","0.56932"
"256.40000","30.76618","0.56938"
"256.60000","30.79021","0.56950"
"256.80000","30.81414","0.56951"
"257.00000","30.83810","0.56956"
"257.20000","30.86207","0.56939"
"257.40000","30.88616","0.56948"
"257.60000","30.91015","0.56968"
"257.80000","30.93409","0.56967"
"258.00000","30.95800","0.56968"
"258.20000","30.98210","0.56979"
"258.40000","31.00614","0.56983"
"258.60000","31.03023","0.56997"
"258.80000","31.05418","0.56980"
"259.00000","31.07809","0.57019"
"259.20000","31.10211","0.56993"
"259.40000","31.12614","0.56992"
"259.60000","31.15021","0.56999"
"259.80000","31.17423","0.56983"
"260.00000","31.19820","0.57033"
"260.20000","31.22219","0.57011"
"260.40000","31.24626","0.56991"
"260.60000","31.27031","0.57007"
"260.80000","31.29440","0.56969"
"261.00000","31.31831","0.56977"
"261.20000","31.34221","0.56967"
"261.40000","31.36623","0.56956"
"261.60000","31.39023","0.56938"
"261.80000","31.41426","0.56953"
"262.00000","31.43812","0.56937"
"262.20000","31.46214","0.56912"
"262.40000","31.48610","0.56932"
"262.60000","31.51013","0.56917"
"262.80000","31.53414","0.56901"
"263.00000","31.55814","0.56920"
"263.20000","31.58214","0.56888"
"263.40000","31.60611","0.56898"
"263.60000","31.63009","0.56895"
"263.80000","31.65409","0.56842"
"264.00000","31.67841","0.56857"
"264.20000","31.70217","0.56833"
"264.40000","31.72612","0.56820"
"264.60000","31.75006","0.56809"
"264.80000","31.77416","0.56794"
"265.00000","31.79824","0.56768"
"265.20000","31.82230","0.56745"
"265.40000","31.84626","0.56758"
"265.60000","31.87028","0.56708"
"265.80000","31.89434","0.56694"
"266.00000","31.91822","0.56680"
"266.20000","31.94235","0.56644"
"266.40000","31.96641","0.56622"
"266.60000","31.99031","0.56598"
"266.80000","32.01423","0.56586"
"267.00000","32.03825","0.56530"
"267.20000","32.06227","0.56514"
"267.40000","32.08630","0.56490"
"267.60000","32.11029","0.56444"
"267.80000","32.13426","0.56402"
"268.00000","32.15817","0.56378"
"268.20000","32.18213","0.56337"
"268.40000","32.20618","0.56306"
"268.60000","32.23014","0.56254"
"268.80000","32.25413","0.56212"
"269.00000","32.27806","0.56148"
"269.20000","32.30213","0.56086"
"269.40000","32.32614","0.56074"
"269.60000","32.35017","0.55965"
"269.80000","32.37416","0.55936"
"270.00000","32.39814","0.55866"
"270.20000","32.42211","0.55770"
"270.40000","32.44616","0.55736"
"270.60000","32.47027","0.55613"
"270.80000","32.49455","0.55523"
"271.00000","32.51822","0.55450"
"271.20000","32.54193","0.55307"
"271.40000","32.56610","0.55223"
"271.60000","32.59008","0.55094"
"271.80000","32.61417","0.54943"
"272.00000","32.63816","0.54817"
"272.20000","32.66212","0.54651"
"272.40000","32.68607","0.54463"
"272.60000","32.71006","0.54287"
"272.80000","32.73418","0.54087"
"273.00000","32.75825","0.53806"
"273.20000","32.78212","0.53539"
"273.40000","32.80600","0.48629"
"273.60000","32.83002","0.46943"
"273.80000","32.85406","0.46051"
"274.00000","32.87815","0.45272"
"274.20000","32.90210","0.44564"
"274.40000","32.92601","0.43947"
"274.60000","32.94994","0.43320"
"274.80000","32.97406","0.42744"
"275.00000","32.99813","0.42232"
"275.20000","33.02217","0.41606"
"275.40000","33.04613","0.41048"
"275.60000","33.07168","0.40472"
"275.80000","33.09395","0.39874"
"276.00000","33.11801","0.39397"
"276.20000","33.14222","0.38799"
"276.40000","33.16628","0.38269"
"276.60000","33.19028","0.37756"
"276.80000","33.21426","0.37217"
"277.00000","33.23829","0.36699"
"277.20000","33.26233","0.36174"
"277.40000","33.28635","0.35655"
"277.60000","33.31023","0.35090"
"277.80000","33.33416","0.34364"
"278.00000","33.35819","0.33609"
"278.20000","33.38212","0.32790"
"278.40000","33.40614","0.31977"
"278.60000","33.43020","0.31035"
"278.80000","33.45411","0.30009"
"279.00000","33.47802","0.28978"
"279.20000","33.50208","0.27688"
"279.40000","33.52614","0.25271"
"279.60000","33.55014","0.23805"
"279.80000","33.57417","0.22413"
"280.00000","33.59911","0.20224"
"280.20000","33.62199","0.16535"
"280.40000","33.64606","-0.00886"
"280.60000","33.67016","-0.02024"
"280.80000","33.69417","-0.02009"
"281.00000","33.71813","-0.01952"
"281.20000","33.74210","-0.01994"
"281.40000","33.76615","-0.01994"
"281.60000","33.79021","-0.02002"
"281.80000","33.81433","-0.02006"
"282.00000","33.83831","-0.02004"
"282.20000","33.86224","-0.01978"
"282.40000","33.88625","-0.02017"
"282.60000","33.91018","-0.01998"
"282.80000","33.93421","-0.02013"
"283.00000","33.95827","-0.02030"
"283.20000","33.98326","-0.02003"
"283.40000","34.00579","-0.01999"
"283.60000","34.03003","-0.02011"
"283.80000","34.05409","-0.02013"
"284.00000","34.07807","-0.02003"
"284.20000","34.10207","-0.02027"
"284.40000","34.12598","-0.01977"
"284.60000","34.15004","-0.02027"
"284.80000","34.17406","-0.02034"
"285.00000","34.19815","-0.01984"
"285.20000","34.22225","-0.02031"
"285.40000","34.24618","-0.02026"
"285.60000","34.27007","-0.02003"
"285.80000","34.29411","-0.02014"
"286.00000","34.31817","-0.02001"
"286.20000","34.34226","-0.01983"
"286.40000","34.36624","-0.02017"
"286.60000","34.39023","-0.01999"
"286.80000","34.41423","-0.01969"
"287.00000","34.43820","-0.02014"
"287.20000","34.46247","-0.01999"
"287.40000","34.48619","-0.01988"
"287.60000","34.51036","-0.02069"
"287.80000","34.53440","-0.01946"
"288.00000","34.55829","-0.01994"
"288.20000","34.58225","-0.02022"
"288.40000","34.60625","-0.01963"
"288.60000","34.63022","-0.01991"
"288.80000","34.65408","-0.01988"
"288.98000","34.67568","-0.01986"