File: 20G1650/ST 20G1650_0011.csv
Rate 1,"0.50000",mm/s
Start date,"9/7/2021"
Specimen label,""

Time,Extension,2 kg Beam Load Cell
(s),(mm),(N)
"0.00000","0.00127","-0.00066"
"0.07500","0.00127","0.00027"
"0.15000","0.02069","0.00038"
"0.22500","0.05381","0.00092"
"0.30000","0.09217","0.00150"
"0.37500","0.13220","0.00219"
"0.45000","0.17278","0.00313"
"0.52500","0.21401","0.00383"
"0.60000","0.25414","0.00449"
"0.67500","0.29442","0.00527"
"0.75000","0.33478","0.00611"
"0.82500","0.37488","0.00699"
"0.90000","0.41493","0.00756"
"0.97500","0.45466","0.00799"
"1.05000","0.49418","0.00892"
"1.12500","0.53356","0.00986"
"1.20000","0.57291","0.00981"
"1.27500","0.61291","0.00872"
"1.35000","0.65069","0.00892"
"1.42500","0.68905","0.00996"
"1.50000","0.72761","0.01123"
"1.57500","0.76621","0.01128"
"1.65000","0.80492","0.01215"
"1.72500","0.84346","0.01328"
"1.80000","0.88195","0.01377"
"1.87500","0.92015","0.01454"
"1.95000","0.95839","0.01531"
"2.02500","0.99676","0.01600"
"2.10000","1.03474","0.01682"
"2.17500","1.07285","0.01754"
"2.25000","1.11096","0.01812"
"2.32500","1.14895","0.01910"
"2.40000","1.18669","0.01985"
"2.47500","1.22438","0.01906"
"2.55000","1.26211","0.02023"
"2.62500","1.29988","0.02050"
"2.70000","1.33772","0.02153"
"2.77500","1.37541","0.02248"
"2.85000","1.41328","0.02277"
"2.92500","1.45229","0.02381"
"3.00000","1.48901","0.02466"
"3.07500","1.52637","0.02426"
"3.15000","1.56406","0.02505"
"3.22500","1.60173","0.02565"
"3.30000","1.63934","0.02675"
"3.37500","1.67700","0.02755"
"3.45000","1.71470","0.02802"
"3.52500","1.75235","0.02869"
"3.60000","1.78990","0.02966"
"3.67500","1.82848","0.03048"
"3.75000","1.86497","0.03098"
"3.82500","1.90232","0.03174"
"3.90000","1.93970","0.03262"
"3.97500","1.97721","0.03364"
"4.05000","2.01481","0.03347"
"4.12500","2.05235","0.03409"
"4.20000","2.08985","0.03476"
"4.27500","2.12733","0.03546"
"4.35000","2.16500","0.03659"
"4.42500","2.20258","0.03713"
"4.50000","2.24005","0.03783"
"4.57500","2.27764","0.03905"
"4.65000","2.31521","0.03932"
"4.72500","2.35288","0.04020"
"4.80000","2.39117","0.04132"
"4.87500","2.42810","0.04200"
"4.95000","2.46529","0.04190"
"5.02500","2.50253","0.04236"
"5.10000","2.53998","0.04333"
"5.17500","2.57748","0.04358"
"5.25000","2.61501","0.04414"
"5.32500","2.65256","0.04473"
"5.40000","2.69009","0.04583"
"5.47500","2.72763","0.04678"
"5.55000","2.76505","0.04736"
"5.62500","2.80265","0.04814"
"5.70000","2.84016","0.04906"
"5.77500","2.87762","0.05017"
"5.85000","2.91506","0.05049"
"5.92500","2.95260","0.05171"
"6.00000","2.99134","0.05260"
"6.07500","3.02838","0.05356"
"6.15000","3.06547","0.05440"
"6.22500","3.10286","0.05370"
"6.30000","3.14005","0.05473"
"6.37500","3.17758","0.05576"
"6.45000","3.21502","0.05623"
"6.52500","3.25249","0.05732"
"6.60000","3.28995","0.05812"
"6.67500","3.32732","0.05905"
"6.75000","3.36503","0.06014"
"6.82500","3.40251","0.06053"
"6.90000","3.44090","0.06162"
"6.97500","3.47791","0.06299"
"7.05000","3.51521","0.06330"
"7.12500","3.55273","0.06436"
"7.20000","3.59020","0.06388"
"7.27500","3.62774","0.06475"
"7.35000","3.66525","0.06557"
"7.42500","3.70269","0.06615"
"7.50000","3.74003","0.06737"
"7.57500","3.77762","0.06826"
"7.65000","3.81587","0.06896"
"7.72500","3.85299","0.06994"
"7.80000","3.89020","0.07077"
"7.87500","3.92768","0.07208"
"7.95000","3.96510","0.07274"
"8.02500","4.00250","0.07342"
"8.10000","4.04007","0.07453"
"8.17500","4.07761","0.07556"
"8.25000","4.11519","0.07655"
"8.32500","4.15259","0.07719"
"8.40000","4.19010","0.07714"
"8.47500","4.22758","0.07769"
"8.55000","4.26509","0.07876"
"8.62500","4.30261","0.07937"
"8.70000","4.34009","0.08052"
"8.77500","4.37762","0.08141"
"8.85000","4.41498","0.08254"
"8.92500","4.45234","0.08356"
"9.00000","4.48984","0.08409"
"9.07500","4.52749","0.08508"
"9.15000","4.56651","0.08553"
"9.22500","4.60316","0.08638"
"9.30000","4.64038","0.08685"
"9.37500","4.67785","0.08834"
"9.45000","4.71523","0.08913"
"9.52500","4.75292","0.09047"
"9.60000","4.79019","0.09113"
"9.67500","4.82752","0.09207"
"9.75000","4.86513","0.09229"
"9.82500","4.90268","0.09331"
"9.90000","4.94018","0.09416"
"9.97500","4.97851","0.09537"
"10.05000","5.01567","0.09613"
"10.12500","5.05277","0.09712"
"10.20000","5.09012","0.09849"
"10.27500","5.12768","0.09960"
"10.35000","5.16521","0.09968"
"10.42500","5.20273","0.10097"
"10.50000","5.24016","0.10184"
"10.57500","5.27772","0.10311"
"10.65000","5.31527","0.10424"
"10.72500","5.35285","0.10482"
"10.80000","5.39047","0.10619"
"10.87500","5.42782","0.10702"
"10.95000","5.46527","0.10814"
"11.02500","5.50274","0.10793"
"11.10000","5.54041","0.10918"
"11.17500","5.57909","0.11022"
"11.25000","5.61580","0.11113"
"11.32500","5.65293","0.11229"
"11.40000","5.69027","0.11317"
"11.47500","5.72758","0.11447"
"11.55000","5.76509","0.11554"
"11.62500","5.80266","0.11650"
"11.70000","5.84019","0.11658"
"11.77500","5.87776","0.11805"
"11.85000","5.91531","0.11894"
"11.92500","5.95311","0.11988"
"12.00000","5.99027","0.12125"
"12.07500","6.02776","0.12215"
"12.15000","6.06531","0.12337"
"12.22500","6.10283","0.12471"
"12.30000","6.14036","0.12549"
"12.37500","6.17780","0.12662"
"12.45000","6.21517","0.12635"
"12.52500","6.25262","0.12782"
"12.60000","6.29012","0.12868"
"12.67500","6.32753","0.12974"
"12.75000","6.36501","0.13105"
"12.82500","6.40256","0.13231"
"12.90000","6.44013","0.13343"
"12.97500","6.47770","0.13424"
"13.05000","6.51681","0.13491"
"13.12500","6.55331","0.13616"
"13.20000","6.59053","0.13731"
"13.27500","6.62788","0.13851"
"13.35000","6.66536","0.13928"
"13.42500","6.70288","0.14066"
"13.50000","6.74034","0.14170"
"13.57500","6.77805","0.14271"
"13.65000","6.81534","0.14366"
"13.72500","6.85279","0.14525"
"13.80000","6.89009","0.14625"
"13.87500","6.92746","0.14717"
"13.95000","6.96536","0.14778"
"14.02500","7.00271","0.14870"
"14.10000","7.04008","0.14984"
"14.17500","7.07769","0.15079"
"14.25000","7.11525","0.15216"
"14.32500","7.15281","0.15344"
"14.40000","7.19027","0.15451"
"14.47500","7.22784","0.15565"
"14.55000","7.26571","0.15678"
"14.62500","7.30323","0.15788"
"14.70000","7.34046","0.15916"
"14.77500","7.37790","0.16053"
"14.85000","7.41539","0.16046"
"14.92500","7.45278","0.16223"
"15.00000","7.49011","0.16329"
"15.07500","7.52750","0.16424"
"15.15000","7.56487","0.16567"
"15.22500","7.60228","0.16676"
"15.30000","7.63979","0.16821"
"15.37500","7.67740","0.16957"
"15.45000","7.71514","0.17083"
"15.52500","7.75284","0.17079"
"15.60000","7.79186","0.17252"
"15.67500","7.82850","0.17363"
"15.75000","7.86551","0.17473"
"15.82500","7.90292","0.17644"
"15.90000","7.94037","0.17750"
"15.97500","7.97787","0.17893"
"16.05000","8.01530","0.18024"
"16.12500","8.05282","0.18133"
"16.20000","8.09028","0.18300"
"16.27500","8.12779","0.18291"
"16.35000","8.16555","0.18430"
"16.42500","8.20261","0.18572"
"16.50000","8.24003","0.18693"
"16.57500","8.27758","0.18830"
"16.65000","8.31505","0.18966"
"16.72500","8.35247","0.19117"
"16.80000","8.39008","0.19235"
"16.87500","8.42762","0.19363"
"16.95000","8.46514","0.19494"
"17.02500","8.50266","0.19631"
"17.10000","8.54041","0.19660"
"17.17500","8.57779","0.19843"
"17.25000","8.61520","0.19942"
"17.32500","8.65263","0.20093"
"17.40000","8.69014","0.20260"
"17.47500","8.72769","0.20373"
"17.55000","8.76520","0.20512"
"17.62500","8.80297","0.20665"
"17.70000","8.84162","0.20788"
"17.77500","8.87826","0.20875"
"17.85000","8.91528","0.21018"
"17.92500","8.95272","0.21163"
"18.00000","8.99022","0.21313"
"18.07500","9.02774","0.21477"
"18.15000","9.06528","0.21581"
"18.22500","9.10284","0.21750"
"18.30000","9.14027","0.21892"
"18.37500","9.17796","0.22035"
"18.45000","9.21528","0.22178"
"18.52500","9.25268","0.22318"
"18.60000","9.29007","0.22423"
"18.67500","9.32747","0.22495"
"18.75000","9.36496","0.22638"
"18.82500","9.40259","0.22773"
"18.90000","9.44020","0.22946"
"18.97500","9.47832","0.23080"
"19.05000","9.51520","0.23236"
"19.12500","9.55266","0.23319"
"19.20000","9.59026","0.23474"
"19.27500","9.62770","0.23634"
"19.35000","9.66525","0.23765"
"19.42500","9.70277","0.23903"
"19.50000","9.74026","0.24048"
"19.57500","9.77774","0.24234"
"19.65000","9.81530","0.24231"
"19.72500","9.85261","0.24447"
"19.80000","9.89017","0.24519"
"19.87500","9.92784","0.24714"
"19.95000","9.96526","0.24907"
"20.02500","10.00262","0.25023"
"20.10000","10.04018","0.25178"
"20.17500","10.07768","0.25343"
"20.25000","10.11514","0.25495"
"20.32500","10.15288","0.25649"
"20.40000","10.19165","0.25802"
"20.47500","10.22874","0.25848"
"20.55000","10.26567","0.26002"
"20.62500","10.30290","0.26147"
"20.70000","10.34034","0.26323"
"20.77500","10.37775","0.26489"
"20.85000","10.41519","0.26646"
"20.92500","10.45280","0.26831"
"21.00000","10.49025","0.26972"
"21.07500","10.52764","0.27139"
"21.15000","10.56512","0.27325"
"21.22500","10.60256","0.27460"
"21.30000","10.64009","0.27589"
"21.37500","10.67763","0.27739"
"21.45000","10.71514","0.27870"
"21.52500","10.75323","0.28029"
"21.60000","10.79091","0.28232"
"21.67500","10.82794","0.28366"
"21.75000","10.86527","0.28513"
"21.82500","10.90274","0.28707"
"21.90000","10.94029","0.28865"
"21.97500","10.97770","0.28942"
"22.05000","11.01528","0.29116"
"22.12500","11.05273","0.29277"
"22.20000","11.09013","0.29419"
"22.27500","11.12764","0.29622"
"22.35000","11.16520","0.29759"
"22.42500","11.20269","0.29931"
"22.50000","11.24091","0.30113"
"22.57500","11.27788","0.30269"
"22.65000","11.31523","0.30434"
"22.72500","11.35273","0.30598"
"22.80000","11.39007","0.30680"
"22.87500","11.42752","0.30848"
"22.95000","11.46504","0.31016"
"23.02500","11.50284","0.31178"
"23.10000","11.54014","0.31350"
"23.17500","11.57756","0.31520"
"23.25000","11.61506","0.31681"
"23.32500","11.65271","0.31773"
"23.40000","11.69019","0.31925"
"23.47500","11.72769","0.32072"
"23.55000","11.76516","0.32294"
"23.62500","11.80267","0.32450"
"23.70000","11.84020","0.32579"
"23.77500","11.87774","0.32778"
"23.85000","11.91537","0.32972"
"23.92500","11.95300","0.33115"
"24.00000","11.99191","0.33263"
"24.07500","12.02853","0.33455"
"24.15000","12.06548","0.33628"
"24.22500","12.10269","0.33656"
"24.30000","12.14006","0.33816"
"24.37500","12.17749","0.33941"
"24.45000","12.21508","0.34164"
"24.52500","12.25263","0.34345"
"24.60000","12.29020","0.34487"
"24.67500","12.32794","0.34638"
"24.75000","12.36539","0.34776"
"24.82500","12.40282","0.34981"
"24.90000","12.44025","0.35095"
"24.97500","12.47782","0.35305"
"25.05000","12.51524","0.35479"
"25.12500","12.55279","0.35622"
"25.20000","12.59047","0.35832"
"25.27500","12.62894","0.35874"
"25.35000","12.66574","0.36065"
"25.42500","12.70271","0.36248"
"25.50000","12.74001","0.36423"
"25.57500","12.77742","0.36580"
"25.65000","12.81486","0.36756"
"25.72500","12.85241","0.36930"
"25.80000","12.89011","0.37105"
"25.87500","12.92764","0.37213"
"25.95000","12.96514","0.37361"
"26.02500","13.00272","0.37585"
"26.10000","13.04026","0.37722"
"26.17500","13.07774","0.37880"
"26.25000","13.11576","0.38073"
"26.32500","13.15306","0.38251"
"26.40000","13.19035","0.38421"
"26.47500","13.22782","0.38599"
"26.55000","13.26529","0.38649"
"26.62500","13.30277","0.38831"
"26.70000","13.34012","0.39004"
"26.77500","13.37755","0.39166"
"26.85000","13.41495","0.39341"
"26.92500","13.45240","0.39508"
"27.00000","13.48986","0.39715"
"27.07500","13.52747","0.39887"
"27.15000","13.56516","0.40029"
"27.22500","13.60278","0.40110"
"27.30000","13.64031","0.40295"
"27.37500","13.67795","0.40478"
"27.45000","13.71717","0.40648"
"27.52500","13.75346","0.40798"
"27.60000","13.79080","0.40994"
"27.67500","13.82800","0.41165"
"27.75000","13.86537","0.41357"
"27.82500","13.90283","0.41491"
"27.90000","13.94009","0.41638"
"27.97500","13.97756","0.41840"
"28.05000","14.01492","0.41975"
"28.12500","14.05237","0.42132"
"28.20000","14.08990","0.42299"
"28.27500","14.12747","0.42483"
"28.35000","14.16501","0.42656"
"28.42500","14.20253","0.42857"
"28.50000","14.24019","0.43019"
"28.57500","14.27778","0.43175"
"28.65000","14.31551","0.43356"
"28.72500","14.35321","0.43402"
"28.80000","14.39121","0.43602"
"28.87500","14.42821","0.43731"
"28.95000","14.46553","0.43938"
"29.02500","14.50301","0.44080"
"29.10000","14.54034","0.44259"
"29.17500","14.57779","0.44422"
"29.25000","14.61512","0.44539"
"29.32500","14.65259","0.44716"
"29.40000","14.69073","0.44869"
"29.47500","14.72861","0.45051"
"29.55000","14.76540","0.45194"
"29.62500","14.80277","0.45355"
"29.70000","14.84022","0.45549"
"29.77500","14.87784","0.45698"
"29.85000","14.91532","0.45864"
"29.92500","14.95292","0.46023"
"30.00000","14.99040","0.46210"
"30.07500","15.02794","0.46241"
"30.15000","15.06598","0.46405"
"30.22500","15.10306","0.46566"
"30.30000","15.14034","0.46745"
"30.37500","15.17778","0.46913"
"30.45000","15.21514","0.47073"
"30.52500","15.25256","0.47230"
"30.60000","15.29005","0.47405"
"30.67500","15.32744","0.47581"
"30.75000","15.36486","0.47734"
"30.82500","15.40248","0.47894"
"30.90000","15.44008","0.48016"
"30.97500","15.47830","0.48199"
"31.05000","15.51546","0.48190"
"31.12500","15.55288","0.48340"
"31.20000","15.59037","0.48450"
"31.27500","15.62791","0.48655"
"31.35000","15.66546","0.48835"
"31.42500","15.70291","0.48994"
"31.50000","15.74039","0.49123"
"31.57500","15.77822","0.49291"
"31.65000","15.81560","0.49491"
"31.72500","15.85287","0.49543"
"31.80000","15.89028","0.49698"
"31.87500","15.92765","0.49845"
"31.95000","15.96514","0.50040"
"32.02500","16.00253","0.50171"
"32.10000","16.03997","0.50311"
"32.17500","16.07801","0.50397"
"32.25000","16.11669","0.50577"
"32.32500","16.15322","0.50701"
"32.40000","16.19053","0.50833"
"32.47500","16.22791","0.50998"
"32.55000","16.26543","0.51192"
"32.62500","16.30283","0.51319"
"32.70000","16.34049","0.51470"
"32.77500","16.37799","0.51591"
"32.85000","16.41545","0.51740"
"32.92500","16.45294","0.51886"
"33.00000","16.49045","0.52027"
"33.07500","16.52768","0.52181"
"33.15000","16.56510","0.52370"
"33.22500","16.60263","0.52491"
"33.30000","16.64016","0.52581"
"33.37500","16.67763","0.52739"
"33.45000","16.71509","0.52878"
"33.52500","16.75256","0.53069"
"33.60000","16.79015","0.53219"
"33.67500","16.82802","0.53361"
"33.75000","16.86671","0.53479"
"33.82500","16.90322","0.53632"
"33.90000","16.94057","0.53786"
"33.97500","16.97805","0.53930"
"34.05000","17.01567","0.54095"
"34.12500","17.05312","0.54258"
"34.20000","17.09052","0.54398"
"34.27500","17.12796","0.54577"
"34.35000","17.16538","0.54631"
"34.42500","17.20283","0.54803"
"34.50000","17.24031","0.54931"
"34.57500","17.27775","0.55096"
"34.65000","17.31535","0.55253"
"34.72500","17.35278","0.55404"
"34.80000","17.39021","0.55525"
"34.87500","17.42772","0.55682"
"34.95000","17.46524","0.55836"
"35.02500","17.50288","0.55961"
"35.10000","17.54033","0.56110"
"35.17500","17.57778","0.56288"
"35.25000","17.61560","0.56416"
"35.32500","17.65340","0.56562"
"35.40000","17.69070","0.56600"
"35.47500","17.72788","0.56732"
"35.55000","17.76524","0.56878"
"35.62500","17.80279","0.57000"
"35.70000","17.84024","0.57146"
"35.77500","17.87776","0.57288"
"35.85000","17.91525","0.57439"
"35.92500","17.95274","0.57578"
"36.00000","17.99026","0.57676"
"36.07500","18.02769","0.57741"
"36.15000","18.06523","0.57917"
"36.22500","18.10311","0.58057"
"36.30000","18.14176","0.58174"
"36.37500","18.17832","0.58309"
"36.45000","18.21553","0.58472"
"36.52500","18.25295","0.58528"
"36.60000","18.29043","0.58677"
"36.67500","18.32786","0.58774"
"36.75000","18.36526","0.58889"
"36.82500","18.40271","0.59039"
"36.90000","18.44023","0.59168"
"36.97500","18.47789","0.59203"
"37.05000","18.51567","0.59391"
"37.12500","18.55271","0.59516"
"37.20000","18.59017","0.59641"
"37.27500","18.62780","0.59763"
"37.35000","18.66536","0.59894"
"37.42500","18.70277","0.60019"
"37.50000","18.74029","0.60113"
"37.57500","18.77786","0.60214"
"37.65000","18.81533","0.60347"
"37.72500","18.85296","0.60450"
"37.80000","18.89063","0.60581"
"37.87500","18.92842","0.60688"
"37.95000","18.96715","0.60829"
"38.02500","19.00336","0.60958"
"38.10000","19.04035","0.61110"
"38.17500","19.07764","0.61122"
"38.25000","19.11508","0.61257"
"38.32500","19.15263","0.61360"
"38.40000","19.19013","0.61463"
"38.47500","19.22783","0.61577"
"38.55000","19.26544","0.61722"
"38.62500","19.30286","0.61856"
"38.70000","19.34036","0.61998"
"38.77500","19.37778","0.62093"
"38.85000","19.41536","0.62202"
"38.92500","19.45308","0.62362"
"39.00000","19.49043","0.62423"
"39.07500","19.52784","0.62552"
"39.15000","19.56530","0.62652"
"39.22500","19.60271","0.62811"
"39.30000","19.64016","0.62942"
"39.37500","19.67772","0.63051"
"39.45000","19.71537","0.63190"
"39.52500","19.75278","0.63310"
"39.60000","19.79023","0.63448"
"39.67500","19.82772","0.63568"
"39.75000","19.86522","0.63699"
"39.82500","19.90278","0.63695"
"39.90000","19.94036","0.63791"
"39.97500","19.97804","0.63931"
"40.05000","20.01586","0.64051"
"40.12500","20.05439","0.64177"
"40.20000","20.09085","0.64291"
"40.27500","20.12815","0.64417"
"40.35000","20.16561","0.64528"
"40.42500","20.20312","0.64675"
"40.50000","20.24033","0.64779"
"40.57500","20.27765","0.64915"
"40.65000","20.31517","0.65061"
"40.72500","20.35266","0.65168"
"40.80000","20.39047","0.65282"
"40.87500","20.42788","0.65284"
"40.95000","20.46524","0.65424"
"41.02500","20.50272","0.65478"
"41.10000","20.54024","0.65628"
"41.17500","20.57771","0.65729"
"41.25000","20.61538","0.65849"
"41.32500","20.65291","0.65995"
"41.40000","20.69036","0.66108"
"41.47500","20.72781","0.66237"
"41.55000","20.76541","0.66334"
"41.62500","20.80338","0.66462"
"41.70000","20.84053","0.66449"
"41.77500","20.87850","0.66619"
"41.85000","20.91518","0.66675"
"41.92500","20.95259","0.66812"
"42.00000","20.99004","0.66971"
"42.07500","21.02760","0.67066"
"42.15000","21.06505","0.67183"
"42.22500","21.10259","0.67315"
"42.30000","21.14022","0.67474"
"42.37500","21.17788","0.67578"
"42.45000","21.21554","0.67692"
"42.52500","21.25313","0.67740"
"42.60000","21.29049","0.67800"
"42.67500","21.32786","0.67947"
"42.75000","21.36536","0.68050"
"42.82500","21.40287","0.68183"
"42.90000","21.44060","0.68276"
"42.97500","21.47760","0.68393"
"43.05000","21.51509","0.68484"
"43.12500","21.55261","0.68601"
"43.20000","21.59017","0.68731"
"43.27500","21.62769","0.68822"
"43.35000","21.66520","0.68864"
"43.42500","21.70269","0.68988"
"43.50000","21.74035","0.69072"
"43.57500","21.77797","0.69215"
"43.65000","21.81552","0.69325"
"43.72500","21.85320","0.69415"
"43.80000","21.89060","0.69548"
"43.87500","21.92795","0.69618"
"43.95000","21.96533","0.69737"
"44.02500","22.00290","0.69862"
"44.10000","22.04034","0.69968"
"44.17500","22.07774","0.70098"
"44.25000","22.11511","0.70245"
"44.32500","22.15258","0.70260"
"44.40000","22.19025","0.70333"
"44.47500","22.22810","0.70492"
"44.55000","22.26534","0.70625"
"44.62500","22.30274","0.70750"
"44.70000","22.34017","0.70787"
"44.77500","22.37758","0.70922"
"44.85000","22.41518","0.71053"
"44.92500","22.45294","0.71172"
"45.00000","22.49257","0.71236"
"45.07500","22.52845","0.71261"
"45.15000","22.56567","0.71423"
"45.22500","22.60297","0.71486"
"45.30000","22.64040","0.71647"
"45.37500","22.67777","0.71750"
"45.45000","22.71509","0.71878"
"45.52500","22.75255","0.71965"
"45.60000","22.78999","0.72068"
"45.67500","22.82767","0.72171"
"45.75000","22.86514","0.72250"
"45.82500","22.90251","0.72337"
"45.90000","22.94001","0.72317"
"45.97500","22.97750","0.72464"
"46.05000","23.01509","0.72568"
"46.12500","23.05258","0.72687"
"46.20000","23.09023","0.72803"
"46.27500","23.12819","0.72918"
"46.35000","23.16543","0.73014"
"46.42500","23.20284","0.73131"
"46.50000","23.24037","0.73172"
"46.57500","23.27790","0.73277"
"46.65000","23.31528","0.73404"
"46.72500","23.35262","0.73503"
"46.80000","23.39005","0.73592"
"46.87500","23.42751","0.73737"
"46.95000","23.46552","0.73743"
"47.02500","23.50264","0.73803"
"47.10000","23.54022","0.73932"
"47.17500","23.57764","0.74050"
"47.25000","23.61497","0.74154"
"47.32500","23.65249","0.74253"
"47.40000","23.69000","0.74366"
"47.47500","23.72778","0.74430"
"47.55000","23.76544","0.74539"
"47.62500","23.80297","0.74592"
"47.70000","23.84052","0.74667"
"47.77500","23.87789","0.74777"
"47.85000","23.91523","0.74812"
"47.92500","23.95272","0.74928"
"48.00000","23.99020","0.75027"
"48.07500","24.02764","0.75149"
"48.15000","24.06513","0.75267"
"48.22500","24.10316","0.75371"
"48.30000","24.14033","0.75451"
"48.37500","24.17863","0.75550"
"48.45000","24.21501","0.75654"
"48.52500","24.25238","0.75656"
"48.60000","24.28975","0.75771"
"48.67500","24.32738","0.75870"
"48.75000","24.36508","0.75979"
"48.82500","24.40296","0.76094"
"48.90000","24.44063","0.76181"
"48.97500","24.47817","0.76254"
"49.05000","24.51568","0.76367"
"49.12500","24.55304","0.76449"
"49.20000","24.59052","0.76531"
"49.27500","24.62802","0.76594"
"49.35000","24.66529","0.76722"
"49.42500","24.70263","0.76835"
"49.50000","24.74008","0.76912"
"49.57500","24.77750","0.76907"
"49.65000","24.81483","0.77005"
"49.72500","24.85232","0.77143"
"49.80000","24.88987","0.77273"
"49.87500","24.92744","0.77345"
"49.95000","24.96534","0.77452"
"50.02500","25.00349","0.77536"
"50.10000","25.04047","0.77614"
"50.17500","25.07798","0.77694"
"50.25000","25.11552","0.77770"
"50.32500","25.15334","0.77857"
"50.40000","25.19074","0.77921"
"50.47500","25.22798","0.78000"
"50.55000","25.26544","0.78055"
"50.62500","25.30282","0.78158"
"50.70000","25.34014","0.78207"
"50.77500","25.37754","0.78288"
"50.85000","25.41494","0.78387"
"50.92500","25.45238","0.78461"
"51.00000","25.49053","0.78547"
"51.07500","25.52766","0.78635"
"51.15000","25.56516","0.78712"
"51.22500","25.60254","0.78814"
"51.30000","25.64012","0.78904"
"51.37500","25.67785","0.78965"
"51.45000","25.71554","0.79048"
"51.52500","25.75311","0.79164"
"51.60000","25.79070","0.79255"
"51.67500","25.82811","0.79333"
"51.75000","25.86558","0.79413"
"51.82500","25.90298","0.79463"
"51.90000","25.94049","0.79514"
"51.97500","25.97778","0.79583"
"52.05000","26.01601","0.79655"
"52.12500","26.05295","0.79747"
"52.20000","26.09020","0.79770"
"52.27500","26.12746","0.79771"
"52.35000","26.16498","0.79850"
"52.42500","26.20239","0.79927"
"52.50000","26.23983","0.80010"
"52.57500","26.27776","0.80067"
"52.65000","26.31678","0.80144"
"52.72500","26.35376","0.80132"
"52.80000","26.39075","0.80240"
"52.87500","26.42798","0.80263"
"52.95000","26.46546","0.80338"
"53.02500","26.50291","0.80392"
"53.10000","26.54032","0.80496"
"53.17500","26.57766","0.80565"
"53.25000","26.61532","0.80621"
"53.32500","26.65273","0.80643"
"53.40000","26.69034","0.80739"
"53.47500","26.72745","0.80779"
"53.55000","26.76485","0.80845"
"53.62500","26.80236","0.80916"
"53.70000","26.83989","0.81017"
"53.77500","26.87757","0.81032"
"53.85000","26.91551","0.81045"
"53.92500","26.95329","0.81088"
"54.00000","26.99054","0.81152"
"54.07500","27.02815","0.81224"
"54.15000","27.06572","0.81240"
"54.22500","27.10327","0.81280"
"54.30000","27.14069","0.81292"
"54.37500","27.17808","0.81335"
"54.45000","27.21580","0.81372"
"54.52500","27.25275","0.81391"
"54.60000","27.29012","0.81480"
"54.67500","27.32767","0.81514"
"54.75000","27.36520","0.81531"
"54.82500","27.40260","0.81571"
"54.90000","27.44001","0.81596"
"54.97500","27.47752","0.81607"
"55.05000","27.51511","0.81634"
"55.12500","27.55270","0.81653"
"55.20000","27.59034","0.81683"
"55.27500","27.62807","0.81730"
"55.35000","27.66573","0.81728"
"55.42500","27.70424","0.81702"
"55.50000","27.74206","0.81748"
"55.57500","27.77840","0.81831"
"55.65000","27.81549","0.81808"
"55.72500","27.85276","0.81842"
"55.80000","27.89013","0.81807"
"55.87500","27.92751","0.81715"
"55.95000","27.96492","0.81714"
"56.02500","28.00237","0.81639"
"56.10000","28.03997","0.81681"
"56.17500","28.07777","0.81714"
"56.25000","28.11509","0.81713"
"56.32500","28.15245","0.81643"
"56.40000","28.19003","0.81679"
"56.47500","28.22770","0.81691"
"56.55000","28.26557","0.81728"
"56.62500","28.30333","0.81740"
"56.70000","28.34064","0.81759"
"56.77500","28.37816","0.81766"
"56.85000","28.41560","0.81809"
"56.92500","28.45298","0.81765"
"57.00000","28.49021","0.81751"
"57.07500","28.52754","0.81781"
"57.15000","28.56538","0.81842"
"57.22500","28.60258","0.81806"
"57.30000","28.64001","0.81823"
"57.37500","28.67752","0.81777"
"57.45000","28.71502","0.81832"
"57.52500","28.75250","0.81859"
"57.60000","28.79016","0.81824"
"57.67500","28.82779","0.81870"
"57.75000","28.86563","0.81865"
"57.82500","28.90332","0.81855"
"57.90000","28.94117","0.81880"
"57.97500","28.97841","0.81883"
"58.05000","29.01680","0.81931"
"58.12500","29.05330","0.81931"
"58.20000","29.09027","0.81963"
"58.27500","29.12759","0.81992"
"58.35000","29.16502","0.82034"
"58.42500","29.20245","0.82048"
"58.50000","29.24001","0.81963"
"58.57500","29.27756","0.81992"
"58.65000","29.31596","0.81996"
"58.72500","29.35255","0.82014"
"58.80000","29.39008","0.82059"
"58.87500","29.42772","0.82076"
"58.95000","29.46535","0.82103"
"59.02500","29.50302","0.82043"
"59.10000","29.54074","0.82046"
"59.17500","29.57829","0.82056"
"59.25000","29.61538","0.82076"
"59.32500","29.65296","0.82079"
"59.40000","29.69053","0.82048"
"59.47500","29.72768","0.82053"
"59.55000","29.76502","0.82088"
"59.62500","29.80240","0.82049"
"59.70000","29.83985","0.81969"
"59.77500","29.87750","0.81995"
"59.85000","29.91509","0.81977"
"59.92500","29.95251","0.81963"
"60.00000","29.99009","0.81912"
"60.07500","30.02764","0.81860"
"60.15000","30.06523","0.81857"
"60.22500","30.10270","0.81796"
"60.30000","30.14034","0.81582"
"60.37500","30.17914","0.81378"
"60.45000","30.21703","0.81287"
"60.52500","30.25342","0.81212"
"60.60000","30.29066","0.81088"
"60.67500","30.32783","0.80903"
"60.75000","30.36520","0.80848"
"60.82500","30.40256","0.80692"
"60.90000","30.44001","0.80657"
"60.97500","30.47768","0.80553"
"61.05000","30.51519","0.80488"
"61.12500","30.55236","0.80449"
"61.20000","30.58984","0.80364"
"61.27500","30.62746","0.80286"
"61.35000","30.66511","0.80241"
"61.42500","30.70263","0.80174"
"61.50000","30.74033","0.80035"
"61.57500","30.77813","0.79986"
"61.65000","30.81561","0.79912"
"61.72500","30.85305","0.79884"
"61.80000","30.89045","0.79822"
"61.87500","30.92785","0.79795"
"61.95000","30.96523","0.79688"
"62.02500","31.00264","0.79676"
"62.10000","31.04012","0.79566"
"62.17500","31.07751","0.79486"
"62.25000","31.11518","0.79423"
"62.32500","31.15277","0.79375"
"62.40000","31.19007","0.79369"
"62.47500","31.22883","0.79293"
"62.55000","31.26523","0.79268"
"62.62500","31.30245","0.79207"
"62.70000","31.33994","0.79166"
"62.77500","31.37751","0.79139"
"62.85000","31.41540","0.79074"
"62.92500","31.45284","0.78994"
"63.00000","31.49041","0.78981"
"63.07500","31.52798","0.78925"
"63.15000","31.56549","0.78904"
"63.22500","31.60289","0.78894"
"63.30000","31.64025","0.78849"
"63.37500","31.67769","0.78831"
"63.45000","31.71508","0.78715"
"63.52500","31.75261","0.78697"
"63.60000","31.79096","0.78674"
"63.67500","31.82748","0.78662"
"63.75000","31.86481","0.78620"
"63.82500","31.90229","0.78583"
"63.90000","31.93995","0.78570"
"63.97500","31.97767","0.78572"
"64.05000","32.01540","0.78539"
"64.12500","32.05303","0.78525"
"64.20000","32.09087","0.78511"
"64.27500","32.12821","0.78517"
"64.35000","32.16568","0.78472"
"64.42500","32.20308","0.78411"
"64.50000","32.24052","0.78402"
"64.57500","32.27789","0.78396"
"64.65000","32.31525","0.78422"
"64.72500","32.35293","0.78372"
"64.80000","32.39196","0.78244"
"64.87500","32.42812","0.78249"
"64.95000","32.46523","0.78265"
"65.02500","32.50279","0.78235"
"65.10000","32.54026","0.78203"
"65.17500","32.57771","0.78229"
"65.25000","32.61538","0.78255"
"65.32500","32.65291","0.78214"
"65.40000","32.69043","0.78231"
"65.47500","32.72807","0.78238"
"65.55000","32.76570","0.78226"
"65.62500","32.80323","0.78279"
"65.70000","32.84063","0.78287"
"65.77500","32.87790","0.78243"
"65.85000","32.91523","0.78273"
"65.92500","32.95382","0.78300"
"66.00000","32.99038","0.78302"
"66.07500","33.02759","0.78359"
"66.15000","33.06499","0.78410"
"66.22500","33.10259","0.78408"
"66.30000","33.14018","0.78460"
"66.37500","33.17775","0.78486"
"66.45000","33.21523","0.78507"
"66.52500","33.25298","0.78544"
"66.60000","33.29053","0.78559"
"66.67500","33.32808","0.78615"
"66.75000","33.36562","0.78627"
"66.82500","33.40321","0.78702"
"66.90000","33.44064","0.78759"
"66.97500","33.47804","0.78785"
"67.05000","33.51543","0.78834"
"67.12500","33.55285","0.78789"
"67.20000","33.59022","0.78893"
"67.27500","33.62812","0.78917"
"67.35000","33.66541","0.78967"
"67.42500","33.70279","0.79004"
"67.50000","33.74010","0.79018"
"67.57500","33.77763","0.79071"
"67.65000","33.81522","0.79032"
"67.72500","33.85282","0.79071"
"67.80000","33.89096","0.79085"
"67.87500","33.92935","0.79143"
"67.95000","33.96593","0.79195"
"68.02500","34.00319","0.79226"
"68.10000","34.04065","0.79264"
"68.17500","34.07804","0.79330"
"68.25000","34.11545","0.79388"
"68.32500","34.15298","0.79437"
"68.40000","34.19041","0.79382"
"68.47500","34.22776","0.79441"
"68.55000","34.26512","0.79498"
"68.62500","34.30260","0.79570"
"68.70000","34.34005","0.79647"
"68.77500","34.37764","0.79694"
"68.85000","34.41525","0.79751"
"68.92500","34.45296","0.79764"
"69.00000","34.49084","0.79809"
"69.07500","34.52813","0.79877"
"69.15000","34.56546","0.79935"
"69.22500","34.60286","0.80036"
"69.30000","34.64055","0.80070"
"69.37500","34.67796","0.80140"
"69.45000","34.71538","0.80206"
"69.52500","34.75287","0.80306"
"69.60000","34.79032","0.80385"
"69.67500","34.82801","0.80430"
"69.75000","34.86547","0.80471"
"69.82500","34.90275","0.80501"
"69.90000","34.94014","0.80576"
"69.97500","34.97768","0.80630"
"70.05000","35.01514","0.80717"
"70.12500","35.05266","0.80804"
"70.20000","35.09020","0.80907"
"70.27500","35.12774","0.80894"
"70.35000","35.16535","0.80988"
"70.42500","35.20293","0.81054"
"70.50000","35.24057","0.81129"
"70.57500","35.27830","0.81212"
"70.65000","35.31722","0.81273"
"70.72500","35.35403","0.81348"
"70.80000","35.39079","0.81383"
"70.87500","35.42800","0.81478"
"70.95000","35.46530","0.81505"
"71.02500","35.50281","0.81577"
"71.10000","35.54019","0.81575"
"71.17500","35.57754","0.81567"
"71.25000","35.61508","0.81644"
"71.32500","35.65279","0.81671"
"71.40000","35.69022","0.81692"
"71.47500","35.72781","0.81732"
"71.55000","35.76564","0.81716"
"71.62500","35.80376","0.81465"
"71.70000","35.84074","0.81524"
"71.77500","35.87793","0.81579"
"71.85000","35.91536","0.81571"
"71.92500","35.95288","0.81670"
"72.00000","35.99046","0.81702"
"72.07500","36.02806","0.81772"
"72.15000","36.06559","0.81857"
"72.22500","36.10289","0.81913"
"72.30000","36.14033","0.81963"
"72.37500","36.17778","0.81930"
"72.45000","36.21524","0.82004"
"72.52500","36.25274","0.82073"
"72.60000","36.29026","0.82133"
"72.67500","36.32803","0.82153"
"72.75000","36.36551","0.82201"
"72.82500","36.40290","0.82278"
"72.90000","36.44044","0.82304"
"72.97500","36.47791","0.82321"
"73.05000","36.51548","0.82298"
"73.12500","36.55298","0.82380"
"73.20000","36.59044","0.82421"
"73.27500","36.62808","0.82451"
"73.35000","36.66613","0.82520"
"73.42500","36.70402","0.82606"
"73.50000","36.74068","0.82664"
"73.57500","36.77786","0.82704"
"73.65000","36.81525","0.82684"
"73.72500","36.85265","0.82738"
"73.80000","36.89002","0.82795"
"73.87500","36.92749","0.82871"
"73.95000","36.96503","0.82913"
"74.02500","37.00293","0.82951"
"74.10000","37.04037","0.83006"
"74.17500","37.07766","0.83023"
"74.25000","37.11524","0.83082"
"74.32500","37.15284","0.83109"
"74.40000","37.19035","0.83196"
"74.47500","37.22791","0.83276"
"74.55000","37.26540","0.83224"
"74.62500","37.30289","0.83297"
"74.70000","37.34039","0.83364"
"74.77500","37.37941","0.83400"
"74.85000","37.41600","0.83449"
"74.92500","37.45303","0.83491"
"75.00000","37.49022","0.83553"
"75.07500","37.52764","0.83630"
"75.15000","37.56510","0.83662"
"75.22500","37.60264","0.83562"
"75.30000","37.64016","0.83646"
"75.37500","37.67765","0.83673"
"75.45000","37.71519","0.83738"
"75.52500","37.75367","0.83778"
"75.60000","37.79089","0.83764"
"75.67500","37.82787","0.83788"
"75.75000","37.86519","0.83856"
"75.82500","37.90262","0.83879"
"75.90000","37.94012","0.83904"
"75.97500","37.97781","0.83941"
"76.05000","38.01540","0.83979"
"76.12500","38.05282","0.84008"
"76.20000","38.09025","0.83997"
"76.27500","38.12776","0.84050"
"76.35000","38.16516","0.84075"
"76.42500","38.20267","0.83992"
"76.50000","38.24022","0.83972"
"76.57500","38.27785","0.83994"
"76.65000","38.31560","0.83997"
"76.72500","38.35427","0.84023"
"76.80000","38.39143","0.83999"
"76.87500","38.42815","0.83968"
"76.95000","38.46536","0.83987"
"77.02500","38.50261","0.83994"
"77.10000","38.53999","0.83993"
"77.17500","38.57745","0.83952"
"77.25000","38.61502","0.83947"
"77.32500","38.65257","0.83882"
"77.40000","38.69010","0.83844"
"77.47500","38.72758","0.83774"
"77.55000","38.76509","0.83753"
"77.62500","38.80296","0.83759"
"77.70000","38.83987","0.83715"
"77.77500","38.87729","0.83646"
"77.85000","38.91486","0.83548"
"77.92500","38.95263","0.83480"
"78.00000","38.99039","0.83412"
"78.07500","39.02888","0.83332"
"78.15000","39.06572","0.83232"
"78.22500","39.10294","0.83163"
"78.30000","39.14034","0.83098"
"78.37500","39.17774","0.82912"
"78.45000","39.21525","0.82782"
"78.52500","39.25277","0.82683"
"78.60000","39.29021","0.82514"
"78.67500","39.32774","0.82368"
"78.75000","39.36519","0.82124"
"78.82500","39.40263","0.81899"
"78.90000","39.44016","0.81707"
"78.97500","39.47761","0.81433"
"79.05000","39.51544","0.78377"
"79.12500","39.55416","0.74668"
"79.20000","39.59054","0.73462"
"79.27500","39.62780","0.72338"
"79.35000","39.66514","0.71458"
"79.42500","39.70265","0.70664"
"79.50000","39.74012","0.69921"
"79.57500","39.77767","0.69165"
"79.65000","39.81516","0.68345"
"79.72500","39.85265","0.67509"
"79.80000","39.89021","0.65477"
"79.87500","39.92761","0.64625"
"79.95000","39.96546","0.62050"
"80.02500","40.00299","0.58192"
"80.10000","40.03997","0.56171"
"80.17500","40.07762","0.54200"
"80.25000","40.11502","0.51837"
"80.32500","40.15257","0.49476"
"80.40000","40.19028","0.45853"
"80.47500","40.22820","0.37612"
"80.55000","40.26543","0.36110"
"80.62500","40.30288","0.34212"
"80.70000","40.34029","0.31826"
"80.77500","40.37775","0.22492"
"80.85000","40.41514","-0.02758"
"80.92500","40.45259","-0.01731"
"81.00000","40.49025","-0.01765"
"81.07500","40.52793","-0.01833"
"81.15000","40.56729","-0.01821"
"81.22500","40.60343","-0.01779"
"81.30000","40.64033","-0.01738"
"81.37500","40.67760","-0.01745"
"81.45000","40.71498","-0.01757"
"81.52500","40.75251","-0.01814"
"81.60000","40.79013","-0.01763"
"81.67500","40.82763","-0.01773"
"81.75000","40.86528","-0.01798"
"81.82500","40.90277","-0.01754"
"81.90000","40.94027","-0.01744"
"81.97500","40.97777","-0.01751"
"82.05000","41.01518","-0.01755"
"82.12500","41.05259","-0.01763"
"82.20000","41.09009","-0.01746"
"82.27500","41.12762","-0.01743"
"82.35000","41.16536","-0.01749"
"82.42500","41.20300","-0.01763"
"82.50000","41.24025","-0.01861"
"82.57500","41.27784","-0.01793"
"82.65000","41.31511","-0.01812"
"82.72500","41.35269","-0.01780"
"82.80000","41.38998","-0.01777"
"82.87500","41.42773","-0.01762"
"82.95000","41.46617","-0.01767"
"83.02500","41.50280","-0.01774"
"83.10000","41.54010","-0.01756"
"83.17500","41.57742","-0.01734"
"83.25000","41.61494","-0.01746"
"83.32500","41.65231","-0.01715"
"83.40000","41.69009","-0.01698"
"83.47500","41.72753","-0.01713"
"83.55000","41.76514","-0.01707"
"83.62500","41.80264","-0.01737"
"83.70000","41.84017","-0.01715"
"83.77500","41.87782","-0.01708"
"83.85000","41.91563","-0.01687"
"83.92500","41.95380","-0.01704"
"84.00000","41.99041","-0.01663"
"84.07500","42.02765","-0.01675"
"84.15000","42.06508","-0.01653"
"84.22500","42.10247","-0.01698"
"84.30000","42.14016","-0.01895"
"84.37500","42.17757","-0.01854"
"84.45000","42.21513","-0.01884"
"84.52500","42.25264","-0.01852"
"84.60000","42.29019","-0.01805"
"84.67500","42.32756","-0.01827"
"84.75000","42.36506","-0.01841"
"84.82500","42.40253","-0.01827"
"84.90000","42.44022","-0.01789"
"84.97500","42.47774","-0.01784"
"85.05000","42.51509","-0.01785"
"85.12500","42.55263","-0.01781"
"85.20000","42.58997","-0.01784"
"85.27500","42.62749","-0.01760"
"85.35000","42.66491","-0.01762"
"85.42500","42.70244","-0.01751"
"85.50000","42.74000","-0.01728"
"85.57500","42.77765","-0.01723"
"85.65000","42.81667","-0.01808"
"85.72500","42.85343","-0.01769"
"85.80000","42.89037","-0.01760"
"85.87500","42.92752","-0.01740"
"85.95000","42.96488","-0.01753"
"86.02500","43.00248","-0.01756"
"86.10000","43.04006","-0.01735"
"86.17500","43.07766","-0.01700"
"86.25000","43.11512","-0.01728"
"86.32500","43.15267","-0.01706"
"86.40000","43.19012","-0.01718"
"86.47500","43.22759","-0.01690"
"86.55000","43.26516","-0.01675"
"86.62500","43.30251","-0.01698"
"86.70000","43.34007","-0.01848"
"86.77500","43.37768","-0.01901"
"86.85000","43.41516","-0.01865"
"86.92500","43.45272","-0.01877"
"86.97500","43.47779","-0.01826"