File: 10G1652/ST 10G1652_0074.csv
Rate 1,"1.60000",mm/s
Start date,"9/25/2021"
Specimen label,""

Time,Extension,2 kg Beam Load Cell
(s),(mm),(N)
"0.00000","0.00127","0.00020"
"0.02500","0.00127","0.00038"
"0.05000","0.00185","0.00183"
"0.07500","0.01034","0.00137"
"0.10000","0.02767","0.00132"
"0.12500","0.05122","0.00144"
"0.15000","0.07989","0.00088"
"0.17500","0.11160","0.00126"
"0.20000","0.14598","0.00136"
"0.22500","0.18235","0.00139"
"0.25000","0.21977","0.00173"
"0.27500","0.25824","0.00196"
"0.30000","0.29782","0.00227"
"0.32500","0.33821","0.00203"
"0.35000","0.37948","0.00236"
"0.37500","0.42141","0.00268"
"0.40000","0.46312","0.00310"
"0.42500","0.50500","0.00329"
"0.45000","0.54714","0.00336"
"0.47500","0.58961","0.00367"
"0.50000","0.63211","0.00421"
"0.52500","0.67461","0.00431"
"0.55000","0.71724","0.00454"
"0.57500","0.75997","0.00473"
"0.60000","0.80288","0.00517"
"0.62500","0.84585","0.00511"
"0.65000","0.88904","0.00557"
"0.67500","0.93209","0.00617"
"0.70000","0.97451","0.00604"
"0.72500","1.01676","0.00635"
"0.75000","1.05907","0.00671"
"0.77500","1.10158","0.00693"
"0.80000","1.14436","0.00731"
"0.82500","1.18720","0.00731"
"0.85000","1.22985","0.00793"
"0.87500","1.27234","0.00803"
"0.90000","1.31477","0.00859"
"0.92500","1.35720","0.00864"
"0.95000","1.39971","0.00862"
"0.97500","1.44224","0.00938"
"1.00000","1.48493","0.00925"
"1.02500","1.52783","0.00972"
"1.05000","1.57048","0.00989"
"1.07500","1.61259","0.01069"
"1.10000","1.65478","0.01060"
"1.12500","1.69704","0.01084"
"1.15000","1.73923","0.01127"
"1.17500","1.78145","0.01125"
"1.20000","1.82369","0.01194"
"1.22500","1.86582","0.01173"
"1.25000","1.90791","0.01231"
"1.27500","1.95001","0.01268"
"1.30000","1.99236","0.01282"
"1.32500","2.03454","0.01321"
"1.35000","2.07670","0.01359"
"1.37500","2.11863","0.01360"
"1.40000","2.16046","0.01402"
"1.42500","2.20222","0.01418"
"1.45000","2.24391","0.01480"
"1.47500","2.28557","0.01500"
"1.50000","2.32718","0.01528"
"1.52500","2.36884","0.01561"
"1.55000","2.41043","0.01536"
"1.57500","2.45191","0.01616"
"1.60000","2.49343","0.01616"
"1.62500","2.53510","0.01660"
"1.65000","2.57674","0.01692"
"1.67500","2.61852","0.01729"
"1.70000","2.66048","0.01755"
"1.72500","2.70165","0.01785"
"1.75000","2.74288","0.01841"
"1.77500","2.78481","0.01830"
"1.80000","2.82668","0.01842"
"1.82500","2.86807","0.01889"
"1.85000","2.90950","0.01965"
"1.87500","2.95097","0.01989"
"1.90000","2.99239","0.02022"
"1.92500","3.03372","0.02006"
"1.95000","3.07479","0.02051"
"1.97500","3.11569","0.02069"
"2.00000","3.15638","0.02120"
"2.02500","3.19703","0.02126"
"2.05000","3.23764","0.02188"
"2.07500","3.27825","0.02199"
"2.10000","3.31889","0.02232"
"2.12500","3.36005","0.02265"
"2.15000","3.40108","0.02263"
"2.17500","3.44137","0.02335"
"2.20000","3.48151","0.02359"
"2.22500","3.52175","0.02373"
"2.25000","3.56206","0.02433"
"2.27500","3.60249","0.02426"
"2.30000","3.64300","0.02471"
"2.32500","3.68331","0.02497"
"2.35000","3.72337","0.02545"
"2.37500","3.76334","0.02536"
"2.40000","3.80336","0.02571"
"2.42500","3.84338","0.02641"
"2.45000","3.88339","0.02646"
"2.47500","3.92377","0.02687"
"2.50000","3.96435","0.02695"
"2.52500","4.00425","0.02727"
"2.55000","4.04411","0.02792"
"2.57500","4.08402","0.02799"
"2.60000","4.12393","0.02848"
"2.62500","4.16388","0.02840"
"2.65000","4.20403","0.02909"
"2.67500","4.24410","0.02918"
"2.70000","4.28404","0.02934"
"2.72500","4.32387","0.02985"
"2.75000","4.36372","0.02992"
"2.77500","4.40366","0.03048"
"2.80000","4.44373","0.03084"
"2.82500","4.48361","0.03101"
"2.85000","4.52334","0.03144"
"2.87500","4.56314","0.03139"
"2.90000","4.60309","0.03194"
"2.92500","4.64298","0.03199"
"2.95000","4.68287","0.03261"
"2.97500","4.72286","0.03291"
"3.00000","4.76324","0.03282"
"3.02500","4.80311","0.03370"
"3.05000","4.84301","0.03359"
"3.07500","4.88302","0.03382"
"3.10000","4.92307","0.03425"
"3.12500","4.96302","0.03445"
"3.15000","5.00287","0.03506"
"3.17500","5.04259","0.03511"
"3.20000","5.08228","0.03551"
"3.22500","5.12203","0.03560"
"3.25000","5.16177","0.03588"
"3.27500","5.20156","0.03632"
"3.30000","5.24158","0.03633"
"3.32500","5.28176","0.03713"
"3.35000","5.32178","0.03705"
"3.37500","5.36199","0.03752"
"3.40000","5.40262","0.03778"
"3.42500","5.44265","0.03803"
"3.45000","5.48253","0.03831"
"3.47500","5.52248","0.03847"
"3.50000","5.56247","0.03905"
"3.52500","5.60237","0.03909"
"3.55000","5.64222","0.03976"
"3.57500","5.68211","0.03980"
"3.60000","5.72190","0.03985"
"3.62500","5.76172","0.04036"
"3.65000","5.80192","0.04055"
"3.67500","5.84220","0.04081"
"3.70000","5.88215","0.04127"
"3.72500","5.92209","0.04142"
"3.75000","5.96219","0.04190"
"3.77500","6.00242","0.04204"
"3.80000","6.04265","0.04234"
"3.82500","6.08294","0.04268"
"3.85000","6.12323","0.04269"
"3.87500","6.16347","0.04321"
"3.90000","6.20364","0.04343"
"3.92500","6.24377","0.04380"
"3.95000","6.28445","0.04397"
"3.97500","6.32546","0.04414"
"4.00000","6.36521","0.04470"
"4.02500","6.40475","0.04480"
"4.05000","6.44457","0.04508"
"4.07500","6.48454","0.04542"
"4.10000","6.52459","0.04584"
"4.12500","6.56476","0.04587"
"4.15000","6.60488","0.04652"
"4.17500","6.64494","0.04656"
"4.20000","6.68514","0.04640"
"4.22500","6.72547","0.04700"
"4.25000","6.76572","0.04731"
"4.27500","6.80581","0.04749"
"4.30000","6.84581","0.04793"
"4.32500","6.88574","0.04822"
"4.35000","6.92575","0.04816"
"4.37500","6.96586","0.04878"
"4.40000","7.00602","0.04909"
"4.42500","7.04592","0.04935"
"4.45000","7.08567","0.04943"
"4.47500","7.12550","0.04972"
"4.50000","7.16549","0.04995"
"4.52500","7.20564","0.05015"
"4.55000","7.24599","0.05071"
"4.57500","7.28625","0.05083"
"4.60000","7.32642","0.05104"
"4.62500","7.36655","0.05126"
"4.65000","7.40703","0.05141"
"4.67500","7.44802","0.05176"
"4.70000","7.48828","0.05204"
"4.72500","7.52789","0.05248"
"4.75000","7.56752","0.05245"
"4.77500","7.60736","0.05294"
"4.80000","7.64732","0.05307"
"4.82500","7.68722","0.05321"
"4.85000","7.72701","0.05372"
"4.87500","7.76702","0.05389"
"4.90000","7.80708","0.05424"
"4.92500","7.84705","0.05444"
"4.95000","7.88705","0.05450"
"4.97500","7.92713","0.05491"
"5.00000","7.96731","0.05529"
"5.02500","8.00744","0.05527"
"5.05000","8.04782","0.05559"
"5.07500","8.08850","0.05597"
"5.10000","8.12842","0.05623"
"5.12500","8.16815","0.05654"
"5.15000","8.20800","0.05677"
"5.17500","8.24792","0.05696"
"5.20000","8.28791","0.05723"
"5.22500","8.32782","0.05751"
"5.25000","8.36772","0.05766"
"5.27500","8.40765","0.05791"
"5.30000","8.44767","0.05822"
"5.32500","8.48799","0.05841"
"5.35000","8.52804","0.05864"
"5.37500","8.56796","0.05891"
"5.40000","8.60798","0.05925"
"5.42500","8.64805","0.05919"
"5.45000","8.68816","0.05966"
"5.47500","8.72830","0.05978"
"5.50000","8.76849","0.06003"
"5.52500","8.80859","0.06036"
"5.55000","8.84890","0.06061"
"5.57500","8.88966","0.06061"
"5.60000","8.93008","0.06099"
"5.62500","8.96969","0.06119"
"5.65000","9.00932","0.06133"
"5.67500","9.04908","0.06175"
"5.70000","9.08908","0.06194"
"5.72500","9.12914","0.06207"
"5.75000","9.16911","0.06257"
"5.77500","9.20909","0.06261"
"5.80000","9.24908","0.06289"
"5.82500","9.28908","0.06314"
"5.85000","9.32910","0.06331"
"5.87500","9.36915","0.06338"
"5.90000","9.40919","0.06362"
"5.92500","9.44912","0.06391"
"5.95000","9.48895","0.06413"
"5.97500","9.52894","0.06446"
"6.00000","9.56892","0.06463"
"6.02500","9.60928","0.06473"
"6.05000","9.64978","0.06502"
"6.07500","9.68953","0.06560"
"6.10000","9.72916","0.06513"
"6.12500","9.76886","0.06551"
"6.15000","9.80878","0.06584"
"6.17500","9.84904","0.06613"
"6.20000","9.88917","0.06610"
"6.22500","9.92916","0.06642"
"6.25000","9.96915","0.06668"
"6.27500","10.00916","0.06662"
"6.30000","10.04916","0.06718"
"6.32500","10.08902","0.06704"
"6.35000","10.12892","0.06742"
"6.37500","10.16886","0.06745"
"6.40000","10.20922","0.06769"
"6.42500","10.24938","0.06804"
"6.45000","10.28942","0.06826"
"6.47500","10.33011","0.06830"
"6.50000","10.37045","0.06846"
"6.52500","10.40999","0.06868"
"6.55000","10.44953","0.06900"
"6.57500","10.48931","0.06896"
"6.60000","10.52935","0.06916"
"6.62500","10.56957","0.06956"
"6.65000","10.60980","0.06947"
"6.67500","10.64995","0.06990"
"6.70000","10.69002","0.06974"
"6.72500","10.72991","0.07018"
"6.75000","10.76964","0.07035"
"6.77500","10.80943","0.07046"
"6.80000","10.84934","0.07072"
"6.82500","10.88931","0.07079"
"6.85000","10.92944","0.07093"
"6.87500","10.96973","0.07091"
"6.90000","11.01010","0.07135"
"6.92500","11.05034","0.07130"
"6.95000","11.08995","0.07151"
"6.97500","11.12965","0.07183"
"7.00000","11.16957","0.07184"
"7.02500","11.20955","0.07208"
"7.05000","11.24962","0.07213"
"7.07500","11.28965","0.07211"
"7.10000","11.32952","0.07237"
"7.12500","11.36933","0.07258"
"7.15000","11.40920","0.07285"
"7.17500","11.44913","0.07255"
"7.20000","11.48905","0.07302"
"7.22500","11.52897","0.07311"
"7.25000","11.56898","0.07284"
"7.27500","11.60938","0.07311"
"7.30000","11.64954","0.07320"
"7.32500","11.68962","0.07325"
"7.35000","11.72951","0.07341"
"7.37500","11.76944","0.07339"
"7.40000","11.80965","0.07364"
"7.42500","11.84975","0.07353"
"7.45000","11.88986","0.07379"
"7.47500","11.92982","0.07352"
"7.50000","11.96966","0.07391"
"7.52500","12.00942","0.07394"
"7.55000","12.04926","0.07365"
"7.57500","12.08918","0.07413"
"7.60000","12.12915","0.07403"
"7.62500","12.16932","0.07426"
"7.65000","12.20945","0.07407"
"7.67500","12.24930","0.07425"
"7.70000","12.28916","0.07438"
"7.72500","12.32917","0.07451"
"7.75000","12.36919","0.07470"
"7.77500","12.40920","0.07447"
"7.80000","12.44934","0.07461"
"7.82500","12.48970","0.07478"
"7.85000","12.52988","0.07457"
"7.87500","12.57049","0.07501"
"7.90000","12.61098","0.07513"
"7.92500","12.65054","0.07518"
"7.95000","12.69012","0.07505"
"7.97500","12.72988","0.07516"
"8.00000","12.76974","0.07532"
"8.02500","12.80958","0.07542"
"8.05000","12.84951","0.07553"
"8.07500","12.88943","0.07530"
"8.10000","12.92937","0.07549"
"8.12500","12.96952","0.07589"
"8.15000","13.00953","0.07553"
"8.17500","13.04947","0.07578"
"8.20000","13.08932","0.07596"
"8.22500","13.12918","0.07605"
"8.25000","13.16900","0.07608"
"8.27500","13.20890","0.07603"
"8.30000","13.24889","0.07635"
"8.32500","13.28899","0.07611"
"8.35000","13.32905","0.07639"
"8.37500","13.36894","0.07609"
"8.40000","13.40879","0.07615"
"8.42500","13.44878","0.07638"
"8.45000","13.48888","0.07619"
"8.47500","13.52909","0.07646"
"8.50000","13.56904","0.07615"
"8.52500","13.60904","0.07647"
"8.55000","13.64910","0.07610"
"8.57500","13.68912","0.07627"
"8.60000","13.72909","0.07633"
"8.62500","13.76899","0.07612"
"8.65000","13.80883","0.07629"
"8.67500","13.84865","0.07617"
"8.70000","13.88850","0.07609"
"8.72500","13.92837","0.07640"
"8.75000","13.96836","0.07589"
"8.77500","14.00850","0.07620"
"8.80000","14.04881","0.07626"
"8.82500","14.08888","0.07632"
"8.85000","14.12914","0.07619"
"8.87500","14.16957","0.07610"
"8.90000","14.20933","0.07641"
"8.92500","14.24903","0.07613"
"8.95000","14.28902","0.07617"
"8.97500","14.32910","0.07615"
"9.00000","14.36923","0.07594"
"9.02500","14.40905","0.07618"
"9.05000","14.44881","0.07609"
"9.07500","14.48861","0.07608"
"9.10000","14.52844","0.07622"
"9.12500","14.56831","0.07591"
"9.15000","14.60824","0.07600"
"9.17500","14.64819","0.07604"
"9.20000","14.68838","0.07617"
"9.22500","14.72860","0.07593"
"9.25000","14.76861","0.07586"
"9.27500","14.80850","0.07609"
"9.30000","14.84843","0.07571"
"9.32500","14.88838","0.07608"
"9.35000","14.92838","0.07585"
"9.37500","14.96840","0.07587"
"9.40000","15.00844","0.07619"
"9.42500","15.04840","0.07591"
"9.45000","15.08849","0.07585"
"9.47500","15.12858","0.07575"
"9.50000","15.16893","0.07590"
"9.52500","15.20900","0.07596"
"9.55000","15.24852","0.07589"
"9.57500","15.28824","0.07614"
"9.60000","15.32810","0.07580"
"9.62500","15.36798","0.07587"
"9.65000","15.40797","0.07585"
"9.67500","15.44804","0.07585"
"9.70000","15.48819","0.07599"
"9.72500","15.52833","0.07582"
"9.75000","15.56844","0.07597"
"9.77500","15.60844","0.07590"
"9.80000","15.64841","0.07608"
"9.82500","15.68837","0.07586"
"9.85000","15.72827","0.07564"
"9.87500","15.76814","0.07602"
"9.90000","15.80841","0.07565"
"9.92500","15.84838","0.07569"
"9.95000","15.88803","0.07566"
"9.97500","15.92766","0.07580"
"10.00000","15.96744","0.07575"
"10.02500","16.00734","0.07567"
"10.05000","16.04756","0.07570"
"10.07500","16.08793","0.07580"
"10.10000","16.12807","0.07577"
"10.12500","16.16820","0.07563"
"10.15000","16.20828","0.07555"
"10.17500","16.24831","0.07577"
"10.20000","16.28833","0.07558"
"10.22500","16.32834","0.07549"
"10.25000","16.36829","0.07582"
"10.27500","16.40809","0.07561"
"10.30000","16.44783","0.07557"
"10.32500","16.48755","0.07550"
"10.35000","16.52726","0.07573"
"10.37500","16.56700","0.07561"
"10.40000","16.60697","0.07556"
"10.42500","16.64709","0.07564"
"10.45000","16.68735","0.07544"
"10.47500","16.72784","0.07582"
"10.50000","16.76859","0.07549"
"10.52500","16.80911","0.07533"
"10.55000","16.84908","0.07576"
"10.57500","16.88890","0.07552"
"10.60000","16.92887","0.07562"
"10.62500","16.96887","0.07562"
"10.65000","17.00879","0.07558"
"10.67500","17.04860","0.07555"
"10.70000","17.08831","0.07554"
"10.72500","17.12815","0.07580"
"10.75000","17.16813","0.07561"
"10.77500","17.20802","0.07583"
"10.80000","17.24783","0.07561"
"10.82500","17.28770","0.07552"
"10.85000","17.32772","0.07582"
"10.87500","17.36785","0.07562"
"10.90000","17.40799","0.07576"
"10.92500","17.44828","0.07574"
"10.95000","17.48893","0.07580"
"10.97500","17.52928","0.07577"
"11.00000","17.56934","0.07539"
"11.02500","17.60919","0.07554"
"11.05000","17.64896","0.07560"
"11.07500","17.68886","0.07562"
"11.10000","17.72868","0.07557"
"11.12500","17.76842","0.07538"
"11.15000","17.80819","0.07564"
"11.17500","17.84803","0.07532"
"11.20000","17.88786","0.07516"
"11.22500","17.92768","0.07544"
"11.25000","17.96767","0.07540"
"11.27500","18.00786","0.07542"
"11.30000","18.04815","0.07535"
"11.32500","18.08839","0.07564"
"11.35000","18.12867","0.07556"
"11.37500","18.16891","0.07548"
"11.40000","18.20899","0.07565"
"11.42500","18.24914","0.07540"
"11.45000","18.28960","0.07590"
"11.47500","18.32954","0.07562"
"11.50000","18.36890","0.07560"
"11.52500","18.40851","0.07581"
"11.55000","18.44823","0.07574"
"11.57500","18.48796","0.07582"
"11.60000","18.52773","0.07576"
"11.62500","18.56762","0.07586"
"11.65000","18.60773","0.07607"
"11.67500","18.64788","0.07570"
"11.70000","18.68806","0.07623"
"11.72500","18.72836","0.07600"
"11.75000","18.76865","0.07602"
"11.77500","18.80879","0.07618"
"11.80000","18.84888","0.07593"
"11.82500","18.88884","0.07629"
"11.85000","18.92911","0.07618"
"11.87500","18.96903","0.07606"
"11.90000","19.00851","0.07625"
"11.92500","19.04819","0.07632"
"11.95000","19.08806","0.07607"
"11.97500","19.12789","0.07605"
"12.00000","19.16778","0.07630"
"12.02500","19.20773","0.07623"
"12.05000","19.24768","0.07602"
"12.07500","19.28760","0.07621"
"12.10000","19.32775","0.07600"
"12.12500","19.36811","0.07634"
"12.15000","19.40844","0.07613"
"12.17500","19.44892","0.07591"
"12.20000","19.48935","0.07612"
"12.22500","19.52960","0.07626"
"12.25000","19.56959","0.07632"
"12.27500","19.60904","0.07597"
"12.30000","19.64859","0.07649"
"12.32500","19.68833","0.07644"
"12.35000","19.72814","0.07630"
"12.37500","19.76795","0.07652"
"12.40000","19.80771","0.07647"
"12.42500","19.84787","0.07674"
"12.45000","19.88811","0.07664"
"12.47500","19.92834","0.07663"
"12.50000","19.96860","0.07663"
"12.52500","20.00852","0.07686"
"12.55000","20.04861","0.07701"
"12.57500","20.08873","0.07662"
"12.60000","20.12872","0.07708"
"12.62500","20.16871","0.07699"
"12.65000","20.20860","0.07696"
"12.67500","20.24835","0.07724"
"12.70000","20.28815","0.07715"
"12.72500","20.32800","0.07715"
"12.75000","20.36797","0.07730"
"12.77500","20.40802","0.07733"
"12.80000","20.44828","0.07745"
"12.82500","20.48825","0.07753"
"12.85000","20.52810","0.07781"
"12.87500","20.56888","0.07750"
"12.90000","20.60992","0.07781"
"12.92500","20.65015","0.07799"
"12.95000","20.68985","0.07765"
"12.97500","20.72968","0.07817"
"13.00000","20.76975","0.07784"
"13.02500","20.80962","0.07815"
"13.05000","20.84931","0.07815"
"13.07500","20.88905","0.07836"
"13.10000","20.92900","0.07839"
"13.12500","20.96904","0.07838"
"13.15000","21.00905","0.07873"
"13.17500","21.04874","0.07832"
"13.20000","21.08852","0.07890"
"13.22500","21.12851","0.07878"
"13.25000","21.16859","0.07864"
"13.27500","21.20877","0.07897"
"13.30000","21.24900","0.07896"
"13.32500","21.28909","0.07885"
"13.35000","21.32920","0.07880"
"13.37500","21.36931","0.07903"
"13.40000","21.40921","0.07903"
"13.42500","21.44883","0.07897"
"13.45000","21.48844","0.07913"
"13.47500","21.52810","0.07893"
"13.50000","21.56789","0.07922"
"13.52500","21.60781","0.07913"
"13.55000","21.64790","0.07908"
"13.57500","21.68788","0.07924"
"13.60000","21.72774","0.07949"
"13.62500","21.76765","0.07926"
"13.65000","21.80760","0.07918"
"13.67500","21.84757","0.07928"
"13.70000","21.88789","0.07911"
"13.72500","21.92822","0.07913"
"13.75000","21.96862","0.07924"
"13.77500","22.00903","0.07925"
"13.80000","22.04928","0.07934"
"13.82500","22.08999","0.07945"
"13.85000","22.12987","0.07919"
"13.87500","22.16920","0.07947"
"13.90000","22.20874","0.07949"
"13.92500","22.24858","0.07946"
"13.95000","22.28847","0.07960"
"13.97500","22.32826","0.07981"
"14.00000","22.36816","0.07975"
"14.02500","22.40815","0.07959"
"14.05000","22.44825","0.07969"
"14.07500","22.48842","0.07975"
"14.10000","22.52849","0.07959"
"14.12500","22.56851","0.07987"
"14.15000","22.60848","0.07979"
"14.17500","22.64843","0.08005"
"14.20000","22.68828","0.07997"
"14.22500","22.72808","0.08010"
"14.25000","22.76793","0.08008"
"14.27500","22.80758","0.08012"
"14.30000","22.84732","0.08015"
"14.32500","22.88717","0.07996"
"14.35000","22.92705","0.08014"
"14.37500","22.96696","0.08042"
"14.40000","23.00688","0.08004"
"14.42500","23.04758","0.08034"
"14.45000","23.08799","0.08023"
"14.47500","23.12857","0.08025"
"14.50000","23.16908","0.08033"
"14.52500","23.20896","0.08003"
"14.55000","23.24875","0.08040"
"14.57500","23.28878","0.08022"
"14.60000","23.32871","0.08016"
"14.62500","23.36849","0.08005"
"14.65000","23.40823","0.08021"
"14.67500","23.44810","0.08025"
"14.70000","23.48804","0.07997"
"14.72500","23.52793","0.08011"
"14.75000","23.56778","0.08004"
"14.77500","23.60762","0.08002"
"14.80000","23.64748","0.07989"
"14.82500","23.68741","0.07958"
"14.85000","23.72750","0.07974"
"14.87500","23.76756","0.07958"
"14.90000","23.80767","0.07951"
"14.92500","23.84802","0.07929"
"14.95000","23.88836","0.07930"
"14.97500","23.92841","0.07925"
"15.00000","23.96829","0.07874"
"15.02500","24.00818","0.07888"
"15.05000","24.04797","0.07858"
"15.07500","24.08774","0.07825"
"15.10000","24.12758","0.07822"
"15.12500","24.16750","0.07765"
"15.15000","24.20777","0.07745"
"15.17500","24.24814","0.07721"
"15.20000","24.28884","0.07680"
"15.22500","24.32902","0.07628"
"15.25000","24.36860","0.07572"
"15.27500","24.40839","0.07531"
"15.30000","24.44842","0.07441"
"15.32500","24.48869","0.07391"
"15.35000","24.52887","0.07323"
"15.37500","24.56878","0.07232"
"15.40000","24.60862","0.07152"
"15.42500","24.64850","0.07044"
"15.45000","24.68856","0.06923"
"15.47500","24.72861","0.06758"
"15.50000","24.76841","0.06611"
"15.52500","24.80816","0.06397"
"15.55000","24.84800","0.06087"
"15.57500","24.88792","0.05348"
"15.60000","24.92796","0.02636"
"15.62500","24.96810","-0.00750"
"15.65000","25.00826","-0.01574"
"15.67500","25.04835","-0.01466"
"15.70000","25.08854","-0.01337"
"15.72500","25.12916","-0.01311"
"15.75000","25.16972","-0.01297"
"15.77500","25.20959","-0.01301"
"15.80000","25.24915","-0.01294"
"15.82500","25.28877","-0.01325"
"15.85000","25.32855","-0.01320"
"15.87500","25.36838","-0.01304"
"15.90000","25.40824","-0.01322"
"15.92500","25.44809","-0.01294"
"15.95000","25.48809","-0.01306"
"15.97500","25.52822","-0.01335"
"16.00000","25.56862","-0.01328"
"16.02500","25.60877","-0.01312"
"16.05000","25.64864","-0.01306"
"16.07500","25.68883","-0.01325"
"16.10000","25.72925","-0.01317"
"16.12500","25.76968","-0.01312"
"16.15000","25.80992","-0.01320"
"16.17500","25.84981","-0.01291"
"16.20000","25.88942","-0.01332"
"16.22500","25.92906","-0.01327"
"16.25000","25.96873","-0.01322"
"16.27500","26.00855","-0.01312"
"16.30000","26.04856","-0.01322"
"16.32500","26.08885","-0.01295"
"16.35000","26.12862","-0.01314"
"16.37500","26.16833","-0.01317"
"16.40000","26.20821","-0.01322"
"16.42500","26.24819","-0.01316"
"16.45000","26.28816","-0.01320"
"16.47500","26.32814","-0.01318"
"16.50000","26.36814","-0.01306"
"16.52500","26.40810","-0.01325"
"16.55000","26.44803","-0.01305"
"16.57500","26.48816","-0.01355"
"16.60000","26.52881","-0.01311"
"16.62500","26.56902","-0.01303"
"16.65000","26.60911","-0.01317"
"16.67500","26.64938","-0.01323"
"16.70000","26.68924","-0.01303"
"16.72500","26.72880","-0.01298"
"16.75000","26.76851","-0.01318"
"16.77500","26.80833","-0.01326"
"16.80000","26.84826","-0.01322"
"16.82500","26.88853","-0.01316"
"16.85000","26.92864","-0.01311"
"16.87500","26.96856","-0.01297"
"16.90000","27.00849","-0.01311"
"16.92500","27.04847","-0.01307"
"16.95000","27.08853","-0.01313"
"16.97500","27.12853","-0.01334"
"17.00000","27.16854","-0.01318"
"17.02500","27.20850","-0.01327"
"17.05000","27.24835","-0.01312"
"17.07500","27.28815","-0.01308"
"17.10000","27.32807","-0.01302"
"17.12500","27.36800","-0.01333"
"17.15000","27.40796","-0.01302"
"17.17500","27.44805","-0.01325"
"17.20000","27.48816","-0.01326"
"17.22500","27.52835","-0.01314"
"17.25000","27.56862","-0.01307"
"17.27500","27.60941","-0.01324"
"17.30000","27.65013","-0.01306"
"17.32500","27.69021","-0.01313"
"17.35000","27.72996","-0.01319"
"17.37500","27.76970","-0.01330"
"17.40000","27.80951","-0.01313"
"17.42500","27.84951","-0.01320"
"17.45000","27.88941","-0.01324"
"17.47500","27.92926","-0.01303"
"17.50000","27.96925","-0.01334"
"17.52500","28.00933","-0.01294"
"17.55000","28.04924","-0.01336"
"17.57500","28.08907","-0.01331"
"17.60000","28.12890","-0.01322"
"17.62500","28.16887","-0.01304"
"17.65000","28.20903","-0.01302"
"17.67500","28.24910","-0.01320"
"17.70000","28.28962","-0.01299"
"17.72500","28.32994","-0.01336"
"17.75000","28.36964","-0.01321"
"17.77500","28.40931","-0.01310"
"17.80000","28.44909","-0.01315"
"17.82500","28.48898","-0.01310"
"17.85000","28.52902","-0.01308"
"17.87500","28.56908","-0.01306"
"17.90000","28.60898","-0.01306"
"17.92500","28.64881","-0.01305"
"17.95000","28.68872","-0.01335"
"17.97500","28.72879","-0.01317"
"18.00000","28.76888","-0.01314"
"18.02500","28.80889","-0.01301"
"18.05000","28.84895","-0.01348"
"18.07500","28.88924","-0.01377"
"18.10000","28.93021","-0.01288"
"18.12500","28.97085","-0.01257"
"18.15000","29.01057","-0.01312"
"18.17500","29.05000","-0.01305"
"18.20000","29.08959","-0.01345"
"18.22500","29.12952","-0.01317"
"18.25000","29.16943","-0.01306"
"18.27500","29.20919","-0.01318"
"18.30000","29.24895","-0.01307"
"18.32500","29.28893","-0.01359"
"18.35000","29.32937","-0.01322"
"18.37500","29.36912","-0.01275"
"18.40000","29.40872","-0.01300"
"18.42500","29.44849","-0.01354"
"18.45000","29.48853","-0.01331"
"18.47500","29.52856","-0.01324"
"18.50000","29.56849","-0.01290"
"18.52500","29.60846","-0.01312"
"18.55000","29.64858","-0.01312"
"18.57500","29.68870","-0.01312"
"18.60000","29.72879","-0.01318"
"18.62500","29.76877","-0.01288"
"18.65000","29.80864","-0.01333"
"18.67500","29.84851","-0.01303"
"18.70000","29.88903","-0.01306"
"18.72500","29.92967","-0.01297"
"18.75000","29.96935","-0.01311"
"18.77500","30.00896","-0.01309"
"18.80000","30.04884","-0.01345"
"18.82500","30.08888","-0.01310"
"18.85000","30.12892","-0.01305"
"18.87500","30.16887","-0.01312"
"18.90000","30.20884","-0.01301"
"18.92500","30.24878","-0.01304"
"18.95000","30.28872","-0.01314"
"18.97500","30.32866","-0.01304"
"19.00000","30.36861","-0.01306"
"19.02500","30.40922","-0.01339"
"19.05000","30.44946","-0.01315"
"19.07500","30.48891","-0.01304"
"19.10000","30.52839","-0.01308"
"19.12500","30.56804","-0.01297"
"19.15000","30.60784","-0.01323"
"19.17500","30.64785","-0.01293"
"19.20000","30.68796","-0.01336"
"19.22500","30.72813","-0.01303"
"19.25000","30.76828","-0.01302"
"19.27500","30.80824","-0.01317"
"19.30000","30.84862","-0.01294"
"19.32500","30.88944","-0.01340"
"19.35000","30.92936","-0.01291"
"19.37500","30.96896","-0.01298"
"19.40000","31.00863","-0.01321"
"19.42500","31.04835","-0.01305"
"19.45000","31.08816","-0.01317"
"19.47500","31.12821","-0.01307"
"19.50000","31.16881","-0.01311"
"19.52500","31.20920","-0.01293"
"19.55000","31.24901","-0.01306"
"19.57500","31.28873","-0.01325"
"19.60000","31.32847","-0.01307"
"19.62500","31.36838","-0.01322"
"19.65000","31.40844","-0.01306"
"19.67500","31.44826","-0.01305"
"19.70000","31.48810","-0.01307"
"19.72500","31.52805","-0.01307"
"19.75000","31.56807","-0.01309"
"19.77500","31.60808","-0.01309"
"19.80000","31.64809","-0.01318"
"19.82500","31.68838","-0.01284"
"19.85000","31.72824","-0.01290"
"19.87500","31.76790","-0.01345"
"19.90000","31.80768","-0.01307"
"19.92500","31.84754","-0.01308"
"19.95000","31.88759","-0.01319"
"19.97500","31.92780","-0.01302"
"20.00000","31.96866","-0.01325"
"20.02500","32.00927","-0.01296"
"20.05000","32.04900","-0.01292"
"20.07500","32.08857","-0.01292"
"20.10000","32.12830","-0.01298"
"20.12500","32.16823","-0.01317"
"20.15000","32.20817","-0.01301"
"20.17500","32.24805","-0.01336"
"20.20000","32.28798","-0.01271"
"20.22500","32.32790","-0.01291"
"20.25000","32.36770","-0.01295"
"20.27500","32.40761","-0.01314"
"20.30000","32.44767","-0.01324"
"20.32500","32.48782","-0.01286"
"20.35000","32.52835","-0.01319"
"20.37500","32.56847","-0.01296"
"20.40000","32.60802","-0.01313"
"20.42500","32.64774","-0.01281"
"20.45000","32.68774","-0.01301"
"20.47500","32.72771","-0.01325"
"20.49200","32.75489","-0.01310"