File: 10G1652/ST 10G1652_0024.csv
Rate 1,"0.50000",mm/s
Start date,"9/23/2021"
Specimen label,""

Time,Extension,2 kg Beam Load Cell
(s),(mm),(N)
"0.00000","0.00000","-0.00053"
"0.05000","0.00000","0.00015"
"0.10000","0.00574","-0.00025"
"0.15000","0.02192","-0.00031"
"0.20000","0.04256","-0.00022"
"0.25000","0.06643","-0.00026"
"0.30000","0.09259","-0.00006"
"0.35000","0.11970","0.00044"
"0.40000","0.14651","0.00042"
"0.45000","0.17364","0.00039"
"0.50000","0.20021","0.00058"
"0.55000","0.22716","0.00064"
"0.60000","0.25414","0.00120"
"0.65000","0.28105","0.00114"
"0.70000","0.30786","0.00130"
"0.75000","0.33458","0.00144"
"0.80000","0.36140","0.00165"
"0.85000","0.38804","0.00168"
"0.90000","0.41457","0.00207"
"0.95000","0.44126","0.00206"
"1.00000","0.46780","0.00228"
"1.05000","0.49394","0.00231"
"1.10000","0.52002","0.00246"
"1.15000","0.54608","0.00266"
"1.20000","0.57205","0.00313"
"1.25000","0.59794","0.00309"
"1.30000","0.62378","0.00347"
"1.35000","0.64964","0.00335"
"1.40000","0.67552","0.00362"
"1.45000","0.70141","0.00392"
"1.50000","0.72809","0.00409"
"1.55000","0.75361","0.00405"
"1.60000","0.77864","0.00432"
"1.65000","0.80423","0.00432"
"1.70000","0.82981","0.00437"
"1.75000","0.85535","0.00460"
"1.80000","0.88093","0.00501"
"1.85000","0.90647","0.00488"
"1.90000","0.93203","0.00517"
"1.95000","0.95761","0.00522"
"2.00000","0.98311","0.00531"
"2.05000","1.00857","0.00564"
"2.10000","1.03392","0.00596"
"2.15000","1.05925","0.00599"
"2.20000","1.08449","0.00608"
"2.25000","1.10976","0.00594"
"2.30000","1.13503","0.00642"
"2.35000","1.16017","0.00673"
"2.40000","1.18553","0.00685"
"2.45000","1.21085","0.00710"
"2.50000","1.23601","0.00706"
"2.55000","1.26105","0.00714"
"2.60000","1.28615","0.00727"
"2.65000","1.31122","0.00756"
"2.70000","1.33638","0.00779"
"2.75000","1.36153","0.00813"
"2.80000","1.38680","0.00807"
"2.85000","1.41199","0.00847"
"2.90000","1.43712","0.00843"
"2.95000","1.46235","0.00839"
"3.00000","1.48770","0.00873"
"3.05000","1.51300","0.00909"
"3.10000","1.53863","0.00894"
"3.15000","1.56357","0.00905"
"3.20000","1.58852","0.00942"
"3.25000","1.61365","0.00960"
"3.30000","1.63895","0.00971"
"3.35000","1.66368","0.01024"
"3.40000","1.68843","0.00973"
"3.45000","1.71351","0.01011"
"3.50000","1.73858","0.01026"
"3.55000","1.76359","0.01063"
"3.60000","1.78853","0.01060"
"3.65000","1.81341","0.01102"
"3.70000","1.83842","0.01091"
"3.75000","1.86337","0.01118"
"3.80000","1.88826","0.01136"
"3.85000","1.91329","0.01162"
"3.90000","1.93842","0.01179"
"3.95000","1.96344","0.01189"
"4.00000","1.98864","0.01162"
"4.05000","2.01424","0.01211"
"4.10000","2.03928","0.01229"
"4.15000","2.06390","0.01248"
"4.20000","2.08879","0.01278"
"4.25000","2.11380","0.01285"
"4.30000","2.13876","0.01278"
"4.35000","2.16369","0.01295"
"4.40000","2.18873","0.01326"
"4.45000","2.21381","0.01356"
"4.50000","2.23886","0.01376"
"4.55000","2.26397","0.01406"
"4.60000","2.28893","0.01375"
"4.65000","2.31398","0.01401"
"4.70000","2.33902","0.01409"
"4.75000","2.36404","0.01452"
"4.80000","2.38902","0.01472"
"4.85000","2.41400","0.01458"
"4.90000","2.43919","0.01498"
"4.95000","2.46439","0.01505"
"5.00000","2.48922","0.01530"
"5.05000","2.51397","0.01548"
"5.10000","2.53878","0.01568"
"5.15000","2.56378","0.01569"
"5.20000","2.58875","0.01590"
"5.25000","2.61369","0.01581"
"5.30000","2.63879","0.01614"
"5.35000","2.66375","0.01622"
"5.40000","2.68881","0.01666"
"5.45000","2.71461","0.01651"
"5.50000","2.73900","0.01686"
"5.55000","2.76378","0.01669"
"5.60000","2.78874","0.01699"
"5.65000","2.81381","0.01719"
"5.70000","2.83891","0.01764"
"5.75000","2.86409","0.01752"
"5.80000","2.88909","0.01799"
"5.85000","2.91404","0.01774"
"5.90000","2.93903","0.01815"
"5.95000","2.96405","0.01824"
"6.00000","2.98897","0.01832"
"6.05000","3.01415","0.01844"
"6.10000","3.03903","0.01869"
"6.15000","3.06393","0.01877"
"6.20000","3.08879","0.01908"
"6.25000","3.11377","0.01912"
"6.30000","3.13874","0.01926"
"6.35000","3.16367","0.01949"
"6.40000","3.18867","0.01976"
"6.45000","3.21362","0.01964"
"6.50000","3.23871","0.02004"
"6.55000","3.26365","0.02015"
"6.60000","3.28866","0.02019"
"6.65000","3.31382","0.02057"
"6.70000","3.33886","0.02059"
"6.75000","3.36395","0.02093"
"6.80000","3.38891","0.02086"
"6.85000","3.41383","0.02106"
"6.90000","3.43876","0.02106"
"6.95000","3.46382","0.02157"
"7.00000","3.48884","0.02148"
"7.05000","3.51380","0.02180"
"7.10000","3.53885","0.02202"
"7.15000","3.56388","0.02208"
"7.20000","3.58896","0.02222"
"7.25000","3.61404","0.02245"
"7.30000","3.63962","0.02237"
"7.35000","3.66523","0.02282"
"7.40000","3.68941","0.02291"
"7.45000","3.71413","0.02310"
"7.50000","3.73892","0.02312"
"7.55000","3.76384","0.02344"
"7.60000","3.78875","0.02327"
"7.65000","3.81372","0.02388"
"7.70000","3.83887","0.02371"
"7.75000","3.86380","0.02402"
"7.80000","3.88880","0.02427"
"7.85000","3.91376","0.02444"
"7.90000","3.93873","0.02451"
"7.95000","3.96373","0.02471"
"8.00000","3.98873","0.02444"
"8.05000","4.01373","0.02490"
"8.10000","4.03873","0.02506"
"8.15000","4.06389","0.02528"
"8.20000","4.08948","0.02561"
"8.25000","4.11414","0.02559"
"8.30000","4.13894","0.02555"
"8.35000","4.16390","0.02588"
"8.40000","4.18890","0.02599"
"8.45000","4.21402","0.02617"
"8.50000","4.23903","0.02638"
"8.55000","4.26404","0.02664"
"8.60000","4.28905","0.02657"
"8.65000","4.31413","0.02681"
"8.70000","4.33918","0.02703"
"8.75000","4.36417","0.02706"
"8.80000","4.38910","0.02739"
"8.85000","4.41409","0.02742"
"8.90000","4.43934","0.02736"
"8.95000","4.46445","0.02757"
"9.00000","4.48906","0.02776"
"9.05000","4.51397","0.02801"
"9.10000","4.53888","0.02834"
"9.15000","4.56381","0.02829"
"9.20000","4.58883","0.02850"
"9.25000","4.61382","0.02848"
"9.30000","4.63880","0.02881"
"9.35000","4.66377","0.02920"
"9.40000","4.68881","0.02955"
"9.45000","4.71396","0.02929"
"9.50000","4.73927","0.02949"
"9.55000","4.76482","0.02952"
"9.60000","4.78929","0.02961"
"9.65000","4.81405","0.02993"
"9.70000","4.83896","0.03032"
"9.75000","4.86409","0.03012"
"9.80000","4.88908","0.03046"
"9.85000","4.91404","0.03025"
"9.90000","4.93899","0.03055"
"9.95000","4.96400","0.03083"
"10.00000","4.98896","0.03107"
"10.05000","5.01394","0.03118"
"10.10000","5.03881","0.03147"
"10.15000","5.06385","0.03136"
"10.20000","5.08884","0.03181"
"10.25000","5.11380","0.03181"
"10.30000","5.13883","0.03215"
"10.35000","5.16434","0.03205"
"10.40000","5.18941","0.03243"
"10.45000","5.21425","0.03215"
"10.50000","5.23911","0.03270"
"10.55000","5.26394","0.03268"
"10.60000","5.28892","0.03304"
"10.65000","5.31387","0.03311"
"10.70000","5.33888","0.03328"
"10.75000","5.36377","0.03333"
"10.80000","5.38878","0.03377"
"10.85000","5.41389","0.03378"
"10.90000","5.43891","0.03385"
"10.95000","5.46392","0.03410"
"11.00000","5.48894","0.03412"
"11.05000","5.51400","0.03400"
"11.10000","5.53905","0.03443"
"11.15000","5.56403","0.03470"
"11.20000","5.58905","0.03492"
"11.25000","5.61409","0.03519"
"11.30000","5.63907","0.03506"
"11.35000","5.66399","0.03516"
"11.40000","5.68907","0.03523"
"11.45000","5.71411","0.03552"
"11.50000","5.74086","0.03584"
"11.55000","5.76464","0.03607"
"11.60000","5.78913","0.03588"
"11.65000","5.81388","0.03611"
"11.70000","5.83882","0.03638"
"11.75000","5.86383","0.03652"
"11.80000","5.88882","0.03665"
"11.85000","5.91381","0.03691"
"11.90000","5.93882","0.03659"
"11.95000","5.96391","0.03700"
"12.00000","5.98899","0.03703"
"12.05000","6.01391","0.03728"
"12.10000","6.03889","0.03744"
"12.15000","6.06411","0.03770"
"12.20000","6.08937","0.03739"
"12.25000","6.11415","0.03791"
"12.30000","6.13911","0.03778"
"12.35000","6.16411","0.03818"
"12.40000","6.18915","0.03833"
"12.45000","6.21420","0.03846"
"12.50000","6.23920","0.03806"
"12.55000","6.26421","0.03849"
"12.60000","6.28924","0.03832"
"12.65000","6.31411","0.03885"
"12.70000","6.33904","0.03915"
"12.75000","6.36385","0.03904"
"12.80000","6.38879","0.03923"
"12.85000","6.41372","0.03939"
"12.90000","6.43874","0.03936"
"12.95000","6.46381","0.03984"
"13.00000","6.48891","0.03993"
"13.05000","6.51405","0.03994"
"13.10000","6.53914","0.04004"
"13.15000","6.56411","0.04017"
"13.20000","6.58903","0.04030"
"13.25000","6.61398","0.04065"
"13.30000","6.63897","0.04070"
"13.35000","6.66392","0.04062"
"13.40000","6.68885","0.04101"
"13.45000","6.71389","0.04085"
"13.50000","6.73893","0.04108"
"13.55000","6.76395","0.04144"
"13.60000","6.78895","0.04152"
"13.65000","6.81401","0.04161"
"13.70000","6.83903","0.04176"
"13.75000","6.86401","0.04178"
"13.80000","6.88894","0.04194"
"13.85000","6.91390","0.04212"
"13.90000","6.93890","0.04236"
"13.95000","6.96406","0.04240"
"14.00000","6.98958","0.04270"
"14.05000","7.01551","0.04261"
"14.10000","7.03942","0.04305"
"14.15000","7.06413","0.04271"
"14.20000","7.08896","0.04293"
"14.25000","7.11382","0.04305"
"14.30000","7.13876","0.04344"
"14.35000","7.16382","0.04344"
"14.40000","7.18878","0.04372"
"14.45000","7.21381","0.04362"
"14.50000","7.23886","0.04401"
"14.55000","7.26410","0.04387"
"14.60000","7.28934","0.04424"
"14.65000","7.31419","0.04413"
"14.70000","7.33907","0.04456"
"14.75000","7.36402","0.04437"
"14.80000","7.38898","0.04463"
"14.85000","7.41394","0.04485"
"14.90000","7.43904","0.04520"
"14.95000","7.46414","0.04496"
"15.00000","7.48913","0.04527"
"15.05000","7.51405","0.04533"
"15.10000","7.53900","0.04553"
"15.15000","7.56399","0.04563"
"15.20000","7.58883","0.04569"
"15.25000","7.61376","0.04600"
"15.30000","7.63878","0.04599"
"15.35000","7.66382","0.04602"
"15.40000","7.68885","0.04645"
"15.45000","7.71394","0.04636"
"15.50000","7.74039","0.04665"
"15.55000","7.76440","0.04668"
"15.60000","7.78901","0.04667"
"15.65000","7.81392","0.04674"
"15.70000","7.83894","0.04710"
"15.75000","7.86390","0.04716"
"15.80000","7.88891","0.04728"
"15.85000","7.91404","0.04761"
"15.90000","7.93920","0.04736"
"15.95000","7.96412","0.04761"
"16.00000","7.98909","0.04766"
"16.05000","8.01410","0.04790"
"16.10000","8.03908","0.04792"
"16.15000","8.06399","0.04832"
"16.20000","8.08903","0.04812"
"16.25000","8.11396","0.04829"
"16.30000","8.13896","0.04818"
"16.35000","8.16384","0.04854"
"16.40000","8.18886","0.04864"
"16.45000","8.21383","0.04896"
"16.50000","8.23879","0.04855"
"16.55000","8.26379","0.04892"
"16.60000","8.28876","0.04854"
"16.65000","8.31378","0.04899"
"16.70000","8.33874","0.04932"
"16.75000","8.36370","0.04944"
"16.80000","8.38893","0.04939"
"16.85000","8.41386","0.04964"
"16.90000","8.43888","0.04957"
"16.95000","8.46388","0.04984"
"17.00000","8.48893","0.04991"
"17.05000","8.51395","0.05005"
"17.10000","8.53903","0.04993"
"17.15000","8.56413","0.05028"
"17.20000","8.58912","0.04994"
"17.25000","8.61410","0.05041"
"17.30000","8.63910","0.05068"
"17.35000","8.66413","0.05063"
"17.40000","8.68910","0.05045"
"17.45000","8.71427","0.05079"
"17.50000","8.73911","0.05059"
"17.55000","8.76412","0.05083"
"17.60000","8.78900","0.05105"
"17.65000","8.81383","0.05117"
"17.70000","8.83893","0.05123"
"17.75000","8.86391","0.05126"
"17.80000","8.88888","0.05122"
"17.85000","8.91380","0.05150"
"17.90000","8.93880","0.05156"
"17.95000","8.96387","0.05166"
"18.00000","8.98882","0.05193"
"18.05000","9.01384","0.05174"
"18.10000","9.03878","0.05203"
"18.15000","9.06378","0.05205"
"18.20000","9.08884","0.05228"
"18.25000","9.11390","0.05215"
"18.30000","9.13892","0.05247"
"18.35000","9.16397","0.05235"
"18.40000","9.18905","0.05250"
"18.45000","9.21416","0.05261"
"18.50000","9.23918","0.05264"
"18.55000","9.26423","0.05293"
"18.60000","9.28910","0.05320"
"18.65000","9.31406","0.05280"
"18.70000","9.33904","0.05320"
"18.75000","9.36400","0.05310"
"18.80000","9.38963","0.05331"
"18.85000","9.41440","0.05341"
"18.90000","9.43929","0.05362"
"18.95000","9.46472","0.05336"
"19.00000","9.49074","0.05382"
"19.05000","9.51446","0.05357"
"19.10000","9.53917","0.05398"
"19.15000","9.56404","0.05389"
"19.20000","9.58896","0.05399"
"19.25000","9.61386","0.05388"
"19.30000","9.63880","0.05429"
"19.35000","9.66377","0.05436"
"19.40000","9.68873","0.05440"
"19.45000","9.71373","0.05452"
"19.50000","9.73870","0.05445"
"19.55000","9.76383","0.05468"
"19.60000","9.78890","0.05491"
"19.65000","9.81403","0.05483"
"19.70000","9.83914","0.05490"
"19.75000","9.86421","0.05506"
"19.80000","9.88912","0.05502"
"19.85000","9.91405","0.05513"
"19.90000","9.93896","0.05533"
"19.95000","9.96386","0.05542"
"20.00000","9.98876","0.05546"
"20.05000","10.01371","0.05543"
"20.10000","10.03874","0.05554"
"20.15000","10.06384","0.05576"
"20.20000","10.08904","0.05578"
"20.25000","10.11407","0.05607"
"20.30000","10.13881","0.05598"
"20.35000","10.16370","0.05611"
"20.40000","10.18880","0.05607"
"20.45000","10.21380","0.05653"
"20.50000","10.23880","0.05648"
"20.55000","10.26374","0.05653"
"20.60000","10.28873","0.05665"
"20.65000","10.31371","0.05656"
"20.70000","10.33880","0.05652"
"20.75000","10.36396","0.05703"
"20.80000","10.38933","0.05697"
"20.85000","10.41410","0.05730"
"20.90000","10.43908","0.05698"
"20.95000","10.46398","0.05713"
"21.00000","10.48898","0.05724"
"21.05000","10.51403","0.05756"
"21.10000","10.53906","0.05758"
"21.15000","10.56408","0.05799"
"21.20000","10.58912","0.05755"
"21.25000","10.61448","0.05750"
"21.30000","10.63915","0.05773"
"21.35000","10.66382","0.05775"
"21.40000","10.68874","0.05801"
"21.45000","10.71372","0.05825"
"21.50000","10.73876","0.05805"
"21.55000","10.76370","0.05823"
"21.60000","10.78861","0.05830"
"21.65000","10.81361","0.05840"
"21.70000","10.83861","0.05861"
"21.75000","10.86366","0.05880"
"21.80000","10.88858","0.05852"
"21.85000","10.91362","0.05862"
"21.90000","10.93894","0.05882"
"21.95000","10.96405","0.05884"
"22.00000","10.99021","0.05920"
"22.05000","11.01498","0.05943"
"22.10000","11.03933","0.05904"
"22.15000","11.06429","0.05910"
"22.20000","11.08925","0.05923"
"22.25000","11.11428","0.05938"
"22.30000","11.13924","0.05954"
"22.35000","11.16421","0.05972"
"22.40000","11.18913","0.05958"
"22.45000","11.21406","0.05976"
"22.50000","11.23914","0.05980"
"22.55000","11.26411","0.05970"
"22.60000","11.28897","0.06011"
"22.65000","11.31386","0.05994"
"22.70000","11.33877","0.05996"
"22.75000","11.36366","0.06004"
"22.80000","11.38872","0.06032"
"22.85000","11.41369","0.06026"
"22.90000","11.43854","0.06083"
"22.95000","11.46350","0.06032"
"23.00000","11.48845","0.06048"
"23.05000","11.51373","0.06026"
"23.10000","11.53938","0.06050"
"23.15000","11.56396","0.06030"
"23.20000","11.58873","0.06106"
"23.25000","11.61370","0.06069"
"23.30000","11.63866","0.06092"
"23.35000","11.66383","0.06078"
"23.40000","11.68897","0.06089"
"23.45000","11.71418","0.06102"
"23.50000","11.73924","0.06114"
"23.55000","11.76440","0.06115"
"23.60000","11.78943","0.06121"
"23.65000","11.81435","0.06114"
"23.70000","11.83930","0.06122"
"23.75000","11.86428","0.06141"
"23.80000","11.89050","0.06144"
"23.85000","11.91467","0.06158"
"23.90000","11.93921","0.06168"
"23.95000","11.96401","0.06142"
"24.00000","11.98887","0.06178"
"24.05000","12.01376","0.06186"
"24.10000","12.03871","0.06198"
"24.15000","12.06360","0.06201"
"24.20000","12.08855","0.06197"
"24.25000","12.11359","0.06197"
"24.30000","12.13865","0.06195"
"24.35000","12.16367","0.06227"
"24.40000","12.18880","0.06219"
"24.45000","12.21393","0.06228"
"24.50000","12.23928","0.06226"
"24.55000","12.26414","0.06220"
"24.60000","12.28900","0.06235"
"24.65000","12.31394","0.06241"
"24.70000","12.33910","0.06231"
"24.75000","12.36423","0.06251"
"24.80000","12.38934","0.06238"
"24.85000","12.41436","0.06240"
"24.90000","12.43959","0.06248"
"24.95000","12.46458","0.06264"
"25.00000","12.48947","0.06250"
"25.05000","12.51436","0.06281"
"25.10000","12.53930","0.06249"
"25.15000","12.56419","0.06265"
"25.20000","12.58920","0.06263"
"25.25000","12.61412","0.06282"
"25.30000","12.63904","0.06283"
"25.35000","12.66389","0.06298"
"25.40000","12.68880","0.06267"
"25.45000","12.71382","0.06306"
"25.50000","12.73892","0.06283"
"25.55000","12.76444","0.06307"
"25.60000","12.79052","0.06285"
"25.65000","12.81422","0.06305"
"25.70000","12.83888","0.06284"
"25.75000","12.86377","0.06322"
"25.80000","12.88876","0.06337"
"25.85000","12.91387","0.06314"
"25.90000","12.93895","0.06327"
"25.95000","12.96414","0.06331"
"26.00000","12.98919","0.06310"
"26.05000","13.01421","0.06353"
"26.10000","13.03926","0.06341"
"26.15000","13.06522","0.06360"
"26.20000","13.08996","0.06353"
"26.25000","13.11445","0.06343"
"26.30000","13.13928","0.06358"
"26.35000","13.16416","0.06365"
"26.40000","13.18910","0.06358"
"26.45000","13.21407","0.06357"
"26.50000","13.23902","0.06377"
"26.55000","13.26396","0.06351"
"26.60000","13.28887","0.06362"
"26.65000","13.31391","0.06396"
"26.70000","13.33895","0.06377"
"26.75000","13.36403","0.06382"
"26.80000","13.38894","0.06398"
"26.85000","13.41400","0.06383"
"26.90000","13.43882","0.06411"
"26.95000","13.46373","0.06393"
"27.00000","13.48863","0.06410"
"27.05000","13.51363","0.06416"
"27.10000","13.53865","0.06424"
"27.15000","13.56371","0.06404"
"27.20000","13.58899","0.06463"
"27.25000","13.61426","0.06439"
"27.30000","13.63938","0.06440"
"27.35000","13.66465","0.06457"
"27.40000","13.68959","0.06441"
"27.45000","13.71443","0.06429"
"27.50000","13.73936","0.06473"
"27.55000","13.76432","0.06444"
"27.60000","13.78925","0.06472"
"27.65000","13.81417","0.06464"
"27.70000","13.83915","0.06479"
"27.75000","13.86420","0.06482"
"27.80000","13.88921","0.06491"
"27.85000","13.91412","0.06473"
"27.90000","13.93909","0.06505"
"27.95000","13.96412","0.06495"
"28.00000","13.98911","0.06484"
"28.05000","14.01387","0.06517"
"28.10000","14.03879","0.06498"
"28.15000","14.06370","0.06496"
"28.20000","14.08881","0.06520"
"28.25000","14.11375","0.06501"
"28.30000","14.13896","0.06507"
"28.35000","14.16379","0.06527"
"28.40000","14.18875","0.06520"
"28.45000","14.21387","0.06525"
"28.50000","14.23903","0.06532"
"28.55000","14.26417","0.06519"
"28.60000","14.28930","0.06511"
"28.65000","14.31444","0.06546"
"28.70000","14.33951","0.06548"
"28.75000","14.36454","0.06548"
"28.80000","14.38956","0.06552"
"28.85000","14.41453","0.06520"
"28.90000","14.43972","0.06524"
"28.95000","14.46468","0.06552"
"29.00000","14.48963","0.06554"
"29.05000","14.51480","0.06595"
"29.10000","14.54086","0.06553"
"29.15000","14.56446","0.06545"
"29.20000","14.58901","0.06516"
"29.25000","14.61383","0.06545"
"29.30000","14.63881","0.06547"
"29.35000","14.66372","0.06613"
"29.40000","14.68869","0.06573"
"29.45000","14.71367","0.06574"
"29.50000","14.73869","0.06560"
"29.55000","14.76365","0.06569"
"29.60000","14.78876","0.06589"
"29.65000","14.81388","0.06613"
"29.70000","14.83922","0.06597"
"29.75000","14.86410","0.06609"
"29.80000","14.88903","0.06585"
"29.85000","14.91412","0.06589"
"29.90000","14.93953","0.06609"
"29.95000","14.96469","0.06632"
"30.00000","14.98958","0.06615"
"30.05000","15.01443","0.06612"
"30.10000","15.03929","0.06604"
"30.15000","15.06424","0.06601"
"30.20000","15.08918","0.06611"
"30.25000","15.11418","0.06618"
"30.30000","15.13920","0.06631"
"30.35000","15.16402","0.06626"
"30.40000","15.18889","0.06615"
"30.45000","15.21381","0.06623"
"30.50000","15.23889","0.06618"
"30.55000","15.26531","0.06624"
"30.60000","15.28932","0.06632"
"30.65000","15.31382","0.06641"
"30.70000","15.33864","0.06612"
"30.75000","15.36372","0.06621"
"30.80000","15.38866","0.06647"
"30.85000","15.41369","0.06622"
"30.90000","15.43878","0.06649"
"30.95000","15.46379","0.06647"
"31.00000","15.48888","0.06662"
"31.05000","15.51403","0.06649"
"31.10000","15.53918","0.06681"
"31.15000","15.56437","0.06651"
"31.20000","15.58992","0.06675"
"31.25000","15.61472","0.06647"
"31.30000","15.63966","0.06631"
"31.35000","15.66458","0.06644"
"31.40000","15.68943","0.06664"
"31.45000","15.71440","0.06663"
"31.50000","15.73926","0.06681"
"31.55000","15.76413","0.06662"
"31.60000","15.78901","0.06678"
"31.65000","15.81392","0.06658"
"31.70000","15.83890","0.06696"
"31.75000","15.86395","0.06662"
"31.80000","15.88971","0.06705"
"31.85000","15.91426","0.06673"
"31.90000","15.93893","0.06699"
"31.95000","15.96386","0.06700"
"32.00000","15.98877","0.06695"
"32.05000","16.01371","0.06708"
"32.10000","16.03883","0.06716"
"32.15000","16.06393","0.06696"
"32.20000","16.08890","0.06720"
"32.25000","16.11390","0.06717"
"32.30000","16.13900","0.06710"
"32.35000","16.16416","0.06724"
"32.40000","16.18934","0.06736"
"32.45000","16.21452","0.06710"
"32.50000","16.24008","0.06729"
"32.55000","16.26491","0.06731"
"32.60000","16.28985","0.06720"
"32.65000","16.31459","0.06731"
"32.70000","16.34124","0.06734"
"32.75000","16.36526","0.06727"
"32.80000","16.38943","0.06732"
"32.85000","16.41410","0.06735"
"32.90000","16.43896","0.06757"
"32.95000","16.46392","0.06772"
"33.00000","16.48890","0.06750"
"33.05000","16.51386","0.06757"
"33.10000","16.53881","0.06757"
"33.15000","16.56380","0.06759"
"33.20000","16.58885","0.06750"
"33.25000","16.61388","0.06776"
"33.30000","16.63895","0.06760"
"33.35000","16.66384","0.06776"
"33.40000","16.68888","0.06773"
"33.45000","16.71402","0.06782"
"33.50000","16.73901","0.06765"
"33.55000","16.76406","0.06789"
"33.60000","16.78920","0.06755"
"33.65000","16.81429","0.06765"
"33.70000","16.83996","0.06754"
"33.75000","16.86489","0.06770"
"33.80000","16.88958","0.06793"
"33.85000","16.91423","0.06780"
"33.90000","16.93914","0.06740"
"33.95000","16.96405","0.06797"
"34.00000","16.98908","0.06773"
"34.05000","17.01402","0.06781"
"34.10000","17.03886","0.06794"
"34.15000","17.06365","0.06794"
"34.20000","17.08858","0.06793"
"34.25000","17.11363","0.06785"
"34.30000","17.13868","0.06787"
"34.35000","17.16366","0.06811"
"34.40000","17.18870","0.06793"
"34.45000","17.21374","0.06799"
"34.50000","17.23874","0.06807"
"34.55000","17.26381","0.06820"
"34.60000","17.29029","0.06807"
"34.65000","17.31428","0.06804"
"34.70000","17.33888","0.06783"
"34.75000","17.36389","0.06799"
"34.80000","17.38886","0.06804"
"34.85000","17.41391","0.06826"
"34.90000","17.43897","0.06797"
"34.95000","17.46427","0.06839"
"35.00000","17.48937","0.06815"
"35.05000","17.51437","0.06794"
"35.10000","17.53941","0.06827"
"35.15000","17.56449","0.06830"
"35.20000","17.58947","0.06844"
"35.25000","17.61445","0.06838"
"35.30000","17.63929","0.06827"
"35.35000","17.66417","0.06816"
"35.40000","17.68906","0.06829"
"35.45000","17.71394","0.06839"
"35.50000","17.73876","0.06844"
"35.55000","17.76382","0.06848"
"35.60000","17.78888","0.06843"
"35.65000","17.81408","0.06823"
"35.70000","17.83884","0.06863"
"35.75000","17.86372","0.06846"
"35.80000","17.88868","0.06886"
"35.85000","17.91370","0.06842"
"35.90000","17.93873","0.06825"
"35.95000","17.96377","0.06832"
"36.00000","17.98889","0.06853"
"36.05000","18.01402","0.06844"
"36.10000","18.04004","0.06886"
"36.15000","18.06612","0.06841"
"36.20000","18.09005","0.06846"
"36.25000","18.11451","0.06858"
"36.30000","18.13942","0.06864"
"36.35000","18.16438","0.06851"
"36.40000","18.18930","0.06881"
"36.45000","18.21422","0.06865"
"36.50000","18.23915","0.06873"
"36.55000","18.26398","0.06868"
"36.60000","18.28890","0.06884"
"36.65000","18.31380","0.06889"
"36.70000","18.33889","0.06904"
"36.75000","18.36400","0.06885"
"36.80000","18.38895","0.06870"
"36.85000","18.41382","0.06889"
"36.90000","18.43873","0.06870"
"36.95000","18.46368","0.06896"
"37.00000","18.48864","0.06913"
"37.05000","18.51361","0.06883"
"37.10000","18.53873","0.06916"
"37.15000","18.56403","0.06894"
"37.20000","18.58883","0.06912"
"37.25000","18.61372","0.06926"
"37.30000","18.63879","0.06903"
"37.35000","18.66402","0.06917"
"37.40000","18.68896","0.06909"
"37.45000","18.71395","0.06934"
"37.50000","18.73907","0.06935"
"37.55000","18.76418","0.06954"
"37.60000","18.78946","0.06925"
"37.65000","18.81437","0.06921"
"37.70000","18.83934","0.06923"
"37.75000","18.86432","0.06931"
"37.80000","18.88928","0.06940"
"37.85000","18.91420","0.06961"
"37.90000","18.93917","0.06928"
"37.95000","18.96406","0.06937"
"38.00000","18.98907","0.06910"
"38.05000","19.01493","0.06919"
"38.10000","19.03993","0.06948"
"38.15000","19.06405","0.06979"
"38.20000","19.08887","0.06948"
"38.25000","19.11370","0.06960"
"38.30000","19.13862","0.06931"
"38.35000","19.16343","0.06931"
"38.40000","19.18864","0.06947"
"38.45000","19.21360","0.06972"
"38.50000","19.23869","0.06962"
"38.55000","19.26388","0.06985"
"38.60000","19.28908","0.06947"
"38.65000","19.31408","0.06958"
"38.70000","19.33908","0.06941"
"38.75000","19.36414","0.06957"
"38.80000","19.38933","0.06952"
"38.85000","19.41448","0.06994"
"38.90000","19.43960","0.06968"
"38.95000","19.46444","0.06963"
"39.00000","19.48944","0.06974"
"39.05000","19.51445","0.06948"
"39.10000","19.53940","0.06973"
"39.15000","19.56426","0.06979"
"39.20000","19.58917","0.06979"
"39.25000","19.61410","0.06989"
"39.30000","19.63898","0.06986"
"39.35000","19.66396","0.06986"
"39.40000","19.68891","0.06984"
"39.45000","19.71386","0.06972"
"39.50000","19.73882","0.06973"
"39.55000","19.76391","0.07005"
"39.60000","19.78897","0.07003"
"39.65000","19.81516","0.06967"
"39.70000","19.84041","0.07003"
"39.75000","19.86451","0.06977"
"39.80000","19.88927","0.06971"
"39.85000","19.91417","0.06991"
"39.90000","19.93920","0.06980"
"39.95000","19.96419","0.06978"
"40.00000","19.98919","0.07013"
"40.05000","20.01425","0.06977"
"40.10000","20.03932","0.06993"
"40.15000","20.06442","0.06981"
"40.20000","20.08945","0.07007"
"40.25000","20.11447","0.07003"
"40.30000","20.13937","0.07000"
"40.35000","20.16441","0.06951"
"40.40000","20.18937","0.06989"
"40.45000","20.21452","0.06984"
"40.50000","20.23951","0.06984"
"40.55000","20.26423","0.06973"
"40.60000","20.28897","0.06987"
"40.65000","20.31392","0.06956"
"40.70000","20.33887","0.07000"
"40.75000","20.36392","0.06976"
"40.80000","20.38894","0.06982"
"40.85000","20.41390","0.06995"
"40.90000","20.43889","0.06982"
"40.95000","20.46395","0.06977"
"41.00000","20.48902","0.06990"
"41.05000","20.51407","0.06988"
"41.10000","20.53921","0.07006"
"41.15000","20.56443","0.07014"
"41.20000","20.58952","0.07003"
"41.25000","20.61447","0.06994"
"41.30000","20.63957","0.06987"
"41.35000","20.66439","0.06989"
"41.40000","20.68929","0.07005"
"41.45000","20.71436","0.07015"
"41.50000","20.73940","0.07004"
"41.55000","20.76438","0.06998"
"41.60000","20.78940","0.07015"
"41.65000","20.81438","0.06998"
"41.70000","20.83933","0.07016"
"41.75000","20.86422","0.07041"
"41.80000","20.88908","0.07012"
"41.85000","20.91399","0.07048"
"41.90000","20.93894","0.07012"
"41.95000","20.96392","0.07043"
"42.00000","20.98890","0.07033"
"42.05000","21.01386","0.07047"
"42.10000","21.03897","0.07050"
"42.15000","21.06580","0.07035"
"42.20000","21.09013","0.07021"
"42.25000","21.11462","0.07017"
"42.30000","21.13940","0.07027"
"42.35000","21.16426","0.07037"
"42.40000","21.18914","0.07008"
"42.45000","21.21411","0.07030"
"42.50000","21.23912","0.06983"
"42.55000","21.26416","0.07026"
"42.60000","21.28917","0.07018"
"42.65000","21.31425","0.07041"
"42.70000","21.33930","0.07038"
"42.75000","21.36425","0.07031"
"42.80000","21.38927","0.06977"
"42.85000","21.41422","0.07003"
"42.90000","21.43912","0.06987"
"42.95000","21.46466","0.06994"
"43.00000","21.49027","0.06983"
"43.05000","21.51459","0.06982"
"43.10000","21.53933","0.06968"
"43.15000","21.56410","0.06975"
"43.20000","21.58896","0.06953"
"43.25000","21.61384","0.06968"
"43.30000","21.63885","0.06964"
"43.35000","21.66380","0.06927"
"43.40000","21.68883","0.06923"
"43.45000","21.71396","0.06930"
"43.50000","21.73912","0.06916"
"43.55000","21.76407","0.06924"
"43.60000","21.78898","0.06923"
"43.65000","21.81399","0.06899"
"43.70000","21.83903","0.06876"
"43.75000","21.86413","0.06893"
"43.80000","21.88916","0.06889"
"43.85000","21.91424","0.06871"
"43.90000","21.93924","0.06876"
"43.95000","21.96422","0.06834"
"44.00000","21.98922","0.06852"
"44.05000","22.01548","0.06836"
"44.10000","22.04052","0.06836"
"44.15000","22.06486","0.06845"
"44.20000","22.08957","0.06854"
"44.25000","22.11441","0.06793"
"44.30000","22.13916","0.06827"
"44.35000","22.16409","0.06806"
"44.40000","22.18893","0.06822"
"44.45000","22.21389","0.06818"
"44.50000","22.23910","0.06818"
"44.55000","22.26385","0.06784"
"44.60000","22.28874","0.06816"
"44.65000","22.31377","0.06774"
"44.70000","22.33881","0.06789"
"44.75000","22.36389","0.06779"
"44.80000","22.38895","0.06784"
"44.85000","22.41399","0.06755"
"44.90000","22.43921","0.06776"
"44.95000","22.46409","0.06761"
"45.00000","22.48906","0.06769"
"45.05000","22.51417","0.06752"
"45.10000","22.53919","0.06755"
"45.15000","22.56421","0.06763"
"45.20000","22.58924","0.06760"
"45.25000","22.61422","0.06757"
"45.30000","22.63919","0.06749"
"45.35000","22.66421","0.06721"
"45.40000","22.68924","0.06731"
"45.45000","22.71422","0.06737"
"45.50000","22.73932","0.06746"
"45.55000","22.76575","0.06713"
"45.60000","22.79067","0.06709"
"45.65000","22.81490","0.06698"
"45.70000","22.83941","0.06686"
"45.75000","22.86415","0.06704"
"45.80000","22.88887","0.06696"
"45.85000","22.91376","0.06675"
"45.90000","22.93874","0.06671"
"45.95000","22.96373","0.06627"
"46.00000","22.98885","0.06631"
"46.05000","23.01388","0.06620"
"46.10000","23.03904","0.06594"
"46.15000","23.06407","0.06612"
"46.20000","23.08909","0.06565"
"46.25000","23.11413","0.06547"
"46.30000","23.13913","0.06540"
"46.35000","23.16416","0.06539"
"46.40000","23.18937","0.06521"
"46.45000","23.21431","0.06544"
"46.50000","23.23930","0.06494"
"46.55000","23.26427","0.06492"
"46.60000","23.28928","0.06457"
"46.65000","23.31429","0.06474"
"46.70000","23.33933","0.06469"
"46.75000","23.36436","0.06485"
"46.80000","23.38934","0.06431"
"46.85000","23.41426","0.06401"
"46.90000","23.43919","0.06382"
"46.95000","23.46415","0.06410"
"47.00000","23.48914","0.06396"
"47.05000","23.51411","0.06386"
"47.10000","23.53928","0.06356"
"47.15000","23.56584","0.06349"
"47.20000","23.59062","0.06367"
"47.25000","23.61486","0.06336"
"47.30000","23.63958","0.06339"
"47.35000","23.66435","0.06324"
"47.40000","23.68908","0.06280"
"47.45000","23.71400","0.06293"
"47.50000","23.73888","0.06263"
"47.55000","23.76388","0.06276"
"47.60000","23.78883","0.06283"
"47.65000","23.81380","0.06269"
"47.70000","23.83888","0.06229"
"47.75000","23.86388","0.06207"
"47.80000","23.88891","0.06214"
"47.85000","23.91396","0.06215"
"47.90000","23.93909","0.06239"
"47.95000","23.96539","0.06203"
"48.00000","23.99004","0.06187"
"48.05000","24.01453","0.06186"
"48.10000","24.03920","0.06181"
"48.15000","24.06405","0.06161"
"48.20000","24.08898","0.06178"
"48.25000","24.11389","0.06162"
"48.30000","24.13884","0.06163"
"48.35000","24.16382","0.06152"
"48.40000","24.18882","0.06137"
"48.45000","24.21378","0.06107"
"48.50000","24.23878","0.06145"
"48.55000","24.26382","0.06104"
"48.60000","24.28889","0.06129"
"48.65000","24.31398","0.06106"
"48.70000","24.33908","0.06092"
"48.75000","24.36547","0.06069"
"48.80000","24.38986","0.06098"
"48.85000","24.41445","0.06052"
"48.90000","24.43921","0.06084"
"48.95000","24.46407","0.06061"
"49.00000","24.48901","0.06050"
"49.05000","24.51400","0.06041"
"49.10000","24.53899","0.06042"
"49.15000","24.56399","0.06005"
"49.20000","24.58894","0.06054"
"49.25000","24.61398","0.06004"
"49.30000","24.63899","0.06039"
"49.35000","24.66401","0.06023"
"49.40000","24.68901","0.06009"
"49.45000","24.71403","0.05999"
"49.50000","24.73909","0.06007"
"49.55000","24.76428","0.05988"
"49.60000","24.78920","0.05994"
"49.65000","24.81405","0.05987"
"49.70000","24.83898","0.05965"
"49.75000","24.86398","0.05958"
"49.80000","24.88892","0.05965"
"49.85000","24.91393","0.05961"
"49.90000","24.93893","0.05970"
"49.95000","24.96394","0.05946"
"50.00000","24.98894","0.05937"
"50.05000","25.01394","0.05948"
"50.10000","25.03909","0.05921"
"50.15000","25.06594","0.05908"
"50.20000","25.09018","0.05925"
"50.25000","25.11447","0.05893"
"50.30000","25.13920","0.05879"
"50.35000","25.16405","0.05890"
"50.40000","25.18900","0.05870"
"50.45000","25.21400","0.05879"
"50.50000","25.23895","0.05878"
"50.55000","25.26397","0.05878"
"50.60000","25.28898","0.05843"
"50.65000","25.31407","0.05855"
"50.70000","25.33909","0.05817"
"50.75000","25.36401","0.05848"
"50.80000","25.38899","0.05841"
"50.85000","25.41392","0.05836"
"50.90000","25.43892","0.05827"
"50.95000","25.46391","0.05843"
"51.00000","25.49047","0.05818"
"51.05000","25.51468","0.05843"
"51.10000","25.53914","0.05819"
"51.15000","25.56396","0.05826"
"51.20000","25.58886","0.05782"
"51.25000","25.61382","0.05794"
"51.30000","25.63892","0.05781"
"51.35000","25.66393","0.05798"
"51.40000","25.68904","0.05811"
"51.45000","25.71405","0.05787"
"51.50000","25.73915","0.05780"
"51.55000","25.76411","0.05758"
"51.60000","25.78910","0.05741"
"51.65000","25.81409","0.05795"
"51.70000","25.83904","0.05769"
"51.75000","25.86398","0.05782"
"51.80000","25.88897","0.05758"
"51.85000","25.91397","0.05761"
"51.90000","25.93894","0.05750"
"51.95000","25.96391","0.05773"
"52.00000","25.98895","0.05759"
"52.05000","26.01388","0.05763"
"52.10000","26.03892","0.05730"
"52.15000","26.06523","0.05699"
"52.20000","26.08986","0.05707"
"52.25000","26.11422","0.05712"
"52.30000","26.13893","0.05721"
"52.35000","26.16369","0.05736"
"52.40000","26.18854","0.05720"
"52.45000","26.21358","0.05682"
"52.50000","26.23861","0.05696"
"52.55000","26.26372","0.05686"
"52.60000","26.28887","0.05702"
"52.65000","26.31396","0.05700"
"52.70000","26.33908","0.05686"
"52.75000","26.36421","0.05676"
"52.80000","26.38918","0.05698"
"52.85000","26.41429","0.05671"
"52.90000","26.43927","0.05693"
"52.95000","26.46430","0.05682"
"53.00000","26.48946","0.05685"
"53.05000","26.51423","0.05667"
"53.10000","26.53904","0.05684"
"53.15000","26.56409","0.05669"
"53.20000","26.58902","0.05682"
"53.25000","26.61399","0.05671"
"53.30000","26.63889","0.05682"
"53.35000","26.66392","0.05649"
"53.40000","26.68898","0.05676"
"53.45000","26.71401","0.05644"
"53.50000","26.73902","0.05691"
"53.55000","26.76402","0.05658"
"53.60000","26.78920","0.05655"
"53.65000","26.81543","0.05660"
"53.70000","26.83966","0.05658"
"53.75000","26.86426","0.05636"
"53.80000","26.88905","0.05661"
"53.85000","26.91400","0.05629"
"53.90000","26.93895","0.05649"
"53.95000","26.96389","0.05657"
"54.00000","26.98882","0.05671"
"54.05000","27.01388","0.05670"
"54.10000","27.03888","0.05670"
"54.15000","27.06389","0.05658"
"54.20000","27.08892","0.05664"
"54.25000","27.11403","0.05679"
"54.30000","27.13890","0.05680"
"54.35000","27.16390","0.05692"
"54.40000","27.18895","0.05674"
"54.45000","27.21400","0.05643"
"54.50000","27.23902","0.05657"
"54.55000","27.26397","0.05661"
"54.60000","27.28897","0.05651"
"54.65000","27.31393","0.05688"
"54.70000","27.33891","0.05656"
"54.75000","27.36390","0.05666"
"54.80000","27.38887","0.05674"
"54.85000","27.41387","0.05695"
"54.90000","27.43887","0.05675"
"54.95000","27.46390","0.05703"
"55.00000","27.48891","0.05662"
"55.05000","27.51391","0.05670"
"55.10000","27.53895","0.05678"
"55.15000","27.56401","0.05710"
"55.20000","27.58906","0.05699"
"55.25000","27.61414","0.05691"
"55.30000","27.64073","0.05648"
"55.35000","27.66515","0.05659"
"55.40000","27.68945","0.05664"
"55.45000","27.71408","0.05675"
"55.50000","27.73884","0.05678"
"55.55000","27.76377","0.05677"
"55.60000","27.78879","0.05648"
"55.65000","27.81379","0.05693"
"55.70000","27.83882","0.05676"
"55.75000","27.86384","0.05707"
"55.80000","27.88884","0.05693"
"55.85000","27.91381","0.05692"
"55.90000","27.93881","0.05666"
"55.95000","27.96374","0.05698"
"56.00000","27.98874","0.05678"
"56.05000","28.01377","0.05695"
"56.10000","28.03910","0.05692"
"56.15000","28.06417","0.05664"
"56.20000","28.08891","0.05671"
"56.25000","28.11390","0.05687"
"56.30000","28.14037","0.05694"
"56.35000","28.16461","0.05723"
"56.40000","28.18917","0.05721"
"56.45000","28.21401","0.05707"
"56.50000","28.23894","0.05687"
"56.55000","28.26390","0.05691"
"56.60000","28.28885","0.05686"
"56.65000","28.31384","0.05711"
"56.70000","28.33879","0.05711"
"56.75000","28.36408","0.05703"
"56.80000","28.38874","0.05696"
"56.85000","28.41371","0.05691"
"56.90000","28.43877","0.05721"
"56.95000","28.46383","0.05718"
"57.00000","28.48883","0.05746"
"57.05000","28.51396","0.05703"
"57.10000","28.53897","0.05714"
"57.15000","28.56396","0.05698"
"57.20000","28.58895","0.05725"
"57.25000","28.61392","0.05736"
"57.30000","28.63888","0.05722"
"57.35000","28.66383","0.05697"
"57.40000","28.68879","0.05723"
"57.45000","28.71388","0.05700"
"57.50000","28.73976","0.05729"
"57.55000","28.76495","0.05734"
"57.60000","28.78930","0.05736"
"57.65000","28.81405","0.05723"
"57.70000","28.83891","0.05738"
"57.75000","28.86394","0.05709"
"57.80000","28.88888","0.05749"
"57.85000","28.91378","0.05727"
"57.90000","28.93876","0.05736"
"57.95000","28.96377","0.05703"
"58.00000","28.98879","0.05710"
"58.05000","29.01381","0.05684"
"58.10000","29.03882","0.05735"
"58.15000","29.06386","0.05749"
"58.20000","29.08886","0.05734"
"58.25000","29.11389","0.05706"
"58.30000","29.13961","0.05697"
"58.35000","29.16501","0.05691"
"58.40000","29.18928","0.05716"
"58.45000","29.21402","0.05715"
"58.50000","29.23883","0.05709"
"58.55000","29.26379","0.05680"
"58.60000","29.28878","0.05662"
"58.65000","29.31373","0.05681"
"58.70000","29.33873","0.05690"
"58.75000","29.36372","0.05658"
"58.80000","29.38874","0.05676"
"58.85000","29.41378","0.05645"
"58.90000","29.43902","0.05618"
"58.95000","29.46470","0.05633"
"59.00000","29.48912","0.05619"
"59.05000","29.51394","0.05633"
"59.10000","29.53890","0.05613"
"59.15000","29.56384","0.05596"
"59.20000","29.58884","0.05543"
"59.25000","29.61383","0.05559"
"59.30000","29.63884","0.05550"
"59.35000","29.66378","0.05535"
"59.40000","29.68882","0.05516"
"59.45000","29.71380","0.05472"
"59.50000","29.73891","0.05420"
"59.55000","29.76394","0.05409"
"59.60000","29.78891","0.05396"
"59.65000","29.81386","0.05409"
"59.70000","29.83887","0.05342"
"59.75000","29.86387","0.05276"
"59.80000","29.88904","0.05184"
"59.85000","29.91483","0.05139"
"59.90000","29.93990","0.04945"
"59.95000","29.96413","0.04580"
"60.00000","29.98893","0.03606"
"60.05000","30.01383","0.02219"
"60.10000","30.03886","0.00360"
"60.15000","30.06383","-0.01336"
"60.20000","30.08879","-0.01437"
"60.25000","30.11380","-0.01387"
"60.30000","30.13883","-0.01424"
"60.35000","30.16375","-0.01413"
"60.40000","30.18874","-0.01412"
"60.45000","30.21376","-0.01399"
"60.50000","30.23876","-0.01404"
"60.55000","30.26377","-0.01376"
"60.60000","30.28880","-0.01424"
"60.65000","30.31383","-0.01425"
"60.70000","30.33893","-0.01410"
"60.75000","30.36405","-0.01385"
"60.80000","30.38907","-0.01369"
"60.85000","30.41393","-0.01387"
"60.90000","30.43897","-0.01420"
"60.95000","30.46395","-0.01417"
"61.00000","30.48892","-0.01416"
"61.05000","30.51389","-0.01415"
"61.10000","30.53888","-0.01383"
"61.15000","30.56386","-0.01397"
"61.20000","30.58892","-0.01402"
"61.25000","30.61394","-0.01404"
"61.30000","30.63891","-0.01405"
"61.35000","30.66394","-0.01392"
"61.40000","30.68885","-0.01369"
"61.45000","30.71387","-0.01390"
"61.50000","30.73891","-0.01395"
"61.55000","30.76392","-0.01427"
"61.60000","30.78891","-0.01418"
"61.65000","30.81389","-0.01420"
"61.70000","30.83884","-0.01371"
"61.75000","30.86384","-0.01391"
"61.80000","30.88880","-0.01406"
"61.85000","30.91387","-0.01401"
"61.90000","30.93873","-0.01416"
"61.95000","30.96378","-0.01415"
"62.00000","30.98898","-0.01361"
"62.05000","31.01435","-0.01397"
"62.10000","31.04078","-0.01368"
"62.15000","31.06481","-0.01414"
"62.20000","31.08946","-0.01410"
"62.25000","31.11412","-0.01409"
"62.30000","31.13898","-0.01395"
"62.35000","31.16390","-0.01410"
"62.40000","31.18875","-0.01389"
"62.45000","31.21373","-0.01406"
"62.50000","31.23882","-0.01367"
"62.55000","31.26373","-0.01386"
"62.60000","31.28875","-0.01415"
"62.65000","31.31390","-0.01408"
"62.70000","31.33884","-0.01402"
"62.75000","31.36386","-0.01399"
"62.80000","31.38893","-0.01390"
"62.85000","31.41389","-0.01385"
"62.90000","31.43877","-0.01381"
"62.95000","31.46375","-0.01396"
"63.00000","31.48876","-0.01376"
"63.05000","31.51380","-0.01421"
"63.10000","31.53884","-0.01383"
"63.15000","31.56386","-0.01402"
"63.20000","31.58892","-0.01400"
"63.25000","31.61392","-0.01382"
"63.30000","31.63887","-0.01394"
"63.35000","31.66391","-0.01400"
"63.40000","31.68894","-0.01406"
"63.45000","31.71390","-0.01400"
"63.50000","31.73889","-0.01406"
"63.55000","31.76380","-0.01392"
"63.60000","31.78881","-0.01411"
"63.65000","31.81381","-0.01403"
"63.70000","31.83879","-0.01406"
"63.75000","31.86388","-0.01402"
"63.80000","31.88902","-0.01417"
"63.85000","31.91394","-0.01365"
"63.90000","31.93963","-0.01405"
"63.95000","31.96528","-0.01406"
"64.00000","31.98950","-0.01410"
"64.05000","32.01424","-0.01401"
"64.10000","32.03915","-0.01406"
"64.15000","32.06396","-0.01378"
"64.20000","32.08887","-0.01411"
"64.25000","32.11377","-0.01391"
"64.30000","32.13868","-0.01400"
"64.35000","32.16370","-0.01408"
"64.40000","32.18877","-0.01412"
"64.45000","32.21381","-0.01373"
"64.50000","32.23884","-0.01411"
"64.55000","32.26385","-0.01397"
"64.60000","32.28886","-0.01412"
"64.65000","32.31386","-0.01397"
"64.70000","32.33891","-0.01412"
"64.75000","32.36395","-0.01391"
"64.80000","32.38892","-0.01424"
"64.85000","32.41385","-0.01416"
"64.90000","32.43879","-0.01423"
"64.95000","32.46385","-0.01400"
"65.00000","32.48883","-0.01391"
"65.05000","32.51390","-0.01396"
"65.10000","32.53894","-0.01413"
"65.15000","32.56391","-0.01393"
"65.20000","32.58883","-0.01416"
"65.25000","32.61385","-0.01411"
"65.30000","32.63888","-0.01377"
"65.35000","32.66391","-0.01411"
"65.40000","32.68891","-0.01391"
"65.45000","32.71389","-0.01401"
"65.50000","32.73883","-0.01416"
"65.55000","32.76383","-0.01418"
"65.60000","32.78973","-0.01398"
"65.65000","32.81487","-0.01400"
"65.70000","32.83925","-0.01392"
"65.75000","32.86413","-0.01392"
"65.80000","32.88903","-0.01406"
"65.85000","32.91390","-0.01401"
"65.90000","32.93884","-0.01405"
"65.95000","32.96384","-0.01407"
"66.00000","32.98883","-0.01396"
"66.05000","33.01379","-0.01419"
"66.10000","33.03876","-0.01394"
"66.15000","33.06374","-0.01401"
"66.20000","33.08874","-0.01404"
"66.21800","33.09772","-0.01397"