File: 10G1652/ST 10G1652_00077.csv
Rate 1,"0.15000",mm/s
Start date,"9/25/2021"
Specimen label,""

Time,Extension,2 kg Beam Load Cell
(s),(mm),(N)
"0.00000","0.00000","-0.00126"
"0.10000","0.00000","-0.00108"
"0.20000","0.00629","-0.00126"
"0.30000","0.02332","-0.00110"
"0.40000","0.04016","-0.00085"
"0.50000","0.05705","-0.00092"
"0.60000","0.07389","-0.00087"
"0.70000","0.09042","-0.00053"
"0.80000","0.10676","-0.00070"
"0.90000","0.12296","-0.00064"
"1.00000","0.13904","-0.00025"
"1.10000","0.15505","-0.00061"
"1.20000","0.17077","-0.00052"
"1.30000","0.18642","-0.00006"
"1.40000","0.20212","-0.00027"
"1.50000","0.21765","-0.00017"
"1.60000","0.23323","0.00006"
"1.70000","0.24848","0.00012"
"1.80000","0.26403","0.00025"
"1.90000","0.27933","0.00036"
"2.00000","0.29466","0.00028"
"2.10000","0.30992","0.00031"
"2.20000","0.32524","0.00043"
"2.30000","0.34051","0.00053"
"2.40000","0.35583","0.00063"
"2.50000","0.37065","0.00045"
"2.60000","0.38588","0.00110"
"2.70000","0.40069","0.00074"
"2.80000","0.41576","0.00092"
"2.90000","0.43074","0.00082"
"3.00000","0.44595","0.00111"
"3.10000","0.46101","0.00088"
"3.20000","0.47584","0.00106"
"3.30000","0.49086","0.00111"
"3.40000","0.50591","0.00130"
"3.50000","0.52102","0.00132"
"3.60000","0.53597","0.00156"
"3.70000","0.55098","0.00156"
"3.80000","0.56599","0.00140"
"3.90000","0.58105","0.00147"
"4.00000","0.59597","0.00179"
"4.10000","0.61093","0.00163"
"4.20000","0.62606","0.00193"
"4.30000","0.64106","0.00204"
"4.40000","0.65603","0.00183"
"4.50000","0.67100","0.00215"
"4.60000","0.68610","0.00211"
"4.70000","0.70122","0.00202"
"4.80000","0.71620","0.00240"
"4.90000","0.73100","0.00240"
"5.00000","0.74608","0.00245"
"5.10000","0.76101","0.00239"
"5.20000","0.77601","0.00247"
"5.30000","0.79105","0.00267"
"5.40000","0.80612","0.00279"
"5.50000","0.82107","0.00269"
"5.60000","0.83604","0.00284"
"5.70000","0.85114","0.00289"
"5.80000","0.86641","0.00307"
"5.90000","0.88121","0.00300"
"6.00000","0.89608","0.00306"
"6.10000","0.91120","0.00314"
"6.20000","0.92618","0.00319"
"6.30000","0.94108","0.00314"
"6.40000","0.95612","0.00354"
"6.50000","0.97122","0.00341"
"6.60000","0.98622","0.00350"
"6.70000","1.00116","0.00345"
"6.80000","1.01755","0.00375"
"6.90000","1.03142","0.00355"
"7.00000","1.04618","0.00390"
"7.10000","1.06103","0.00372"
"7.20000","1.07612","0.00377"
"7.30000","1.09119","0.00397"
"7.40000","1.10615","0.00401"
"7.50000","1.12114","0.00387"
"7.60000","1.13625","0.00406"
"7.70000","1.15128","0.00404"
"7.80000","1.16621","0.00411"
"7.90000","1.18115","0.00438"
"8.00000","1.19622","0.00429"
"8.10000","1.21120","0.00445"
"8.20000","1.22613","0.00434"
"8.30000","1.24112","0.00449"
"8.40000","1.25618","0.00450"
"8.50000","1.27126","0.00438"
"8.60000","1.28616","0.00447"
"8.70000","1.30111","0.00490"
"8.80000","1.31618","0.00461"
"8.90000","1.33114","0.00472"
"9.00000","1.34608","0.00497"
"9.10000","1.36111","0.00466"
"9.20000","1.37621","0.00509"
"9.30000","1.39119","0.00526"
"9.40000","1.40617","0.00505"
"9.50000","1.42119","0.00512"
"9.60000","1.43624","0.00540"
"9.70000","1.45119","0.00522"
"9.80000","1.46611","0.00536"
"9.90000","1.48116","0.00550"
"10.00000","1.49619","0.00539"
"10.10000","1.51114","0.00554"
"10.20000","1.52610","0.00581"
"10.30000","1.54120","0.00579"
"10.40000","1.55621","0.00591"
"10.50000","1.57114","0.00584"
"10.60000","1.58616","0.00603"
"10.70000","1.60128","0.00594"
"10.80000","1.61630","0.00616"
"10.90000","1.63154","0.00618"
"11.00000","1.64622","0.00604"
"11.10000","1.66126","0.00619"
"11.20000","1.67623","0.00649"
"11.30000","1.69115","0.00653"
"11.40000","1.70617","0.00638"
"11.50000","1.72125","0.00644"
"11.60000","1.73622","0.00638"
"11.70000","1.75122","0.00660"
"11.80000","1.76629","0.00681"
"11.90000","1.78135","0.00686"
"12.00000","1.79628","0.00701"
"12.10000","1.81124","0.00712"
"12.20000","1.82631","0.00691"
"12.30000","1.84131","0.00708"
"12.40000","1.85624","0.00740"
"12.50000","1.87122","0.00722"
"12.60000","1.88626","0.00721"
"12.70000","1.90126","0.00736"
"12.80000","1.91619","0.00748"
"12.90000","1.93120","0.00742"
"13.00000","1.94646","0.00771"
"13.10000","1.96127","0.00768"
"13.20000","1.97617","0.00771"
"13.30000","1.99118","0.00786"
"13.40000","2.00633","0.00794"
"13.50000","2.02146","0.00801"
"13.60000","2.03613","0.00804"
"13.70000","2.05118","0.00823"
"13.80000","2.06619","0.00820"
"13.90000","2.08117","0.00829"
"14.00000","2.09612","0.00835"
"14.10000","2.11115","0.00852"
"14.20000","2.12620","0.00842"
"14.30000","2.14113","0.00876"
"14.40000","2.15610","0.00888"
"14.50000","2.17119","0.00865"
"14.60000","2.18622","0.00891"
"14.70000","2.20113","0.00904"
"14.80000","2.21611","0.00882"
"14.90000","2.23123","0.00937"
"15.00000","2.24627","0.00940"
"15.10000","2.26120","0.00911"
"15.20000","2.27622","0.00936"
"15.30000","2.29133","0.00958"
"15.40000","2.30627","0.00922"
"15.50000","2.32130","0.00963"
"15.60000","2.33651","0.00984"
"15.70000","2.35179","0.00953"
"15.80000","2.36657","0.00986"
"15.90000","2.38118","0.01013"
"16.00000","2.39617","0.00978"
"16.10000","2.41125","0.00989"
"16.20000","2.42620","0.01022"
"16.30000","2.44118","0.01026"
"16.40000","2.45623","0.01034"
"16.50000","2.47126","0.01015"
"16.60000","2.48618","0.01017"
"16.70000","2.50117","0.01050"
"16.80000","2.51619","0.01052"
"16.90000","2.53119","0.01054"
"17.00000","2.54611","0.01070"
"17.10000","2.56111","0.01071"
"17.20000","2.57621","0.01066"
"17.30000","2.59117","0.01061"
"17.40000","2.60613","0.01087"
"17.50000","2.62115","0.01097"
"17.60000","2.63625","0.01106"
"17.70000","2.65122","0.01106"
"17.80000","2.66619","0.01136"
"17.90000","2.68122","0.01124"
"18.00000","2.69626","0.01110"
"18.10000","2.71123","0.01127"
"18.20000","2.72613","0.01157"
"18.30000","2.74120","0.01135"
"18.40000","2.75626","0.01158"
"18.50000","2.77130","0.01164"
"18.60000","2.78772","0.01169"
"18.70000","2.80191","0.01186"
"18.80000","2.81626","0.01194"
"18.90000","2.83104","0.01192"
"19.00000","2.84600","0.01187"
"19.10000","2.86113","0.01214"
"19.20000","2.87612","0.01221"
"19.30000","2.89109","0.01215"
"19.40000","2.90613","0.01251"
"19.50000","2.92121","0.01246"
"19.60000","2.93619","0.01229"
"19.70000","2.95114","0.01257"
"19.80000","2.96619","0.01253"
"19.90000","2.98129","0.01255"
"20.00000","2.99625","0.01287"
"20.10000","3.01122","0.01293"
"20.20000","3.02629","0.01263"
"20.30000","3.04131","0.01302"
"20.40000","3.05616","0.01301"
"20.50000","3.07116","0.01308"
"20.60000","3.08620","0.01340"
"20.70000","3.10126","0.01323"
"20.80000","3.11623","0.01316"
"20.90000","3.13112","0.01344"
"21.00000","3.14623","0.01340"
"21.10000","3.16119","0.01354"
"21.20000","3.17606","0.01375"
"21.30000","3.19105","0.01366"
"21.40000","3.20613","0.01364"
"21.50000","3.22113","0.01385"
"21.60000","3.23613","0.01391"
"21.70000","3.25110","0.01390"
"21.80000","3.26620","0.01390"
"21.90000","3.28115","0.01423"
"22.00000","3.29623","0.01437"
"22.10000","3.31124","0.01416"
"22.20000","3.32636","0.01424"
"22.30000","3.34151","0.01443"
"22.40000","3.35608","0.01439"
"22.50000","3.37109","0.01460"
"22.60000","3.38616","0.01459"
"22.70000","3.40109","0.01448"
"22.80000","3.41614","0.01494"
"22.90000","3.43126","0.01491"
"23.00000","3.44634","0.01493"
"23.10000","3.46118","0.01494"
"23.20000","3.47615","0.01499"
"23.30000","3.49117","0.01490"
"23.40000","3.50625","0.01534"
"23.50000","3.52121","0.01500"
"23.60000","3.53619","0.01535"
"23.70000","3.55132","0.01555"
"23.80000","3.56628","0.01550"
"23.90000","3.58128","0.01555"
"24.00000","3.59626","0.01571"
"24.10000","3.61147","0.01567"
"24.20000","3.62636","0.01573"
"24.30000","3.64127","0.01589"
"24.40000","3.65633","0.01582"
"24.50000","3.67142","0.01608"
"24.60000","3.68639","0.01617"
"24.70000","3.70128","0.01601"
"24.80000","3.71635","0.01631"
"24.90000","3.73134","0.01624"
"25.00000","3.74627","0.01629"
"25.10000","3.76127","0.01657"
"25.20000","3.77646","0.01652"
"25.30000","3.79138","0.01638"
"25.40000","3.80628","0.01665"
"25.50000","3.82121","0.01635"
"25.60000","3.83624","0.01671"
"25.70000","3.85121","0.01667"
"25.80000","3.86611","0.01674"
"25.90000","3.88108","0.01671"
"26.00000","3.89620","0.01692"
"26.10000","3.91122","0.01686"
"26.20000","3.92618","0.01709"
"26.30000","3.94121","0.01711"
"26.40000","3.95625","0.01711"
"26.50000","3.97119","0.01735"
"26.60000","3.98616","0.01710"
"26.70000","4.00123","0.01736"
"26.80000","4.01628","0.01743"
"26.90000","4.03119","0.01702"
"27.00000","4.04619","0.01763"
"27.10000","4.06128","0.01748"
"27.20000","4.07629","0.01749"
"27.30000","4.09122","0.01788"
"27.40000","4.10613","0.01752"
"27.50000","4.12141","0.01761"
"27.60000","4.13864","0.01777"
"27.70000","4.15149","0.01774"
"27.80000","4.16610","0.01787"
"27.90000","4.18105","0.01803"
"28.00000","4.19608","0.01810"
"28.10000","4.21108","0.01808"
"28.20000","4.22613","0.01826"
"28.30000","4.24123","0.01821"
"28.40000","4.25619","0.01825"
"28.50000","4.27113","0.01824"
"28.60000","4.28622","0.01841"
"28.70000","4.30128","0.01843"
"28.80000","4.31617","0.01866"
"28.90000","4.33116","0.01861"
"29.00000","4.34619","0.01876"
"29.10000","4.36121","0.01848"
"29.20000","4.37607","0.01860"
"29.30000","4.39106","0.01876"
"29.40000","4.40616","0.01886"
"29.50000","4.42122","0.01898"
"29.60000","4.43617","0.01901"
"29.70000","4.45117","0.01893"
"29.80000","4.46620","0.01903"
"29.90000","4.48115","0.01902"
"30.00000","4.49611","0.01898"
"30.10000","4.51112","0.01937"
"30.20000","4.52621","0.01924"
"30.30000","4.54121","0.01932"
"30.40000","4.55617","0.01925"
"30.50000","4.57115","0.01942"
"30.60000","4.58625","0.01942"
"30.70000","4.60125","0.01954"
"30.80000","4.61624","0.01964"
"30.90000","4.63128","0.01927"
"31.00000","4.64633","0.01951"
"31.10000","4.66131","0.01964"
"31.20000","4.67616","0.01973"
"31.30000","4.69130","0.01960"
"31.40000","4.70630","0.01987"
"31.50000","4.72118","0.01987"
"31.60000","4.73616","0.01976"
"31.70000","4.75127","0.01999"
"31.80000","4.76630","0.02007"
"31.90000","4.78123","0.01993"
"32.00000","4.79623","0.02020"
"32.10000","4.81130","0.02026"
"32.20000","4.82629","0.01995"
"32.30000","4.84125","0.02025"
"32.40000","4.85630","0.02042"
"32.50000","4.87138","0.02027"
"32.60000","4.88643","0.02028"
"32.70000","4.90240","0.02058"
"32.80000","4.91625","0.02050"
"32.90000","4.93118","0.02044"
"33.00000","4.94613","0.02059"
"33.10000","4.96112","0.02056"
"33.20000","4.97623","0.02056"
"33.30000","4.99126","0.02065"
"33.40000","5.00617","0.02092"
"33.50000","5.02107","0.02084"
"33.60000","5.03616","0.02098"
"33.70000","5.05116","0.02093"
"33.80000","5.06609","0.02099"
"33.90000","5.08110","0.02118"
"34.00000","5.09620","0.02122"
"34.10000","5.11122","0.02102"
"34.20000","5.12614","0.02114"
"34.30000","5.14114","0.02134"
"34.40000","5.15627","0.02125"
"34.50000","5.17131","0.02140"
"34.60000","5.18630","0.02145"
"34.70000","5.20127","0.02131"
"34.80000","5.21631","0.02144"
"34.90000","5.23119","0.02158"
"35.00000","5.24618","0.02152"
"35.10000","5.26122","0.02173"
"35.20000","5.27625","0.02180"
"35.30000","5.29116","0.02183"
"35.40000","5.30615","0.02175"
"35.50000","5.32124","0.02159"
"35.60000","5.33629","0.02200"
"35.70000","5.35121","0.02212"
"35.80000","5.36616","0.02202"
"35.90000","5.38124","0.02200"
"36.00000","5.39625","0.02208"
"36.10000","5.41122","0.02203"
"36.20000","5.42624","0.02259"
"36.30000","5.44132","0.02225"
"36.40000","5.45631","0.02202"
"36.50000","5.47128","0.02246"
"36.60000","5.48626","0.02251"
"36.70000","5.50131","0.02239"
"36.80000","5.51627","0.02266"
"36.90000","5.53117","0.02276"
"37.00000","5.54621","0.02265"
"37.10000","5.56130","0.02284"
"37.20000","5.57623","0.02290"
"37.30000","5.59119","0.02284"
"37.40000","5.60622","0.02292"
"37.50000","5.62132","0.02296"
"37.60000","5.63626","0.02310"
"37.70000","5.65127","0.02321"
"37.80000","5.66635","0.02319"
"37.90000","5.68119","0.02319"
"38.00000","5.69612","0.02315"
"38.10000","5.71108","0.02350"
"38.20000","5.72619","0.02331"
"38.30000","5.74118","0.02337"
"38.40000","5.75611","0.02377"
"38.50000","5.77114","0.02330"
"38.60000","5.78627","0.02361"
"38.70000","5.80123","0.02385"
"38.80000","5.81615","0.02381"
"38.90000","5.83118","0.02362"
"39.00000","5.84627","0.02399"
"39.10000","5.86126","0.02374"
"39.20000","5.87623","0.02381"
"39.30000","5.89146","0.02397"
"39.40000","5.90633","0.02404"
"39.50000","5.92116","0.02408"
"39.60000","5.93613","0.02424"
"39.70000","5.95121","0.02425"
"39.80000","5.96624","0.02423"
"39.90000","5.98121","0.02436"
"40.00000","5.99618","0.02427"
"40.10000","6.01129","0.02467"
"40.20000","6.02633","0.02448"
"40.30000","6.04124","0.02448"
"40.40000","6.05625","0.02453"
"40.50000","6.07137","0.02453"
"40.60000","6.08637","0.02478"
"40.70000","6.10130","0.02483"
"40.80000","6.11638","0.02451"
"40.90000","6.13294","0.02486"
"41.00000","6.14702","0.02496"
"41.10000","6.16119","0.02490"
"41.20000","6.17607","0.02487"
"41.30000","6.19108","0.02489"
"41.40000","6.20603","0.02490"
"41.50000","6.22106","0.02493"
"41.60000","6.23615","0.02525"
"41.70000","6.25116","0.02516"
"41.80000","6.26606","0.02516"
"41.90000","6.28107","0.02542"
"42.00000","6.29614","0.02550"
"42.10000","6.31116","0.02525"
"42.20000","6.32607","0.02570"
"42.30000","6.34106","0.02525"
"42.40000","6.35617","0.02541"
"42.50000","6.37119","0.02578"
"42.60000","6.38612","0.02570"
"42.70000","6.40116","0.02555"
"42.80000","6.41625","0.02590"
"42.90000","6.43119","0.02580"
"43.00000","6.44614","0.02586"
"43.10000","6.46110","0.02590"
"43.20000","6.47622","0.02564"
"43.30000","6.49122","0.02606"
"43.40000","6.50618","0.02619"
"43.50000","6.52122","0.02603"
"43.60000","6.53628","0.02605"
"43.70000","6.55118","0.02617"
"43.80000","6.56611","0.02602"
"43.90000","6.58118","0.02628"
"44.00000","6.59625","0.02615"
"44.10000","6.61122","0.02625"
"44.20000","6.62620","0.02644"
"44.30000","6.64131","0.02629"
"44.40000","6.65632","0.02638"
"44.50000","6.67122","0.02655"
"44.60000","6.68621","0.02639"
"44.70000","6.70137","0.02666"
"44.80000","6.71641","0.02673"
"44.90000","6.73195","0.02654"
"45.00000","6.74651","0.02682"
"45.10000","6.76120","0.02675"
"45.20000","6.77614","0.02651"
"45.30000","6.79109","0.02678"
"45.40000","6.80620","0.02689"
"45.50000","6.82124","0.02667"
"45.60000","6.83625","0.02689"
"45.70000","6.85117","0.02688"
"45.80000","6.86619","0.02700"
"45.90000","6.88121","0.02696"
"46.00000","6.89609","0.02708"
"46.10000","6.91105","0.02706"
"46.20000","6.92616","0.02715"
"46.30000","6.94119","0.02723"
"46.40000","6.95610","0.02724"
"46.50000","6.97106","0.02733"
"46.60000","6.98616","0.02713"
"46.70000","7.00126","0.02723"
"46.80000","7.01620","0.02715"
"46.90000","7.03116","0.02753"
"47.00000","7.04625","0.02751"
"47.10000","7.06120","0.02726"
"47.20000","7.07614","0.02741"
"47.30000","7.09117","0.02745"
"47.40000","7.10627","0.02734"
"47.50000","7.12118","0.02766"
"47.60000","7.13614","0.02745"
"47.70000","7.15116","0.02732"
"47.80000","7.16625","0.02741"
"47.90000","7.18121","0.02774"
"48.00000","7.19613","0.02750"
"48.10000","7.21116","0.02759"
"48.20000","7.22621","0.02759"
"48.30000","7.24136","0.02761"
"48.40000","7.25653","0.02776"
"48.50000","7.27111","0.02783"
"48.60000","7.28607","0.02772"
"48.70000","7.30104","0.02775"
"48.80000","7.31607","0.02766"
"48.90000","7.33123","0.02790"
"49.00000","7.34630","0.02797"
"49.10000","7.36125","0.02785"
"49.20000","7.37623","0.02801"
"49.30000","7.39132","0.02797"
"49.40000","7.40631","0.02798"
"49.50000","7.42126","0.02825"
"49.60000","7.43624","0.02800"
"49.70000","7.45132","0.02794"
"49.80000","7.46638","0.02817"
"49.90000","7.48124","0.02803"
"50.00000","7.49625","0.02815"
"50.10000","7.51127","0.02832"
"50.20000","7.52615","0.02813"
"50.30000","7.54111","0.02829"
"50.40000","7.55618","0.02837"
"50.50000","7.57121","0.02824"
"50.60000","7.58614","0.02826"
"50.70000","7.60110","0.02850"
"50.80000","7.61619","0.02835"
"50.90000","7.63120","0.02834"
"51.00000","7.64616","0.02847"
"51.10000","7.66111","0.02856"
"51.20000","7.67622","0.02880"
"51.30000","7.69122","0.02882"
"51.40000","7.70615","0.02864"
"51.50000","7.72121","0.02890"
"51.60000","7.73642","0.02898"
"51.70000","7.75136","0.02884"
"51.80000","7.76623","0.02889"
"51.90000","7.78116","0.02860"
"52.00000","7.79622","0.02892"
"52.10000","7.81120","0.02889"
"52.20000","7.82616","0.02891"
"52.30000","7.84123","0.02888"
"52.40000","7.85627","0.02893"
"52.50000","7.87117","0.02885"
"52.60000","7.88619","0.02904"
"52.70000","7.90125","0.02915"
"52.80000","7.91619","0.02897"
"52.90000","7.93115","0.02904"
"53.00000","7.94619","0.02902"
"53.10000","7.96133","0.02892"
"53.20000","7.97635","0.02911"
"53.30000","7.99126","0.02923"
"53.40000","8.00631","0.02914"
"53.50000","8.02149","0.02925"
"53.60000","8.03650","0.02928"
"53.70000","8.05286","0.02936"
"53.80000","8.06631","0.02935"
"53.90000","8.08119","0.02921"
"54.00000","8.09614","0.02940"
"54.10000","8.11108","0.02940"
"54.20000","8.12615","0.02933"
"54.30000","8.14119","0.02946"
"54.40000","8.15617","0.02926"
"54.50000","8.17109","0.02959"
"54.60000","8.18615","0.02982"
"54.70000","8.20114","0.02963"
"54.80000","8.21611","0.02952"
"54.90000","8.23108","0.02978"
"55.00000","8.24620","0.02979"
"55.10000","8.26122","0.02982"
"55.20000","8.27631","0.03014"
"55.30000","8.29117","0.02985"
"55.40000","8.30621","0.02977"
"55.50000","8.32119","0.03012"
"55.60000","8.33611","0.03007"
"55.70000","8.35114","0.03001"
"55.80000","8.36619","0.03013"
"55.90000","8.38118","0.03026"
"56.00000","8.39612","0.03018"
"56.10000","8.41121","0.03045"
"56.20000","8.42623","0.03033"
"56.30000","8.44116","0.03009"
"56.40000","8.45615","0.03051"
"56.50000","8.47126","0.03055"
"56.60000","8.48624","0.03055"
"56.70000","8.50115","0.03057"
"56.80000","8.51615","0.03068"
"56.90000","8.53129","0.03062"
"57.00000","8.54634","0.03065"
"57.10000","8.56128","0.03072"
"57.20000","8.57753","0.03072"
"57.30000","8.59138","0.03078"
"57.40000","8.60623","0.03078"
"57.50000","8.62117","0.03072"
"57.60000","8.63617","0.03091"
"57.70000","8.65129","0.03092"
"57.80000","8.66625","0.03079"
"57.90000","8.68120","0.03091"
"58.00000","8.69619","0.03116"
"58.10000","8.71128","0.03109"
"58.20000","8.72623","0.03112"
"58.30000","8.74116","0.03128"
"58.40000","8.75620","0.03107"
"58.50000","8.77128","0.03147"
"58.60000","8.78620","0.03107"
"58.70000","8.80118","0.03135"
"58.80000","8.81622","0.03137"
"58.90000","8.83121","0.03144"
"59.00000","8.84608","0.03149"
"59.10000","8.86105","0.03151"
"59.20000","8.87611","0.03156"
"59.30000","8.89111","0.03165"
"59.40000","8.90605","0.03172"
"59.50000","8.92106","0.03143"
"59.60000","8.93627","0.03184"
"59.70000","8.95164","0.03182"
"59.80000","8.96628","0.03165"
"59.90000","8.98098","0.03183"
"60.00000","8.99605","0.03179"
"60.10000","9.01102","0.03183"
"60.20000","9.02601","0.03211"
"60.30000","9.04113","0.03204"
"60.40000","9.05622","0.03205"
"60.50000","9.07113","0.03210"
"60.60000","9.08613","0.03200"
"60.70000","9.10122","0.03210"
"60.80000","9.11625","0.03225"
"60.90000","9.13122","0.03226"
"61.00000","9.14620","0.03232"
"61.10000","9.16130","0.03232"
"61.20000","9.17632","0.03235"
"61.30000","9.19129","0.03241"
"61.40000","9.20633","0.03227"
"61.50000","9.22152","0.03253"
"61.60000","9.23650","0.03239"
"61.70000","9.25138","0.03240"
"61.80000","9.26639","0.03248"
"61.90000","9.28208","0.03263"
"62.00000","9.29664","0.03246"
"62.10000","9.31133","0.03269"
"62.20000","9.32629","0.03247"
"62.30000","9.34133","0.03253"
"62.40000","9.35630","0.03269"
"62.50000","9.37126","0.03262"
"62.60000","9.38635","0.03253"
"62.70000","9.40143","0.03287"
"62.80000","9.41630","0.03259"
"62.90000","9.43126","0.03274"
"63.00000","9.44629","0.03279"
"63.10000","9.46130","0.03260"
"63.20000","9.47622","0.03268"
"63.30000","9.49116","0.03270"
"63.40000","9.50623","0.03257"
"63.50000","9.52125","0.03290"
"63.60000","9.53627","0.03295"
"63.70000","9.55117","0.03266"
"63.80000","9.56624","0.03290"
"63.90000","9.58114","0.03276"
"64.00000","9.59608","0.03278"
"64.10000","9.61107","0.03293"
"64.20000","9.62622","0.03294"
"64.30000","9.64122","0.03288"
"64.40000","9.65615","0.03319"
"64.50000","9.67119","0.03319"
"64.60000","9.68626","0.03291"
"64.70000","9.70119","0.03320"
"64.80000","9.71623","0.03301"
"64.90000","9.73139","0.03297"
"65.00000","9.74644","0.03334"
"65.10000","9.76340","0.03324"
"65.20000","9.77631","0.03313"
"65.30000","9.79112","0.03342"
"65.40000","9.80617","0.03315"
"65.50000","9.82113","0.03358"
"65.60000","9.83615","0.03350"
"65.70000","9.85129","0.03334"
"65.80000","9.86631","0.03323"
"65.90000","9.88127","0.03348"
"66.00000","9.89637","0.03335"
"66.10000","9.91138","0.03342"
"66.20000","9.92642","0.03355"
"66.30000","9.94132","0.03351"
"66.40000","9.95629","0.03333"
"66.50000","9.97139","0.03357"
"66.60000","9.98630","0.03365"
"66.70000","10.00125","0.03356"
"66.80000","10.01628","0.03359"
"66.90000","10.03131","0.03361"
"67.00000","10.04623","0.03362"
"67.10000","10.06125","0.03342"
"67.20000","10.07633","0.03391"
"67.30000","10.09139","0.03364"
"67.40000","10.10620","0.03361"
"67.50000","10.12124","0.03375"
"67.60000","10.13624","0.03374"
"67.70000","10.15116","0.03358"
"67.80000","10.16606","0.03394"
"67.90000","10.18105","0.03369"
"68.00000","10.19614","0.03379"
"68.10000","10.21113","0.03387"
"68.20000","10.22610","0.03391"
"68.30000","10.24114","0.03396"
"68.40000","10.25619","0.03382"
"68.50000","10.27112","0.03392"
"68.60000","10.28608","0.03384"
"68.70000","10.30116","0.03404"
"68.80000","10.31627","0.03413"
"68.90000","10.33123","0.03412"
"69.00000","10.34618","0.03406"
"69.10000","10.36121","0.03395"
"69.20000","10.37626","0.03409"
"69.30000","10.39120","0.03423"
"69.40000","10.40615","0.03415"
"69.50000","10.42123","0.03423"
"69.60000","10.43627","0.03415"
"69.70000","10.45122","0.03455"
"69.80000","10.46620","0.03420"
"69.90000","10.48132","0.03429"
"70.00000","10.49633","0.03437"
"70.10000","10.51126","0.03431"
"70.20000","10.52629","0.03415"
"70.30000","10.54140","0.03451"
"70.40000","10.55641","0.03438"
"70.50000","10.57141","0.03452"
"70.60000","10.58750","0.03445"
"70.70000","10.60136","0.03432"
"70.80000","10.61612","0.03446"
"70.90000","10.63115","0.03453"
"71.00000","10.64616","0.03439"
"71.10000","10.66123","0.03448"
"71.20000","10.67616","0.03444"
"71.30000","10.69119","0.03439"
"71.40000","10.70628","0.03448"
"71.50000","10.72130","0.03435"
"71.60000","10.73614","0.03424"
"71.70000","10.75107","0.03464"
"71.80000","10.76618","0.03437"
"71.90000","10.78117","0.03458"
"72.00000","10.79612","0.03463"
"72.10000","10.81111","0.03441"
"72.20000","10.82616","0.03437"
"72.30000","10.84111","0.03473"
"72.40000","10.85609","0.03433"
"72.50000","10.87109","0.03467"
"72.60000","10.88629","0.03461"
"72.70000","10.90123","0.03459"
"72.80000","10.91611","0.03458"
"72.90000","10.93111","0.03512"
"73.00000","10.94620","0.03472"
"73.10000","10.96113","0.03463"
"73.20000","10.97613","0.03480"
"73.30000","10.99117","0.03500"
"73.40000","11.00625","0.03489"
"73.50000","11.02115","0.03496"
"73.60000","11.03610","0.03496"
"73.70000","11.05123","0.03500"
"73.80000","11.06628","0.03519"
"73.90000","11.08121","0.03498"
"74.00000","11.09618","0.03497"
"74.10000","11.11132","0.03506"
"74.20000","11.12634","0.03520"
"74.30000","11.14313","0.03502"
"74.40000","11.15639","0.03511"
"74.50000","11.17116","0.03515"
"74.60000","11.18611","0.03516"
"74.70000","11.20113","0.03519"
"74.80000","11.21619","0.03520"
"74.90000","11.23132","0.03533"
"75.00000","11.24624","0.03527"
"75.10000","11.26124","0.03539"
"75.20000","11.27625","0.03542"
"75.30000","11.29130","0.03527"
"75.40000","11.30617","0.03520"
"75.50000","11.32115","0.03535"
"75.60000","11.33621","0.03559"
"75.70000","11.35124","0.03550"
"75.80000","11.36617","0.03541"
"75.90000","11.38112","0.03528"
"76.00000","11.39621","0.03559"
"76.10000","11.41121","0.03567"
"76.20000","11.42611","0.03535"
"76.30000","11.44112","0.03542"
"76.40000","11.45619","0.03556"
"76.50000","11.47123","0.03553"
"76.60000","11.48623","0.03566"
"76.70000","11.50119","0.03563"
"76.80000","11.51621","0.03552"
"76.90000","11.53116","0.03558"
"77.00000","11.54609","0.03561"
"77.10000","11.56116","0.03564"
"77.20000","11.57623","0.03592"
"77.30000","11.59111","0.03604"
"77.40000","11.60607","0.03585"
"77.50000","11.62114","0.03578"
"77.60000","11.63620","0.03581"
"77.70000","11.65115","0.03592"
"77.80000","11.66612","0.03601"
"77.90000","11.68118","0.03589"
"78.00000","11.69622","0.03597"
"78.10000","11.71122","0.03587"
"78.20000","11.72620","0.03607"
"78.30000","11.74131","0.03622"
"78.40000","11.75640","0.03597"
"78.50000","11.77136","0.03595"
"78.60000","11.78630","0.03615"
"78.70000","11.80146","0.03590"
"78.80000","11.81684","0.03606"
"78.90000","11.83210","0.03635"
"79.00000","11.84618","0.03611"
"79.10000","11.86120","0.03607"
"79.20000","11.87621","0.03641"
"79.30000","11.89118","0.03635"
"79.40000","11.90621","0.03623"
"79.50000","11.92133","0.03657"
"79.60000","11.93625","0.03620"
"79.70000","11.95121","0.03616"
"79.80000","11.96624","0.03640"
"79.90000","11.98128","0.03633"
"80.00000","11.99625","0.03629"
"80.10000","12.01116","0.03625"
"80.20000","12.02617","0.03604"
"80.30000","12.04115","0.03610"
"80.40000","12.05609","0.03619"
"80.50000","12.07103","0.03593"
"80.60000","12.08613","0.03606"
"80.70000","12.10114","0.03574"
"80.80000","12.11606","0.03571"
"80.90000","12.13120","0.03589"
"81.00000","12.14624","0.03588"
"81.10000","12.16118","0.03592"
"81.20000","12.17612","0.03599"
"81.30000","12.19119","0.03581"
"81.40000","12.20754","0.03581"
"81.50000","12.22118","0.03584"
"81.60000","12.23594","0.03578"
"81.70000","12.25098","0.03579"
"81.80000","12.26609","0.03589"
"81.90000","12.28108","0.03571"
"82.00000","12.29609","0.03583"
"82.10000","12.31121","0.03586"
"82.20000","12.32627","0.03583"
"82.30000","12.34119","0.03596"
"82.40000","12.35611","0.03603"
"82.50000","12.37127","0.03570"
"82.60000","12.38629","0.03600"
"82.70000","12.40125","0.03610"
"82.80000","12.41626","0.03569"
"82.90000","12.43136","0.03592"
"83.00000","12.44640","0.03588"
"83.10000","12.46140","0.03589"
"83.20000","12.47644","0.03577"
"83.30000","12.49154","0.03597"
"83.40000","12.50646","0.03582"
"83.50000","12.52141","0.03579"
"83.60000","12.53650","0.03587"
"83.70000","12.55162","0.03587"
"83.80000","12.56642","0.03574"
"83.90000","12.58134","0.03592"
"84.00000","12.59636","0.03589"
"84.10000","12.61139","0.03589"
"84.20000","12.62626","0.03582"
"84.30000","12.64136","0.03582"
"84.40000","12.65634","0.03575"
"84.50000","12.67123","0.03589"
"84.60000","12.68610","0.03611"
"84.70000","12.70110","0.03581"
"84.80000","12.71619","0.03591"
"84.90000","12.73117","0.03589"
"85.00000","12.74609","0.03577"
"85.10000","12.76113","0.03585"
"85.20000","12.77627","0.03596"
"85.30000","12.79125","0.03594"
"85.40000","12.80630","0.03576"
"85.50000","12.82131","0.03601"
"85.60000","12.83639","0.03595"
"85.70000","12.85136","0.03591"
"85.80000","12.86621","0.03580"
"85.90000","12.88122","0.03595"
"86.00000","12.89625","0.03599"
"86.10000","12.91116","0.03573"
"86.20000","12.92611","0.03583"
"86.30000","12.94123","0.03592"
"86.40000","12.95629","0.03581"
"86.50000","12.97122","0.03611"
"86.60000","12.98620","0.03584"
"86.70000","13.00131","0.03567"
"86.80000","13.01630","0.03604"
"86.90000","13.03125","0.03600"
"87.00000","13.04624","0.03583"
"87.10000","13.06138","0.03617"
"87.20000","13.07637","0.03612"
"87.30000","13.09176","0.03584"
"87.40000","13.10744","0.03620"
"87.50000","13.12147","0.03606"
"87.60000","13.13625","0.03599"
"87.70000","13.15113","0.03623"
"87.80000","13.16620","0.03615"
"87.90000","13.18131","0.03611"
"88.00000","13.19625","0.03630"
"88.10000","13.21114","0.03617"
"88.20000","13.22622","0.03631"
"88.30000","13.24123","0.03617"
"88.40000","13.25617","0.03618"
"88.50000","13.27112","0.03606"
"88.60000","13.28616","0.03619"
"88.70000","13.30114","0.03626"
"88.80000","13.31603","0.03639"
"88.90000","13.33106","0.03639"
"89.00000","13.34610","0.03641"
"89.10000","13.36107","0.03654"
"89.20000","13.37607","0.03624"
"89.30000","13.39110","0.03621"
"89.40000","13.40620","0.03648"
"89.50000","13.42128","0.03638"
"89.60000","13.43617","0.03647"
"89.70000","13.45110","0.03651"
"89.80000","13.46621","0.03642"
"89.90000","13.48119","0.03650"
"90.00000","13.49623","0.03671"
"90.10000","13.51118","0.03633"
"90.20000","13.52624","0.03653"
"90.30000","13.54112","0.03652"
"90.40000","13.55615","0.03649"
"90.50000","13.57124","0.03651"
"90.60000","13.58629","0.03675"
"90.70000","13.60114","0.03656"
"90.80000","13.61616","0.03669"
"90.90000","13.63305","0.03672"
"91.00000","13.64641","0.03664"
"91.10000","13.66105","0.03665"
"91.20000","13.67609","0.03664"
"91.30000","13.69117","0.03666"
"91.40000","13.70620","0.03657"
"91.50000","13.72118","0.03664"
"91.60000","13.73625","0.03690"
"91.70000","13.75138","0.03666"
"91.80000","13.76632","0.03679"
"91.90000","13.78130","0.03712"
"92.00000","13.79636","0.03684"
"92.10000","13.81145","0.03677"
"92.20000","13.82643","0.03686"
"92.30000","13.84134","0.03675"
"92.40000","13.85627","0.03695"
"92.50000","13.87127","0.03683"
"92.60000","13.88618","0.03699"
"92.70000","13.90121","0.03709"
"92.80000","13.91629","0.03692"
"92.90000","13.93122","0.03711"
"93.00000","13.94606","0.03670"
"93.10000","13.96104","0.03681"
"93.20000","13.97615","0.03695"
"93.30000","13.99114","0.03711"
"93.40000","14.00613","0.03714"
"93.50000","14.02114","0.03713"
"93.60000","14.03619","0.03698"
"93.70000","14.05124","0.03685"
"93.80000","14.06617","0.03706"
"93.90000","14.08113","0.03702"
"94.00000","14.09629","0.03719"
"94.10000","14.11125","0.03706"
"94.20000","14.12615","0.03708"
"94.30000","14.14117","0.03715"
"94.40000","14.15623","0.03719"
"94.50000","14.17118","0.03710"
"94.60000","14.18617","0.03704"
"94.70000","14.20124","0.03713"
"94.80000","14.21630","0.03724"
"94.90000","14.23124","0.03709"
"95.00000","14.24621","0.03712"
"95.10000","14.26129","0.03731"
"95.20000","14.27632","0.03706"
"95.30000","14.29136","0.03729"
"95.40000","14.30635","0.03738"
"95.50000","14.32138","0.03699"
"95.60000","14.33632","0.03738"
"95.70000","14.35126","0.03759"
"95.80000","14.36627","0.03722"
"95.90000","14.38139","0.03762"
"96.00000","14.39633","0.03762"
"96.10000","14.41127","0.03748"
"96.20000","14.42630","0.03760"
"96.30000","14.44138","0.03741"
"96.40000","14.45796","0.03767"
"96.50000","14.47135","0.03763"
"96.60000","14.48614","0.03751"
"96.70000","14.50117","0.03755"
"96.80000","14.51609","0.03752"
"96.90000","14.53105","0.03759"
"97.00000","14.54610","0.03774"
"97.10000","14.56109","0.03767"
"97.20000","14.57599","0.03770"
"97.30000","14.59099","0.03780"
"97.40000","14.60608","0.03766"
"97.50000","14.62117","0.03767"
"97.60000","14.63607","0.03767"
"97.70000","14.65104","0.03759"
"97.80000","14.66614","0.03781"
"97.90000","14.68115","0.03786"
"98.00000","14.69612","0.03782"
"98.10000","14.71116","0.03788"
"98.20000","14.72624","0.03774"
"98.30000","14.74121","0.03770"
"98.40000","14.75620","0.03781"
"98.50000","14.77123","0.03775"
"98.60000","14.78630","0.03784"
"98.70000","14.80119","0.03792"
"98.80000","14.81619","0.03780"
"98.90000","14.83129","0.03795"
"99.00000","14.84628","0.03784"
"99.10000","14.86135","0.03786"
"99.20000","14.87626","0.03809"
"99.30000","14.89128","0.03784"
"99.40000","14.90629","0.03792"
"99.50000","14.92124","0.03805"
"99.60000","14.93626","0.03787"
"99.70000","14.95132","0.03783"
"99.80000","14.96632","0.03798"
"99.90000","14.98132","0.03793"
"100.00000","14.99634","0.03800"
"100.10000","15.01150","0.03812"
"100.20000","15.02643","0.03794"
"100.30000","15.04134","0.03819"
"100.40000","15.05636","0.03838"
"100.50000","15.07147","0.03814"
"100.60000","15.08642","0.03799"
"100.70000","15.10136","0.03841"
"100.80000","15.11650","0.03819"
"100.90000","15.13364","0.03835"
"101.00000","15.14654","0.03824"
"101.10000","15.16109","0.03826"
"101.20000","15.17604","0.03819"
"101.30000","15.19107","0.03823"
"101.40000","15.20597","0.03833"
"101.50000","15.22097","0.03830"
"101.60000","15.23602","0.03814"
"101.70000","15.25107","0.03820"
"101.80000","15.26602","0.03824"
"101.90000","15.28108","0.03823"
"102.00000","15.29619","0.03843"
"102.10000","15.31125","0.03812"
"102.20000","15.32611","0.03802"
"102.30000","15.34109","0.03819"
"102.40000","15.35621","0.03832"
"102.50000","15.37117","0.03824"
"102.60000","15.38616","0.03826"
"102.70000","15.40121","0.03819"
"102.80000","15.41624","0.03806"
"102.90000","15.43115","0.03820"
"103.00000","15.44608","0.03829"
"103.10000","15.46122","0.03815"
"103.20000","15.47628","0.03823"
"103.30000","15.49127","0.03818"
"103.40000","15.50619","0.03816"
"103.50000","15.52129","0.03821"
"103.60000","15.53628","0.03817"
"103.70000","15.55126","0.03821"
"103.80000","15.56761","0.03811"
"103.90000","15.58142","0.03837"
"104.00000","15.59620","0.03810"
"104.10000","15.61109","0.03823"
"104.20000","15.62617","0.03840"
"104.30000","15.64128","0.03800"
"104.40000","15.65629","0.03823"
"104.50000","15.67126","0.03840"
"104.60000","15.68632","0.03805"
"104.70000","15.70139","0.03801"
"104.80000","15.71636","0.03849"
"104.90000","15.73132","0.03815"
"105.00000","15.74632","0.03817"
"105.10000","15.76137","0.03816"
"105.20000","15.77628","0.03829"
"105.30000","15.79130","0.03826"
"105.40000","15.80628","0.03797"
"105.50000","15.82126","0.03810"
"105.60000","15.83615","0.03814"
"105.70000","15.85113","0.03794"
"105.80000","15.86620","0.03810"
"105.90000","15.88120","0.03813"
"106.00000","15.89606","0.03785"
"106.10000","15.91106","0.03793"
"106.20000","15.92616","0.03795"
"106.30000","15.94119","0.03778"
"106.40000","15.95612","0.03807"
"106.50000","15.97111","0.03792"
"106.60000","15.98624","0.03767"
"106.70000","16.00117","0.03779"
"106.80000","16.01739","0.03795"
"106.90000","16.03123","0.03765"
"107.00000","16.04612","0.03785"
"107.10000","16.06102","0.03777"
"107.20000","16.07604","0.03770"
"107.30000","16.09118","0.03781"
"107.40000","16.10623","0.03775"
"107.50000","16.12117","0.03758"
"107.60000","16.13616","0.03775"
"107.70000","16.15125","0.03776"
"107.80000","16.16630","0.03753"
"107.90000","16.18126","0.03777"
"108.00000","16.19629","0.03767"
"108.10000","16.21138","0.03781"
"108.20000","16.22637","0.03752"
"108.30000","16.24129","0.03781"
"108.40000","16.25633","0.03781"
"108.50000","16.27151","0.03760"
"108.60000","16.28654","0.03754"
"108.70000","16.30145","0.03766"
"108.80000","16.31648","0.03768"
"108.90000","16.33153","0.03774"
"109.00000","16.34643","0.03778"
"109.10000","16.36140","0.03753"
"109.20000","16.37644","0.03758"
"109.30000","16.39143","0.03769"
"109.40000","16.40644","0.03749"
"109.50000","16.42183","0.03759"
"109.60000","16.43644","0.03788"
"109.70000","16.45131","0.03735"
"109.80000","16.46619","0.03743"
"109.90000","16.48115","0.03753"
"110.00000","16.49623","0.03743"
"110.10000","16.51122","0.03759"
"110.20000","16.52611","0.03751"
"110.30000","16.54111","0.03734"
"110.40000","16.55628","0.03744"
"110.50000","16.57130","0.03774"
"110.60000","16.58622","0.03742"
"110.70000","16.60120","0.03742"
"110.80000","16.61629","0.03748"
"110.90000","16.63125","0.03739"
"111.00000","16.64621","0.03738"
"111.10000","16.66128","0.03734"
"111.20000","16.67632","0.03744"
"111.30000","16.69120","0.03729"
"111.40000","16.70619","0.03727"
"111.50000","16.72126","0.03743"
"111.60000","16.73633","0.03749"
"111.70000","16.75127","0.03713"
"111.80000","16.76625","0.03749"
"111.90000","16.78133","0.03742"
"112.00000","16.79638","0.03708"
"112.10000","16.81133","0.03744"
"112.20000","16.82632","0.03726"
"112.30000","16.84145","0.03707"
"112.40000","16.85644","0.03723"
"112.50000","16.87139","0.03728"
"112.60000","16.88637","0.03723"
"112.70000","16.90150","0.03719"
"112.80000","16.91651","0.03716"
"112.90000","16.93143","0.03727"
"113.00000","16.94645","0.03712"
"113.10000","16.96161","0.03707"
"113.20000","16.97696","0.03718"
"113.30000","16.99271","0.03706"
"113.40000","17.00665","0.03725"
"113.50000","17.02138","0.03738"
"113.60000","17.03622","0.03723"
"113.70000","17.05114","0.03717"
"113.80000","17.06621","0.03722"
"113.90000","17.08127","0.03719"
"114.00000","17.09621","0.03714"
"114.10000","17.11112","0.03710"
"114.20000","17.12621","0.03708"
"114.30000","17.14119","0.03716"
"114.40000","17.15609","0.03728"
"114.50000","17.17104","0.03701"
"114.60000","17.18616","0.03710"
"114.70000","17.20112","0.03706"
"114.80000","17.21612","0.03704"
"114.90000","17.23116","0.03706"
"115.00000","17.24625","0.03723"
"115.10000","17.26119","0.03697"
"115.20000","17.27625","0.03709"
"115.30000","17.29122","0.03714"
"115.40000","17.30620","0.03698"
"115.50000","17.32118","0.03677"
"115.60000","17.33612","0.03690"
"115.70000","17.35126","0.03679"
"115.80000","17.36633","0.03679"
"115.90000","17.38122","0.03698"
"116.00000","17.39617","0.03690"
"116.10000","17.41123","0.03673"
"116.20000","17.42632","0.03684"
"116.30000","17.44124","0.03656"
"116.40000","17.45625","0.03664"
"116.50000","17.47133","0.03656"
"116.60000","17.48634","0.03638"
"116.70000","17.50130","0.03656"
"116.80000","17.51629","0.03665"
"116.90000","17.53137","0.03647"
"117.00000","17.54635","0.03647"
"117.10000","17.56127","0.03628"
"117.20000","17.57631","0.03623"
"117.30000","17.59143","0.03643"
"117.40000","17.60643","0.03630"
"117.50000","17.62256","0.03618"
"117.60000","17.63653","0.03613"
"117.70000","17.65139","0.03606"
"117.80000","17.66621","0.03609"
"117.90000","17.68116","0.03603"
"118.00000","17.69620","0.03588"
"118.10000","17.71126","0.03596"
"118.20000","17.72616","0.03584"
"118.30000","17.74115","0.03555"
"118.40000","17.75621","0.03571"
"118.50000","17.77113","0.03561"
"118.60000","17.78603","0.03512"
"118.70000","17.80108","0.03521"
"118.80000","17.81620","0.03505"
"118.90000","17.83120","0.03471"
"119.00000","17.84612","0.03477"
"119.10000","17.86107","0.03475"
"119.20000","17.87620","0.03433"
"119.30000","17.89121","0.03439"
"119.40000","17.90618","0.03436"
"119.50000","17.92122","0.03412"
"119.60000","17.93627","0.03417"
"119.70000","17.95119","0.03404"
"119.80000","17.96619","0.03389"
"119.90000","17.98124","0.03389"
"120.00000","17.99631","0.03386"
"120.10000","18.01136","0.03374"
"120.20000","18.02622","0.03373"
"120.30000","18.04131","0.03345"
"120.40000","18.05630","0.03358"
"120.50000","18.07122","0.03334"
"120.60000","18.08620","0.03346"
"120.70000","18.10135","0.03329"
"120.80000","18.11639","0.03325"
"120.90000","18.13130","0.03327"
"121.00000","18.14625","0.03290"
"121.10000","18.16135","0.03288"
"121.20000","18.17638","0.03300"
"121.30000","18.19131","0.03273"
"121.40000","18.20638","0.03280"
"121.50000","18.22149","0.03277"
"121.60000","18.23644","0.03263"
"121.70000","18.25144","0.03251"
"121.80000","18.26806","0.03248"
"121.90000","18.28156","0.03256"
"122.00000","18.29616","0.03221"
"122.10000","18.31106","0.03227"
"122.20000","18.32615","0.03252"
"122.30000","18.34124","0.03229"
"122.40000","18.35618","0.03210"
"122.50000","18.37115","0.03224"
"122.60000","18.38623","0.03226"
"122.70000","18.40124","0.03217"
"122.80000","18.41618","0.03209"
"122.90000","18.43117","0.03208"
"123.00000","18.44624","0.03198"
"123.10000","18.46124","0.03181"
"123.20000","18.47614","0.03201"
"123.30000","18.49113","0.03193"
"123.40000","18.50619","0.03183"
"123.50000","18.52127","0.03189"
"123.60000","18.53615","0.03183"
"123.70000","18.55117","0.03161"
"123.80000","18.56625","0.03177"
"123.90000","18.58123","0.03174"
"124.00000","18.59624","0.03139"
"124.10000","18.61126","0.03180"
"124.20000","18.62628","0.03170"
"124.30000","18.64120","0.03124"
"124.40000","18.65623","0.03153"
"124.50000","18.67129","0.03154"
"124.60000","18.68630","0.03106"
"124.70000","18.70119","0.03126"
"124.80000","18.71619","0.03107"
"124.90000","18.73134","0.03092"
"125.00000","18.74653","0.03113"
"125.10000","18.76137","0.03092"
"125.20000","18.77643","0.03069"
"125.30000","18.79145","0.03071"
"125.40000","18.80638","0.03087"
"125.50000","18.82127","0.03067"
"125.60000","18.83629","0.03078"
"125.70000","18.85140","0.03047"
"125.80000","18.86637","0.03040"
"125.90000","18.88134","0.03046"
"126.00000","18.89637","0.03054"
"126.10000","18.91142","0.03045"
"126.20000","18.92632","0.03035"
"126.30000","18.94128","0.03037"
"126.40000","18.95631","0.03031"
"126.50000","18.97135","0.03019"
"126.60000","18.98626","0.03014"
"126.70000","19.00125","0.03030"
"126.80000","19.01636","0.03018"
"126.90000","19.03157","0.03034"
"127.00000","19.04627","0.03023"
"127.10000","19.06124","0.03008"
"127.20000","19.07633","0.02991"
"127.30000","19.09121","0.03007"
"127.40000","19.10605","0.03013"
"127.50000","19.12107","0.02989"
"127.60000","19.13623","0.03005"
"127.70000","19.15120","0.03003"
"127.80000","19.16619","0.03002"
"127.90000","19.18115","0.02991"
"128.00000","19.19623","0.02980"
"128.10000","19.21121","0.02971"
"128.20000","19.22621","0.02998"
"128.30000","19.24125","0.02986"
"128.40000","19.25633","0.02982"
"128.50000","19.27120","0.02973"
"128.60000","19.28618","0.02970"
"128.70000","19.30129","0.02977"
"128.80000","19.31631","0.02962"
"128.90000","19.33121","0.02958"
"129.00000","19.34623","0.02956"
"129.10000","19.36128","0.02949"
"129.20000","19.37628","0.02956"
"129.30000","19.39128","0.02957"
"129.40000","19.40629","0.02934"
"129.50000","19.42137","0.02972"
"129.60000","19.43638","0.02944"
"129.70000","19.45344","0.02926"
"129.80000","19.46673","0.02923"
"129.90000","19.48145","0.02920"
"130.00000","19.49620","0.02913"
"130.10000","19.51106","0.02924"
"130.20000","19.52618","0.02908"
"130.30000","19.54123","0.02903"
"130.40000","19.55614","0.02917"
"130.50000","19.57110","0.02908"
"130.60000","19.58615","0.02892"
"130.70000","19.60118","0.02885"
"130.80000","19.61616","0.02907"
"130.90000","19.63113","0.02886"
"131.00000","19.64616","0.02890"
"131.10000","19.66117","0.02878"
"131.20000","19.67609","0.02883"
"131.30000","19.69109","0.02871"
"131.40000","19.70616","0.02883"
"131.50000","19.72111","0.02863"
"131.60000","19.73603","0.02864"
"131.70000","19.75110","0.02871"
"131.80000","19.76617","0.02866"
"131.90000","19.78115","0.02849"
"132.00000","19.79608","0.02829"
"132.10000","19.81107","0.02850"
"132.20000","19.82621","0.02839"
"132.30000","19.84114","0.02828"
"132.40000","19.85611","0.02848"
"132.50000","19.87120","0.02808"
"132.60000","19.88625","0.02805"
"132.70000","19.90218","0.02850"
"132.80000","19.91620","0.02813"
"132.90000","19.93120","0.02787"
"133.00000","19.94614","0.02814"
"133.10000","19.96112","0.02806"
"133.20000","19.97610","0.02765"
"133.30000","19.99128","0.02807"
"133.40000","20.00628","0.02799"
"133.50000","20.02120","0.02790"
"133.60000","20.03617","0.02792"
"133.70000","20.05126","0.02786"
"133.80000","20.06625","0.02780"
"133.90000","20.08121","0.02789"
"134.00000","20.09626","0.02781"
"134.10000","20.11134","0.02788"
"134.20000","20.12627","0.02784"
"134.30000","20.14125","0.02801"
"134.40000","20.15626","0.02770"
"134.50000","20.17137","0.02763"
"134.60000","20.18633","0.02769"
"134.70000","20.20128","0.02794"
"134.80000","20.21632","0.02774"
"134.90000","20.23141","0.02769"
"135.00000","20.24628","0.02756"
"135.10000","20.26123","0.02755"
"135.20000","20.27629","0.02759"
"135.30000","20.29150","0.02745"
"135.40000","20.30624","0.02738"
"135.50000","20.32123","0.02769"
"135.60000","20.33632","0.02747"
"135.70000","20.35124","0.02739"
"135.80000","20.36616","0.02735"
"135.90000","20.38115","0.02723"
"136.00000","20.39625","0.02720"
"136.10000","20.41122","0.02720"
"136.20000","20.42616","0.02730"
"136.30000","20.44116","0.02720"
"136.40000","20.45627","0.02694"
"136.50000","20.47128","0.02702"
"136.60000","20.48622","0.02714"
"136.70000","20.50127","0.02681"
"136.80000","20.51630","0.02700"
"136.90000","20.53123","0.02696"
"137.00000","20.54626","0.02658"
"137.10000","20.56131","0.02695"
"137.20000","20.57631","0.02684"
"137.30000","20.59124","0.02670"
"137.40000","20.60620","0.02647"
"137.50000","20.62131","0.02655"
"137.60000","20.63634","0.02637"
"137.70000","20.65130","0.02635"
"137.80000","20.66628","0.02627"
"137.90000","20.68135","0.02622"
"138.00000","20.69634","0.02642"
"138.10000","20.71129","0.02635"
"138.20000","20.72631","0.02614"
"138.30000","20.74140","0.02595"
"138.40000","20.75640","0.02597"
"138.50000","20.77315","0.02576"
"138.60000","20.78677","0.02597"
"138.70000","20.80149","0.02577"
"138.80000","20.81624","0.02560"
"138.90000","20.83115","0.02532"
"139.00000","20.84620","0.02555"
"139.10000","20.86126","0.02537"
"139.20000","20.87625","0.02504"
"139.30000","20.89121","0.02531"
"139.40000","20.90626","0.02483"
"139.50000","20.92129","0.02465"
"139.60000","20.93621","0.02463"
"139.70000","20.95120","0.02433"
"139.80000","20.96632","0.02369"
"139.90000","20.98126","0.02299"
"140.00000","20.99611","0.02211"
"140.10000","21.01114","0.02121"
"140.20000","21.02619","0.02076"
"140.30000","21.04114","0.01995"
"140.40000","21.05612","0.01871"
"140.50000","21.07113","0.01680"
"140.60000","21.08624","0.01194"
"140.70000","21.10117","0.00743"
"140.80000","21.11613","0.00569"
"140.90000","21.13113","0.00449"
"141.00000","21.14621","0.00185"
"141.10000","21.16115","-0.00106"
"141.20000","21.17613","-0.00663"
"141.30000","21.19122","-0.00891"
"141.40000","21.20629","-0.01050"
"141.50000","21.22121","-0.01434"
"141.60000","21.23620","-0.01478"
"141.70000","21.25128","-0.01493"
"141.80000","21.26634","-0.01480"
"141.90000","21.28125","-0.01467"
"142.00000","21.29623","-0.01476"
"142.10000","21.31131","-0.01493"
"142.20000","21.32636","-0.01465"
"142.30000","21.34138","-0.01474"
"142.40000","21.35644","-0.01468"
"142.50000","21.37142","-0.01474"
"142.60000","21.38634","-0.01496"
"142.70000","21.40116","-0.01495"
"142.80000","21.41623","-0.01475"
"142.90000","21.43132","-0.01498"
"143.00000","21.44628","-0.01493"
"143.10000","21.46124","-0.01473"
"143.20000","21.47631","-0.01486"
"143.30000","21.49136","-0.01491"
"143.40000","21.50628","-0.01469"
"143.50000","21.52123","-0.01506"
"143.60000","21.53630","-0.01505"
"143.70000","21.55121","-0.01487"
"143.80000","21.56630","-0.01486"
"143.90000","21.58119","-0.01490"
"144.00000","21.59628","-0.01487"
"144.10000","21.61127","-0.01477"
"144.20000","21.62621","-0.01463"
"144.30000","21.64111","-0.01516"
"144.40000","21.65630","-0.01479"
"144.50000","21.67125","-0.01468"
"144.60000","21.68611","-0.01501"
"144.70000","21.70123","-0.01472"
"144.80000","21.71627","-0.01465"
"144.90000","21.73129","-0.01500"
"145.00000","21.74615","-0.01470"
"145.10000","21.76119","-0.01503"
"145.20000","21.77629","-0.01493"
"145.30000","21.79170","-0.01463"
"145.40000","21.80759","-0.01494"
"145.50000","21.82155","-0.01513"
"145.60000","21.83618","-0.01482"
"145.70000","21.85105","-0.01491"
"145.80000","21.86599","-0.01492"
"145.90000","21.88111","-0.01480"
"146.00000","21.89610","-0.01507"
"146.10000","21.91102","-0.01497"
"146.20000","21.92601","-0.01476"
"146.30000","21.94119","-0.01493"
"146.40000","21.95621","-0.01493"
"146.50000","21.97115","-0.01505"
"146.60000","21.98619","-0.01477"
"146.70000","22.00134","-0.01505"
"146.80000","22.01612","-0.01481"
"146.90000","22.03128","-0.01493"
"147.00000","22.04616","-0.01486"
"147.10000","22.06135","-0.01498"
"147.20000","22.07619","-0.01511"
"147.30000","22.09123","-0.01489"
"147.40000","22.10622","-0.01491"
"147.50000","22.12134","-0.01513"
"147.60000","22.13625","-0.01491"
"147.70000","22.15123","-0.01489"
"147.80000","22.16622","-0.01520"
"147.90000","22.18126","-0.01474"
"148.00000","22.19617","-0.01501"
"148.10000","22.21115","-0.01495"
"148.20000","22.22621","-0.01472"
"148.30000","22.24114","-0.01514"
"148.40000","22.25612","-0.01514"
"148.50000","22.27106","-0.01484"
"148.60000","22.28623","-0.01498"
"148.68900","22.29954","-0.01473"