File: 15G1650/ST 15G1650_001.csv
Rate 1,"0.50000",mm/s
Start date,"8/11/2021"
Specimen label,""

Time,Extension,Beam 1 Kg Load Cell
(s),(mm),(N)
"0.00000","0.00000","-0.00198"
"0.05000","0.00000","-0.00147"
"0.10000","0.00233","-0.00151"
"0.15000","0.01933","-0.00132"
"0.20000","0.04113","-0.00134"
"0.25000","0.06578","-0.00118"
"0.30000","0.09176","-0.00116"
"0.35000","0.11798","-0.00058"
"0.40000","0.14474","-0.00051"
"0.45000","0.17200","-0.00015"
"0.50000","0.19888","-0.00030"
"0.55000","0.22596","0.00022"
"0.60000","0.25304","0.00045"
"0.65000","0.28011","0.00082"
"0.70000","0.30710","0.00094"
"0.75000","0.33388","0.00133"
"0.80000","0.36055","0.00116"
"0.85000","0.38721","0.00172"
"0.90000","0.41384","0.00177"
"0.95000","0.44038","0.00250"
"1.00000","0.46674","0.00240"
"1.05000","0.49311","0.00272"
"1.10000","0.52045","0.00278"
"1.15000","0.54619","0.00324"
"1.20000","0.57192","0.00336"
"1.25000","0.59795","0.00385"
"1.30000","0.62378","0.00407"
"1.35000","0.64966","0.00425"
"1.40000","0.67563","0.00424"
"1.45000","0.70140","0.00445"
"1.50000","0.72716","0.00495"
"1.55000","0.75286","0.00537"
"1.60000","0.77846","0.00526"
"1.65000","0.80410","0.00568"
"1.70000","0.82968","0.00569"
"1.75000","0.85534","0.00607"
"1.80000","0.88077","0.00633"
"1.85000","0.90623","0.00648"
"1.90000","0.93169","0.00670"
"1.95000","0.95725","0.00657"
"2.00000","0.98280","0.00721"
"2.05000","1.00833","0.00742"
"2.10000","1.03368","0.00794"
"2.15000","1.05898","0.00828"
"2.20000","1.08415","0.00810"
"2.25000","1.10966","0.00839"
"2.30000","1.13481","0.00867"
"2.35000","1.15996","0.00862"
"2.40000","1.18536","0.00931"
"2.45000","1.21071","0.00948"
"2.50000","1.23610","0.00971"
"2.55000","1.26189","0.00965"
"2.60000","1.28657","0.01000"
"2.65000","1.31155","0.01023"
"2.70000","1.33670","0.01073"
"2.75000","1.36200","0.01094"
"2.80000","1.38708","0.01136"
"2.85000","1.41216","0.01109"
"2.90000","1.43724","0.01133"
"2.95000","1.46234","0.01162"
"3.00000","1.48741","0.01232"
"3.05000","1.51245","0.01238"
"3.10000","1.53755","0.01257"
"3.15000","1.56270","0.01253"
"3.20000","1.58784","0.01322"
"3.25000","1.61299","0.01315"
"3.30000","1.63820","0.01363"
"3.35000","1.66335","0.01384"
"3.40000","1.68842","0.01393"
"3.45000","1.71372","0.01392"
"3.50000","1.73924","0.01440"
"3.55000","1.76394","0.01470"
"3.60000","1.78880","0.01518"
"3.65000","1.81377","0.01530"
"3.70000","1.83879","0.01565"
"3.75000","1.86362","0.01557"
"3.80000","1.88854","0.01599"
"3.85000","1.91360","0.01594"
"3.90000","1.93882","0.01646"
"3.95000","1.96392","0.01624"
"4.00000","1.98883","0.01697"
"4.05000","2.01370","0.01717"
"4.10000","2.03873","0.01761"
"4.15000","2.06368","0.01800"
"4.20000","2.08849","0.01777"
"4.25000","2.11362","0.01830"
"4.30000","2.13908","0.01830"
"4.35000","2.16447","0.01876"
"4.40000","2.18900","0.01868"
"4.45000","2.21383","0.01914"
"4.50000","2.23884","0.01952"
"4.55000","2.26378","0.01996"
"4.60000","2.28882","0.02011"
"4.65000","2.31375","0.02013"
"4.70000","2.33892","0.02013"
"4.75000","2.36384","0.02081"
"4.80000","2.38877","0.02088"
"4.85000","2.41383","0.02154"
"4.90000","2.43890","0.02147"
"4.95000","2.46387","0.02175"
"5.00000","2.48882","0.02171"
"5.05000","2.51390","0.02247"
"5.10000","2.53894","0.02257"
"5.15000","2.56388","0.02299"
"5.20000","2.58893","0.02296"
"5.25000","2.61393","0.02308"
"5.30000","2.63899","0.02345"
"5.35000","2.66386","0.02378"
"5.40000","2.68889","0.02410"
"5.45000","2.71489","0.02464"
"5.50000","2.73952","0.02435"
"5.55000","2.76404","0.02483"
"5.60000","2.78889","0.02488"
"5.65000","2.81375","0.02540"
"5.70000","2.83870","0.02571"
"5.75000","2.86366","0.02595"
"5.80000","2.88880","0.02608"
"5.85000","2.91383","0.02642"
"5.90000","2.93882","0.02657"
"5.95000","2.96381","0.02711"
"6.00000","2.98885","0.02733"
"6.05000","3.01388","0.02775"
"6.10000","3.03883","0.02776"
"6.15000","3.06388","0.02798"
"6.20000","3.08888","0.02835"
"6.25000","3.11390","0.02864"
"6.30000","3.13891","0.02903"
"6.35000","3.16394","0.02930"
"6.40000","3.18890","0.02958"
"6.45000","3.21393","0.02971"
"6.50000","3.23889","0.03006"
"6.55000","3.26480","0.03039"
"6.60000","3.28928","0.03084"
"6.65000","3.31404","0.03082"
"6.70000","3.33881","0.03101"
"6.75000","3.36376","0.03121"
"6.80000","3.38867","0.03171"
"6.85000","3.41371","0.03184"
"6.90000","3.43863","0.03244"
"6.95000","3.46359","0.03238"
"7.00000","3.48865","0.03297"
"7.05000","3.51370","0.03306"
"7.10000","3.53870","0.03348"
"7.15000","3.56379","0.03373"
"7.20000","3.58879","0.03413"
"7.25000","3.61378","0.03420"
"7.30000","3.63881","0.03479"
"7.35000","3.66399","0.03488"
"7.40000","3.68978","0.03548"
"7.45000","3.71429","0.03558"
"7.50000","3.73907","0.03591"
"7.55000","3.76408","0.03604"
"7.60000","3.78894","0.03639"
"7.65000","3.81391","0.03672"
"7.70000","3.83890","0.03708"
"7.75000","3.86387","0.03721"
"7.80000","3.88889","0.03758"
"7.85000","3.91387","0.03776"
"7.90000","3.93890","0.03829"
"7.95000","3.96374","0.03869"
"8.00000","3.98867","0.03887"
"8.05000","4.01364","0.03904"
"8.10000","4.03859","0.03941"
"8.15000","4.06357","0.03965"
"8.20000","4.08873","0.04023"
"8.25000","4.11371","0.04035"
"8.30000","4.13881","0.04074"
"8.35000","4.16409","0.04099"
"8.40000","4.18908","0.04141"
"8.45000","4.21398","0.04177"
"8.50000","4.23896","0.04202"
"8.55000","4.26398","0.04223"
"8.60000","4.28896","0.04249"
"8.65000","4.31396","0.04284"
"8.70000","4.33897","0.04299"
"8.75000","4.36499","0.04379"
"8.80000","4.38944","0.04381"
"8.85000","4.41418","0.04410"
"8.90000","4.43908","0.04425"
"8.95000","4.46394","0.04475"
"9.00000","4.48893","0.04505"
"9.05000","4.51390","0.04554"
"9.10000","4.53877","0.04552"
"9.15000","4.56368","0.04601"
"9.20000","4.58867","0.04610"
"9.25000","4.61385","0.04663"
"9.30000","4.63875","0.04701"
"9.35000","4.66356","0.04766"
"9.40000","4.68850","0.04778"
"9.45000","4.71344","0.04794"
"9.50000","4.73854","0.04825"
"9.55000","4.76365","0.04875"
"9.60000","4.78874","0.04903"
"9.65000","4.81389","0.04949"
"9.70000","4.83900","0.04948"
"9.75000","4.86386","0.05005"
"9.80000","4.88877","0.05018"
"9.85000","4.91377","0.05073"
"9.90000","4.93876","0.05112"
"9.95000","4.96389","0.05159"
"10.00000","4.98886","0.05160"
"10.05000","5.01386","0.05206"
"10.10000","5.03898","0.05220"
"10.15000","5.06400","0.05274"
"10.20000","5.09021","0.05305"
"10.25000","5.11458","0.05348"
"10.30000","5.13929","0.05389"
"10.35000","5.16421","0.05413"
"10.40000","5.18908","0.05437"
"10.45000","5.21395","0.05483"
"10.50000","5.23882","0.05510"
"10.55000","5.26377","0.05556"
"10.60000","5.28875","0.05577"
"10.65000","5.31382","0.05645"
"10.70000","5.33881","0.05663"
"10.75000","5.36381","0.05698"
"10.80000","5.38876","0.05739"
"10.85000","5.41381","0.05769"
"10.90000","5.43882","0.05814"
"10.95000","5.46382","0.05818"
"11.00000","5.48900","0.05887"
"11.05000","5.51485","0.05906"
"11.10000","5.53934","0.05954"
"11.15000","5.56410","0.05971"
"11.20000","5.58897","0.06027"
"11.25000","5.61400","0.06071"
"11.30000","5.63890","0.06108"
"11.35000","5.66387","0.06118"
"11.40000","5.68879","0.06177"
"11.45000","5.71382","0.06191"
"11.50000","5.73879","0.06250"
"11.55000","5.76384","0.06254"
"11.60000","5.78887","0.06316"
"11.65000","5.81410","0.06325"
"11.70000","5.83902","0.06405"
"11.75000","5.86392","0.06410"
"11.80000","5.88885","0.06487"
"11.85000","5.91379","0.06486"
"11.90000","5.93869","0.06524"
"11.95000","5.96377","0.06547"
"12.00000","5.98894","0.06618"
"12.05000","6.01412","0.06661"
"12.10000","6.03899","0.06696"
"12.15000","6.06396","0.06720"
"12.20000","6.08887","0.06782"
"12.25000","6.11382","0.06804"
"12.30000","6.13884","0.06864"
"12.35000","6.16379","0.06876"
"12.40000","6.18887","0.06949"
"12.45000","6.21385","0.06951"
"12.50000","6.23888","0.06994"
"12.55000","6.26389","0.07044"
"12.60000","6.28953","0.07090"
"12.65000","6.31404","0.07157"
"12.70000","6.33882","0.07175"
"12.75000","6.36385","0.07187"
"12.80000","6.38885","0.07232"
"12.85000","6.41369","0.07256"
"12.90000","6.43868","0.07339"
"12.95000","6.46375","0.07381"
"13.00000","6.48886","0.07414"
"13.05000","6.51465","0.07440"
"13.10000","6.53966","0.07461"
"13.15000","6.56416","0.07532"
"13.20000","6.58894","0.07571"
"13.25000","6.61391","0.07632"
"13.30000","6.63896","0.07653"
"13.35000","6.66388","0.07696"
"13.40000","6.68893","0.07705"
"13.45000","6.71391","0.07778"
"13.50000","6.73891","0.07823"
"13.55000","6.76468","0.07865"
"13.60000","6.78928","0.07892"
"13.65000","6.81398","0.07960"
"13.70000","6.83888","0.07987"
"13.75000","6.86385","0.08039"
"13.80000","6.88881","0.08040"
"13.85000","6.91376","0.08115"
"13.90000","6.93884","0.08138"
"13.95000","6.96385","0.08202"
"14.00000","6.98891","0.08207"
"14.05000","7.01391","0.08278"
"14.10000","7.03886","0.08307"
"14.15000","7.06378","0.08374"
"14.20000","7.08877","0.08389"
"14.25000","7.11380","0.08458"
"14.30000","7.13884","0.08480"
"14.35000","7.16389","0.08532"
"14.40000","7.18908","0.08560"
"14.45000","7.21412","0.08620"
"14.50000","7.23906","0.08667"
"14.55000","7.26398","0.08709"
"14.60000","7.28895","0.08759"
"14.65000","7.31393","0.08811"
"14.70000","7.33889","0.08839"
"14.75000","7.36395","0.08881"
"14.80000","7.38890","0.08925"
"14.85000","7.41390","0.08970"
"14.90000","7.43895","0.09019"
"14.95000","7.46393","0.09051"
"15.00000","7.48898","0.09100"
"15.05000","7.51412","0.09140"
"15.10000","7.53946","0.09182"
"15.15000","7.56524","0.09242"
"15.20000","7.58946","0.09299"
"15.25000","7.61407","0.09326"
"15.30000","7.63888","0.09371"
"15.35000","7.66387","0.09412"
"15.40000","7.68880","0.09480"
"15.45000","7.71381","0.09501"
"15.50000","7.73888","0.09568"
"15.55000","7.76389","0.09579"
"15.60000","7.78886","0.09653"
"15.65000","7.81380","0.09677"
"15.70000","7.83872","0.09762"
"15.75000","7.86373","0.09805"
"15.80000","7.88879","0.09846"
"15.85000","7.91399","0.09840"
"15.90000","7.93923","0.09923"
"15.95000","7.96421","0.09954"
"16.00000","7.98910","0.10055"
"16.05000","8.01409","0.10068"
"16.10000","8.03897","0.10137"
"16.15000","8.06395","0.10145"
"16.20000","8.08890","0.10214"
"16.25000","8.11381","0.10245"
"16.30000","8.13879","0.10333"
"16.35000","8.16373","0.10375"
"16.40000","8.18872","0.10411"
"16.45000","8.21383","0.10448"
"16.50000","8.23890","0.10500"
"16.55000","8.26400","0.10555"
"16.60000","8.28903","0.10626"
"16.65000","8.31400","0.10662"
"16.70000","8.33897","0.10722"
"16.75000","8.36395","0.10726"
"16.80000","8.38899","0.10795"
"16.85000","8.41393","0.10833"
"16.90000","8.43887","0.10904"
"16.95000","8.46380","0.10944"
"17.00000","8.48875","0.10992"
"17.05000","8.51366","0.11046"
"17.10000","8.53864","0.11079"
"17.15000","8.56366","0.11138"
"17.20000","8.58912","0.11180"
"17.25000","8.61527","0.11238"
"17.30000","8.63932","0.11299"
"17.35000","8.66400","0.11329"
"17.40000","8.68891","0.11371"
"17.45000","8.71378","0.11450"
"17.50000","8.73875","0.11488"
"17.55000","8.76375","0.11547"
"17.60000","8.78886","0.11580"
"17.65000","8.81389","0.11650"
"17.70000","8.83883","0.11666"
"17.75000","8.86379","0.11739"
"17.80000","8.88879","0.11783"
"17.85000","8.91377","0.11866"
"17.90000","8.93886","0.11890"
"17.95000","8.96391","0.11941"
"18.00000","8.98901","0.11979"
"18.05000","9.01435","0.12040"
"18.10000","9.03925","0.12056"
"18.15000","9.06423","0.12169"
"18.20000","9.08912","0.12193"
"18.25000","9.11395","0.12267"
"18.30000","9.13892","0.12282"
"18.35000","9.16384","0.12346"
"18.40000","9.18887","0.12405"
"18.45000","9.21380","0.12470"
"18.50000","9.23876","0.12503"
"18.55000","9.26379","0.12577"
"18.60000","9.28879","0.12583"
"18.65000","9.31422","0.12658"
"18.70000","9.33908","0.12707"
"18.75000","9.36409","0.12796"
"18.80000","9.38908","0.12821"
"18.85000","9.41399","0.12848"
"18.90000","9.43900","0.12916"
"18.95000","9.46390","0.12973"
"19.00000","9.48884","0.13024"
"19.05000","9.51387","0.13101"
"19.10000","9.53884","0.13125"
"19.15000","9.56397","0.13190"
"19.20000","9.58925","0.13201"
"19.25000","9.61458","0.13280"
"19.30000","9.64098","0.13363"
"19.35000","9.66480","0.13414"
"19.40000","9.68940","0.13462"
"19.45000","9.71409","0.13480"
"19.50000","9.73895","0.13566"
"19.55000","9.76386","0.13635"
"19.60000","9.78869","0.13688"
"19.65000","9.81357","0.13729"
"19.70000","9.83855","0.13806"
"19.75000","9.86353","0.13820"
"19.80000","9.88854","0.13895"
"19.85000","9.91362","0.13935"
"19.90000","9.93870","0.14033"
"19.95000","9.96378","0.14044"
"20.00000","9.98920","0.14128"
"20.05000","10.01418","0.14151"
"20.10000","10.03894","0.14226"
"20.15000","10.06397","0.14259"
"20.20000","10.08883","0.14344"
"20.25000","10.11384","0.14378"
"20.30000","10.13881","0.14444"
"20.35000","10.16386","0.14467"
"20.40000","10.18893","0.14562"
"20.45000","10.21408","0.14617"
"20.50000","10.23909","0.14697"
"20.55000","10.26411","0.14705"
"20.60000","10.28906","0.14777"
"20.65000","10.31410","0.14812"
"20.70000","10.33909","0.14880"
"20.75000","10.36424","0.14940"
"20.80000","10.38932","0.14998"
"20.85000","10.41413","0.15039"
"20.90000","10.43879","0.15087"
"20.95000","10.46368","0.15145"
"21.00000","10.48870","0.15205"
"21.05000","10.51362","0.15246"
"21.10000","10.53862","0.15322"
"21.15000","10.56372","0.15353"
"21.20000","10.58876","0.15429"
"21.25000","10.61373","0.15481"
"21.30000","10.63886","0.15548"
"21.35000","10.66411","0.15591"
"21.40000","10.68912","0.15658"
"21.45000","10.71534","0.15694"
"21.50000","10.74041","0.15750"
"21.55000","10.76460","0.15825"
"21.60000","10.78937","0.15878"
"21.65000","10.81428","0.15917"
"21.70000","10.83913","0.15973"
"21.75000","10.86406","0.16057"
"21.80000","10.88916","0.16094"
"21.85000","10.91403","0.16155"
"21.90000","10.93897","0.16196"
"21.95000","10.96391","0.16270"
"22.00000","10.98887","0.16310"
"22.05000","11.01379","0.16375"
"22.10000","11.03883","0.16413"
"22.15000","11.06388","0.16493"
"22.20000","11.08885","0.16529"
"22.25000","11.11400","0.16607"
"22.30000","11.13865","0.16661"
"22.35000","11.16364","0.16740"
"22.40000","11.18867","0.16762"
"22.45000","11.21368","0.16838"
"22.50000","11.23879","0.16864"
"22.55000","11.26386","0.16952"
"22.60000","11.28897","0.16983"
"22.65000","11.31400","0.17075"
"22.70000","11.33913","0.17102"
"22.75000","11.36423","0.17169"
"22.80000","11.38927","0.17196"
"22.85000","11.41417","0.17294"
"22.90000","11.43919","0.17337"
"22.95000","11.46416","0.17400"
"23.00000","11.48914","0.17426"
"23.05000","11.51413","0.17494"
"23.10000","11.53916","0.17559"
"23.15000","11.56411","0.17624"
"23.20000","11.58914","0.17669"
"23.25000","11.61407","0.17741"
"23.30000","11.63900","0.17771"
"23.35000","11.66400","0.17827"
"23.40000","11.68899","0.17882"
"23.45000","11.71397","0.17959"
"23.50000","11.73886","0.18029"
"23.55000","11.76379","0.18067"
"23.60000","11.78879","0.18118"
"23.65000","11.81378","0.18173"
"23.70000","11.83874","0.18214"
"23.75000","11.86380","0.18284"
"23.80000","11.88892","0.18352"
"23.85000","11.91397","0.18400"
"23.90000","11.94086","0.18437"
"23.95000","11.96489","0.18468"
"24.00000","11.98934","0.18549"
"24.05000","12.01424","0.18590"
"24.10000","12.03918","0.18661"
"24.15000","12.06417","0.18706"
"24.20000","12.08911","0.18767"
"24.25000","12.11414","0.18804"
"24.30000","12.13912","0.18856"
"24.35000","12.16424","0.18898"
"24.40000","12.18939","0.18987"
"24.45000","12.21420","0.18998"
"24.50000","12.23902","0.19077"
"24.55000","12.26395","0.19110"
"24.60000","12.28890","0.19200"
"24.65000","12.31390","0.19238"
"24.70000","12.33881","0.19305"
"24.75000","12.36373","0.19329"
"24.80000","12.38869","0.19433"
"24.85000","12.41363","0.19428"
"24.90000","12.43896","0.19520"
"24.95000","12.46404","0.19533"
"25.00000","12.48951","0.19626"
"25.05000","12.51395","0.19652"
"25.10000","12.53879","0.19740"
"25.15000","12.56384","0.19772"
"25.20000","12.58891","0.19812"
"25.25000","12.61395","0.19875"
"25.30000","12.63890","0.19937"
"25.35000","12.66398","0.19998"
"25.40000","12.68895","0.20035"
"25.45000","12.71396","0.20073"
"25.50000","12.73902","0.20147"
"25.55000","12.76402","0.20190"
"25.60000","12.78909","0.20271"
"25.65000","12.81423","0.20311"
"25.70000","12.83913","0.20356"
"25.75000","12.86405","0.20397"
"25.80000","12.88903","0.20429"
"25.85000","12.91401","0.20510"
"25.90000","12.93895","0.20552"
"25.95000","12.96397","0.20624"
"26.00000","12.98906","0.20658"
"26.05000","13.01560","0.20705"
"26.10000","13.03946","0.20746"
"26.15000","13.06400","0.20816"
"26.20000","13.08890","0.20885"
"26.25000","13.11378","0.20949"
"26.30000","13.13875","0.20964"
"26.35000","13.16369","0.21023"
"26.40000","13.18876","0.21048"
"26.45000","13.21393","0.21134"
"26.50000","13.23904","0.21171"
"26.55000","13.26397","0.21236"
"26.60000","13.28896","0.21251"
"26.65000","13.31395","0.21342"
"26.70000","13.33897","0.21337"
"26.75000","13.36396","0.21435"
"26.80000","13.38898","0.21453"
"26.85000","13.41400","0.21532"
"26.90000","13.43907","0.21539"
"26.95000","13.46409","0.21608"
"27.00000","13.48913","0.21658"
"27.05000","13.51403","0.21735"
"27.10000","13.53903","0.21771"
"27.15000","13.56397","0.21817"
"27.20000","13.58906","0.21855"
"27.25000","13.61387","0.21926"
"27.30000","13.63881","0.21962"
"27.35000","13.66378","0.22048"
"27.40000","13.68879","0.22063"
"27.45000","13.71380","0.22126"
"27.50000","13.73879","0.22159"
"27.55000","13.76385","0.22232"
"27.60000","13.78877","0.22275"
"27.65000","13.81374","0.22327"
"27.70000","13.83879","0.22361"
"27.75000","13.86411","0.22414"
"27.80000","13.88922","0.22470"
"27.85000","13.91430","0.22513"
"27.90000","13.93914","0.22560"
"27.95000","13.96424","0.22592"
"28.00000","13.98912","0.22650"
"28.05000","14.01412","0.22681"
"28.10000","14.03922","0.22736"
"28.15000","14.06451","0.22759"
"28.20000","14.08930","0.22832"
"28.25000","14.11426","0.22855"
"28.30000","14.13921","0.22897"
"28.35000","14.16419","0.22933"
"28.40000","14.18907","0.22973"
"28.45000","14.21404","0.23028"
"28.50000","14.23894","0.23082"
"28.55000","14.26401","0.23125"
"28.60000","14.28906","0.23161"
"28.65000","14.31419","0.23197"
"28.70000","14.33944","0.23293"
"28.75000","14.36424","0.23292"
"28.80000","14.38916","0.23375"
"28.85000","14.41401","0.23373"
"28.90000","14.43897","0.23457"
"28.95000","14.46396","0.23481"
"29.00000","14.48881","0.23545"
"29.05000","14.51392","0.23589"
"29.10000","14.53888","0.23644"
"29.15000","14.56388","0.23666"
"29.20000","14.58889","0.23708"
"29.25000","14.61394","0.23749"
"29.30000","14.63891","0.23826"
"29.35000","14.66396","0.23836"
"29.40000","14.68907","0.23895"
"29.45000","14.71426","0.23902"
"29.50000","14.73953","0.23968"
"29.55000","14.76426","0.24002"
"29.60000","14.78911","0.24059"
"29.65000","14.81406","0.24098"
"29.70000","14.83915","0.24149"
"29.75000","14.86428","0.24183"
"29.80000","14.89120","0.24230"
"29.85000","14.91484","0.24263"
"29.90000","14.93930","0.24302"
"29.95000","14.96406","0.24340"
"30.00000","14.98890","0.24388"
"30.05000","15.01372","0.24463"
"30.10000","15.03876","0.24486"
"30.15000","15.06382","0.24539"
"30.20000","15.08896","0.24571"
"30.25000","15.11408","0.24606"
"30.30000","15.13904","0.24662"
"30.35000","15.16396","0.24704"
"30.40000","15.18894","0.24764"
"30.45000","15.21395","0.24799"
"30.50000","15.23896","0.24807"
"30.55000","15.26410","0.24882"
"30.60000","15.28913","0.24916"
"30.65000","15.31413","0.24993"
"30.70000","15.33910","0.25016"
"30.75000","15.36402","0.25049"
"30.80000","15.38905","0.25068"
"30.85000","15.41413","0.25099"
"30.90000","15.43921","0.25135"
"30.95000","15.46438","0.25233"
"31.00000","15.48906","0.25225"
"31.05000","15.51390","0.25287"
"31.10000","15.53877","0.25270"
"31.15000","15.56369","0.25358"
"31.20000","15.58872","0.25364"
"31.25000","15.61372","0.25405"
"31.30000","15.63882","0.25433"
"31.35000","15.66394","0.25479"
"31.40000","15.68944","0.25487"
"31.45000","15.71430","0.25544"
"31.50000","15.73914","0.25545"
"31.55000","15.76421","0.25599"
"31.60000","15.78907","0.25583"
"31.65000","15.81398","0.25626"
"31.70000","15.83890","0.25641"
"31.75000","15.86384","0.25675"
"31.80000","15.88891","0.25705"
"31.85000","15.91400","0.25754"
"31.90000","15.93905","0.25787"
"31.95000","15.96403","0.25820"
"32.00000","15.98909","0.25856"
"32.05000","16.01415","0.25893"
"32.10000","16.03922","0.25925"
"32.15000","16.06425","0.25934"
"32.20000","16.08909","0.25959"
"32.25000","16.11399","0.26005"
"32.30000","16.13898","0.26050"
"32.35000","16.16410","0.26075"
"32.40000","16.18939","0.26140"
"32.45000","16.21448","0.26146"
"32.50000","16.23916","0.26196"
"32.55000","16.26402","0.26203"
"32.60000","16.28896","0.26259"
"32.65000","16.31403","0.26275"
"32.70000","16.33902","0.26311"
"32.75000","16.36414","0.26332"
"32.80000","16.38901","0.26409"
"32.85000","16.41404","0.26434"
"32.90000","16.43905","0.26470"
"32.95000","16.46414","0.26492"
"33.00000","16.48946","0.26529"
"33.05000","16.51524","0.26519"
"33.10000","16.54017","0.26595"
"33.15000","16.56444","0.26602"
"33.20000","16.58921","0.26654"
"33.25000","16.61411","0.26652"
"33.30000","16.63897","0.26674"
"33.35000","16.66386","0.26679"
"33.40000","16.68871","0.26759"
"33.45000","16.71365","0.26779"
"33.50000","16.73886","0.26829"
"33.55000","16.76396","0.26841"
"33.60000","16.78895","0.26881"
"33.65000","16.81387","0.26888"
"33.70000","16.83888","0.26945"
"33.75000","16.86380","0.26987"
"33.80000","16.88879","0.27025"
"33.85000","16.91380","0.27022"
"33.90000","16.93881","0.27059"
"33.95000","16.96393","0.27104"
"34.00000","16.98901","0.27143"
"34.05000","17.01408","0.27173"
"34.10000","17.03926","0.27202"
"34.15000","17.06439","0.27190"
"34.20000","17.08928","0.27218"
"34.25000","17.11422","0.27255"
"34.30000","17.13960","0.27308"
"34.35000","17.16447","0.27353"
"34.40000","17.18931","0.27364"
"34.45000","17.21431","0.27401"
"34.50000","17.23924","0.27415"
"34.55000","17.26417","0.27477"
"34.60000","17.28904","0.27497"
"34.65000","17.31393","0.27547"
"34.70000","17.33888","0.27566"
"34.75000","17.36377","0.27566"
"34.80000","17.38881","0.27593"
"34.85000","17.41387","0.27655"
"34.90000","17.43900","0.27687"
"34.95000","17.46402","0.27738"
"35.00000","17.48900","0.27728"
"35.05000","17.51456","0.27761"
"35.10000","17.53929","0.27779"
"35.15000","17.56412","0.27820"
"35.20000","17.58908","0.27838"
"35.25000","17.61409","0.27899"
"35.30000","17.63901","0.27897"
"35.35000","17.66390","0.27941"
"35.40000","17.68895","0.27947"
"35.45000","17.71397","0.28008"
"35.50000","17.73901","0.28014"
"35.55000","17.76408","0.28061"
"35.60000","17.78911","0.28067"
"35.65000","17.81407","0.28118"
"35.70000","17.83907","0.28120"
"35.75000","17.86409","0.28173"
"35.80000","17.88911","0.28184"
"35.85000","17.91395","0.28225"
"35.90000","17.93890","0.28220"
"35.95000","17.96396","0.28277"
"36.00000","17.99059","0.28296"
"36.05000","18.01544","0.28337"
"36.10000","18.03939","0.28335"
"36.15000","18.06407","0.28349"
"36.20000","18.08894","0.28387"
"36.25000","18.11380","0.28398"
"36.30000","18.13881","0.28419"
"36.35000","18.16375","0.28458"
"36.40000","18.18885","0.28473"
"36.45000","18.21387","0.28483"
"36.50000","18.23893","0.28515"
"36.55000","18.26411","0.28541"
"36.60000","18.28920","0.28561"
"36.65000","18.31420","0.28576"
"36.70000","18.33914","0.28601"
"36.75000","18.36412","0.28604"
"36.80000","18.38909","0.28645"
"36.85000","18.41412","0.28655"
"36.90000","18.43909","0.28678"
"36.95000","18.46396","0.28673"
"37.00000","18.48880","0.28688"
"37.05000","18.51380","0.28679"
"37.10000","18.53883","0.28735"
"37.15000","18.56388","0.28735"
"37.20000","18.58886","0.28791"
"37.25000","18.61396","0.28779"
"37.30000","18.63926","0.28832"
"37.35000","18.66403","0.28833"
"37.40000","18.68892","0.28863"
"37.45000","18.71381","0.28862"
"37.50000","18.73875","0.28910"
"37.55000","18.76382","0.28904"
"37.60000","18.78876","0.28928"
"37.65000","18.81384","0.28919"
"37.70000","18.83895","0.28977"
"37.75000","18.86398","0.28949"
"37.80000","18.88914","0.29009"
"37.85000","18.91421","0.29010"
"37.90000","18.93930","0.29047"
"37.95000","18.96432","0.29043"
"38.00000","18.98927","0.29045"
"38.05000","19.01421","0.29063"
"38.10000","19.03947","0.29086"
"38.15000","19.06448","0.29096"
"38.20000","19.08939","0.29149"
"38.25000","19.11425","0.29145"
"38.30000","19.13918","0.29152"
"38.35000","19.16394","0.29157"
"38.40000","19.18884","0.29204"
"38.45000","19.21386","0.29232"
"38.50000","19.23880","0.29249"
"38.55000","19.26379","0.29254"
"38.60000","19.28880","0.29242"
"38.65000","19.31379","0.29263"
"38.70000","19.33882","0.29266"
"38.75000","19.36384","0.29308"
"38.80000","19.38896","0.29334"
"38.85000","19.41388","0.29343"
"38.90000","19.43895","0.29319"
"38.95000","19.46425","0.29344"
"39.00000","19.48933","0.29357"
"39.05000","19.51418","0.29400"
"39.10000","19.53922","0.29403"
"39.15000","19.56421","0.29432"
"39.20000","19.58926","0.29412"
"39.25000","19.61455","0.29434"
"39.30000","19.64026","0.29440"
"39.35000","19.66556","0.29505"
"39.40000","19.68935","0.29489"
"39.45000","19.71405","0.29497"
"39.50000","19.73896","0.29463"
"39.55000","19.76389","0.29482"
"39.60000","19.78876","0.29485"
"39.65000","19.81372","0.29533"
"39.70000","19.83873","0.29526"
"39.75000","19.86370","0.29546"
"39.80000","19.88879","0.29534"
"39.85000","19.91381","0.29569"
"39.90000","19.93916","0.29573"
"39.95000","19.96400","0.29605"
"40.00000","19.98895","0.29593"
"40.05000","20.01389","0.29628"
"40.10000","20.03885","0.29625"
"40.15000","20.06378","0.29654"
"40.20000","20.08868","0.29641"
"40.25000","20.11366","0.29688"
"40.30000","20.13874","0.29674"
"40.35000","20.16397","0.29710"
"40.40000","20.18896","0.29702"
"40.45000","20.21394","0.29725"
"40.50000","20.23897","0.29737"
"40.55000","20.26403","0.29760"
"40.60000","20.28913","0.29761"
"40.65000","20.31510","0.29788"
"40.70000","20.33949","0.29789"
"40.75000","20.36419","0.29811"
"40.80000","20.38906","0.29817"
"40.85000","20.41402","0.29843"
"40.90000","20.43887","0.29862"
"40.95000","20.46380","0.29841"
"41.00000","20.48871","0.29886"
"41.05000","20.51373","0.29882"
"41.10000","20.53871","0.29906"
"41.15000","20.56367","0.29897"
"41.20000","20.58868","0.29927"
"41.25000","20.61374","0.29930"
"41.30000","20.63929","0.29954"
"41.35000","20.66448","0.29952"
"41.40000","20.68874","0.29975"
"41.45000","20.71367","0.29979"
"41.50000","20.73869","0.29998"
"41.55000","20.76383","0.29996"
"41.60000","20.78885","0.30019"
"41.65000","20.81392","0.30014"
"41.70000","20.83898","0.30046"
"41.75000","20.86410","0.30036"
"41.80000","20.88924","0.30064"
"41.85000","20.91429","0.30065"
"41.90000","20.93937","0.30085"
"41.95000","20.96433","0.30073"
"42.00000","20.99018","0.30109"
"42.05000","21.01554","0.30089"
"42.10000","21.03939","0.30111"
"42.15000","21.06420","0.30096"
"42.20000","21.08909","0.30127"
"42.25000","21.11408","0.30105"
"42.30000","21.13898","0.30108"
"42.35000","21.16383","0.30108"
"42.40000","21.18862","0.30141"
"42.45000","21.21364","0.30120"
"42.50000","21.23869","0.30131"
"42.55000","21.26361","0.30140"
"42.60000","21.28914","0.30152"
"42.65000","21.31363","0.30151"
"42.70000","21.33851","0.30159"
"42.75000","21.36354","0.30123"
"42.80000","21.38865","0.30143"
"42.85000","21.41369","0.30127"
"42.90000","21.43897","0.30146"
"42.95000","21.46408","0.30141"
"43.00000","21.48922","0.30133"
"43.05000","21.51430","0.30125"
"43.10000","21.53936","0.30124"
"43.15000","21.56443","0.30136"
"43.20000","21.58947","0.30134"
"43.25000","21.61436","0.30133"
"43.30000","21.63931","0.30094"
"43.35000","21.66422","0.30084"
"43.40000","21.68919","0.30059"
"43.45000","21.71514","0.30072"
"43.50000","21.73925","0.30064"
"43.55000","21.76384","0.30045"
"43.60000","21.78885","0.30014"
"43.65000","21.81378","0.29996"
"43.70000","21.83871","0.29935"
"43.75000","21.86362","0.29954"
"43.80000","21.88861","0.29933"
"43.85000","21.91359","0.29964"
"43.90000","21.93857","0.29913"
"43.95000","21.96361","0.29924"
"44.00000","21.98869","0.29910"
"44.05000","22.01375","0.29949"
"44.10000","22.03885","0.29920"
"44.15000","22.06419","0.29922"
"44.20000","22.08924","0.29881"
"44.25000","22.11430","0.29914"
"44.30000","22.13945","0.29910"
"44.35000","22.16577","0.29932"
"44.40000","22.18988","0.29906"
"44.45000","22.21462","0.29904"
"44.50000","22.23952","0.29872"
"44.55000","22.26437","0.29884"
"44.60000","22.28928","0.29877"
"44.65000","22.31426","0.29896"
"44.70000","22.33921","0.29870"
"44.75000","22.36411","0.29856"
"44.80000","22.38903","0.29841"
"44.85000","22.41410","0.29865"
"44.90000","22.43899","0.29863"
"44.95000","22.46376","0.29878"
"45.00000","22.48870","0.29868"
"45.05000","22.51366","0.29854"
"45.10000","22.53864","0.29844"
"45.15000","22.56366","0.29856"
"45.20000","22.58865","0.29865"
"45.25000","22.61365","0.29858"
"45.30000","22.63875","0.29833"
"45.35000","22.66404","0.29823"
"45.40000","22.68919","0.29853"
"45.45000","22.71411","0.29835"
"45.50000","22.73917","0.29860"
"45.55000","22.76426","0.29821"
"45.60000","22.78935","0.29815"
"45.65000","22.81443","0.29786"
"45.70000","22.83943","0.29809"
"45.75000","22.86444","0.29803"
"45.80000","22.88938","0.29829"
"45.85000","22.91437","0.29770"
"45.90000","22.93949","0.29764"
"45.95000","22.96449","0.29741"
"46.00000","22.98948","0.29767"
"46.05000","23.01448","0.29753"
"46.10000","23.03952","0.29768"
"46.15000","23.06417","0.29721"
"46.20000","23.08902","0.29733"
"46.25000","23.11390","0.29696"
"46.30000","23.13879","0.29735"
"46.35000","23.16374","0.29735"
"46.40000","23.18872","0.29740"
"46.45000","23.21367","0.29721"
"46.50000","23.23863","0.29735"
"46.55000","23.26371","0.29718"
"46.60000","23.28869","0.29732"
"46.65000","23.31376","0.29727"
"46.70000","23.33886","0.29748"
"46.75000","23.36395","0.29709"
"46.80000","23.38912","0.29724"
"46.85000","23.41424","0.29704"
"46.90000","23.43931","0.29702"
"46.95000","23.46437","0.29707"
"47.00000","23.48955","0.29708"
"47.05000","23.51458","0.29697"
"47.10000","23.53967","0.29694"
"47.15000","23.56448","0.29662"
"47.20000","23.58970","0.29672"
"47.25000","23.61467","0.29672"
"47.30000","23.63942","0.29667"
"47.35000","23.66528","0.29655"
"47.40000","23.69098","0.29629"
"47.45000","23.71448","0.29646"
"47.50000","23.73907","0.29618"
"47.55000","23.76387","0.29573"
"47.60000","23.78876","0.29542"
"47.65000","23.81364","0.29530"
"47.70000","23.83862","0.29504"
"47.75000","23.86367","0.29395"
"47.80000","23.88870","0.29309"
"47.85000","23.91362","0.29256"
"47.90000","23.93880","0.29202"
"47.95000","23.96380","0.29199"
"48.00000","23.98892","0.29178"
"48.05000","24.01404","0.29159"
"48.10000","24.03931","0.29085"
"48.15000","24.06527","0.29074"
"48.20000","24.08994","0.29026"
"48.25000","24.11458","0.29045"
"48.30000","24.13953","0.29013"
"48.35000","24.16458","0.29019"
"48.40000","24.18969","0.28968"
"48.45000","24.21446","0.28968"
"48.50000","24.23941","0.28941"
"48.55000","24.26437","0.28949"
"48.60000","24.28926","0.28898"
"48.65000","24.31409","0.28894"
"48.70000","24.33892","0.28836"
"48.75000","24.36382","0.28857"
"48.80000","24.38882","0.28810"
"48.85000","24.41469","0.28804"
"48.90000","24.43922","0.28657"
"48.95000","24.46372","0.28622"
"49.00000","24.48872","0.28550"
"49.05000","24.51373","0.28504"
"49.10000","24.53876","0.28476"
"49.15000","24.56383","0.28448"
"49.20000","24.58893","0.28408"
"49.25000","24.61400","0.28361"
"49.30000","24.63911","0.28327"
"49.35000","24.66430","0.28314"
"49.40000","24.68921","0.28266"
"49.45000","24.71428","0.28276"
"49.50000","24.73938","0.28232"
"49.55000","24.76452","0.28176"
"49.60000","24.78969","0.28136"
"49.65000","24.81469","0.28113"
"49.70000","24.83966","0.28124"
"49.75000","24.86450","0.28089"
"49.80000","24.88941","0.28065"
"49.85000","24.91472","0.28015"
"49.90000","24.93932","0.28001"
"49.95000","24.96410","0.27967"
"50.00000","24.98899","0.27963"
"50.05000","25.01511","0.27925"
"50.10000","25.03977","0.27919"
"50.15000","25.06403","0.27846"
"50.20000","25.08884","0.27838"
"50.25000","25.11373","0.27828"
"50.30000","25.13862","0.27844"
"50.35000","25.16363","0.27795"
"50.40000","25.18864","0.27788"
"50.45000","25.21392","0.27721"
"50.50000","25.23900","0.27724"
"50.55000","25.26408","0.27689"
"50.60000","25.28907","0.27718"
"50.65000","25.31415","0.27665"
"50.70000","25.33915","0.27648"
"50.75000","25.36437","0.27602"
"50.80000","25.38964","0.27603"
"50.85000","25.41468","0.27589"
"50.90000","25.43986","0.27592"
"50.95000","25.46463","0.27534"
"51.00000","25.48954","0.27526"
"51.05000","25.51452","0.27473"
"51.10000","25.53948","0.27487"
"51.15000","25.56431","0.27470"
"51.20000","25.58918","0.27476"
"51.25000","25.61400","0.27437"
"51.30000","25.63889","0.27428"
"51.35000","25.66392","0.27408"
"51.40000","25.68890","0.27413"
"51.45000","25.71387","0.27369"
"51.50000","25.73885","0.27372"
"51.55000","25.76377","0.27345"
"51.60000","25.78879","0.27335"
"51.65000","25.81404","0.27331"
"51.70000","25.83997","0.27311"
"51.75000","25.86438","0.27318"
"51.80000","25.88912","0.27287"
"51.85000","25.91408","0.27275"
"51.90000","25.93917","0.27250"
"51.95000","25.96416","0.27252"
"52.00000","25.98934","0.27219"
"52.05000","26.01448","0.27198"
"52.10000","26.03976","0.27200"
"52.15000","26.06463","0.27192"
"52.20000","26.08956","0.27128"
"52.25000","26.11453","0.27106"
"52.30000","26.13946","0.27083"
"52.35000","26.16433","0.27089"
"52.40000","26.18921","0.27063"
"52.45000","26.21411","0.27054"
"52.50000","26.23911","0.27044"
"52.55000","26.26417","0.27032"
"52.60000","26.28912","0.26992"
"52.65000","26.31407","0.27006"
"52.70000","26.33933","0.26994"
"52.75000","26.36416","0.27025"
"52.80000","26.38901","0.26992"
"52.85000","26.41423","0.26990"
"52.90000","26.43933","0.26950"
"52.95000","26.46417","0.26962"
"53.00000","26.48926","0.26954"
"53.05000","26.51446","0.26962"
"53.10000","26.54095","0.26899"
"53.15000","26.56500","0.26884"
"53.20000","26.58961","0.26870"
"53.25000","26.61444","0.26910"
"53.30000","26.63934","0.26899"
"53.35000","26.66436","0.26901"
"53.40000","26.68939","0.26886"
"53.45000","26.71425","0.26869"
"53.50000","26.73916","0.26827"
"53.55000","26.76416","0.26849"
"53.60000","26.78926","0.26869"
"53.65000","26.81421","0.26884"
"53.70000","26.83891","0.26855"
"53.75000","26.86383","0.26866"
"53.80000","26.88877","0.26847"
"53.85000","26.91369","0.26864"
"53.90000","26.93879","0.26868"
"53.95000","26.96375","0.26853"
"54.00000","26.98881","0.26865"
"54.05000","27.01373","0.26845"
"54.10000","27.03873","0.26849"
"54.15000","27.06382","0.26871"
"54.20000","27.08894","0.26902"
"54.25000","27.11483","0.26868"
"54.30000","27.13950","0.26879"
"54.35000","27.16401","0.26857"
"54.40000","27.18900","0.26856"
"54.45000","27.21408","0.26858"
"54.50000","27.23919","0.26883"
"54.55000","27.26424","0.26890"
"54.60000","27.28932","0.26887"
"54.65000","27.31447","0.26867"
"54.70000","27.33958","0.26882"
"54.75000","27.36464","0.26875"
"54.80000","27.38957","0.26900"
"54.85000","27.41448","0.26872"
"54.90000","27.43929","0.26892"
"54.95000","27.46418","0.26881"
"55.00000","27.48902","0.26899"
"55.05000","27.51400","0.26868"
"55.10000","27.53887","0.26896"
"55.15000","27.56389","0.26891"
"55.20000","27.58875","0.26899"
"55.25000","27.61378","0.26887"
"55.30000","27.63892","0.26926"
"55.35000","27.66389","0.26878"
"55.40000","27.68890","0.26893"
"55.45000","27.71406","0.26877"
"55.50000","27.73914","0.26899"
"55.55000","27.76410","0.26890"
"55.60000","27.78910","0.26872"
"55.65000","27.81416","0.26883"
"55.70000","27.83916","0.26897"
"55.75000","27.86423","0.26885"
"55.80000","27.88918","0.26887"
"55.85000","27.91425","0.26870"
"55.90000","27.93930","0.26855"
"55.95000","27.96431","0.26834"
"56.00000","27.98939","0.26864"
"56.05000","28.01454","0.26856"
"56.10000","28.03969","0.26845"
"56.15000","28.06445","0.26805"
"56.20000","28.08955","0.26802"
"56.25000","28.11429","0.26808"
"56.30000","28.13907","0.26792"
"56.35000","28.16385","0.26810"
"56.40000","28.18882","0.26784"
"56.45000","28.21383","0.26785"
"56.50000","28.23879","0.26756"
"56.55000","28.26363","0.26773"
"56.60000","28.28859","0.26762"
"56.65000","28.31349","0.26737"
"56.70000","28.33858","0.26666"
"56.75000","28.36363","0.26649"
"56.80000","28.38882","0.26605"
"56.85000","28.41389","0.26597"
"56.90000","28.43898","0.26551"
"56.95000","28.46409","0.26549"
"57.00000","28.48921","0.26494"
"57.05000","28.51464","0.26461"
"57.10000","28.53980","0.26402"
"57.15000","28.56465","0.26407"
"57.20000","28.59144","0.26340"
"57.25000","28.61530","0.26313"
"57.30000","28.63979","0.26240"
"57.35000","28.66446","0.26235"
"57.40000","28.68930","0.26163"
"57.45000","28.71423","0.26162"
"57.50000","28.73925","0.26100"
"57.55000","28.76407","0.26099"
"57.60000","28.78890","0.26045"
"57.65000","28.81382","0.26027"
"57.70000","28.83875","0.26009"
"57.75000","28.86363","0.25992"
"57.80000","28.88875","0.25949"
"57.85000","28.91378","0.25952"
"57.90000","28.93871","0.25908"
"57.95000","28.96372","0.25927"
"58.00000","28.98866","0.25897"
"58.05000","29.01449","0.25882"
"58.10000","29.03927","0.25819"
"58.15000","29.06411","0.25554"
"58.20000","29.08903","0.25222"
"58.25000","29.11403","0.25230"
"58.30000","29.13910","0.25232"
"58.35000","29.16423","0.25211"
"58.40000","29.18932","0.25219"
"58.45000","29.21438","0.25215"
"58.50000","29.23944","0.25227"
"58.55000","29.26445","0.25201"
"58.60000","29.28961","0.25219"
"58.65000","29.31464","0.25212"
"58.70000","29.33954","0.25196"
"58.75000","29.36454","0.25188"
"58.80000","29.38934","0.25206"
"58.85000","29.41417","0.25212"
"58.90000","29.43985","0.25219"
"58.95000","29.46494","0.25183"
"59.00000","29.48902","0.25202"
"59.05000","29.51383","0.25193"
"59.10000","29.53875","0.25222"
"59.15000","29.56383","0.25211"
"59.20000","29.58882","0.25239"
"59.25000","29.61389","0.25206"
"59.30000","29.63898","0.25229"
"59.35000","29.66403","0.25236"
"59.40000","29.68907","0.25267"
"59.45000","29.71415","0.25263"
"59.50000","29.73921","0.25278"
"59.55000","29.76432","0.25243"
"59.60000","29.78947","0.25278"
"59.65000","29.81460","0.25268"
"59.70000","29.84020","0.25267"
"59.75000","29.86505","0.25263"
"59.80000","29.88976","0.25289"
"59.85000","29.91470","0.25273"
"59.90000","29.93964","0.25308"
"59.95000","29.96459","0.25286"
"60.00000","29.98954","0.25323"
"60.05000","30.01441","0.25309"
"60.10000","30.03922","0.25319"
"60.15000","30.06400","0.25307"
"60.20000","30.08894","0.25343"
"60.25000","30.11388","0.25321"
"60.30000","30.13893","0.25338"
"60.35000","30.16395","0.25333"
"60.40000","30.18890","0.25327"
"60.45000","30.21395","0.25337"
"60.50000","30.23905","0.25327"
"60.55000","30.26530","0.25319"
"60.60000","30.29079","0.25334"
"60.65000","30.31473","0.25314"
"60.70000","30.33944","0.25306"
"60.75000","30.36435","0.25301"
"60.80000","30.38927","0.25293"
"60.85000","30.41428","0.25288"
"60.90000","30.43934","0.25270"
"60.95000","30.46442","0.25271"
"61.00000","30.48959","0.25226"
"61.05000","30.51475","0.25227"
"61.10000","30.53973","0.25195"
"61.15000","30.56450","0.25195"
"61.20000","30.58939","0.25124"
"61.25000","30.61429","0.25127"
"61.30000","30.63914","0.25083"
"61.35000","30.66400","0.25088"
"61.40000","30.68893","0.25017"
"61.45000","30.71381","0.24973"
"61.50000","30.73880","0.24900"
"61.55000","30.76377","0.24870"
"61.60000","30.78905","0.24788"
"61.65000","30.81481","0.24767"
"61.70000","30.83906","0.24660"
"61.75000","30.86384","0.24594"
"61.80000","30.88878","0.24458"
"61.85000","30.91381","0.24393"
"61.90000","30.93891","0.24237"
"61.95000","30.96399","0.24112"
"62.00000","30.98920","0.23342"
"62.05000","31.01432","0.22292"
"62.10000","31.03951","0.21377"
"62.15000","31.06463","0.20558"
"62.20000","31.08977","0.19527"
"62.25000","31.11487","0.18631"
"62.30000","31.13969","0.18115"
"62.35000","31.16460","0.17639"
"62.40000","31.18949","0.17144"
"62.45000","31.21445","0.16682"
"62.50000","31.23940","0.16153"
"62.55000","31.26427","0.15595"
"62.60000","31.28921","0.14680"
"62.65000","31.31415","0.09595"
"62.70000","31.33907","0.04534"
"62.75000","31.36409","0.02847"
"62.80000","31.38920","-0.01073"
"62.85000","31.41419","-0.01865"
"62.90000","31.43903","-0.01650"
"62.95000","31.46399","-0.01796"
"63.00000","31.48891","-0.01674"
"63.05000","31.51400","-0.01779"
"63.10000","31.53897","-0.01653"
"63.15000","31.56406","-0.01782"
"63.20000","31.58910","-0.01683"
"63.25000","31.61415","-0.01803"
"63.30000","31.63917","-0.01669"
"63.35000","31.66440","-0.01747"
"63.40000","31.69130","-0.01656"
"63.45000","31.71590","-0.01784"
"63.50000","31.74017","-0.01686"
"63.55000","31.76483","-0.01791"
"63.60000","31.78959","-0.01663"
"63.65000","31.81441","-0.01769"
"63.70000","31.83938","-0.01662"
"63.75000","31.86425","-0.01767"
"63.80000","31.88919","-0.01698"
"63.85000","31.91419","-0.01757"
"63.90000","31.93907","-0.01703"
"63.95000","31.96402","-0.01750"
"64.00000","31.98890","-0.01741"
"64.05000","32.01390","-0.01756"
"64.10000","32.03903","-0.01710"
"64.15000","32.06395","-0.01766"
"64.20000","32.08900","-0.01685"
"64.25000","32.11408","-0.01662"
"64.30000","32.13865","-0.01675"
"64.35000","32.16385","-0.01769"
"64.40000","32.18902","-0.01724"
"64.45000","32.21379","-0.01786"
"64.50000","32.23899","-0.01675"
"64.55000","32.26423","-0.01738"
"64.60000","32.28943","-0.01699"
"64.65000","32.31439","-0.01747"
"64.70000","32.33941","-0.01685"
"64.75000","32.36449","-0.01704"
"64.80000","32.38940","-0.01720"
"64.85000","32.41443","-0.01711"
"64.90000","32.43933","-0.01724"
"64.95000","32.46459","-0.01726"
"65.00000","32.48954","-0.01724"
"65.05000","32.51451","-0.01714"
"65.10000","32.53962","-0.01731"
"65.15000","32.56453","-0.01717"
"65.20000","32.58908","-0.01686"
"65.25000","32.61391","-0.01719"
"65.30000","32.63906","-0.01716"
"65.35000","32.66380","-0.01727"
"65.40000","32.68871","-0.01729"
"65.45000","32.71383","-0.01730"
"65.50000","32.73895","-0.01750"
"65.55000","32.76394","-0.01709"
"65.60000","32.78885","-0.01721"
"65.65000","32.81401","-0.01704"
"65.70000","32.83913","-0.01731"
"65.75000","32.86423","-0.01710"
"65.80000","32.89127","-0.01746"
"65.85000","32.91578","-0.01709"
"65.90000","32.94012","-0.01746"
"65.95000","32.96468","-0.01725"
"66.00000","32.98949","-0.01722"
"66.05000","33.01428","-0.01723"
"66.10000","33.03923","-0.01739"
"66.15000","33.06429","-0.01701"
"66.20000","33.08926","-0.01720"
"66.25000","33.11423","-0.01715"
"66.30000","33.13925","-0.01727"
"66.35000","33.16420","-0.01704"
"66.40000","33.18909","-0.01726"
"66.45000","33.21404","-0.01717"
"66.50000","33.23899","-0.01742"
"66.55000","33.26396","-0.01709"
"66.60000","33.28894","-0.01728"
"66.65000","33.31511","-0.01717"
"66.70000","33.33969","-0.01720"
"66.75000","33.36415","-0.01721"
"66.80000","33.38897","-0.01739"
"66.85000","33.41402","-0.01729"
"66.90000","33.43901","-0.01718"
"66.95000","33.46394","-0.01719"
"67.00000","33.48899","-0.01738"
"67.05000","33.51412","-0.01734"
"67.10000","33.53909","-0.01735"
"67.15000","33.56409","-0.01709"
"67.20000","33.58915","-0.01704"
"67.25000","33.61413","-0.01713"
"67.30000","33.63915","-0.01708"
"67.35000","33.66415","-0.01752"
"67.40000","33.68999","-0.01735"
"67.45000","33.71482","-0.01726"
"67.50000","33.73935","-0.01675"
"67.50300","33.74084","-0.01686"