File: 15G1650/ST 15G1650_0002.csv
Rate 1,"0.15000",mm/s
Start date,"8/10/2021"
Specimen label,""

Time,Extension,Beam 1 Kg Load Cell
(s),(mm),(N)
"0.00000","-0.00127","-0.00300"
"0.10000","-0.00127","-0.00241"
"0.20000","0.00543","-0.00237"
"0.30000","0.02243","-0.00254"
"0.40000","0.03910","-0.00224"
"0.50000","0.05575","-0.00194"
"0.60000","0.07247","-0.00196"
"0.70000","0.08933","-0.00170"
"0.80000","0.10560","-0.00140"
"0.90000","0.12171","-0.00163"
"1.00000","0.13762","-0.00126"
"1.10000","0.15355","-0.00081"
"1.20000","0.16938","-0.00092"
"1.30000","0.18498","-0.00077"
"1.40000","0.20052","-0.00054"
"1.50000","0.21599","-0.00050"
"1.60000","0.23160","-0.00024"
"1.70000","0.24705","0.00012"
"1.80000","0.26273","0.00037"
"1.90000","0.27826","0.00015"
"2.00000","0.29293","0.00033"
"2.10000","0.30827","0.00043"
"2.20000","0.32328","0.00075"
"2.30000","0.33863","0.00107"
"2.40000","0.35381","0.00113"
"2.50000","0.36911","0.00123"
"2.60000","0.38430","0.00142"
"2.70000","0.39937","0.00154"
"2.80000","0.41450","0.00165"
"2.90000","0.42959","0.00160"
"3.00000","0.44458","0.00198"
"3.10000","0.45966","0.00214"
"3.20000","0.47471","0.00235"
"3.30000","0.48982","0.00240"
"3.40000","0.50470","0.00263"
"3.50000","0.51972","0.00249"
"3.60000","0.53481","0.00279"
"3.70000","0.54986","0.00277"
"3.80000","0.56479","0.00322"
"3.90000","0.57979","0.00338"
"4.00000","0.59489","0.00332"
"4.10000","0.60982","0.00333"
"4.20000","0.62479","0.00356"
"4.30000","0.63981","0.00366"
"4.40000","0.65602","0.00399"
"4.50000","0.67004","0.00420"
"4.60000","0.68480","0.00395"
"4.70000","0.69976","0.00434"
"4.80000","0.71487","0.00456"
"4.90000","0.72988","0.00465"
"5.00000","0.74485","0.00515"
"5.10000","0.75988","0.00523"
"5.20000","0.77501","0.00482"
"5.30000","0.78983","0.00523"
"5.40000","0.80479","0.00559"
"5.50000","0.81985","0.00551"
"5.60000","0.83564","0.00549"
"5.70000","0.84990","0.00613"
"5.80000","0.86466","0.00604"
"5.90000","0.87975","0.00605"
"6.00000","0.89484","0.00654"
"6.10000","0.90966","0.00645"
"6.20000","0.92480","0.00662"
"6.30000","0.93992","0.00695"
"6.40000","0.95492","0.00702"
"6.50000","0.96981","0.00710"
"6.60000","0.98493","0.00759"
"6.70000","0.99992","0.00744"
"6.80000","1.01486","0.00768"
"6.90000","1.02987","0.00789"
"7.00000","1.04490","0.00794"
"7.10000","1.06001","0.00805"
"7.20000","1.07489","0.00833"
"7.30000","1.08986","0.00839"
"7.40000","1.10492","0.00855"
"7.50000","1.11994","0.00876"
"7.60000","1.13491","0.00868"
"7.70000","1.14992","0.00913"
"7.80000","1.16502","0.00905"
"7.90000","1.18004","0.00923"
"8.00000","1.19494","0.00925"
"8.10000","1.21001","0.00955"
"8.20000","1.22502","0.00970"
"8.30000","1.24004","0.00996"
"8.40000","1.25602","0.00968"
"8.50000","1.27020","0.00997"
"8.60000","1.28509","0.01023"
"8.70000","1.29998","0.01047"
"8.80000","1.31496","0.01049"
"8.90000","1.32998","0.01060"
"9.00000","1.34501","0.01077"
"9.10000","1.35997","0.01118"
"9.20000","1.37493","0.01111"
"9.30000","1.39000","0.01126"
"9.40000","1.40503","0.01143"
"9.50000","1.41997","0.01167"
"9.60000","1.43494","0.01208"
"9.70000","1.45004","0.01227"
"9.80000","1.46501","0.01217"
"9.90000","1.47987","0.01216"
"10.00000","1.49486","0.01258"
"10.10000","1.50992","0.01272"
"10.20000","1.52494","0.01293"
"10.30000","1.53985","0.01319"
"10.40000","1.55487","0.01314"
"10.50000","1.56990","0.01327"
"10.60000","1.58491","0.01337"
"10.70000","1.59982","0.01373"
"10.80000","1.61492","0.01379"
"10.90000","1.63135","0.01426"
"11.00000","1.64526","0.01411"
"11.10000","1.65988","0.01440"
"11.20000","1.67485","0.01437"
"11.30000","1.68990","0.01449"
"11.40000","1.70491","0.01466"
"11.50000","1.71977","0.01512"
"11.60000","1.73497","0.01482"
"11.70000","1.74996","0.01524"
"11.80000","1.76493","0.01538"
"11.90000","1.77991","0.01541"
"12.00000","1.79501","0.01565"
"12.10000","1.81003","0.01594"
"12.20000","1.82493","0.01595"
"12.30000","1.83993","0.01592"
"12.40000","1.85502","0.01636"
"12.50000","1.87005","0.01642"
"12.60000","1.88499","0.01658"
"12.70000","1.89996","0.01665"
"12.80000","1.91503","0.01685"
"12.90000","1.92999","0.01701"
"13.00000","1.94500","0.01740"
"13.10000","1.96005","0.01748"
"13.20000","1.97516","0.01738"
"13.30000","1.99015","0.01759"
"13.40000","2.00634","0.01795"
"13.50000","2.02027","0.01808"
"13.60000","2.03507","0.01817"
"13.70000","2.04989","0.01854"
"13.80000","2.06478","0.01853"
"13.90000","2.07990","0.01892"
"14.00000","2.09490","0.01903"
"14.10000","2.10984","0.01906"
"14.20000","2.12481","0.01921"
"14.30000","2.13990","0.01957"
"14.40000","2.15496","0.01963"
"14.50000","2.16995","0.01983"
"14.60000","2.18491","0.02005"
"14.70000","2.19997","0.02015"
"14.80000","2.21495","0.02033"
"14.90000","2.22987","0.02042"
"15.00000","2.24489","0.02065"
"15.10000","2.25998","0.02078"
"15.20000","2.27496","0.02104"
"15.30000","2.28991","0.02112"
"15.40000","2.30498","0.02134"
"15.50000","2.32000","0.02140"
"15.60000","2.33503","0.02150"
"15.70000","2.34999","0.02163"
"15.80000","2.36500","0.02193"
"15.90000","2.38004","0.02213"
"16.00000","2.39490","0.02229"
"16.10000","2.40991","0.02257"
"16.20000","2.42496","0.02240"
"16.30000","2.44000","0.02272"
"16.40000","2.45496","0.02302"
"16.50000","2.46990","0.02299"
"16.60000","2.48508","0.02309"
"16.70000","2.50001","0.02365"
"16.80000","2.51496","0.02378"
"16.90000","2.52995","0.02367"
"17.00000","2.54499","0.02379"
"17.10000","2.56000","0.02426"
"17.20000","2.57496","0.02424"
"17.30000","2.58998","0.02457"
"17.40000","2.60506","0.02483"
"17.50000","2.62002","0.02489"
"17.60000","2.63501","0.02503"
"17.70000","2.65013","0.02536"
"17.80000","2.66516","0.02565"
"17.90000","2.68003","0.02551"
"18.00000","2.69496","0.02601"
"18.10000","2.71000","0.02599"
"18.20000","2.72504","0.02626"
"18.30000","2.74000","0.02645"
"18.40000","2.75604","0.02663"
"18.50000","2.77019","0.02661"
"18.60000","2.78496","0.02684"
"18.70000","2.79982","0.02713"
"18.80000","2.81482","0.02731"
"18.90000","2.82996","0.02733"
"19.00000","2.84493","0.02746"
"19.10000","2.85983","0.02769"
"19.20000","2.87487","0.02786"
"19.30000","2.88997","0.02807"
"19.40000","2.90493","0.02821"
"19.50000","2.91987","0.02842"
"19.60000","2.93490","0.02847"
"19.70000","2.94997","0.02888"
"19.80000","2.96494","0.02883"
"19.90000","2.97991","0.02919"
"20.00000","2.99499","0.02926"
"20.10000","3.01006","0.02930"
"20.20000","3.02499","0.02950"
"20.30000","3.03993","0.02984"
"20.40000","3.05502","0.02993"
"20.50000","3.07002","0.03019"
"20.60000","3.08495","0.03046"
"20.70000","3.09993","0.03041"
"20.80000","3.11502","0.03076"
"20.90000","3.13005","0.03066"
"21.00000","3.14501","0.03097"
"21.10000","3.16005","0.03140"
"21.20000","3.17634","0.03128"
"21.30000","3.19028","0.03148"
"21.40000","3.20493","0.03195"
"21.50000","3.21988","0.03193"
"21.60000","3.23504","0.03212"
"21.70000","3.24997","0.03260"
"21.80000","3.26495","0.03256"
"21.90000","3.28000","0.03254"
"22.00000","3.29509","0.03298"
"22.10000","3.30994","0.03309"
"22.20000","3.32488","0.03337"
"22.30000","3.33992","0.03365"
"22.40000","3.35499","0.03353"
"22.50000","3.36991","0.03382"
"22.60000","3.38491","0.03425"
"22.70000","3.39998","0.03456"
"22.80000","3.41498","0.03439"
"22.90000","3.42992","0.03463"
"23.00000","3.44492","0.03482"
"23.10000","3.46001","0.03497"
"23.20000","3.47501","0.03525"
"23.30000","3.48996","0.03540"
"23.40000","3.50496","0.03559"
"23.50000","3.52000","0.03568"
"23.60000","3.53497","0.03603"
"23.70000","3.54990","0.03588"
"23.80000","3.56496","0.03604"
"23.90000","3.58004","0.03633"
"24.00000","3.59501","0.03670"
"24.10000","3.60994","0.03662"
"24.20000","3.62501","0.03697"
"24.30000","3.64005","0.03706"
"24.40000","3.65496","0.03739"
"24.50000","3.66995","0.03745"
"24.60000","3.68501","0.03773"
"24.70000","3.70005","0.03796"
"24.80000","3.71493","0.03818"
"24.90000","3.72991","0.03834"
"25.00000","3.74500","0.03865"
"25.10000","3.76004","0.03876"
"25.20000","3.77497","0.03885"
"25.30000","3.78992","0.03927"
"25.40000","3.80498","0.03936"
"25.50000","3.81999","0.03945"
"25.60000","3.83497","0.03980"
"25.70000","3.85000","0.04003"
"25.80000","3.86506","0.04003"
"25.90000","3.88001","0.04026"
"26.00000","3.89495","0.04069"
"26.10000","3.90999","0.04073"
"26.20000","3.92506","0.04092"
"26.30000","3.94001","0.04129"
"26.40000","3.95490","0.04142"
"26.50000","3.97014","0.04175"
"26.60000","3.98616","0.04196"
"26.70000","4.00047","0.04186"
"26.80000","4.01508","0.04218"
"26.90000","4.03000","0.04234"
"27.00000","4.04496","0.04264"
"27.10000","4.05988","0.04272"
"27.20000","4.07488","0.04312"
"27.30000","4.08997","0.04302"
"27.40000","4.10493","0.04320"
"27.50000","4.11987","0.04350"
"27.60000","4.13487","0.04376"
"27.70000","4.14998","0.04376"
"27.80000","4.16492","0.04410"
"27.90000","4.17989","0.04429"
"28.00000","4.19495","0.04432"
"28.10000","4.21002","0.04480"
"28.20000","4.22500","0.04495"
"28.30000","4.23993","0.04505"
"28.40000","4.25499","0.04512"
"28.50000","4.27004","0.04540"
"28.60000","4.28490","0.04559"
"28.70000","4.29987","0.04581"
"28.80000","4.31495","0.04608"
"28.90000","4.32999","0.04630"
"29.00000","4.34495","0.04643"
"29.10000","4.35991","0.04703"
"29.20000","4.37502","0.04683"
"29.30000","4.39003","0.04719"
"29.40000","4.40497","0.04736"
"29.50000","4.42004","0.04753"
"29.60000","4.43518","0.04779"
"29.70000","4.45007","0.04790"
"29.80000","4.46496","0.04843"
"29.90000","4.47996","0.04838"
"30.00000","4.49503","0.04864"
"30.10000","4.51003","0.04880"
"30.20000","4.52496","0.04927"
"30.30000","4.54000","0.04931"
"30.40000","4.55504","0.04954"
"30.50000","4.56996","0.04969"
"30.60000","4.58497","0.04997"
"30.70000","4.60004","0.05018"
"30.80000","4.61505","0.05040"
"30.90000","4.62993","0.05060"
"31.00000","4.64485","0.05062"
"31.10000","4.65998","0.05106"
"31.20000","4.67500","0.05126"
"31.30000","4.69000","0.05140"
"31.40000","4.70570","0.05146"
"31.50000","4.72009","0.05173"
"31.60000","4.73493","0.05175"
"31.70000","4.74986","0.05201"
"31.80000","4.76485","0.05237"
"31.90000","4.77999","0.05259"
"32.00000","4.79492","0.05254"
"32.10000","4.80995","0.05290"
"32.20000","4.82497","0.05303"
"32.30000","4.84004","0.05328"
"32.40000","4.85498","0.05374"
"32.50000","4.86995","0.05364"
"32.60000","4.88495","0.05388"
"32.70000","4.89998","0.05415"
"32.80000","4.91491","0.05425"
"32.90000","4.92995","0.05438"
"33.00000","4.94499","0.05484"
"33.10000","4.95999","0.05509"
"33.20000","4.97490","0.05530"
"33.30000","4.98987","0.05570"
"33.40000","5.00494","0.05563"
"33.50000","5.01999","0.05595"
"33.60000","5.03494","0.05631"
"33.70000","5.04994","0.05656"
"33.80000","5.06505","0.05659"
"33.90000","5.08003","0.05691"
"34.00000","5.09495","0.05714"
"34.10000","5.10996","0.05728"
"34.20000","5.12505","0.05767"
"34.30000","5.14001","0.05774"
"34.40000","5.15501","0.05781"
"34.50000","5.17002","0.05822"
"34.60000","5.18501","0.05857"
"34.70000","5.19994","0.05861"
"34.80000","5.21491","0.05880"
"34.90000","5.22996","0.05898"
"35.00000","5.24500","0.05921"
"35.10000","5.25992","0.05926"
"35.20000","5.27488","0.05965"
"35.30000","5.28994","0.05981"
"35.40000","5.30494","0.06014"
"35.50000","5.31986","0.06021"
"35.60000","5.33485","0.06052"
"35.70000","5.34995","0.06077"
"35.80000","5.36499","0.06098"
"35.90000","5.37997","0.06101"
"36.00000","5.39503","0.06125"
"36.10000","5.41005","0.06144"
"36.20000","5.42504","0.06180"
"36.30000","5.43996","0.06202"
"36.40000","5.45497","0.06201"
"36.50000","5.47001","0.06239"
"36.60000","5.48502","0.06268"
"36.70000","5.49996","0.06301"
"36.80000","5.51504","0.06318"
"36.90000","5.53005","0.06341"
"37.00000","5.54497","0.06345"
"37.10000","5.55995","0.06381"
"37.20000","5.57503","0.06400"
"37.30000","5.59011","0.06426"
"37.40000","5.60508","0.06447"
"37.50000","5.62126","0.06488"
"37.60000","5.63528","0.06503"
"37.70000","5.64997","0.06517"
"37.80000","5.66480","0.06538"
"37.90000","5.67976","0.06565"
"38.00000","5.69483","0.06585"
"38.10000","5.70995","0.06603"
"38.20000","5.72494","0.06625"
"38.30000","5.73999","0.06642"
"38.40000","5.75505","0.06650"
"38.50000","5.76999","0.06710"
"38.60000","5.78494","0.06731"
"38.70000","5.79998","0.06727"
"38.80000","5.81506","0.06772"
"38.90000","5.82997","0.06802"
"39.00000","5.84488","0.06797"
"39.10000","5.85995","0.06825"
"39.20000","5.87502","0.06860"
"39.30000","5.88992","0.06882"
"39.40000","5.90490","0.06907"
"39.50000","5.91997","0.06926"
"39.60000","5.93498","0.06942"
"39.70000","5.94992","0.06971"
"39.80000","5.96492","0.06998"
"39.90000","5.97999","0.07012"
"40.00000","5.99498","0.07030"
"40.10000","6.00996","0.07083"
"40.20000","6.02501","0.07089"
"40.30000","6.04006","0.07109"
"40.40000","6.05506","0.07140"
"40.50000","6.06999","0.07161"
"40.60000","6.08505","0.07188"
"40.70000","6.10013","0.07199"
"40.80000","6.11511","0.07236"
"40.90000","6.13156","0.07273"
"41.00000","6.14524","0.07276"
"41.10000","6.16009","0.07284"
"41.20000","6.17487","0.07338"
"41.30000","6.18989","0.07350"
"41.40000","6.20493","0.07366"
"41.50000","6.21993","0.07420"
"41.60000","6.23489","0.07423"
"41.70000","6.24990","0.07452"
"41.80000","6.26505","0.07484"
"41.90000","6.28001","0.07478"
"42.00000","6.29493","0.07504"
"42.10000","6.30994","0.07548"
"42.20000","6.32497","0.07553"
"42.30000","6.34000","0.07568"
"42.40000","6.35505","0.07591"
"42.50000","6.37006","0.07629"
"42.60000","6.38505","0.07667"
"42.70000","6.39997","0.07679"
"42.80000","6.41491","0.07695"
"42.90000","6.42998","0.07733"
"43.00000","6.44505","0.07731"
"43.10000","6.46002","0.07778"
"43.20000","6.47498","0.07779"
"43.30000","6.49004","0.07812"
"43.40000","6.50503","0.07843"
"43.50000","6.51993","0.07858"
"43.60000","6.53491","0.07880"
"43.70000","6.55001","0.07925"
"43.80000","6.56504","0.07947"
"43.90000","6.57988","0.07929"
"44.00000","6.59488","0.07974"
"44.10000","6.61002","0.08013"
"44.20000","6.62504","0.08041"
"44.30000","6.63996","0.08056"
"44.40000","6.65499","0.08097"
"44.50000","6.67005","0.08098"
"44.60000","6.68502","0.08131"
"44.70000","6.70000","0.08166"
"44.80000","6.71503","0.08180"
"44.90000","6.73010","0.08206"
"45.00000","6.74504","0.08231"
"45.10000","6.76000","0.08268"
"45.20000","6.77502","0.08291"
"45.30000","6.79007","0.08322"
"45.40000","6.80501","0.08322"
"45.50000","6.81994","0.08374"
"45.60000","6.83500","0.08367"
"45.70000","6.85003","0.08419"
"45.80000","6.86498","0.08440"
"45.90000","6.87996","0.08455"
"46.00000","6.89502","0.08492"
"46.10000","6.91003","0.08513"
"46.20000","6.92494","0.08529"
"46.30000","6.93998","0.08571"
"46.40000","6.95506","0.08595"
"46.50000","6.97006","0.08605"
"46.60000","6.98496","0.08623"
"46.70000","7.00172","0.08651"
"46.80000","7.01572","0.08680"
"46.90000","7.03010","0.08696"
"47.00000","7.04488","0.08714"
"47.10000","7.05981","0.08733"
"47.20000","7.07490","0.08769"
"47.30000","7.08987","0.08793"
"47.40000","7.10485","0.08813"
"47.50000","7.11990","0.08853"
"47.60000","7.13493","0.08859"
"47.70000","7.14984","0.08879"
"47.80000","7.16483","0.08910"
"47.90000","7.17988","0.08927"
"48.00000","7.19492","0.08935"
"48.10000","7.20982","0.08978"
"48.20000","7.22478","0.09000"
"48.30000","7.23990","0.09050"
"48.40000","7.25501","0.09071"
"48.50000","7.26994","0.09100"
"48.60000","7.28492","0.09125"
"48.70000","7.29999","0.09132"
"48.80000","7.31489","0.09146"
"48.90000","7.32990","0.09185"
"49.00000","7.34496","0.09223"
"49.10000","7.36006","0.09250"
"49.20000","7.37501","0.09264"
"49.30000","7.38996","0.09299"
"49.40000","7.40499","0.09319"
"49.50000","7.42002","0.09318"
"49.60000","7.43495","0.09377"
"49.70000","7.44988","0.09414"
"49.80000","7.46496","0.09397"
"49.90000","7.48000","0.09423"
"50.00000","7.49494","0.09467"
"50.10000","7.50991","0.09481"
"50.20000","7.52505","0.09534"
"50.30000","7.54005","0.09547"
"50.40000","7.55496","0.09542"
"50.50000","7.57099","0.09584"
"50.60000","7.58518","0.09598"
"50.70000","7.60005","0.09624"
"50.80000","7.61489","0.09668"
"50.90000","7.62992","0.09705"
"51.00000","7.64498","0.09674"
"51.10000","7.65991","0.09689"
"51.20000","7.67491","0.09747"
"51.30000","7.68993","0.09753"
"51.40000","7.70491","0.09767"
"51.50000","7.71987","0.09812"
"51.60000","7.73483","0.09841"
"51.70000","7.74986","0.09852"
"51.80000","7.76493","0.09889"
"51.90000","7.77985","0.09897"
"52.00000","7.79486","0.09930"
"52.10000","7.80991","0.09974"
"52.20000","7.82498","0.09994"
"52.30000","7.83983","0.09992"
"52.40000","7.85485","0.10045"
"52.50000","7.86992","0.10072"
"52.60000","7.88497","0.10070"
"52.70000","7.89991","0.10114"
"52.80000","7.91493","0.10157"
"52.90000","7.93009","0.10162"
"53.00000","7.94510","0.10173"
"53.10000","7.96098","0.10209"
"53.20000","7.97519","0.10252"
"53.30000","7.99007","0.10250"
"53.40000","8.00497","0.10287"
"53.50000","8.01987","0.10325"
"53.60000","8.03496","0.10313"
"53.70000","8.05008","0.10368"
"53.80000","8.06497","0.10404"
"53.90000","8.07987","0.10430"
"54.00000","8.09496","0.10429"
"54.10000","8.10995","0.10454"
"54.20000","8.12489","0.10468"
"54.30000","8.13985","0.10502"
"54.40000","8.15496","0.10532"
"54.50000","8.17003","0.10554"
"54.60000","8.18502","0.10576"
"54.70000","8.19999","0.10598"
"54.80000","8.21504","0.10608"
"54.90000","8.23001","0.10660"
"55.00000","8.24493","0.10673"
"55.10000","8.25996","0.10693"
"55.20000","8.27502","0.10723"
"55.30000","8.29000","0.10745"
"55.40000","8.30490","0.10787"
"55.50000","8.31995","0.10783"
"55.60000","8.33497","0.10806"
"55.70000","8.34992","0.10837"
"55.80000","8.36511","0.10875"
"55.90000","8.38007","0.10901"
"56.00000","8.39496","0.10902"
"56.10000","8.40989","0.10932"
"56.20000","8.42483","0.10960"
"56.30000","8.43988","0.10966"
"56.40000","8.45487","0.11005"
"56.50000","8.46980","0.11024"
"56.60000","8.48482","0.11049"
"56.70000","8.49993","0.11098"
"56.80000","8.51495","0.11111"
"56.90000","8.52987","0.11129"
"57.00000","8.54490","0.11142"
"57.10000","8.55997","0.11189"
"57.20000","8.57498","0.11185"
"57.30000","8.58995","0.11230"
"57.40000","8.60497","0.11261"
"57.50000","8.62008","0.11276"
"57.60000","8.63510","0.11303"
"57.70000","8.65004","0.11337"
"57.80000","8.66513","0.11339"
"57.90000","8.68156","0.11363"
"58.00000","8.69546","0.11405"
"58.10000","8.70991","0.11409"
"58.20000","8.72487","0.11438"
"58.30000","8.73992","0.11475"
"58.40000","8.75484","0.11505"
"58.50000","8.76988","0.11500"
"58.60000","8.78496","0.11551"
"58.70000","8.80000","0.11547"
"58.80000","8.81490","0.11555"
"58.90000","8.82994","0.11599"
"59.00000","8.84505","0.11628"
"59.10000","8.86002","0.11629"
"59.20000","8.87499","0.11658"
"59.30000","8.89000","0.11687"
"59.40000","8.90508","0.11692"
"59.50000","8.92009","0.11737"
"59.60000","8.93498","0.11765"
"59.70000","8.95000","0.11775"
"59.80000","8.96507","0.11793"
"59.90000","8.97999","0.11831"
"60.00000","8.99494","0.11850"
"60.10000","9.00998","0.11875"
"60.20000","9.02499","0.11891"
"60.30000","9.03986","0.11925"
"60.40000","9.05484","0.11937"
"60.50000","9.06995","0.11972"
"60.60000","9.08495","0.11986"
"60.70000","9.09991","0.12008"
"60.80000","9.11490","0.12034"
"60.90000","9.12995","0.12073"
"61.00000","9.14496","0.12071"
"61.10000","9.15990","0.12089"
"61.20000","9.17491","0.12134"
"61.30000","9.18998","0.12156"
"61.40000","9.20494","0.12182"
"61.50000","9.21991","0.12199"
"61.60000","9.23494","0.12233"
"61.70000","9.25108","0.12228"
"61.80000","9.26541","0.12246"
"61.90000","9.27991","0.12281"
"62.00000","9.29495","0.12305"
"62.10000","9.31000","0.12309"
"62.20000","9.32495","0.12354"
"62.30000","9.33994","0.12378"
"62.40000","9.35499","0.12367"
"62.50000","9.37000","0.12408"
"62.60000","9.38490","0.12422"
"62.70000","9.39985","0.12466"
"62.80000","9.41495","0.12452"
"62.90000","9.43000","0.12494"
"63.00000","9.44493","0.12519"
"63.10000","9.45996","0.12546"
"63.20000","9.47500","0.12543"
"63.30000","9.48995","0.12564"
"63.40000","9.50488","0.12579"
"63.50000","9.51989","0.12597"
"63.60000","9.53499","0.12624"
"63.70000","9.55000","0.12652"
"63.80000","9.56499","0.12664"
"63.90000","9.58002","0.12659"
"64.00000","9.59508","0.12693"
"64.10000","9.60998","0.12716"
"64.20000","9.62492","0.12720"
"64.30000","9.63999","0.12749"
"64.40000","9.65504","0.12787"
"64.50000","9.67110","0.12773"
"64.60000","9.68513","0.12806"
"64.70000","9.69994","0.12826"
"64.80000","9.71492","0.12811"
"64.90000","9.72984","0.12854"
"65.00000","9.74478","0.12890"
"65.10000","9.75990","0.12877"
"65.20000","9.77495","0.12899"
"65.30000","9.78987","0.12933"
"65.40000","9.80489","0.12957"
"65.50000","9.82000","0.12971"
"65.60000","9.83500","0.12990"
"65.70000","9.84992","0.13006"
"65.80000","9.86494","0.12997"
"65.90000","9.88002","0.13040"
"66.00000","9.89501","0.13064"
"66.10000","9.90996","0.13059"
"66.20000","9.92502","0.13105"
"66.30000","9.94005","0.13124"
"66.40000","9.95496","0.13126"
"66.50000","9.96996","0.13154"
"66.60000","9.98499","0.13171"
"66.70000","9.99998","0.13168"
"66.80000","10.01493","0.13187"
"66.90000","10.02989","0.13204"
"67.00000","10.04498","0.13216"
"67.10000","10.05996","0.13230"
"67.20000","10.07491","0.13257"
"67.30000","10.08989","0.13264"
"67.40000","10.10499","0.13276"
"67.50000","10.12000","0.13321"
"67.60000","10.13584","0.13322"
"67.70000","10.14997","0.13313"
"67.80000","10.16492","0.13341"
"67.90000","10.17988","0.13374"
"68.00000","10.19481","0.13364"
"68.10000","10.20987","0.13393"
"68.20000","10.22500","0.13419"
"68.30000","10.23996","0.13438"
"68.40000","10.25490","0.13425"
"68.50000","10.26995","0.13441"
"68.60000","10.28496","0.13455"
"68.70000","10.29990","0.13492"
"68.80000","10.31488","0.13519"
"68.90000","10.32993","0.13523"
"69.00000","10.34496","0.13520"
"69.10000","10.35992","0.13541"
"69.20000","10.37492","0.13550"
"69.30000","10.39001","0.13563"
"69.40000","10.40501","0.13585"
"69.50000","10.41995","0.13579"
"69.60000","10.43493","0.13603"
"69.70000","10.45005","0.13637"
"69.80000","10.46504","0.13660"
"69.90000","10.47997","0.13643"
"70.00000","10.49572","0.13645"
"70.10000","10.51023","0.13664"
"70.20000","10.52495","0.13681"
"70.30000","10.53991","0.13681"
"70.40000","10.55499","0.13718"
"70.50000","10.57006","0.13723"
"70.60000","10.58499","0.13722"
"70.70000","10.59994","0.13715"
"70.80000","10.61501","0.13731"
"70.90000","10.63006","0.13766"
"71.00000","10.64501","0.13778"
"71.10000","10.65995","0.13758"
"71.20000","10.67500","0.13775"
"71.30000","10.69004","0.13802"
"71.40000","10.70510","0.13784"
"71.50000","10.71993","0.13815"
"71.60000","10.73514","0.13813"
"71.70000","10.75017","0.13832"
"71.80000","10.76482","0.13837"
"71.90000","10.77982","0.13866"
"72.00000","10.79492","0.13840"
"72.10000","10.80997","0.13874"
"72.20000","10.82493","0.13901"
"72.30000","10.83997","0.13893"
"72.40000","10.85499","0.13881"
"72.50000","10.86999","0.13898"
"72.60000","10.88494","0.13915"
"72.70000","10.89998","0.13895"
"72.80000","10.91502","0.13931"
"72.90000","10.92994","0.13920"
"73.00000","10.94487","0.13925"
"73.10000","10.96001","0.13926"
"73.20000","10.97507","0.13971"
"73.30000","10.99001","0.13943"
"73.40000","11.00495","0.13934"
"73.50000","11.02002","0.13940"
"73.60000","11.03499","0.13945"
"73.70000","11.04996","0.13944"
"73.80000","11.06500","0.13965"
"73.90000","11.08009","0.13961"
"74.00000","11.09508","0.13944"
"74.10000","11.11004","0.13951"
"74.20000","11.12509","0.13938"
"74.30000","11.14017","0.13954"
"74.40000","11.15511","0.13939"
"74.50000","11.17000","0.13934"
"74.60000","11.18502","0.13923"
"74.70000","11.20008","0.13952"
"74.80000","11.21503","0.13941"
"74.90000","11.23002","0.13939"
"75.00000","11.24508","0.13943"
"75.10000","11.26022","0.13952"
"75.20000","11.27668","0.13935"
"75.30000","11.29058","0.13938"
"75.40000","11.30504","0.13931"
"75.50000","11.31991","0.13884"
"75.60000","11.33480","0.13915"
"75.70000","11.34984","0.13916"
"75.80000","11.36491","0.13904"
"75.90000","11.37994","0.13891"
"76.00000","11.39486","0.13913"
"76.10000","11.40985","0.13890"
"76.20000","11.42498","0.13908"
"76.30000","11.43997","0.13907"
"76.40000","11.45490","0.13907"
"76.50000","11.46988","0.13902"
"76.60000","11.48501","0.13903"
"76.70000","11.50023","0.13928"
"76.80000","11.51481","0.13902"
"76.90000","11.52983","0.13933"
"77.00000","11.54492","0.13939"
"77.10000","11.55986","0.13925"
"77.20000","11.57479","0.13913"
"77.30000","11.58993","0.13913"
"77.40000","11.60499","0.13920"
"77.50000","11.61992","0.13936"
"77.60000","11.63489","0.13939"
"77.70000","11.64998","0.13950"
"77.80000","11.66502","0.13941"
"77.90000","11.67999","0.13943"
"78.00000","11.69540","0.13912"
"78.10000","11.70998","0.13905"
"78.20000","11.72492","0.13924"
"78.30000","11.73988","0.13900"
"78.40000","11.75491","0.13910"
"78.50000","11.77001","0.13911"
"78.60000","11.78498","0.13923"
"78.70000","11.79990","0.13889"
"78.80000","11.81496","0.13908"
"78.90000","11.83013","0.13896"
"79.00000","11.84500","0.13896"
"79.10000","11.85997","0.13895"
"79.20000","11.87499","0.13895"
"79.30000","11.89000","0.13891"
"79.40000","11.90493","0.13915"
"79.50000","11.91990","0.13903"
"79.60000","11.93495","0.13898"
"79.70000","11.94995","0.13900"
"79.80000","11.96481","0.13901"
"79.90000","11.97979","0.13888"
"80.00000","11.99494","0.13894"
"80.10000","12.01000","0.13901"
"80.20000","12.02498","0.13889"
"80.30000","12.03994","0.13917"
"80.40000","12.05502","0.13922"
"80.50000","12.06999","0.13903"
"80.60000","12.08493","0.13884"
"80.70000","12.09995","0.13935"
"80.80000","12.11505","0.13919"
"80.90000","12.13004","0.13909"
"81.00000","12.14501","0.13915"
"81.10000","12.16012","0.13910"
"81.20000","12.17689","0.13907"
"81.30000","12.19024","0.13910"
"81.40000","12.20489","0.13912"
"81.50000","12.21986","0.13920"
"81.60000","12.23483","0.13887"
"81.70000","12.24975","0.13887"
"81.80000","12.26474","0.13906"
"81.90000","12.27988","0.13881"
"82.00000","12.29493","0.13917"
"82.10000","12.30982","0.13891"
"82.20000","12.32483","0.13902"
"82.30000","12.33993","0.13910"
"82.40000","12.35494","0.13911"
"82.50000","12.36988","0.13898"
"82.60000","12.38487","0.13891"
"82.70000","12.39995","0.13896"
"82.80000","12.41489","0.13911"
"82.90000","12.42991","0.13890"
"83.00000","12.44500","0.13894"
"83.10000","12.46005","0.13905"
"83.20000","12.47499","0.13888"
"83.30000","12.48992","0.13878"
"83.40000","12.50496","0.13879"
"83.50000","12.52004","0.13899"
"83.60000","12.53502","0.13875"
"83.70000","12.55059","0.13881"
"83.80000","12.56503","0.13869"
"83.90000","12.57988","0.13879"
"84.00000","12.59483","0.13856"
"84.10000","12.60984","0.13870"
"84.20000","12.62494","0.13890"
"84.30000","12.63997","0.13867"
"84.40000","12.65489","0.13862"
"84.50000","12.66989","0.13875"
"84.60000","12.68501","0.13896"
"84.70000","12.70001","0.13865"
"84.80000","12.71496","0.13879"
"84.90000","12.72996","0.13874"
"85.00000","12.74505","0.13884"
"85.10000","12.76004","0.13874"
"85.20000","12.77498","0.13883"
"85.30000","12.79004","0.13877"
"85.40000","12.80508","0.13902"
"85.50000","12.81999","0.13875"
"85.60000","12.83497","0.13897"
"85.70000","12.85000","0.13898"
"85.80000","12.86500","0.13882"
"85.90000","12.88009","0.13896"
"86.00000","12.89516","0.13915"
"86.10000","12.90996","0.13888"
"86.20000","12.92494","0.13896"
"86.30000","12.93987","0.13889"
"86.40000","12.95492","0.13871"
"86.50000","12.97007","0.13902"
"86.60000","12.98504","0.13895"
"86.70000","12.99992","0.13905"
"86.80000","13.01489","0.13902"
"86.90000","13.03000","0.13880"
"87.00000","13.04503","0.13899"
"87.10000","13.05995","0.13906"
"87.20000","13.07500","0.13894"
"87.30000","13.09006","0.13888"
"87.40000","13.10497","0.13878"
"87.50000","13.11997","0.13890"
"87.60000","13.13500","0.13900"
"87.70000","13.15006","0.13905"
"87.80000","13.16497","0.13892"
"87.90000","13.17993","0.13889"
"88.00000","13.19509","0.13917"
"88.10000","13.21024","0.13893"
"88.20000","13.22494","0.13911"
"88.30000","13.23986","0.13916"
"88.40000","13.25495","0.13914"
"88.50000","13.27001","0.13919"
"88.60000","13.28494","0.13925"
"88.70000","13.29990","0.13926"
"88.80000","13.31500","0.13905"
"88.90000","13.32998","0.13910"
"89.00000","13.34495","0.13925"
"89.10000","13.36000","0.13934"
"89.20000","13.37508","0.13934"
"89.30000","13.39010","0.13935"
"89.40000","13.40510","0.13933"
"89.50000","13.42013","0.13940"
"89.60000","13.43512","0.13932"
"89.70000","13.45009","0.13928"
"89.80000","13.46502","0.13896"
"89.90000","13.48002","0.13898"
"90.00000","13.49499","0.13896"
"90.10000","13.50993","0.13923"
"90.20000","13.52487","0.13886"
"90.30000","13.53994","0.13879"
"90.40000","13.55494","0.13904"
"90.50000","13.56988","0.13875"
"90.60000","13.58489","0.13873"
"90.70000","13.59997","0.13907"
"90.80000","13.61497","0.13880"
"90.90000","13.63004","0.13839"
"91.00000","13.64594","0.13885"
"91.10000","13.66009","0.13879"
"91.20000","13.67492","0.13850"
"91.30000","13.68979","0.13862"
"91.40000","13.70484","0.13861"
"91.50000","13.71993","0.13863"
"91.60000","13.73499","0.13865"
"91.70000","13.74996","0.13894"
"91.80000","13.76500","0.13853"
"91.90000","13.78001","0.13837"
"92.00000","13.79495","0.13879"
"92.10000","13.80989","0.13860"
"92.20000","13.82495","0.13830"
"92.30000","13.84002","0.13851"
"92.40000","13.85496","0.13837"
"92.50000","13.87005","0.13845"
"92.60000","13.88495","0.13845"
"92.70000","13.89993","0.13816"
"92.80000","13.91490","0.13813"
"92.90000","13.92988","0.13853"
"93.00000","13.94495","0.13827"
"93.10000","13.95994","0.13804"
"93.20000","13.97490","0.13815"
"93.30000","13.98996","0.13825"
"93.40000","14.00508","0.13819"
"93.50000","14.02009","0.13835"
"93.60000","14.03505","0.13831"
"93.70000","14.05004","0.13801"
"93.80000","14.06510","0.13830"
"93.90000","14.07998","0.13835"
"94.00000","14.09502","0.13825"
"94.10000","14.10999","0.13818"
"94.20000","14.12503","0.13831"
"94.30000","14.13998","0.13844"
"94.40000","14.15496","0.13846"
"94.50000","14.17000","0.13826"
"94.60000","14.18499","0.13808"
"94.70000","14.19990","0.13800"
"94.80000","14.21679","0.13823"
"94.90000","14.23033","0.13810"
"95.00000","14.24494","0.13827"
"95.10000","14.25973","0.13807"
"95.20000","14.27474","0.13798"
"95.30000","14.28987","0.13829"
"95.40000","14.30490","0.13801"
"95.50000","14.31987","0.13816"
"95.60000","14.33497","0.13822"
"95.70000","14.35000","0.13809"
"95.80000","14.36491","0.13811"
"95.90000","14.37992","0.13826"
"96.00000","14.39494","0.13820"
"96.10000","14.41001","0.13804"
"96.20000","14.42498","0.13830"
"96.30000","14.43989","0.13844"
"96.40000","14.45498","0.13822"
"96.50000","14.47002","0.13842"
"96.60000","14.48496","0.13865"
"96.70000","14.49994","0.13850"
"96.80000","14.51505","0.13859"
"96.90000","14.52999","0.13885"
"97.00000","14.54490","0.13857"
"97.10000","14.55994","0.13870"
"97.20000","14.57504","0.13894"
"97.30000","14.59007","0.13880"
"97.40000","14.60499","0.13893"
"97.50000","14.62004","0.13909"
"97.60000","14.63512","0.13885"
"97.70000","14.65042","0.13915"
"97.80000","14.66507","0.13938"
"97.90000","14.68003","0.13907"
"98.00000","14.69512","0.13897"
"98.10000","14.71007","0.13925"
"98.20000","14.72499","0.13931"
"98.30000","14.73999","0.13930"
"98.40000","14.75501","0.13951"
"98.50000","14.76991","0.13958"
"98.60000","14.78488","0.13935"
"98.70000","14.79998","0.13977"
"98.80000","14.81497","0.13969"
"98.90000","14.82986","0.13958"
"99.00000","14.84485","0.13975"
"99.10000","14.85996","0.13974"
"99.20000","14.87495","0.13980"
"99.30000","14.88989","0.13992"
"99.40000","14.90488","0.14003"
"99.50000","14.91999","0.13978"
"99.60000","14.93498","0.14006"
"99.70000","14.95001","0.14018"
"99.80000","14.96498","0.14038"
"99.90000","14.98005","0.14008"
"100.00000","14.99499","0.14039"
"100.10000","15.00995","0.14046"
"100.20000","15.02499","0.14057"
"100.30000","15.04003","0.14080"
"100.40000","15.05494","0.14062"
"100.50000","15.06992","0.14055"
"100.60000","15.08497","0.14072"
"100.70000","15.10001","0.14094"
"100.80000","15.11496","0.14082"
"100.90000","15.12995","0.14101"
"101.00000","15.14506","0.14083"
"101.10000","15.16013","0.14102"
"101.20000","15.17505","0.14103"
"101.30000","15.19030","0.14119"
"101.40000","15.20516","0.14108"
"101.50000","15.22014","0.14143"
"101.60000","15.23555","0.14134"
"101.70000","15.25063","0.14140"
"101.80000","15.26514","0.14144"
"101.90000","15.27999","0.14158"
"102.00000","15.29496","0.14144"
"102.10000","15.31000","0.14155"
"102.20000","15.32509","0.14155"
"102.30000","15.34003","0.14169"
"102.40000","15.35497","0.14197"
"102.50000","15.37000","0.14183"
"102.60000","15.38509","0.14190"
"102.70000","15.40001","0.14222"
"102.80000","15.41496","0.14202"
"102.90000","15.43004","0.14194"
"103.00000","15.44511","0.14247"
"103.10000","15.45993","0.14222"
"103.20000","15.47484","0.14214"
"103.30000","15.48993","0.14233"
"103.40000","15.50489","0.14243"
"103.50000","15.51984","0.14211"
"103.60000","15.53484","0.14244"
"103.70000","15.54993","0.14241"
"103.80000","15.56500","0.14227"
"103.90000","15.57996","0.14239"
"104.00000","15.59496","0.14242"
"104.10000","15.61004","0.14218"
"104.20000","15.62493","0.14218"
"104.30000","15.63990","0.14239"
"104.40000","15.65499","0.14239"
"104.50000","15.67025","0.14258"
"104.60000","15.68505","0.14262"
"104.70000","15.69991","0.14257"
"104.80000","15.71500","0.14270"
"104.90000","15.73003","0.14282"
"105.00000","15.74493","0.14288"
"105.10000","15.75996","0.14287"
"105.20000","15.77504","0.14290"
"105.30000","15.79002","0.14275"
"105.40000","15.80496","0.14301"
"105.50000","15.81996","0.14295"
"105.60000","15.83509","0.14298"
"105.70000","15.85005","0.14317"
"105.80000","15.86499","0.14311"
"105.90000","15.88001","0.14310"
"106.00000","15.89507","0.14327"
"106.10000","15.91004","0.14332"
"106.20000","15.92501","0.14342"
"106.30000","15.94003","0.14339"
"106.40000","15.95511","0.14338"
"106.50000","15.97006","0.14348"
"106.60000","15.98503","0.14366"
"106.70000","16.00178","0.14348"
"106.80000","16.01528","0.14368"
"106.90000","16.02987","0.14360"
"107.00000","16.04478","0.14364"
"107.10000","16.05988","0.14357"
"107.20000","16.07495","0.14368"
"107.30000","16.08988","0.14384"
"107.40000","16.10483","0.14359"
"107.50000","16.12002","0.14374"
"107.60000","16.13495","0.14388"
"107.70000","16.14987","0.14385"
"107.80000","16.16484","0.14376"
"107.90000","16.17991","0.14400"
"108.00000","16.19494","0.14379"
"108.10000","16.20979","0.14382"
"108.20000","16.22486","0.14395"
"108.30000","16.24000","0.14394"
"108.40000","16.25500","0.14368"
"108.50000","16.26995","0.14366"
"108.60000","16.28499","0.14350"
"108.70000","16.30002","0.14332"
"108.80000","16.31497","0.14371"
"108.90000","16.32995","0.14333"
"109.00000","16.34500","0.14293"
"109.10000","16.36004","0.14296"
"109.20000","16.37496","0.14300"
"109.30000","16.38995","0.14248"
"109.40000","16.40502","0.14270"
"109.50000","16.42003","0.14268"
"109.60000","16.43495","0.14243"
"109.70000","16.44999","0.14244"
"109.80000","16.46507","0.14272"
"109.90000","16.48005","0.14222"
"110.00000","16.49501","0.14212"
"110.10000","16.51001","0.14249"
"110.20000","16.52512","0.14227"
"110.30000","16.54008","0.14224"
"110.40000","16.55504","0.14237"
"110.50000","16.57084","0.14244"
"110.60000","16.58576","0.14215"
"110.70000","16.60004","0.14219"
"110.80000","16.61489","0.14222"
"110.90000","16.62988","0.14226"
"111.00000","16.64494","0.14215"
"111.10000","16.65991","0.14227"
"111.20000","16.67488","0.14219"
"111.30000","16.68995","0.14210"
"111.40000","16.70496","0.14205"
"111.50000","16.71991","0.14224"
"111.60000","16.73485","0.14215"
"111.70000","16.74991","0.14218"
"111.80000","16.76495","0.14211"
"111.90000","16.77984","0.14187"
"112.00000","16.79487","0.14226"
"112.10000","16.80996","0.14216"
"112.20000","16.82494","0.14216"
"112.30000","16.83988","0.14234"
"112.40000","16.85487","0.14244"
"112.50000","16.86995","0.14210"
"112.60000","16.88489","0.14231"
"112.70000","16.89985","0.14243"
"112.80000","16.91492","0.14232"
"112.90000","16.92999","0.14228"
"113.00000","16.94492","0.14238"
"113.10000","16.95986","0.14222"
"113.20000","16.97492","0.14224"
"113.30000","16.98996","0.14241"
"113.40000","17.00491","0.14225"
"113.50000","17.01990","0.14221"
"113.60000","17.03499","0.14213"
"113.70000","17.05004","0.14193"
"113.80000","17.06496","0.14182"
"113.90000","17.08017","0.14189"
"114.00000","17.09600","0.14150"
"114.10000","17.11005","0.14109"
"114.20000","17.12483","0.14075"
"114.30000","17.13978","0.14005"
"114.40000","17.15495","0.13958"
"114.50000","17.16998","0.13947"
"114.60000","17.18490","0.13884"
"114.70000","17.19994","0.13775"
"114.80000","17.21507","0.13746"
"114.90000","17.23001","0.13688"
"115.00000","17.24499","0.13622"
"115.10000","17.26002","0.13570"
"115.20000","17.27507","0.13559"
"115.30000","17.28995","0.13469"
"115.40000","17.30495","0.13446"
"115.50000","17.32004","0.13428"
"115.60000","17.33507","0.13331"
"115.70000","17.34993","0.13291"
"115.80000","17.36484","0.13263"
"115.90000","17.37990","0.13221"
"116.00000","17.39488","0.13175"
"116.10000","17.40981","0.13149"
"116.20000","17.42486","0.13108"
"116.30000","17.44000","0.13060"
"116.40000","17.45497","0.13018"
"116.50000","17.46987","0.12937"
"116.60000","17.48487","0.12854"
"116.70000","17.50001","0.12809"
"116.80000","17.51498","0.12736"
"116.90000","17.52990","0.12658"
"117.00000","17.54500","0.12572"
"117.10000","17.56027","0.12506"
"117.20000","17.57506","0.12404"
"117.30000","17.58990","0.12258"
"117.40000","17.60492","0.12146"
"117.50000","17.62008","0.11994"
"117.60000","17.63501","0.11569"
"117.70000","17.64986","0.11387"
"117.80000","17.66500","0.11229"
"117.90000","17.68004","0.11069"
"118.00000","17.69495","0.10979"
"118.10000","17.70992","0.10860"
"118.20000","17.72506","0.10763"
"118.30000","17.74003","0.10690"
"118.40000","17.75497","0.10550"
"118.50000","17.76999","0.10421"
"118.60000","17.78510","0.10328"
"118.70000","17.80005","0.10241"
"118.80000","17.81501","0.10161"
"118.90000","17.83005","0.10098"
"119.00000","17.84513","0.10003"
"119.10000","17.86012","0.09948"
"119.20000","17.87508","0.09896"
"119.30000","17.89011","0.09844"
"119.40000","17.90514","0.09783"
"119.50000","17.92014","0.09778"
"119.60000","17.93528","0.09728"
"119.70000","17.95016","0.09704"
"119.80000","17.96509","0.09642"
"119.90000","17.97997","0.09622"
"120.00000","17.99492","0.09568"
"120.10000","18.01003","0.09562"
"120.20000","18.02503","0.09531"
"120.30000","18.03991","0.09483"
"120.40000","18.05485","0.09459"
"120.50000","18.06994","0.09405"
"120.60000","18.08493","0.09358"
"120.70000","18.09990","0.09252"
"120.80000","18.11490","0.09183"
"120.90000","18.13005","0.09023"
"121.00000","18.14499","0.08803"
"121.10000","18.15995","0.08697"
"121.20000","18.17496","0.08636"
"121.30000","18.19001","0.08557"
"121.40000","18.20500","0.08488"
"121.50000","18.21997","0.08436"
"121.60000","18.23504","0.08385"
"121.70000","18.25009","0.08330"
"121.80000","18.26522","0.08266"
"121.90000","18.28127","0.08231"
"122.00000","18.29523","0.08202"
"122.10000","18.30997","0.08147"
"122.20000","18.32482","0.08077"
"122.30000","18.33977","0.08025"
"122.40000","18.35485","0.07982"
"122.50000","18.36991","0.07968"
"122.60000","18.38489","0.07888"
"122.70000","18.39991","0.07836"
"122.80000","18.41500","0.07788"
"122.90000","18.42997","0.07744"
"123.00000","18.44487","0.07688"
"123.10000","18.45996","0.07646"
"123.20000","18.47506","0.07591"
"123.30000","18.49000","0.07558"
"123.40000","18.50499","0.07517"
"123.50000","18.52001","0.07433"
"123.60000","18.53510","0.07406"
"123.70000","18.54998","0.07329"
"123.80000","18.56492","0.07297"
"123.90000","18.57996","0.07252"
"124.00000","18.59499","0.07213"
"124.10000","18.60987","0.07150"
"124.20000","18.62478","0.07105"
"124.30000","18.63988","0.07048"
"124.40000","18.65491","0.06985"
"124.50000","18.66982","0.06875"
"124.60000","18.68479","0.06763"
"124.70000","18.69990","0.06661"
"124.80000","18.71494","0.06529"
"124.90000","18.72989","0.06155"
"125.00000","18.74491","0.05942"
"125.10000","18.75999","0.05681"
"125.20000","18.77492","0.05358"
"125.30000","18.78992","0.05069"
"125.40000","18.80500","0.04789"
"125.50000","18.82003","0.04501"
"125.60000","18.83503","0.04151"
"125.70000","18.84997","0.03823"
"125.80000","18.86494","0.03251"
"125.90000","18.87996","0.02766"
"126.00000","18.89491","0.02347"
"126.10000","18.90991","0.01892"
"126.20000","18.92498","0.01448"
"126.30000","18.94002","0.00956"
"126.40000","18.95495","-0.00758"
"126.50000","18.96998","-0.01313"
"126.60000","18.98606","-0.01821"
"126.70000","19.00040","-0.02620"
"126.80000","19.01486","-0.02559"
"126.90000","19.02980","-0.02606"
"127.00000","19.04490","-0.02576"
"127.10000","19.05990","-0.02595"
"127.20000","19.07491","-0.02580"
"127.30000","19.08998","-0.02601"
"127.40000","19.10505","-0.02593"
"127.50000","19.12002","-0.02610"
"127.60000","19.13503","-0.02589"
"127.70000","19.15004","-0.02597"
"127.80000","19.16509","-0.02615"
"127.90000","19.17999","-0.02590"
"128.00000","19.19493","-0.02597"
"128.10000","19.21001","-0.02583"
"128.20000","19.22501","-0.02577"
"128.30000","19.23989","-0.02597"
"128.40000","19.25481","-0.02584"
"128.50000","19.26997","-0.02557"
"128.60000","19.28491","-0.02579"
"128.70000","19.29988","-0.02586"
"128.80000","19.31501","-0.02585"
"128.90000","19.33009","-0.02577"
"129.00000","19.34500","-0.02580"
"129.10000","19.35983","-0.02571"
"129.20000","19.37494","-0.02598"
"129.30000","19.38989","-0.02598"
"129.40000","19.40506","-0.02554"
"129.50000","19.41989","-0.02583"
"129.60000","19.43495","-0.02586"
"129.70000","19.45002","-0.02582"
"129.80000","19.46492","-0.02604"
"129.90000","19.47982","-0.02575"
"130.00000","19.49520","-0.02564"
"130.10000","19.50998","-0.02553"
"130.20000","19.52509","-0.02584"
"130.30000","19.53992","-0.02581"
"130.40000","19.55501","-0.02597"
"130.50000","19.57004","-0.02592"
"130.60000","19.58499","-0.02576"
"130.70000","19.59999","-0.02592"
"130.80000","19.61500","-0.02598"
"130.90000","19.63011","-0.02582"
"131.00000","19.64499","-0.02583"
"131.10000","19.66011","-0.02606"
"131.20000","19.67515","-0.02593"
"131.30000","19.69136","-0.02580"
"131.40000","19.70500","-0.02613"
"131.50000","19.71984","-0.02594"
"131.60000","19.73508","-0.02587"
"131.70000","19.74992","-0.02567"
"131.80000","19.76495","-0.02602"
"131.90000","19.77997","-0.02601"
"132.00000","19.79503","-0.02590"
"132.10000","19.81010","-0.02587"
"132.20000","19.82506","-0.02593"
"132.30000","19.84009","-0.02593"
"132.40000","19.85501","-0.02591"
"132.50000","19.86994","-0.02586"
"132.60000","19.88492","-0.02569"
"132.70000","19.89997","-0.02606"
"132.80000","19.91503","-0.02575"
"132.90000","19.92991","-0.02578"
"133.00000","19.94482","-0.02579"
"133.10000","19.95987","-0.02590"
"133.20000","19.97494","-0.02577"
"133.30000","19.98990","-0.02575"
"133.40000","20.00490","-0.02572"
"133.50000","20.01999","-0.02575"
"133.60000","20.03496","-0.02574"
"133.70000","20.04997","-0.02566"
"133.80000","20.06501","-0.02574"
"133.90000","20.08004","-0.02577"
"134.00000","20.09492","-0.02578"
"134.10000","20.10995","-0.02563"
"134.20000","20.12500","-0.02581"
"134.30000","20.14008","-0.02568"
"134.40000","20.15499","-0.02587"
"134.50000","20.17002","-0.02577"
"134.60000","20.18509","-0.02578"
"134.70000","20.20018","-0.02578"
"134.80000","20.21503","-0.02597"
"134.90000","20.22995","-0.02578"
"135.00000","20.24501","-0.02563"
"135.10000","20.25999","-0.02598"
"135.20000","20.27497","-0.02585"
"135.28900","20.28835","-0.02571"